Workbook

Sheet 工作表1
B2: 台羅拼音帶調字符表[1]
B3: 字母、陰平（一聲） | D3: 陰上（二聲） | E3: 陰去（三聲） | F3: 陰入（四聲） | G3: 陽平（五聲） | H3: 陽上（六聲） | I3: 陽去（七聲） | J3: 陽入（八聲） | K3: （九聲）
B4: 組合附加符號 | D4: ́ (U+0301) | E4: ̀ (U+0300) | F4: h | G4: ̂ (U+0302) | H4: ̌ (U+030C) | I4: ̄ (U+0304) | J4: ̍h (U+030D) | K4: ̋ (U+030B)
B5: 大寫 | C5: A | D5: Á (U+00C1) | E5: À (U+00C0) | F5: AH | G5: Â (U+00C2) | H5: Ǎ (U+01CD) | I5: Ā (U+0100) | J5: A̍H (U+0041 U+030D) | K5: A̋ (U+0041 U+030B)
C6: E | D6: É (U+00C9) | E6: È (U+00C8) | F6: EH | G6: Ê (U+00CA) | H6: Ě (U+011A) | I6: Ē (U+0112) | J6: E̍H (U+0045 U+030D) | K6: E̋ (U+0045 U+030B)
C7: I | D7: Í (U+00CD) | E7: Ì (U+00CC) | F7: IH | G7: Î (U+00CE) | H7: Ǐ (U+01CF) | I7: Ī (U+012A) | J7: I̍H (U+0049 U+030D) | K7: I̋ (U+0049 U+030B)
C8: O | D8: Ó (U+00D3) | E8: Ò (U+00D2) | F8: OH | G8: Ô (U+00D4) | H8: Ǒ (U+01D1) | I8: Ō (U+014C) | J8: O̍H (U+004F U+030D) | K8: Ő (U+0150)
C9: U | D9: Ú (U+00DA) | E9: Ù (U+00D9) | F9: UH | G9: Û (U+00DB) | H9: Ǔ (U+01D3) | I9: Ū (U+016A) | J9: U̍H (U+0055 U+030D) | K9: Ű (U+0170)
C10: M | D10: Ḿ (U+1E3E) | E10: M̀ (U+004D U+0300) | F10: MH | G10: M̂ (U+004D U+0302) | H10: M̌ (U+004D U+030C) | I10: M̄ (U+004D U+0304) | J10: M̍H (U+004D U+030D) | K10: M̋ (U+004D U+030B)
C11: N | D11: Ń (U+0143) | E11: Ǹ (U+01F8) | F11: NH | G11: N̂ (U+004E U+0302) | H11: Ň (U+0147) | I11: N̄ (U+004E U+0304) | J11: N̍H (U+004E U+030D) | K11: N̋ (U+004E U+030B)
B12: 小寫 | C12: a | D12: á (U+00E1) | E12: à (U+00E0) | F12: ah | G12: â (U+00E2) | H12: ǎ (U+01CE) | I12: ā (U+0101) | J12: a̍h (U+0061 U+030D) | K12: a̋ (U+0061 U+030B)
C13: e | D13: é (U+00E9) | E13: è (U+00E8) | F13: eh | G13: ê (U+00EA) | H13: ě (U+011B) | I13: ē (U+0113) | J13: e̍h (U+0065 U+030D) | K13: e̋ (U+0065 U+030B)
C14: i | D14: í (U+00ED) | E14: ì (U+00EC) | F14: ih | G14: î (U+00EE) | H14: ǐ (U+01D0) | I14: ī (U+012B) | J14: i̍h (U+0069 U+030D) | K14: i̋ (U+0069 U+030B)
C15: o | D15: ó (U+00F3) | E15: ò (U+00F2) | F15: oh | G15: ô (U+00F4) | H15: ǒ (U+01D2) | I15: ō (U+014D) | J15: o̍h (U+006F U+030D) | K15: ő (U+0151)
C16: u | D16: ú (U+00FA) | E16: ù (U+00F9) | F16: uh | G16: û (U+00FB) | H16: ǔ (U+01D4) | I16: ū (U+016B) | J16: u̍h (U+0075 U+030D) | K16: ű (U+0171)
C17: m | D17: ḿ (U+1E3F) | E17: m̀ (U+006D U+0300) | F17: mh | G17: m̂ (U+006D U+0302) | H17: m̌ (U+006D U+030C) | I17: m̄ (U+006D U+0304) | J17: m̍h (U+006D U+030D) | K17: m̋ (U+006D U+030B)
C18: n | D18: ń (U+0144) | E18: ǹ (U+01F9) | F18: nh | G18: n̂ (U+006E U+0302) | H18: ň (U+0148) | I18: n̄ (U+006E U+0304) | J18: n̍h (U+006E U+030D) | K18: n̋ (U+006E U+030B)
A21: =ROW() - 21 -> 0 | B21: =ROUNDDOWN( A21/9, 0) -> 0 | C21: 1 | D21: =LEFT(H21) -> A | E21: ="""" & D21 & """" & ": (" & """" & F21 & """, " & """" & C21 & """" & ")," -> "A": ("A", "1"), | F21: {=INDIRECT( ADDRESS( ROW($21:$21), COLUMN($D:$D)))} -> A | H21: {=INDIRECT(K21)} -> A | I21: {=COLUMN($C:$C)} -> 3 | J21: {=ROW($5:$5) + B21} -> 5 | K21: =ADDRESS(J21, I21,4) -> C5
A22: =ROW() - 21 -> 1 | B22: =ROUNDDOWN( A22/9, 0) -> 0 | C22: 2 | D22: =LEFT(H22) -> Á | E22: ="""" & D22 & """" & ": (" & """" & F22 & """, " & """" & C22 & """" & ")," -> "Á": ("A", "2"), | F22: {=INDIRECT( ADDRESS( ROW($21:$21), COLUMN($D:$D)))} -> A | H22: {=INDIRECT(K22)} -> Á (U+00C1) | I22: =C22 - 1 +$I$21 -> 4 | J22: {=ROW($5:$5) + B22} -> 5 | K22: =ADDRESS(J22, I22,4) -> D5
A23: =ROW() - 21 -> 2 | B23: =ROUNDDOWN( A23/9, 0) -> 0 | C23: 3 | D23: =LEFT(H23) -> À | E23: ="""" & D23 & """" & ": (" & """" & F23 & """, " & """" & C23 & """" & ")," -> "À": ("A", "3"), | F23: {=INDIRECT( ADDRESS( ROW($21:$21), COLUMN($D:$D)))} -> A | H23: {=INDIRECT(K23)} -> À (U+00C0) | I23: =C23 - 1 +$I$21 -> 5 | J23: {=ROW($5:$5) + B23} -> 5 | K23: =ADDRESS(J23, I23,4) -> E5
A24: =ROW() - 21 -> 3 | B24: =ROUNDDOWN( A24/9, 0) -> 0 | C24: 4 | D24: =LEFT(H24) -> A | E24: ="""" & D24 & """" & ": (" & """" & F24 & """, " & """" & C24 & """" & ")," -> "A": ("A", "4"), | F24: {=INDIRECT( ADDRESS( ROW($21:$21), COLUMN($D:$D)))} -> A | H24: {=INDIRECT(K24)} -> AH | I24: =C24 - 1 +$I$21 -> 6 | J24: {=ROW($5:$5) + B24} -> 5 | K24: =ADDRESS(J24, I24,4) -> F5
A25: =ROW() - 21 -> 4 | B25: =ROUNDDOWN( A25/9, 0) -> 0 | C25: 5 | D25: =LEFT(H25) -> Â | E25: ="""" & D25 & """" & ": (" & """" & F25 & """, " & """" & C25 & """" & ")," -> "Â": ("A", "5"), | F25: {=INDIRECT( ADDRESS( ROW($21:$21), COLUMN($D:$D)))} -> A | H25: {=INDIRECT(K25)} -> Â (U+00C2) | I25: =C25 - 1 +$I$21 -> 7 | J25: {=ROW($5:$5) + B25} -> 5 | K25: =ADDRESS(J25, I25,4) -> G5
A26: =ROW() - 21 -> 5 | B26: =ROUNDDOWN( A26/9, 0) -> 0 | C26: 6 | D26: =LEFT(H26) -> Ǎ | E26: ="""" & D26 & """" & ": (" & """" & F26 & """, " & """" & C26 & """" & ")," -> "Ǎ": ("A", "6"), | F26: {=INDIRECT( ADDRESS( ROW($21:$21), COLUMN($D:$D)))} -> A | H26: {=INDIRECT(K26)} -> Ǎ (U+01CD) | I26: =C26 - 1 +$I$21 -> 8 | J26: {=ROW($5:$5) + B26} -> 5 | K26: =ADDRESS(J26, I26,4) -> H5
A27: =ROW() - 21 -> 6 | B27: =ROUNDDOWN( A27/9, 0) -> 0 | C27: 7 | D27: =LEFT(H27) -> Ā | E27: ="""" & D27 & """" & ": (" & """" & F27 & """, " & """" & C27 & """" & ")," -> "Ā": ("A", "7"), | F27: {=INDIRECT( ADDRESS( ROW($21:$21), COLUMN($D:$D)))} -> A | H27: {=INDIRECT(K27)} -> Ā (U+0100) | I27: =C27 - 1 +$I$21 -> 9 | J27: {=ROW($5:$5) + B27} -> 5 | K27: =ADDRESS(J27, I27,4) -> I5
A28: =ROW() - 21 -> 7 | B28: =ROUNDDOWN( A28/9, 0) -> 0 | C28: 8 | D28: =LEFT(H28,2) -> A̍ | E28: ="""" & D28 & """" & ": (" & """" & F28 & """, " & """" & C28 & """" & ")," -> "A̍": ("A", "8"), | F28: {=INDIRECT( ADDRESS( ROW($21:$21), COLUMN($D:$D)))} -> A | H28: {=INDIRECT(K28)} -> A̍H (U+0041 U+030D) | I28: =C28 - 1 +$I$21 -> 10 | J28: {=ROW($5:$5) + B28} -> 5 | K28: =ADDRESS(J28, I28,4) -> J5
A29: =ROW() - 21 -> 8 | B29: =ROUNDDOWN( A29/9, 0) -> 0 | C29: 9 | D29: =LEFT(H29,2) -> A̋ | E29: ="""" & D29 & """" & ": (" & """" & F29 & """, " & """" & C29 & """" & ")," -> "A̋": ("A", "9"), | F29: {=INDIRECT( ADDRESS( ROW($21:$21), COLUMN($D:$D)))} -> A | H29: {=INDIRECT(K29)} -> A̋ (U+0041 U+030B) | I29: =C29 - 1 +$I$21 -> 11 | J29: {=ROW($5:$5) + B29} -> 5 | K29: =ADDRESS(J29, I29,4) -> K5
A30: =ROW() - 21 -> 9 | B30: =ROUNDDOWN( A30/9, 0) -> 1 | C30: 1 | D30: =LEFT(H30) -> E | E30: ="""" & D30 & """" & ": (" & """" & F30 & """, " & """" & C30 & """" & ")," -> "E": ("E", "1"), | F30: {=INDIRECT( ADDRESS( ROW($21:$21) + B30*9, COLUMN($D:$D)))} -> E | H30: {=INDIRECT(K30)} -> E | I30: =I21 -> 3 | J30: {=ROW($5:$5) + B30} -> 6 | K30: =ADDRESS(J30, I30,4) -> C6
A31: =ROW() - 21 -> 10 | B31: =ROUNDDOWN( A31/9, 0) -> 1 | C31: 2 | D31: =LEFT(H31) -> É | E31: ="""" & D31 & """" & ": (" & """" & F31 & """, " & """" & C31 & """" & ")," -> "É": ("E", "2"), | F31: {=INDIRECT( ADDRESS( ROW($21:$21) + B31*9, COLUMN($D:$D)))} -> E | H31: {=INDIRECT(K31)} -> É (U+00C9) | I31: =I22 -> 4 | J31: {=ROW($5:$5) + B31} -> 6 | K31: =ADDRESS(J31, I31,4) -> D6
A32: =ROW() - 21 -> 11 | B32: =ROUNDDOWN( A32/9, 0) -> 1 | C32: 3 | D32: =LEFT(H32) -> È | E32: ="""" & D32 & """" & ": (" & """" & F32 & """, " & """" & C32 & """" & ")," -> "È": ("E", "3"), | F32: {=INDIRECT( ADDRESS( ROW($21:$21) + B32*9, COLUMN($D:$D)))} -> E | H32: {=INDIRECT(K32)} -> È (U+00C8) | I32: =I23 -> 5 | J32: {=ROW($5:$5) + B32} -> 6 | K32: =ADDRESS(J32, I32,4) -> E6
A33: =ROW() - 21 -> 12 | B33: =ROUNDDOWN( A33/9, 0) -> 1 | C33: 4 | D33: =LEFT(H33) -> E | E33: ="""" & D33 & """" & ": (" & """" & F33 & """, " & """" & C33 & """" & ")," -> "E": ("E", "4"), | F33: {=INDIRECT( ADDRESS( ROW($21:$21) + B33*9, COLUMN($D:$D)))} -> E | H33: {=INDIRECT(K33)} -> EH | I33: =I24 -> 6 | J33: {=ROW($5:$5) + B33} -> 6 | K33: =ADDRESS(J33, I33,4) -> F6
A34: =ROW() - 21 -> 13 | B34: =ROUNDDOWN( A34/9, 0) -> 1 | C34: 5 | D34: =LEFT(H34) -> Ê | E34: ="""" & D34 & """" & ": (" & """" & F34 & """, " & """" & C34 & """" & ")," -> "Ê": ("E", "5"), | F34: {=INDIRECT( ADDRESS( ROW($21:$21) + B34*9, COLUMN($D:$D)))} -> E | H34: {=INDIRECT(K34)} -> Ê (U+00CA) | I34: =I25 -> 7 | J34: {=ROW($5:$5) + B34} -> 6 | K34: =ADDRESS(J34, I34,4) -> G6
A35: =ROW() - 21 -> 14 | B35: =ROUNDDOWN( A35/9, 0) -> 1 | C35: 6 | D35: =LEFT(H35) -> Ě | E35: ="""" & D35 & """" & ": (" & """" & F35 & """, " & """" & C35 & """" & ")," -> "Ě": ("E", "6"), | F35: {=INDIRECT( ADDRESS( ROW($21:$21) + B35*9, COLUMN($D:$D)))} -> E | H35: {=INDIRECT(K35)} -> Ě (U+011A) | I35: =I26 -> 8 | J35: {=ROW($5:$5) + B35} -> 6 | K35: =ADDRESS(J35, I35,4) -> H6
A36: =ROW() - 21 -> 15 | B36: =ROUNDDOWN( A36/9, 0) -> 1 | C36: 7 | D36: =LEFT(H36) -> Ē | E36: ="""" & D36 & """" & ": (" & """" & F36 & """, " & """" & C36 & """" & ")," -> "Ē": ("E", "7"), | F36: {=INDIRECT( ADDRESS( ROW($21:$21) + B36*9, COLUMN($D:$D)))} -> E | H36: {=INDIRECT(K36)} -> Ē (U+0112) | I36: =I27 -> 9 | J36: {=ROW($5:$5) + B36} -> 6 | K36: =ADDRESS(J36, I36,4) -> I6
A37: =ROW() - 21 -> 16 | B37: =ROUNDDOWN( A37/9, 0) -> 1 | C37: 8 | D37: =LEFT(H37,2) -> E̍ | E37: ="""" & D37 & """" & ": (" & """" & F37 & """, " & """" & C37 & """" & ")," -> "E̍": ("E", "8"), | F37: {=INDIRECT( ADDRESS( ROW($21:$21) + B37*9, COLUMN($D:$D)))} -> E | H37: {=INDIRECT(K37)} -> E̍H (U+0045 U+030D) | I37: =I28 -> 10 | J37: {=ROW($5:$5) + B37} -> 6 | K37: =ADDRESS(J37, I37,4) -> J6
A38: =ROW() - 21 -> 17 | B38: =ROUNDDOWN( A38/9, 0) -> 1 | C38: 9 | D38: =LEFT(H38,2) -> E̋ | E38: ="""" & D38 & """" & ": (" & """" & F38 & """, " & """" & C38 & """" & ")," -> "E̋": ("E", "9"), | F38: {=INDIRECT( ADDRESS( ROW($21:$21) + B38*9, COLUMN($D:$D)))} -> E | H38: {=INDIRECT(K38)} -> E̋ (U+0045 U+030B) | I38: =I29 -> 11 | J38: {=ROW($5:$5) + B38} -> 6 | K38: =ADDRESS(J38, I38,4) -> K6
A39: =ROW() - 21 -> 18 | B39: =ROUNDDOWN( A39/9, 0) -> 2 | C39: 1 | D39: =LEFT(H39) -> I | E39: ="""" & D39 & """" & ": (" & """" & F39 & """, " & """" & C39 & """" & ")," -> "I": ("I", "1"), | F39: {=INDIRECT( ADDRESS( ROW($21:$21) + B39*9, COLUMN($D:$D)))} -> I | H39: {=INDIRECT(K39)} -> I | I39: {=COLUMN($C:$C)} -> 3 | J39: {=ROW($5:$5) + B39} -> 7 | K39: =ADDRESS(J39, I39,4) -> C7
A40: =ROW() - 21 -> 19 | B40: =ROUNDDOWN( A40/9, 0) -> 2 | C40: 2 | D40: =LEFT(H40) -> Í | E40: ="""" & D40 & """" & ": (" & """" & F40 & """, " & """" & C40 & """" & ")," -> "Í": ("I", "2"), | F40: {=INDIRECT( ADDRESS( ROW($21:$21) + B40*9, COLUMN($D:$D)))} -> I | H40: {=INDIRECT(K40)} -> Í (U+00CD) | I40: =C40 - 1 +$I$21 -> 4 | J40: {=ROW($5:$5) + B40} -> 7 | K40: =ADDRESS(J40, I40,4) -> D7
A41: =ROW() - 21 -> 20 | B41: =ROUNDDOWN( A41/9, 0) -> 2 | C41: 3 | D41: =LEFT(H41) -> Ì | E41: ="""" & D41 & """" & ": (" & """" & F41 & """, " & """" & C41 & """" & ")," -> "Ì": ("I", "3"), | F41: {=INDIRECT( ADDRESS( ROW($21:$21) + B41*9, COLUMN($D:$D)))} -> I | H41: {=INDIRECT(K41)} -> Ì (U+00CC) | I41: =C41 - 1 +$I$21 -> 5 | J41: {=ROW($5:$5) + B41} -> 7 | K41: =ADDRESS(J41, I41,4) -> E7
A42: =ROW() - 21 -> 21 | B42: =ROUNDDOWN( A42/9, 0) -> 2 | C42: 4 | D42: =LEFT(H42) -> I | E42: ="""" & D42 & """" & ": (" & """" & F42 & """, " & """" & C42 & """" & ")," -> "I": ("I", "4"), | F42: {=INDIRECT( ADDRESS( ROW($21:$21) + B42*9, COLUMN($D:$D)))} -> I | H42: {=INDIRECT(K42)} -> IH | I42: =C42 - 1 +$I$21 -> 6 | J42: {=ROW($5:$5) + B42} -> 7 | K42: =ADDRESS(J42, I42,4) -> F7
A43: =ROW() - 21 -> 22 | B43: =ROUNDDOWN( A43/9, 0) -> 2 | C43: 5 | D43: =LEFT(H43) -> Î | E43: ="""" & D43 & """" & ": (" & """" & F43 & """, " & """" & C43 & """" & ")," -> "Î": ("I", "5"), | F43: {=INDIRECT( ADDRESS( ROW($21:$21) + B43*9, COLUMN($D:$D)))} -> I | H43: {=INDIRECT(K43)} -> Î (U+00CE) | I43: =C43 - 1 +$I$21 -> 7 | J43: {=ROW($5:$5) + B43} -> 7 | K43: =ADDRESS(J43, I43,4) -> G7
...

Sheet 韻母標調
B2: 台羅拼音帶調字符表
B3: 組合附加符號 | C3: 字母 | D3: 一聲（陰平） | E3: 二聲（陰上） | F3: 三聲（陰去） | G3: 四聲（陰入） | H3: 五聲（陽平） | I3: 六聲（陽上） | J3: 七聲（陽去） | K3: 八聲（陽入） | L3: 九聲
B4: 調符 Unicode | E4: U+0301 | F4: U+0300 | H4: U+0302 | I4: U+030C | J4: U+0304 | K4: U+030D | L4: U+030B
B5: 小寫 | C5: a | D5: a | E5: =_xlfn.CONCAT($C5, _xlfn.UNICHAR(HEX2DEC(RIGHT(E$4,4)))) -> á | F5: =_xlfn.CONCAT($C5, _xlfn.UNICHAR(HEX2DEC(RIGHT(F$4,4)))) -> à | G5: =_xlfn.CONCAT($C5, "h") -> ah | H5: =_xlfn.CONCAT($C5, _xlfn.UNICHAR(HEX2DEC(RIGHT(H$4,4)))) -> â | I5: =_xlfn.CONCAT($C5, _xlfn.UNICHAR(HEX2DEC(RIGHT(I$4,4)))) -> ǎ | J5: =_xlfn.CONCAT($C5, _xlfn.UNICHAR(HEX2DEC(RIGHT(J$4,4)))) -> ā | K5: =_xlfn.CONCAT($C5, _xlfn.UNICHAR(HEX2DEC(RIGHT(K$4,4))), "h") -> a̍h | L5: =_xlfn.CONCAT($C5, _xlfn.UNICHAR(HEX2DEC(RIGHT(L$4,4)))) -> a̋
C6: e | D6: e | E6: =_xlfn.CONCAT($C6, _xlfn.UNICHAR(HEX2DEC(RIGHT(E$4,4)))) -> é | F6: =_xlfn.CONCAT($C6, _xlfn.UNICHAR(HEX2DEC(RIGHT(F$4,4)))) -> è | G6: =_xlfn.CONCAT($C6, "h") -> eh | H6: =_xlfn.CONCAT($C6, _xlfn.UNICHAR(HEX2DEC(RIGHT(H$4,4)))) -> ê | I6: =_xlfn.CONCAT($C6, _xlfn.UNICHAR(HEX2DEC(RIGHT(I$4,4)))) -> ě | J6: =_xlfn.CONCAT($C6, _xlfn.UNICHAR(HEX2DEC(RIGHT(J$4,4)))) -> ē | K6: =_xlfn.CONCAT($C6, _xlfn.UNICHAR(HEX2DEC(RIGHT(K$4,4))), "h") -> e̍h | L6: =_xlfn.CONCAT($C6, _xlfn.UNICHAR(HEX2DEC(RIGHT(L$4,4)))) -> e̋
C7: i | D7: i | E7: =_xlfn.CONCAT($C7, _xlfn.UNICHAR(HEX2DEC(RIGHT(E$4,4)))) -> í | F7: =_xlfn.CONCAT($C7, _xlfn.UNICHAR(HEX2DEC(RIGHT(F$4,4)))) -> ì | G7: =_xlfn.CONCAT($C7, "h") -> ih | H7: =_xlfn.CONCAT($C7, _xlfn.UNICHAR(HEX2DEC(RIGHT(H$4,4)))) -> î | I7: =_xlfn.CONCAT($C7, _xlfn.UNICHAR(HEX2DEC(RIGHT(I$4,4)))) -> ǐ | J7: =_xlfn.CONCAT($C7, _xlfn.UNICHAR(HEX2DEC(RIGHT(J$4,4)))) -> ī | K7: =_xlfn.CONCAT($C7, _xlfn.UNICHAR(HEX2DEC(RIGHT(K$4,4))), "h") -> i̍h | L7: =_xlfn.CONCAT($C7, _xlfn.UNICHAR(HEX2DEC(RIGHT(L$4,4)))) -> i̋
C8: o | D8: o | E8: =_xlfn.CONCAT($C8, _xlfn.UNICHAR(HEX2DEC(RIGHT(E$4,4)))) -> ó | F8: =_xlfn.CONCAT($C8, _xlfn.UNICHAR(HEX2DEC(RIGHT(F$4,4)))) -> ò | G8: =_xlfn.CONCAT($C8, "h") -> oh | H8: =_xlfn.CONCAT($C8, _xlfn.UNICHAR(HEX2DEC(RIGHT(H$4,4)))) -> ô | I8: =_xlfn.CONCAT($C8, _xlfn.UNICHAR(HEX2DEC(RIGHT(I$4,4)))) -> ǒ | J8: =_xlfn.CONCAT($C8, _xlfn.UNICHAR(HEX2DEC(RIGHT(J$4,4)))) -> ō | K8: =_xlfn.CONCAT($C8, _xlfn.UNICHAR(HEX2DEC(RIGHT(K$4,4))), "h") -> o̍h | L8: =_xlfn.CONCAT($C8, _xlfn.UNICHAR(HEX2DEC(RIGHT(L$4,4)))) -> ő
C9: u | D9: u | E9: =_xlfn.CONCAT($C9, _xlfn.UNICHAR(HEX2DEC(RIGHT(E$4,4)))) -> ú | F9: =_xlfn.CONCAT($C9, _xlfn.UNICHAR(HEX2DEC(RIGHT(F$4,4)))) -> ù | G9: =_xlfn.CONCAT($C9, "h") -> uh | H9: =_xlfn.CONCAT($C9, _xlfn.UNICHAR(HEX2DEC(RIGHT(H$4,4)))) -> û | I9: =_xlfn.CONCAT($C9, _xlfn.UNICHAR(HEX2DEC(RIGHT(I$4,4)))) -> ǔ | J9: =_xlfn.CONCAT($C9, _xlfn.UNICHAR(HEX2DEC(RIGHT(J$4,4)))) -> ū | K9: =_xlfn.CONCAT($C9, _xlfn.UNICHAR(HEX2DEC(RIGHT(K$4,4))), "h") -> u̍h | L9: =_xlfn.CONCAT($C9, _xlfn.UNICHAR(HEX2DEC(RIGHT(L$4,4)))) -> ű
C10: m | D10: m | E10: =_xlfn.CONCAT($C10, _xlfn.UNICHAR(HEX2DEC(RIGHT(E$4,4)))) -> ḿ | F10: =_xlfn.CONCAT($C10, _xlfn.UNICHAR(HEX2DEC(RIGHT(F$4,4)))) -> m̀ | G10: =_xlfn.CONCAT($C10, "h") -> mh | H10: =_xlfn.CONCAT($C10, _xlfn.UNICHAR(HEX2DEC(RIGHT(H$4,4)))) -> m̂ | I10: =_xlfn.CONCAT($C10, _xlfn.UNICHAR(HEX2DEC(RIGHT(I$4,4)))) -> m̌ | J10: =_xlfn.CONCAT($C10, _xlfn.UNICHAR(HEX2DEC(RIGHT(J$4,4)))) -> m̄ | K10: =_xlfn.CONCAT($C10, _xlfn.UNICHAR(HEX2DEC(RIGHT(K$4,4))), "h") -> m̍h | L10: =_xlfn.CONCAT($C10, _xlfn.UNICHAR(HEX2DEC(RIGHT(L$4,4)))) -> m̋
C11: n | D11: n | E11: =_xlfn.CONCAT($C11, _xlfn.UNICHAR(HEX2DEC(RIGHT(E$4,4)))) -> ń | F11: =_xlfn.CONCAT($C11, _xlfn.UNICHAR(HEX2DEC(RIGHT(F$4,4)))) -> ǹ | G11: =_xlfn.CONCAT($C11, "h") -> nh | H11: =_xlfn.CONCAT($C11, _xlfn.UNICHAR(HEX2DEC(RIGHT(H$4,4)))) -> n̂ | I11: =_xlfn.CONCAT($C11, _xlfn.UNICHAR(HEX2DEC(RIGHT(I$4,4)))) -> ň | J11: =_xlfn.CONCAT($C11, _xlfn.UNICHAR(HEX2DEC(RIGHT(J$4,4)))) -> n̄ | K11: =_xlfn.CONCAT($C11, _xlfn.UNICHAR(HEX2DEC(RIGHT(K$4,4))), "h") -> n̍h | L11: =_xlfn.CONCAT($C11, _xlfn.UNICHAR(HEX2DEC(RIGHT(L$4,4)))) -> n̋
B12: 大寫 | C12: A | D12: A | E12: =_xlfn.CONCAT($C12, _xlfn.UNICHAR(HEX2DEC(RIGHT(E$4,4)))) -> Á | F12: =_xlfn.CONCAT($C12, _xlfn.UNICHAR(HEX2DEC(RIGHT(F$4,4)))) -> À | G12: =_xlfn.CONCAT($C12, "h") -> Ah | H12: =_xlfn.CONCAT($C12, _xlfn.UNICHAR(HEX2DEC(RIGHT(H$4,4)))) -> Â | I12: =_xlfn.CONCAT($C12, _xlfn.UNICHAR(HEX2DEC(RIGHT(I$4,4)))) -> Ǎ | J12: =_xlfn.CONCAT($C12, _xlfn.UNICHAR(HEX2DEC(RIGHT(J$4,4)))) -> Ā | K12: =_xlfn.CONCAT($C12, _xlfn.UNICHAR(HEX2DEC(RIGHT(K$4,4))), "h") -> A̍h | L12: =_xlfn.CONCAT($C12, _xlfn.UNICHAR(HEX2DEC(RIGHT(L$4,4)))) -> A̋
C13: E | D13: E | E13: =_xlfn.CONCAT($C13, _xlfn.UNICHAR(HEX2DEC(RIGHT(E$4,4)))) -> É | F13: =_xlfn.CONCAT($C13, _xlfn.UNICHAR(HEX2DEC(RIGHT(F$4,4)))) -> È | G13: =_xlfn.CONCAT($C13, "h") -> Eh | H13: =_xlfn.CONCAT($C13, _xlfn.UNICHAR(HEX2DEC(RIGHT(H$4,4)))) -> Ê | I13: =_xlfn.CONCAT($C13, _xlfn.UNICHAR(HEX2DEC(RIGHT(I$4,4)))) -> Ě | J13: =_xlfn.CONCAT($C13, _xlfn.UNICHAR(HEX2DEC(RIGHT(J$4,4)))) -> Ē | K13: =_xlfn.CONCAT($C13, _xlfn.UNICHAR(HEX2DEC(RIGHT(K$4,4))), "h") -> E̍h | L13: =_xlfn.CONCAT($C13, _xlfn.UNICHAR(HEX2DEC(RIGHT(L$4,4)))) -> E̋
C14: I | D14: I | E14: =_xlfn.CONCAT($C14, _xlfn.UNICHAR(HEX2DEC(RIGHT(E$4,4)))) -> Í | F14: =_xlfn.CONCAT($C14, _xlfn.UNICHAR(HEX2DEC(RIGHT(F$4,4)))) -> Ì | G14: =_xlfn.CONCAT($C14, "h") -> Ih | H14: =_xlfn.CONCAT($C14, _xlfn.UNICHAR(HEX2DEC(RIGHT(H$4,4)))) -> Î | I14: =_xlfn.CONCAT($C14, _xlfn.UNICHAR(HEX2DEC(RIGHT(I$4,4)))) -> Ǐ | J14: =_xlfn.CONCAT($C14, _xlfn.UNICHAR(HEX2DEC(RIGHT(J$4,4)))) -> Ī | K14: =_xlfn.CONCAT($C14, _xlfn.UNICHAR(HEX2DEC(RIGHT(K$4,4))), "h") -> I̍h | L14: =_xlfn.CONCAT($C14, _xlfn.UNICHAR(HEX2DEC(RIGHT(L$4,4)))) -> I̋
C15: O | D15: O | E15: =_xlfn.CONCAT($C15, _xlfn.UNICHAR(HEX2DEC(RIGHT(E$4,4)))) -> Ó | F15: =_xlfn.CONCAT($C15, _xlfn.UNICHAR(HEX2DEC(RIGHT(F$4,4)))) -> Ò | G15: =_xlfn.CONCAT($C15, "h") -> Oh | H15: =_xlfn.CONCAT($C15, _xlfn.UNICHAR(HEX2DEC(RIGHT(H$4,4)))) -> Ô | I15: =_xlfn.CONCAT($C15, _xlfn.UNICHAR(HEX2DEC(RIGHT(I$4,4)))) -> Ǒ | J15: =_xlfn.CONCAT($C15, _xlfn.UNICHAR(HEX2DEC(RIGHT(J$4,4)))) -> Ō | K15: =_xlfn.CONCAT($C15, _xlfn.UNICHAR(HEX2DEC(RIGHT(K$4,4))), "h") -> O̍h | L15: =_xlfn.CONCAT($C15, _xlfn.UNICHAR(HEX2DEC(RIGHT(L$4,4)))) -> Ő
C16: U | D16: U | E16: =_xlfn.CONCAT($C16, _xlfn.UNICHAR(HEX2DEC(RIGHT(E$4,4)))) -> Ú | F16: =_xlfn.CONCAT($C16, _xlfn.UNICHAR(HEX2DEC(RIGHT(F$4,4)))) -> Ù | G16: =_xlfn.CONCAT($C16, "h") -> Uh | H16: =_xlfn.CONCAT($C16, _xlfn.UNICHAR(HEX2DEC(RIGHT(H$4,4)))) -> Û | I16: =_xlfn.CONCAT($C16, _xlfn.UNICHAR(HEX2DEC(RIGHT(I$4,4)))) -> Ǔ | J16: =_xlfn.CONCAT($C16, _xlfn.UNICHAR(HEX2DEC(RIGHT(J$4,4)))) -> Ū | K16: =_xlfn.CONCAT($C16, _xlfn.UNICHAR(HEX2DEC(RIGHT(K$4,4))), "h") -> U̍h | L16: =_xlfn.CONCAT($C16, _xlfn.UNICHAR(HEX2DEC(RIGHT(L$4,4)))) -> Ű
C17: M | D17: M | E17: =_xlfn.CONCAT($C17, _xlfn.UNICHAR(HEX2DEC(RIGHT(E$4,4)))) -> Ḿ | F17: =_xlfn.CONCAT($C17, _xlfn.UNICHAR(HEX2DEC(RIGHT(F$4,4)))) -> M̀ | G17: =_xlfn.CONCAT($C17, "h") -> Mh | H17: =_xlfn.CONCAT($C17, _xlfn.UNICHAR(HEX2DEC(RIGHT(H$4,4)))) -> M̂ | I17: =_xlfn.CONCAT($C17, _xlfn.UNICHAR(HEX2DEC(RIGHT(I$4,4)))) -> M̌ | J17: =_xlfn.CONCAT($C17, _xlfn.UNICHAR(HEX2DEC(RIGHT(J$4,4)))) -> M̄ | K17: =_xlfn.CONCAT($C17, _xlfn.UNICHAR(HEX2DEC(RIGHT(K$4,4))), "h") -> M̍h | L17: =_xlfn.CONCAT($C17, _xlfn.UNICHAR(HEX2DEC(RIGHT(L$4,4)))) -> M̋
C18: N | D18: N | E18: =_xlfn.CONCAT($C18, _xlfn.UNICHAR(HEX2DEC(RIGHT(E$4,4)))) -> Ń | F18: =_xlfn.CONCAT($C18, _xlfn.UNICHAR(HEX2DEC(RIGHT(F$4,4)))) -> Ǹ | G18: =_xlfn.CONCAT($C18, "h") -> Nh | H18: =_xlfn.CONCAT($C18, _xlfn.UNICHAR(HEX2DEC(RIGHT(H$4,4)))) -> N̂ | I18: =_xlfn.CONCAT($C18, _xlfn.UNICHAR(HEX2DEC(RIGHT(I$4,4)))) -> Ň | J18: =_xlfn.CONCAT($C18, _xlfn.UNICHAR(HEX2DEC(RIGHT(J$4,4)))) -> N̄ | K18: =_xlfn.CONCAT($C18, _xlfn.UNICHAR(HEX2DEC(RIGHT(K$4,4))), "h") -> N̍h | L18: =_xlfn.CONCAT($C18, _xlfn.UNICHAR(HEX2DEC(RIGHT(L$4,4)))) -> N̋

Sheet 調符
B2: 台羅調符
B4: Unicode 編碼 | C4: 拼音字母 | D4: 組合結果 | E4: 註釋
B5: U+0301 | C5: a | D5: =_xlfn.CONCAT(C5,_xlfn.UNICHAR(HEX2DEC(RIGHT(B5,4)))) -> á | E5: 二聲（陰上）
B6: U+0300 | C6: a | D6: =_xlfn.CONCAT(C6,_xlfn.UNICHAR(HEX2DEC(RIGHT(B6,4)))) -> à | E6: 三聲（陰去）
B7: U+0302 | C7: a | D7: =_xlfn.CONCAT(C7,_xlfn.UNICHAR(HEX2DEC(RIGHT(B7,4)))) -> â | E7: 五聲（陽平）
B8: U+030C | C8: a | D8: =_xlfn.CONCAT(C8,_xlfn.UNICHAR(HEX2DEC(RIGHT(B8,4)))) -> ǎ | E8: 六聲（陽上）
B9: U+0304 | C9: a | D9: =_xlfn.CONCAT(C9,_xlfn.UNICHAR(HEX2DEC(RIGHT(B9,4)))) -> ā | E9: 七聲（陽去）
B10: U+030D | C10: a | D10: =_xlfn.CONCAT(C10,_xlfn.UNICHAR(HEX2DEC(RIGHT(B10,4)))) -> a̍ | E10: 八聲（陽入）
B11: U+030B | C11: a | D11: =_xlfn.CONCAT(C11,_xlfn.UNICHAR(HEX2DEC(RIGHT(B11,4)))) -> a̋ | E11: 九聲
B13: 閩拼調符
B15: Unicode 編碼 | C15: 拼音字母 | D15: 組合結果 | E15: 註釋
B16: U+0304 | C16: a | D16: =_xlfn.CONCAT(C16,_xlfn.UNICHAR(HEX2DEC(RIGHT(B16,4)))) -> ā | E16: 一聲（陰平）
B17: U+0301 | C17: a | D17: =_xlfn.CONCAT(C17,_xlfn.UNICHAR(HEX2DEC(RIGHT(B17,4)))) -> á | E17: 二聲（陽平）
B18: U+030C | C18: a | D18: =_xlfn.CONCAT(C18,_xlfn.UNICHAR(HEX2DEC(RIGHT(B18,4)))) -> ǎ | E18: 三聲（陰上）
B19: U+0300 | C19: a | D19: =_xlfn.CONCAT(C19,_xlfn.UNICHAR(HEX2DEC(RIGHT(B19,4)))) -> à | E19: 五聲（陰去）
B20: U+0302 | C20: a | D20: =_xlfn.CONCAT(C20,_xlfn.UNICHAR(HEX2DEC(RIGHT(B20,4)))) -> â | E20: 六聲（陽去）
B21: U+0304 | C21: a | D21: =_xlfn.CONCAT(C21,_xlfn.UNICHAR(HEX2DEC(RIGHT(B21,4))),"h") -> āh | E21: 七聲（陰入）
B22: U+0301 | C22: a | D22: =_xlfn.CONCAT(C22,_xlfn.UNICHAR(HEX2DEC(RIGHT(B22,4))),"h") -> áh | E22: 八聲（陽入）

Sheet 元音標調
C2: =_xlfn.CONCAT("o", _xlfn.UNICHAR(HEX2DEC(RIGHT("U+0358",4)))) -> o͘ | D2: a | E2: i | F2: u | G2: e | H2: o | I2: m | J2: n
B3: 1 | C3: =IFERROR( _xlfn.CONCAT("o", _xlfn.UNICHAR(HEX2DEC(RIGHT("U+0358",4))), _xlfn.UNICHAR(HEX2DEC(RIGHT([1]調表!E4,4)))), $C$2) -> o͘ | D3: =IFERROR( _xlfn.CONCAT(D$2, IF([1]調表!$E4="", "", _xlfn.UNICHAR(HEX2DEC(RIGHT([1]調表!$E4,4))))), "") -> a | E3: =IFERROR( _xlfn.CONCAT(E$2, IF([1]調表!$E4="", "", _xlfn.UNICHAR(HEX2DEC(RIGHT([1]調表!$E4,4))))), "") -> i | F3: =IFERROR( _xlfn.CONCAT(F$2, IF([1]調表!$E4="", "", _xlfn.UNICHAR(HEX2DEC(RIGHT([1]調表!$E4,4))))), "") -> u | G3: =IFERROR( _xlfn.CONCAT(G$2, IF([1]調表!$E4="", "", _xlfn.UNICHAR(HEX2DEC(RIGHT([1]調表!$E4,4))))), "") -> e | H3: =IFERROR( _xlfn.CONCAT(H$2, IF([1]調表!$E4="", "", _xlfn.UNICHAR(HEX2DEC(RIGHT([1]調表!$E4,4))))), "") -> o | I3: =IFERROR( _xlfn.CONCAT(I$2, IF([1]調表!$E4="", "", _xlfn.UNICHAR(HEX2DEC(RIGHT([1]調表!$E4,4))))), "") -> m | J3: =IFERROR( _xlfn.CONCAT(J$2, IF([1]調表!$E4="", "", _xlfn.UNICHAR(HEX2DEC(RIGHT([1]調表!$E4,4))))), "") -> n
B4: 2 | C4: =IFERROR( _xlfn.CONCAT("o", _xlfn.UNICHAR(HEX2DEC(RIGHT("U+0358",4))), _xlfn.UNICHAR(HEX2DEC(RIGHT([1]調表!E5,4)))), $C$2) -> ó͘ | D4: =IFERROR( _xlfn.CONCAT(D$2, IF([1]調表!$E5="", "", _xlfn.UNICHAR(HEX2DEC(RIGHT([1]調表!$E5,4))))), "") -> á | E4: =IFERROR( _xlfn.CONCAT(E$2, IF([1]調表!$E5="", "", _xlfn.UNICHAR(HEX2DEC(RIGHT([1]調表!$E5,4))))), "") -> í | F4: =IFERROR( _xlfn.CONCAT(F$2, IF([1]調表!$E5="", "", _xlfn.UNICHAR(HEX2DEC(RIGHT([1]調表!$E5,4))))), "") -> ú | G4: =IFERROR( _xlfn.CONCAT(G$2, IF([1]調表!$E5="", "", _xlfn.UNICHAR(HEX2DEC(RIGHT([1]調表!$E5,4))))), "") -> é | H4: =IFERROR( _xlfn.CONCAT(H$2, IF([1]調表!$E5="", "", _xlfn.UNICHAR(HEX2DEC(RIGHT([1]調表!$E5,4))))), "") -> ó | I4: =IFERROR( _xlfn.CONCAT(I$2, IF([1]調表!$E5="", "", _xlfn.UNICHAR(HEX2DEC(RIGHT([1]調表!$E5,4))))), "") -> ḿ | J4: =IFERROR( _xlfn.CONCAT(J$2, IF([1]調表!$E5="", "", _xlfn.UNICHAR(HEX2DEC(RIGHT([1]調表!$E5,4))))), "") -> ń
B5: 3 | C5: =IFERROR( _xlfn.CONCAT("o", _xlfn.UNICHAR(HEX2DEC(RIGHT("U+0358",4))), _xlfn.UNICHAR(HEX2DEC(RIGHT([1]調表!E6,4)))), $C$2) -> ò͘ | D5: =IFERROR( _xlfn.CONCAT(D$2, IF([1]調表!$E6="", "", _xlfn.UNICHAR(HEX2DEC(RIGHT([1]調表!$E6,4))))), "") -> à | E5: =IFERROR( _xlfn.CONCAT(E$2, IF([1]調表!$E6="", "", _xlfn.UNICHAR(HEX2DEC(RIGHT([1]調表!$E6,4))))), "") -> ì | F5: =IFERROR( _xlfn.CONCAT(F$2, IF([1]調表!$E6="", "", _xlfn.UNICHAR(HEX2DEC(RIGHT([1]調表!$E6,4))))), "") -> ù | G5: =IFERROR( _xlfn.CONCAT(G$2, IF([1]調表!$E6="", "", _xlfn.UNICHAR(HEX2DEC(RIGHT([1]調表!$E6,4))))), "") -> è | H5: =IFERROR( _xlfn.CONCAT(H$2, IF([1]調表!$E6="", "", _xlfn.UNICHAR(HEX2DEC(RIGHT([1]調表!$E6,4))))), "") -> ò | I5: =IFERROR( _xlfn.CONCAT(I$2, IF([1]調表!$E6="", "", _xlfn.UNICHAR(HEX2DEC(RIGHT([1]調表!$E6,4))))), "") -> m̀ | J5: =IFERROR( _xlfn.CONCAT(J$2, IF([1]調表!$E6="", "", _xlfn.UNICHAR(HEX2DEC(RIGHT([1]調表!$E6,4))))), "") -> ǹ
B6: 4 | C6: =IFERROR( _xlfn.CONCAT("o", _xlfn.UNICHAR(HEX2DEC(RIGHT("U+0358",4))), _xlfn.UNICHAR(HEX2DEC(RIGHT([1]調表!E7,4)))), $C$2) -> o͘ | D6: =IFERROR( _xlfn.CONCAT(D$2, IF([1]調表!$E7="", "", _xlfn.UNICHAR(HEX2DEC(RIGHT([1]調表!$E7,4))))), "") -> a | E6: =IFERROR( _xlfn.CONCAT(E$2, IF([1]調表!$E7="", "", _xlfn.UNICHAR(HEX2DEC(RIGHT([1]調表!$E7,4))))), "") -> i | F6: =IFERROR( _xlfn.CONCAT(F$2, IF([1]調表!$E7="", "", _xlfn.UNICHAR(HEX2DEC(RIGHT([1]調表!$E7,4))))), "") -> u | G6: =IFERROR( _xlfn.CONCAT(G$2, IF([1]調表!$E7="", "", _xlfn.UNICHAR(HEX2DEC(RIGHT([1]調表!$E7,4))))), "") -> e | H6: =IFERROR( _xlfn.CONCAT(H$2, IF([1]調表!$E7="", "", _xlfn.UNICHAR(HEX2DEC(RIGHT([1]調表!$E7,4))))), "") -> o | I6: =IFERROR( _xlfn.CONCAT(I$2, IF([1]調表!$E7="", "", _xlfn.UNICHAR(HEX2DEC(RIGHT([1]調表!$E7,4))))), "") -> m | J6: =IFERROR( _xlfn.CONCAT(J$2, IF([1]調表!$E7="", "", _xlfn.UNICHAR(HEX2DEC(RIGHT([1]調表!$E7,4))))), "") -> n
B7: 5 | C7: =IFERROR( _xlfn.CONCAT("o", _xlfn.UNICHAR(HEX2DEC(RIGHT("U+0358",4))), _xlfn.UNICHAR(HEX2DEC(RIGHT([1]調表!E8,4)))), "") -> ǒ͘ | D7: =IFERROR( _xlfn.CONCAT(D$2, IF([1]調表!$E8="", "", _xlfn.UNICHAR(HEX2DEC(RIGHT([1]調表!$E8,4))))), "") -> ǎ | E7: =IFERROR( _xlfn.CONCAT(E$2, IF([1]調表!$E8="", "", _xlfn.UNICHAR(HEX2DEC(RIGHT([1]調表!$E8,4))))), "") -> ǐ | F7: =IFERROR( _xlfn.CONCAT(F$2, IF([1]調表!$E8="", "", _xlfn.UNICHAR(HEX2DEC(RIGHT([1]調表!$E8,4))))), "") -> ǔ | G7: =IFERROR( _xlfn.CONCAT(G$2, IF([1]調表!$E8="", "", _xlfn.UNICHAR(HEX2DEC(RIGHT([1]調表!$E8,4))))), "") -> ě | H7: =IFERROR( _xlfn.CONCAT(H$2, IF([1]調表!$E8="", "", _xlfn.UNICHAR(HEX2DEC(RIGHT([1]調表!$E8,4))))), "") -> ǒ | I7: =IFERROR( _xlfn.CONCAT(I$2, IF([1]調表!$E8="", "", _xlfn.UNICHAR(HEX2DEC(RIGHT([1]調表!$E8,4))))), "") -> m̌ | J7: =IFERROR( _xlfn.CONCAT(J$2, IF([1]調表!$E8="", "", _xlfn.UNICHAR(HEX2DEC(RIGHT([1]調表!$E8,4))))), "") -> ň
B8: 6 | C8: =IFERROR( _xlfn.CONCAT("o", _xlfn.UNICHAR(HEX2DEC(RIGHT("U+0358",4))), _xlfn.UNICHAR(HEX2DEC(RIGHT([1]調表!E9,4)))), "") -> ó͘ | D8: =IFERROR( _xlfn.CONCAT(D$2, IF([1]調表!$E9="", "", _xlfn.UNICHAR(HEX2DEC(RIGHT([1]調表!$E9,4))))), "") -> á | E8: =IFERROR( _xlfn.CONCAT(E$2, IF([1]調表!$E9="", "", _xlfn.UNICHAR(HEX2DEC(RIGHT([1]調表!$E9,4))))), "") -> í | F8: =IFERROR( _xlfn.CONCAT(F$2, IF([1]調表!$E9="", "", _xlfn.UNICHAR(HEX2DEC(RIGHT([1]調表!$E9,4))))), "") -> ú | G8: =IFERROR( _xlfn.CONCAT(G$2, IF([1]調表!$E9="", "", _xlfn.UNICHAR(HEX2DEC(RIGHT([1]調表!$E9,4))))), "") -> é | H8: =IFERROR( _xlfn.CONCAT(H$2, IF([1]調表!$E9="", "", _xlfn.UNICHAR(HEX2DEC(RIGHT([1]調表!$E9,4))))), "") -> ó | I8: =IFERROR( _xlfn.CONCAT(I$2, IF([1]調表!$E9="", "", _xlfn.UNICHAR(HEX2DEC(RIGHT([1]調表!$E9,4))))), "") -> ḿ | J8: =IFERROR( _xlfn.CONCAT(J$2, IF([1]調表!$E9="", "", _xlfn.UNICHAR(HEX2DEC(RIGHT([1]調表!$E9,4))))), "") -> ń
B9: 7 | C9: =IFERROR( _xlfn.CONCAT("o", _xlfn.UNICHAR(HEX2DEC(RIGHT("U+0358",4))), _xlfn.UNICHAR(HEX2DEC(RIGHT([1]調表!E10,4)))), "") -> ō͘ | D9: =IFERROR( _xlfn.CONCAT(D$2, IF([1]調表!$E10="", "", _xlfn.UNICHAR(HEX2DEC(RIGHT([1]調表!$E10,4))))), "") -> ā | E9: =IFERROR( _xlfn.CONCAT(E$2, IF([1]調表!$E10="", "", _xlfn.UNICHAR(HEX2DEC(RIGHT([1]調表!$E10,4))))), "") -> ī | F9: =IFERROR( _xlfn.CONCAT(F$2, IF([1]調表!$E10="", "", _xlfn.UNICHAR(HEX2DEC(RIGHT([1]調表!$E10,4))))), "") -> ū | G9: =IFERROR( _xlfn.CONCAT(G$2, IF([1]調表!$E10="", "", _xlfn.UNICHAR(HEX2DEC(RIGHT([1]調表!$E10,4))))), "") -> ē | H9: =IFERROR( _xlfn.CONCAT(H$2, IF([1]調表!$E10="", "", _xlfn.UNICHAR(HEX2DEC(RIGHT([1]調表!$E10,4))))), "") -> ō | I9: =IFERROR( _xlfn.CONCAT(I$2, IF([1]調表!$E10="", "", _xlfn.UNICHAR(HEX2DEC(RIGHT([1]調表!$E10,4))))), "") -> m̄ | J9: =IFERROR( _xlfn.CONCAT(J$2, IF([1]調表!$E10="", "", _xlfn.UNICHAR(HEX2DEC(RIGHT([1]調表!$E10,4))))), "") -> n̄
B10: 8 | C10: =IFERROR( _xlfn.CONCAT("o", _xlfn.UNICHAR(HEX2DEC(RIGHT("U+0358",4))), _xlfn.UNICHAR(HEX2DEC(RIGHT([1]調表!E11,4)))), "") -> o̍͘ | D10: =IFERROR( _xlfn.CONCAT(D$2, IF([1]調表!$E11="", "", _xlfn.UNICHAR(HEX2DEC(RIGHT([1]調表!$E11,4))))), "") -> a̍ | E10: =IFERROR( _xlfn.CONCAT(E$2, IF([1]調表!$E11="", "", _xlfn.UNICHAR(HEX2DEC(RIGHT([1]調表!$E11,4))))), "") -> i̍ | F10: =IFERROR( _xlfn.CONCAT(F$2, IF([1]調表!$E11="", "", _xlfn.UNICHAR(HEX2DEC(RIGHT([1]調表!$E11,4))))), "") -> u̍ | G10: =IFERROR( _xlfn.CONCAT(G$2, IF([1]調表!$E11="", "", _xlfn.UNICHAR(HEX2DEC(RIGHT([1]調表!$E11,4))))), "") -> e̍ | H10: =IFERROR( _xlfn.CONCAT(H$2, IF([1]調表!$E11="", "", _xlfn.UNICHAR(HEX2DEC(RIGHT([1]調表!$E11,4))))), "") -> o̍ | I10: =IFERROR( _xlfn.CONCAT(I$2, IF([1]調表!$E11="", "", _xlfn.UNICHAR(HEX2DEC(RIGHT([1]調表!$E11,4))))), "") -> m̍ | J10: =IFERROR( _xlfn.CONCAT(J$2, IF([1]調表!$E11="", "", _xlfn.UNICHAR(HEX2DEC(RIGHT([1]調表!$E11,4))))), "") -> n̍
B11: 9 | C11: =IFERROR( _xlfn.CONCAT("o", _xlfn.UNICHAR(HEX2DEC(RIGHT("U+0358",4))), _xlfn.UNICHAR(HEX2DEC(RIGHT([1]調表!E12,4)))), "") -> ő͘ | D11: =IFERROR( _xlfn.CONCAT(D$2, IF([1]調表!$E12="", "", _xlfn.UNICHAR(HEX2DEC(RIGHT([1]調表!$E12,4))))), "") -> a̋ | E11: =IFERROR( _xlfn.CONCAT(E$2, IF([1]調表!$E12="", "", _xlfn.UNICHAR(HEX2DEC(RIGHT([1]調表!$E12,4))))), "") -> i̋ | F11: =IFERROR( _xlfn.CONCAT(F$2, IF([1]調表!$E12="", "", _xlfn.UNICHAR(HEX2DEC(RIGHT([1]調表!$E12,4))))), "") -> ű | G11: =IFERROR( _xlfn.CONCAT(G$2, IF([1]調表!$E12="", "", _xlfn.UNICHAR(HEX2DEC(RIGHT([1]調表!$E12,4))))), "") -> e̋ | H11: =IFERROR( _xlfn.CONCAT(H$2, IF([1]調表!$E12="", "", _xlfn.UNICHAR(HEX2DEC(RIGHT([1]調表!$E12,4))))), "") -> ő | I11: =IFERROR( _xlfn.CONCAT(I$2, IF([1]調表!$E12="", "", _xlfn.UNICHAR(HEX2DEC(RIGHT([1]調表!$E12,4))))), "") -> m̋ | J11: =IFERROR( _xlfn.CONCAT(J$2, IF([1]調表!$E12="", "", _xlfn.UNICHAR(HEX2DEC(RIGHT([1]調表!$E12,4))))), "") -> n̋
B12: 0 | C12: =IFERROR( _xlfn.CONCAT("o", _xlfn.UNICHAR(HEX2DEC(RIGHT("U+0358",4))), _xlfn.UNICHAR(HEX2DEC(RIGHT([1]調表!E13,4)))), "") -> o̊͘ | D12: =IFERROR( _xlfn.CONCAT(D$2, IF([1]調表!$E13="", "", _xlfn.UNICHAR(HEX2DEC(RIGHT([1]調表!$E13,4))))), "") -> å | E12: =IFERROR( _xlfn.CONCAT(E$2, IF([1]調表!$E13="", "", _xlfn.UNICHAR(HEX2DEC(RIGHT([1]調表!$E13,4))))), "") -> i̊ | F12: =IFERROR( _xlfn.CONCAT(F$2, IF([1]調表!$E13="", "", _xlfn.UNICHAR(HEX2DEC(RIGHT([1]調表!$E13,4))))), "") -> ů | G12: =IFERROR( _xlfn.CONCAT(G$2, IF([1]調表!$E13="", "", _xlfn.UNICHAR(HEX2DEC(RIGHT([1]調表!$E13,4))))), "") -> e̊ | H12: =IFERROR( _xlfn.CONCAT(H$2, IF([1]調表!$E13="", "", _xlfn.UNICHAR(HEX2DEC(RIGHT([1]調表!$E13,4))))), "") -> o̊ | I12: =IFERROR( _xlfn.CONCAT(I$2, IF([1]調表!$E13="", "", _xlfn.UNICHAR(HEX2DEC(RIGHT([1]調表!$E13,4))))), "") -> m̊ | J12: =IFERROR( _xlfn.CONCAT(J$2, IF([1]調表!$E13="", "", _xlfn.UNICHAR(HEX2DEC(RIGHT([1]調表!$E13,4))))), "") -> n̊
C15: a | D15: i | E15: u | F15: e | G15: o | H15: m | I15: n | L15: =IFERROR( _xlfn.CONCAT("l", "u", _xlfn.UNICHAR(HEX2DEC(RIGHT([1]調表!$O4,4))), "n"), "") -> lūn | M15: =IFERROR( _xlfn.CONCAT("n", "g", "o", _xlfn.UNICHAR(HEX2DEC(RIGHT([1]調表!$O4,4))), "o"), "") -> ngōo
B16: 1 | C16: =IFERROR( _xlfn.CONCAT(D$2, IF([1]調表!$E17="", "", _xlfn.UNICHAR(HEX2DEC(RIGHT([1]調表!$E17,4))))), "") -> ā | D16: =IFERROR( _xlfn.CONCAT(E$2, IF([1]調表!$E17="", "", _xlfn.UNICHAR(HEX2DEC(RIGHT([1]調表!$E17,4))))), "") -> ī | E16: =IFERROR( _xlfn.CONCAT(F$2, IF([1]調表!$E17="", "", _xlfn.UNICHAR(HEX2DEC(RIGHT([1]調表!$E17,4))))), "") -> ū | F16: =IFERROR( _xlfn.CONCAT(G$2, IF([1]調表!$E17="", "", _xlfn.UNICHAR(HEX2DEC(RIGHT([1]調表!$E17,4))))), "") -> ē | G16: =IFERROR( _xlfn.CONCAT(H$2, IF([1]調表!$E17="", "", _xlfn.UNICHAR(HEX2DEC(RIGHT([1]調表!$E17,4))))), "") -> ō | H16: =IFERROR( _xlfn.CONCAT(I$2, IF([1]調表!$E17="", "", _xlfn.UNICHAR(HEX2DEC(RIGHT([1]調表!$E17,4))))), "") -> m̄ | I16: =IFERROR( _xlfn.CONCAT(J$2, IF([1]調表!$E17="", "", _xlfn.UNICHAR(HEX2DEC(RIGHT([1]調表!$E17,4))))), "") -> n̄ | L16: =IFERROR( _xlfn.CONCAT("l", "u", _xlfn.UNICHAR(HEX2DEC(RIGHT([1]調表!$O7,4))), "n"), "") -> lǔn | M16: =IFERROR( _xlfn.CONCAT("n", "g", "o", _xlfn.UNICHAR(HEX2DEC(RIGHT([1]調表!$O7,4))), "o"), "") -> ngǒo
B17: 2 | C17: =IFERROR( _xlfn.CONCAT(D$2, IF([1]調表!$E18="", "", _xlfn.UNICHAR(HEX2DEC(RIGHT([1]調表!$E18,4))))), "") -> á | D17: =IFERROR( _xlfn.CONCAT(E$2, IF([1]調表!$E18="", "", _xlfn.UNICHAR(HEX2DEC(RIGHT([1]調表!$E18,4))))), "") -> í | E17: =IFERROR( _xlfn.CONCAT(F$2, IF([1]調表!$E18="", "", _xlfn.UNICHAR(HEX2DEC(RIGHT([1]調表!$E18,4))))), "") -> ú | F17: =IFERROR( _xlfn.CONCAT(G$2, IF([1]調表!$E18="", "", _xlfn.UNICHAR(HEX2DEC(RIGHT([1]調表!$E18,4))))), "") -> é | G17: =IFERROR( _xlfn.CONCAT(H$2, IF([1]調表!$E18="", "", _xlfn.UNICHAR(HEX2DEC(RIGHT([1]調表!$E18,4))))), "") -> ó | H17: =IFERROR( _xlfn.CONCAT(I$2, IF([1]調表!$E18="", "", _xlfn.UNICHAR(HEX2DEC(RIGHT([1]調表!$E18,4))))), "") -> ḿ | I17: =IFERROR( _xlfn.CONCAT(J$2, IF([1]調表!$E18="", "", _xlfn.UNICHAR(HEX2DEC(RIGHT([1]調表!$E18,4))))), "") -> ń | L17: =IFERROR( _xlfn.CONCAT("l", "u", _xlfn.UNICHAR(HEX2DEC(RIGHT([1]調表!$O6,4))), "n"), "") -> lùn | M17: =IFERROR( _xlfn.CONCAT("n", "g", "o", _xlfn.UNICHAR(HEX2DEC(RIGHT([1]調表!$O6,4))), "o"), "") -> ngòo
B18: 3 | C18: =IFERROR( _xlfn.CONCAT(D$2, IF([1]調表!$E19="", "", _xlfn.UNICHAR(HEX2DEC(RIGHT([1]調表!$E19,4))))), "") -> ǎ | D18: =IFERROR( _xlfn.CONCAT(E$2, IF([1]調表!$E19="", "", _xlfn.UNICHAR(HEX2DEC(RIGHT([1]調表!$E19,4))))), "") -> ǐ | E18: =IFERROR( _xlfn.CONCAT(F$2, IF([1]調表!$E19="", "", _xlfn.UNICHAR(HEX2DEC(RIGHT([1]調表!$E19,4))))), "") -> ǔ | F18: =IFERROR( _xlfn.CONCAT(G$2, IF([1]調表!$E19="", "", _xlfn.UNICHAR(HEX2DEC(RIGHT([1]調表!$E19,4))))), "") -> ě | G18: =IFERROR( _xlfn.CONCAT(H$2, IF([1]調表!$E19="", "", _xlfn.UNICHAR(HEX2DEC(RIGHT([1]調表!$E19,4))))), "") -> ǒ | H18: =IFERROR( _xlfn.CONCAT(I$2, IF([1]調表!$E19="", "", _xlfn.UNICHAR(HEX2DEC(RIGHT([1]調表!$E19,4))))), "") -> m̌ | I18: =IFERROR( _xlfn.CONCAT(J$2, IF([1]調表!$E19="", "", _xlfn.UNICHAR(HEX2DEC(RIGHT([1]調表!$E19,4))))), "") -> ň | L18: =IFERROR( _xlfn.CONCAT("l", "u", _xlfn.UNICHAR(HEX2DEC(RIGHT([1]調表!$O9,4))), "n"), "") -> lūn | M18: =IFERROR( _xlfn.CONCAT("n", "g", "o", _xlfn.UNICHAR(HEX2DEC(RIGHT([1]調表!$O9,4))), "o"), "") -> ngōo
B19: 4 | C19: =IFERROR( _xlfn.CONCAT(D$2, IF([1]調表!$E20="", "", _xlfn.UNICHAR(HEX2DEC(RIGHT([1]調表!$E20,4))))), "") -> ǎ | D19: =IFERROR( _xlfn.CONCAT(E$2, IF([1]調表!$E20="", "", _xlfn.UNICHAR(HEX2DEC(RIGHT([1]調表!$E20,4))))), "") -> ǐ | E19: =IFERROR( _xlfn.CONCAT(F$2, IF([1]調表!$E20="", "", _xlfn.UNICHAR(HEX2DEC(RIGHT([1]調表!$E20,4))))), "") -> ǔ | F19: =IFERROR( _xlfn.CONCAT(G$2, IF([1]調表!$E20="", "", _xlfn.UNICHAR(HEX2DEC(RIGHT([1]調表!$E20,4))))), "") -> ě | G19: =IFERROR( _xlfn.CONCAT(H$2, IF([1]調表!$E20="", "", _xlfn.UNICHAR(HEX2DEC(RIGHT([1]調表!$E20,4))))), "") -> ǒ | H19: =IFERROR( _xlfn.CONCAT(I$2, IF([1]調表!$E20="", "", _xlfn.UNICHAR(HEX2DEC(RIGHT([1]調表!$E20,4))))), "") -> m̌ | I19: =IFERROR( _xlfn.CONCAT(J$2, IF([1]調表!$E20="", "", _xlfn.UNICHAR(HEX2DEC(RIGHT([1]調表!$E20,4))))), "") -> ň | L19: =IFERROR( _xlfn.CONCAT("l", "u", _xlfn.UNICHAR(HEX2DEC(RIGHT([1]調表!$O8,4))), "n"), "") -> lún | M19: =IFERROR( _xlfn.CONCAT("n", "g", "o", _xlfn.UNICHAR(HEX2DEC(RIGHT([1]調表!$O8,4))), "o"), "") -> ngóo
B20: 5 | C20: =IFERROR( _xlfn.CONCAT(D$2, IF([1]調表!$E21="", "", _xlfn.UNICHAR(HEX2DEC(RIGHT([1]調表!$E21,4))))), "") -> à | D20: =IFERROR( _xlfn.CONCAT(E$2, IF([1]調表!$E21="", "", _xlfn.UNICHAR(HEX2DEC(RIGHT([1]調表!$E21,4))))), "") -> ì | E20: =IFERROR( _xlfn.CONCAT(F$2, IF([1]調表!$E21="", "", _xlfn.UNICHAR(HEX2DEC(RIGHT([1]調表!$E21,4))))), "") -> ù | F20: =IFERROR( _xlfn.CONCAT(G$2, IF([1]調表!$E21="", "", _xlfn.UNICHAR(HEX2DEC(RIGHT([1]調表!$E21,4))))), "") -> è | G20: =IFERROR( _xlfn.CONCAT(H$2, IF([1]調表!$E21="", "", _xlfn.UNICHAR(HEX2DEC(RIGHT([1]調表!$E21,4))))), "") -> ò | H20: =IFERROR( _xlfn.CONCAT(I$2, IF([1]調表!$E21="", "", _xlfn.UNICHAR(HEX2DEC(RIGHT([1]調表!$E21,4))))), "") -> m̀ | I20: =IFERROR( _xlfn.CONCAT(J$2, IF([1]調表!$E21="", "", _xlfn.UNICHAR(HEX2DEC(RIGHT([1]調表!$E21,4))))), "") -> ǹ | L20: =IFERROR( _xlfn.CONCAT("l", "u", _xlfn.UNICHAR(HEX2DEC(RIGHT([1]調表!$O11,4))), "n"), "") -> lǔn | M20: =IFERROR( _xlfn.CONCAT("n", "g", "o", _xlfn.UNICHAR(HEX2DEC(RIGHT([1]調表!$O11,4))), "o"), "") -> ngǒo
B21: 6 | C21: =IFERROR( _xlfn.CONCAT(D$2, IF([1]調表!$E22="", "", _xlfn.UNICHAR(HEX2DEC(RIGHT([1]調表!$E22,4))))), "") -> â | D21: =IFERROR( _xlfn.CONCAT(E$2, IF([1]調表!$E22="", "", _xlfn.UNICHAR(HEX2DEC(RIGHT([1]調表!$E22,4))))), "") -> î | E21: =IFERROR( _xlfn.CONCAT(F$2, IF([1]調表!$E22="", "", _xlfn.UNICHAR(HEX2DEC(RIGHT([1]調表!$E22,4))))), "") -> û | F21: =IFERROR( _xlfn.CONCAT(G$2, IF([1]調表!$E22="", "", _xlfn.UNICHAR(HEX2DEC(RIGHT([1]調表!$E22,4))))), "") -> ê | G21: =IFERROR( _xlfn.CONCAT(H$2, IF([1]調表!$E22="", "", _xlfn.UNICHAR(HEX2DEC(RIGHT([1]調表!$E22,4))))), "") -> ô | H21: =IFERROR( _xlfn.CONCAT(I$2, IF([1]調表!$E22="", "", _xlfn.UNICHAR(HEX2DEC(RIGHT([1]調表!$E22,4))))), "") -> m̂ | I21: =IFERROR( _xlfn.CONCAT(J$2, IF([1]調表!$E22="", "", _xlfn.UNICHAR(HEX2DEC(RIGHT([1]調表!$E22,4))))), "") -> n̂ | L21: =IFERROR( _xlfn.CONCAT("l", "u", _xlfn.UNICHAR(HEX2DEC(RIGHT([1]調表!$O5,4))), "n"), "") -> lûn | M21: =IFERROR( _xlfn.CONCAT("n", "g", "o", _xlfn.UNICHAR(HEX2DEC(RIGHT([1]調表!$O5,4))), "o"), "") -> ngôo
B22: 7 | C22: =IFERROR( _xlfn.CONCAT(D$2, IF([1]調表!$E23="", "", _xlfn.UNICHAR(HEX2DEC(RIGHT([1]調表!$E23,4))))), "") -> ā | D22: =IFERROR( _xlfn.CONCAT(E$2, IF([1]調表!$E23="", "", _xlfn.UNICHAR(HEX2DEC(RIGHT([1]調表!$E23,4))))), "") -> ī | E22: =IFERROR( _xlfn.CONCAT(F$2, IF([1]調表!$E23="", "", _xlfn.UNICHAR(HEX2DEC(RIGHT([1]調表!$E23,4))))), "") -> ū | F22: =IFERROR( _xlfn.CONCAT(G$2, IF([1]調表!$E23="", "", _xlfn.UNICHAR(HEX2DEC(RIGHT([1]調表!$E23,4))))), "") -> ē | G22: =IFERROR( _xlfn.CONCAT(H$2, IF([1]調表!$E23="", "", _xlfn.UNICHAR(HEX2DEC(RIGHT([1]調表!$E23,4))))), "") -> ō | H22: =IFERROR( _xlfn.CONCAT(I$2, IF([1]調表!$E23="", "", _xlfn.UNICHAR(HEX2DEC(RIGHT([1]調表!$E23,4))))), "") -> m̄ | I22: =IFERROR( _xlfn.CONCAT(J$2, IF([1]調表!$E23="", "", _xlfn.UNICHAR(HEX2DEC(RIGHT([1]調表!$E23,4))))), "") -> n̄ | L22: =IFERROR( _xlfn.CONCAT("l", "u", _xlfn.UNICHAR(HEX2DEC(RIGHT([1]調表!$O10,4))), "n"), "") -> lún | M22: =IFERROR( _xlfn.CONCAT("n", "g", "o", _xlfn.UNICHAR(HEX2DEC(RIGHT([1]調表!$O10,4))), "o"), "") -> ngóo
B23: 8 | C23: =IFERROR( _xlfn.CONCAT(D$2, IF([1]調表!$E24="", "", _xlfn.UNICHAR(HEX2DEC(RIGHT([1]調表!$E24,4))))), "") -> á | D23: =IFERROR( _xlfn.CONCAT(E$2, IF([1]調表!$E24="", "", _xlfn.UNICHAR(HEX2DEC(RIGHT([1]調表!$E24,4))))), "") -> í | E23: =IFERROR( _xlfn.CONCAT(F$2, IF([1]調表!$E24="", "", _xlfn.UNICHAR(HEX2DEC(RIGHT([1]調表!$E24,4))))), "") -> ú | F23: =IFERROR( _xlfn.CONCAT(G$2, IF([1]調表!$E24="", "", _xlfn.UNICHAR(HEX2DEC(RIGHT([1]調表!$E24,4))))), "") -> é | G23: =IFERROR( _xlfn.CONCAT(H$2, IF([1]調表!$E24="", "", _xlfn.UNICHAR(HEX2DEC(RIGHT([1]調表!$E24,4))))), "") -> ó | H23: =IFERROR( _xlfn.CONCAT(I$2, IF([1]調表!$E24="", "", _xlfn.UNICHAR(HEX2DEC(RIGHT([1]調表!$E24,4))))), "") -> ḿ | I23: =IFERROR( _xlfn.CONCAT(J$2, IF([1]調表!$E24="", "", _xlfn.UNICHAR(HEX2DEC(RIGHT([1]調表!$E24,4))))), "") -> ń
C28: a | D28: i | E28: u | F28: e | G28: o | H28: m | I28: n | L28: o | M28: o
B29: 1 | C29: =IFERROR( _xlfn.CONCAT(D$2, IF([1]調表!$E28="", "", _xlfn.UNICHAR(HEX2DEC(RIGHT([1]調表!$E28,4))))), "") -> a | D29: =IFERROR( _xlfn.CONCAT(E$2, IF([1]調表!$E28="", "", _xlfn.UNICHAR(HEX2DEC(RIGHT([1]調表!$E28,4))))), "") -> i | E29: =IFERROR( _xlfn.CONCAT(F$2, IF([1]調表!$E28="", "", _xlfn.UNICHAR(HEX2DEC(RIGHT([1]調表!$E28,4))))), "") -> u | F29: =IFERROR( _xlfn.CONCAT(G$2, IF([1]調表!$E28="", "", _xlfn.UNICHAR(HEX2DEC(RIGHT([1]調表!$E28,4))))), "") -> e | G29: =IFERROR( _xlfn.CONCAT(H$2, IF([1]調表!$E28="", "", _xlfn.UNICHAR(HEX2DEC(RIGHT([1]調表!$E28,4))))), "") -> o | H29: =IFERROR( _xlfn.CONCAT(I$2, IF([1]調表!$E28="", "", _xlfn.UNICHAR(HEX2DEC(RIGHT([1]調表!$E28,4))))), "") -> m | I29: =IFERROR( _xlfn.CONCAT(J$2, IF([1]調表!$E28="", "", _xlfn.UNICHAR(HEX2DEC(RIGHT([1]調表!$E28,4))))), "") -> n | L29: =IFERROR( _xlfn.CONCAT("l", "o", IF([1]調表!$M4="", "", _xlfn.UNICHAR(HEX2DEC(RIGHT([1]調表!$M4,4))))), "") -> lo | M29: =IFERROR( _xlfn.CONCAT("l", "o", IF([1]調表!$M4="", "", _xlfn.UNICHAR(HEX2DEC(RIGHT([1]調表!$M4,4)))), "r", IF(OR(B29=4, B29=8), "k", "")), "") -> lor
B30: 2 | C30: =IFERROR( _xlfn.CONCAT(D$2, IF([1]調表!$M3="", "", _xlfn.UNICHAR(HEX2DEC(RIGHT([1]調表!$M3,4))))), "") | D30: =IFERROR( _xlfn.CONCAT(E$2, IF([1]調表!$M3="", "", _xlfn.UNICHAR(HEX2DEC(RIGHT([1]調表!$M3,4))))), "") | E30: =IFERROR( _xlfn.CONCAT(F$2, IF([1]調表!$M3="", "", _xlfn.UNICHAR(HEX2DEC(RIGHT([1]調表!$M3,4))))), "") | F30: =IFERROR( _xlfn.CONCAT(G$2, IF([1]調表!$M3="", "", _xlfn.UNICHAR(HEX2DEC(RIGHT([1]調表!$M3,4))))), "") | G30: =IFERROR( _xlfn.CONCAT(H$2, IF([1]調表!$M3="", "", _xlfn.UNICHAR(HEX2DEC(RIGHT([1]調表!$M3,4))))), "") | H30: =IFERROR( _xlfn.CONCAT(I$2, IF([1]調表!$M3="", "", _xlfn.UNICHAR(HEX2DEC(RIGHT([1]調表!$M3,4))))), "") | I30: =IFERROR( _xlfn.CONCAT(J$2, IF([1]調表!$M3="", "", _xlfn.UNICHAR(HEX2DEC(RIGHT([1]調表!$M3,4))))), "") | L30: =IFERROR( _xlfn.CONCAT("l", "o", IF([1]調表!$M6="", "", _xlfn.UNICHAR(HEX2DEC(RIGHT([1]調表!$M6,4))))), "") -> ló | M30: =IFERROR( _xlfn.CONCAT("l", "o", IF([1]調表!$M6="", "", _xlfn.UNICHAR(HEX2DEC(RIGHT([1]調表!$M6,4)))), "r", IF(OR(B30=4, B30=8), "k", "")), "") -> lór
B31: 3 | C31: =IFERROR( _xlfn.CONCAT(D$2, IF([1]調表!$M4="", "", _xlfn.UNICHAR(HEX2DEC(RIGHT([1]調表!$M4,4))))), "") -> a | D31: =IFERROR( _xlfn.CONCAT(E$2, IF([1]調表!$M4="", "", _xlfn.UNICHAR(HEX2DEC(RIGHT([1]調表!$M4,4))))), "") -> i | E31: =IFERROR( _xlfn.CONCAT(F$2, IF([1]調表!$M4="", "", _xlfn.UNICHAR(HEX2DEC(RIGHT([1]調表!$M4,4))))), "") -> u | F31: =IFERROR( _xlfn.CONCAT(G$2, IF([1]調表!$M4="", "", _xlfn.UNICHAR(HEX2DEC(RIGHT([1]調表!$M4,4))))), "") -> e | G31: =IFERROR( _xlfn.CONCAT(H$2, IF([1]調表!$M4="", "", _xlfn.UNICHAR(HEX2DEC(RIGHT([1]調表!$M4,4))))), "") -> o | H31: =IFERROR( _xlfn.CONCAT(I$2, IF([1]調表!$M4="", "", _xlfn.UNICHAR(HEX2DEC(RIGHT([1]調表!$M4,4))))), "") -> m | I31: =IFERROR( _xlfn.CONCAT(J$2, IF([1]調表!$M4="", "", _xlfn.UNICHAR(HEX2DEC(RIGHT([1]調表!$M4,4))))), "") -> n | L31: =IFERROR( _xlfn.CONCAT("l", "o", IF([1]調表!$M7="", "", _xlfn.UNICHAR(HEX2DEC(RIGHT([1]調表!$M7,4))))), "") -> lò | M31: =IFERROR( _xlfn.CONCAT("l", "o", IF([1]調表!$M7="", "", _xlfn.UNICHAR(HEX2DEC(RIGHT([1]調表!$M7,4)))), "r", IF(OR(B31=4, B31=8), "k", "")), "") -> lòr
B32: 4 | C32: =IFERROR( _xlfn.CONCAT(D$2, IF([1]調表!$M6="", "", _xlfn.UNICHAR(HEX2DEC(RIGHT([1]調表!$M6,4))))), "") -> á | D32: =IFERROR( _xlfn.CONCAT(E$2, IF([1]調表!$M6="", "", _xlfn.UNICHAR(HEX2DEC(RIGHT([1]調表!$M6,4))))), "") -> í | E32: =IFERROR( _xlfn.CONCAT(F$2, IF([1]調表!$M6="", "", _xlfn.UNICHAR(HEX2DEC(RIGHT([1]調表!$M6,4))))), "") -> ú | F32: =IFERROR( _xlfn.CONCAT(G$2, IF([1]調表!$M6="", "", _xlfn.UNICHAR(HEX2DEC(RIGHT([1]調表!$M6,4))))), "") -> é | G32: =IFERROR( _xlfn.CONCAT(H$2, IF([1]調表!$M6="", "", _xlfn.UNICHAR(HEX2DEC(RIGHT([1]調表!$M6,4))))), "") -> ó | H32: =IFERROR( _xlfn.CONCAT(I$2, IF([1]調表!$M6="", "", _xlfn.UNICHAR(HEX2DEC(RIGHT([1]調表!$M6,4))))), "") -> ḿ | I32: =IFERROR( _xlfn.CONCAT(J$2, IF([1]調表!$M6="", "", _xlfn.UNICHAR(HEX2DEC(RIGHT([1]調表!$M6,4))))), "") -> ń | L32: =IFERROR( _xlfn.CONCAT("l", "o", IF([1]調表!$M8="", "", _xlfn.UNICHAR(HEX2DEC(RIGHT([1]調表!$M8,4)))), "k"), "") -> lók | M32: =IFERROR( _xlfn.CONCAT("l", "o", IF([1]調表!$M8="", "", _xlfn.UNICHAR(HEX2DEC(RIGHT([1]調表!$M8,4)))), "r", IF(OR(B32=4, B32=8), "k", "")), "") -> lórk
B33: 5 | C33: =IFERROR( _xlfn.CONCAT(D$2, IF([1]調表!$M7="", "", _xlfn.UNICHAR(HEX2DEC(RIGHT([1]調表!$M7,4))))), "") -> à | D33: =IFERROR( _xlfn.CONCAT(E$2, IF([1]調表!$M7="", "", _xlfn.UNICHAR(HEX2DEC(RIGHT([1]調表!$M7,4))))), "") -> ì | E33: =IFERROR( _xlfn.CONCAT(F$2, IF([1]調表!$M7="", "", _xlfn.UNICHAR(HEX2DEC(RIGHT([1]調表!$M7,4))))), "") -> ù | F33: =IFERROR( _xlfn.CONCAT(G$2, IF([1]調表!$M7="", "", _xlfn.UNICHAR(HEX2DEC(RIGHT([1]調表!$M7,4))))), "") -> è | G33: =IFERROR( _xlfn.CONCAT(H$2, IF([1]調表!$M7="", "", _xlfn.UNICHAR(HEX2DEC(RIGHT([1]調表!$M7,4))))), "") -> ò | H33: =IFERROR( _xlfn.CONCAT(I$2, IF([1]調表!$M7="", "", _xlfn.UNICHAR(HEX2DEC(RIGHT([1]調表!$M7,4))))), "") -> m̀ | I33: =IFERROR( _xlfn.CONCAT(J$2, IF([1]調表!$M7="", "", _xlfn.UNICHAR(HEX2DEC(RIGHT([1]調表!$M7,4))))), "") -> ǹ | L33: =IFERROR( _xlfn.CONCAT("l", "o", IF([1]調表!$M9="", "", _xlfn.UNICHAR(HEX2DEC(RIGHT([1]調表!$M9,4))))), "") -> lǒ | M33: =IFERROR( _xlfn.CONCAT("l", "o", IF([1]調表!$M9="", "", _xlfn.UNICHAR(HEX2DEC(RIGHT([1]調表!$M9,4)))), "r", IF(OR(B33=4, B33=8), "k", "")), "") -> lǒr
B34: 6 | C34: =IFERROR( _xlfn.CONCAT(D$2, IF([1]調表!$M8="", "", _xlfn.UNICHAR(HEX2DEC(RIGHT([1]調表!$M8,4))))), "") -> á | D34: =IFERROR( _xlfn.CONCAT(E$2, IF([1]調表!$M8="", "", _xlfn.UNICHAR(HEX2DEC(RIGHT([1]調表!$M8,4))))), "") -> í | E34: =IFERROR( _xlfn.CONCAT(F$2, IF([1]調表!$M8="", "", _xlfn.UNICHAR(HEX2DEC(RIGHT([1]調表!$M8,4))))), "") -> ú | F34: =IFERROR( _xlfn.CONCAT(G$2, IF([1]調表!$M8="", "", _xlfn.UNICHAR(HEX2DEC(RIGHT([1]調表!$M8,4))))), "") -> é | G34: =IFERROR( _xlfn.CONCAT(H$2, IF([1]調表!$M8="", "", _xlfn.UNICHAR(HEX2DEC(RIGHT([1]調表!$M8,4))))), "") -> ó | H34: =IFERROR( _xlfn.CONCAT(I$2, IF([1]調表!$M8="", "", _xlfn.UNICHAR(HEX2DEC(RIGHT([1]調表!$M8,4))))), "") -> ḿ | I34: =IFERROR( _xlfn.CONCAT(J$2, IF([1]調表!$M8="", "", _xlfn.UNICHAR(HEX2DEC(RIGHT([1]調表!$M8,4))))), "") -> ń | L34: =IFERROR( _xlfn.CONCAT("l", "o", IF([1]調表!$M11="", "", _xlfn.UNICHAR(HEX2DEC(RIGHT([1]調表!$M11,4))))), "") -> ló | M34: =IFERROR( _xlfn.CONCAT("l", "o", IF([1]調表!$M11="", "", _xlfn.UNICHAR(HEX2DEC(RIGHT([1]調表!$M11,4)))), "r", IF(OR(B34=4, B34=8), "k", "")), "") -> lór
B35: 7 | C35: =IFERROR( _xlfn.CONCAT(D$2, IF([1]調表!$M9="", "", _xlfn.UNICHAR(HEX2DEC(RIGHT([1]調表!$M9,4))))), "") -> ǎ | D35: =IFERROR( _xlfn.CONCAT(E$2, IF([1]調表!$M9="", "", _xlfn.UNICHAR(HEX2DEC(RIGHT([1]調表!$M9,4))))), "") -> ǐ | E35: =IFERROR( _xlfn.CONCAT(F$2, IF([1]調表!$M9="", "", _xlfn.UNICHAR(HEX2DEC(RIGHT([1]調表!$M9,4))))), "") -> ǔ | F35: =IFERROR( _xlfn.CONCAT(G$2, IF([1]調表!$M9="", "", _xlfn.UNICHAR(HEX2DEC(RIGHT([1]調表!$M9,4))))), "") -> ě | G35: =IFERROR( _xlfn.CONCAT(H$2, IF([1]調表!$M9="", "", _xlfn.UNICHAR(HEX2DEC(RIGHT([1]調表!$M9,4))))), "") -> ǒ | H35: =IFERROR( _xlfn.CONCAT(I$2, IF([1]調表!$M9="", "", _xlfn.UNICHAR(HEX2DEC(RIGHT([1]調表!$M9,4))))), "") -> m̌ | I35: =IFERROR( _xlfn.CONCAT(J$2, IF([1]調表!$M9="", "", _xlfn.UNICHAR(HEX2DEC(RIGHT([1]調表!$M9,4))))), "") -> ň | L35: =IFERROR( _xlfn.CONCAT("l", "o", IF([1]調表!$M5="", "", _xlfn.UNICHAR(HEX2DEC(RIGHT([1]調表!$M5,4))))), "") -> lō | M35: =IFERROR( _xlfn.CONCAT("l", "o", IF([1]調表!$M5="", "", _xlfn.UNICHAR(HEX2DEC(RIGHT([1]調表!$M5,4)))), "r", IF(OR(B35=4, B35=8), "k", "")), "") -> lōr
B36: 8 | C36: =IFERROR( _xlfn.CONCAT(D$2, IF([1]調表!$M11="", "", _xlfn.UNICHAR(HEX2DEC(RIGHT([1]調表!$M11,4))))), "") -> á | D36: =IFERROR( _xlfn.CONCAT(E$2, IF([1]調表!$M11="", "", _xlfn.UNICHAR(HEX2DEC(RIGHT([1]調表!$M11,4))))), "") -> í | E36: =IFERROR( _xlfn.CONCAT(F$2, IF([1]調表!$M11="", "", _xlfn.UNICHAR(HEX2DEC(RIGHT([1]調表!$M11,4))))), "") -> ú | F36: =IFERROR( _xlfn.CONCAT(G$2, IF([1]調表!$M11="", "", _xlfn.UNICHAR(HEX2DEC(RIGHT([1]調表!$M11,4))))), "") -> é | G36: =IFERROR( _xlfn.CONCAT(H$2, IF([1]調表!$M11="", "", _xlfn.UNICHAR(HEX2DEC(RIGHT([1]調表!$M11,4))))), "") -> ó | H36: =IFERROR( _xlfn.CONCAT(I$2, IF([1]調表!$M11="", "", _xlfn.UNICHAR(HEX2DEC(RIGHT([1]調表!$M11,4))))), "") -> ḿ | I36: =IFERROR( _xlfn.CONCAT(J$2, IF([1]調表!$M11="", "", _xlfn.UNICHAR(HEX2DEC(RIGHT([1]調表!$M11,4))))), "") -> ń | L36: =IFERROR( _xlfn.CONCAT("l", "o", IF([1]調表!$M10="", "", _xlfn.UNICHAR(HEX2DEC(RIGHT([1]調表!$M10,4)))), "k"), "") -> lo̍k | M36: =IFERROR( _xlfn.CONCAT("l", "o", IF([1]調表!$M10="", "", _xlfn.UNICHAR(HEX2DEC(RIGHT([1]調表!$M10,4)))), "r", IF(OR(B36=4, B36=8), "k", "")), "") -> lo̍rk

Sheet 調號
B2: 調號 | C2: 上標值
B3: 1 | C3: ¹
B4: 2 | C4: ²
B5: 3 | C5: ³
B6: 4 | C6: ⁴
B7: 5 | C7: ⁵
B8: 6 | C8: ⁶
B9: 7 | C9: ⁷
B10: 8 | C10: ⁸
B11: 9 | C11: ⁹
B12: 0 | C12: ⁰

Sheet HEX數值
B2: Unicode 編碼 | C2: 拼音字母 | D2: 組合結果 | E2: 註釋 | G2: 十進制編碼 | H2: Unicode 編碼 | J2: 陰上（二聲） | K2: ́ (U+0301) | L2: =FIND("(",$K2) -> 3 | M2: =FIND(")",$K2) -> 10 | N2: =MID(K2,L2+1,M2-L2-1) -> U+0301 | O2: =FIND("（",$J2) -> 3 | P2: =FIND("）",$J2) -> 6 | Q2: =MID(J2,O2+1,2) -> 二聲 | R2: =Q2 & "（" & LEFT(J2,2) & "）" -> 二聲（陰上）
B3: U+0303 | C3: a | D3: =_xlfn.CONCAT(C3,_xlfn.UNICHAR(HEX2DEC(RIGHT(B3,4)))) -> ã | G3: 771 | H3: ="U+" & DEC2HEX(G3,4) -> U+0303 | J3: 陰去（三聲） | K3: ̀ (U+0300) | L3: =FIND("(",$K3) -> 3 | M3: =FIND(")",$K3) -> 10 | N3: =MID(K3,L3+1,M3-L3-1) -> U+0300 | O3: =FIND("（",$J3) -> 3 | P3: =FIND("）",$J3) -> 6 | Q3: =MID(J3,O3+1,2) -> 三聲 | R3: =Q3 & "（" & LEFT(J3,2) & "）" -> 三聲（陰去）
B4: U+0294 | C4: a | D4: =_xlfn.CONCAT(C4,_xlfn.UNICHAR(HEX2DEC(RIGHT(B4,4)))) -> aʔ | G4: 660 | H4: ="U+" & DEC2HEX(G4,4) -> U+0294 | J4: 陽平（五聲） | K4: ̂ (U+0302) | L4: =FIND("(",$K4) -> 3 | M4: =FIND(")",$K4) -> 10 | N4: =MID(K4,L4+1,M4-L4-1) -> U+0302 | O4: =FIND("（",$J4) -> 3 | P4: =FIND("）",$J4) -> 6 | Q4: =MID(J4,O4+1,2) -> 五聲 | R4: =Q4 & "（" & LEFT(J4,2) & "）" -> 五聲（陽平）
B5: U+0358 | C5: o | D5: =_xlfn.CONCAT(C5,_xlfn.UNICHAR(HEX2DEC(RIGHT(B5,4)))) -> o͘ | G5: 856 | H5: ="U+" & DEC2HEX(G5,4) -> U+0358 | J5: 陽上（六聲） | K5: ̌ (U+030C) | L5: =FIND("(",$K5) -> 3 | M5: =FIND(")",$K5) -> 10 | N5: =MID(K5,L5+1,M5-L5-1) -> U+030C | O5: =FIND("（",$J5) -> 3 | P5: =FIND("）",$J5) -> 6 | Q5: =MID(J5,O5+1,2) -> 六聲 | R5: =Q5 & "（" & LEFT(J5,2) & "）" -> 六聲（陽上）
J6: 陽去（七聲） | K6: ̄ (U+0304) | L6: =FIND("(",$K6) -> 3 | M6: =FIND(")",$K6) -> 10 | N6: =MID(K6,L6+1,M6-L6-1) -> U+0304 | O6: =FIND("（",$J6) -> 3 | P6: =FIND("）",$J6) -> 6 | Q6: =MID(J6,O6+1,2) -> 七聲 | R6: =Q6 & "（" & LEFT(J6,2) & "）" -> 七聲（陽去）
B7: 台羅調符 | J7: 陽入（八聲） | K7: ̍h (U+030D) | L7: =FIND("(",$K7) -> 4 | M7: =FIND(")",$K7) -> 11 | N7: =MID(K7,L7+1,M7-L7-1) -> U+030D | O7: =FIND("（",$J7) -> 3 | P7: =FIND("）",$J7) -> 6 | Q7: =MID(J7,O7+1,2) -> 八聲 | R7: =Q7 & "（" & LEFT(J7,2) & "）" -> 八聲（陽入）
J8: （九聲） | K8: ̋ (U+030B) | L8: =FIND("(",$K8) -> 3 | M8: =FIND(")",$K8) -> 10 | N8: =MID(K8,L8+1,M8-L8-1) -> U+030B | O8: =FIND("（",$J8) -> 1 | P8: =FIND("）",$J8) -> 4 | Q8: =MID(J8,O8+1,2) -> 九聲
B9: Unicode 編碼 | C9: 拼音字母 | D9: 組合結果 | E9: 註釋
B10: U+0301 | C10: a | D10: =_xlfn.CONCAT(C10,_xlfn.UNICHAR(HEX2DEC(RIGHT(B10,4)))) -> á | E10: 二聲（陰上）
B11: U+0300 | C11: a | D11: =_xlfn.CONCAT(C11,_xlfn.UNICHAR(HEX2DEC(RIGHT(B11,4)))) -> à | E11: 三聲（陰去）
B12: U+0302 | C12: a | D12: =_xlfn.CONCAT(C12,_xlfn.UNICHAR(HEX2DEC(RIGHT(B12,4)))) -> â | E12: 五聲（陽平）
B13: U+030C | C13: a | D13: =_xlfn.CONCAT(C13,_xlfn.UNICHAR(HEX2DEC(RIGHT(B13,4)))) -> ǎ | E13: 六聲（陽上）
B14: U+0304 | C14: a | D14: =_xlfn.CONCAT(C14,_xlfn.UNICHAR(HEX2DEC(RIGHT(B14,4)))) -> ā | E14: 七聲（陽去）
B15: U+030D | C15: a | D15: =_xlfn.CONCAT(C15,_xlfn.UNICHAR(HEX2DEC(RIGHT(B15,4)))) -> a̍ | E15: 八聲（陽入）
B16: U+030B | C16: a | D16: =_xlfn.CONCAT(C16,_xlfn.UNICHAR(HEX2DEC(RIGHT(B16,4)))) -> a̋ | E16: 陽入（八聲）
B17: U+030B | C17: a | D17: =_xlfn.CONCAT(C17,_xlfn.UNICHAR(HEX2DEC(RIGHT(B17,4)))) -> a̋ | E17: 九聲

Sheet DEC數值
A1: Unicode字元 | B1: DEC | C1: Unicode 編碼
A2: á | B2: =_xlfn.UNICODE(A2) -> 225 | C2: ="U+" & DEC2HEX(B2,4) -> U+00E1
A3: ô | B3: =_xlfn.UNICODE(A3) -> 244 | C3: ="U+" & DEC2HEX(B3,4) -> U+00F4
A4: o͘ | B4: =_xlfn.UNICODE(A4) -> 111 | C4: ="U+" & DEC2HEX(B4,4) -> U+006F
A5: ㄥ | B5: =_xlfn.UNICODE(A5) -> 12581 | C5: ="U+" & DEC2HEX(B5,4) -> U+3125
A6: ㆭ | B6: =_xlfn.UNICODE(A6) -> 12717 | C6: ="U+" & DEC2HEX(B6,4) -> U+31AD
A7: ə | B7: =_xlfn.UNICODE(A7) -> 601 | C7: ="U+" & DEC2HEX(B7,4) -> U+0259
A8: ŋ | B8: =_xlfn.UNICODE(A8) -> 331 | C8: ="U+" & DEC2HEX(B8,4) -> U+014B
A13: əŋ | B13: ㄥ
A14: ŋ̍ | B14: ㆭ

Sheet 鼻音韻母
B3: Unicode 編碼 | C3: 拼音字母 | D3: 組合結果 | J3: aɪʔ
B4: U+0303 | C4: i | D4: =_xlfn.CONCAT(C4,_xlfn.UNICHAR(HEX2DEC(RIGHT(B4,4)))) -> ĩ
B5: U+0303 | C5: a | D5: =_xlfn.CONCAT(C5,_xlfn.UNICHAR(HEX2DEC(RIGHT(B5,4)))) -> ã
B6: U+0303 | C6: u | D6: =_xlfn.CONCAT(C6,_xlfn.UNICHAR(HEX2DEC(RIGHT(B6,4)))) -> ũ
C8: 韻母標音 | D8: 完整格式 | E8: 簡要格式
C9: i | D9: =D4 -> ĩ | E9: =D9 -> ĩ | G9: =D9 & ", " & D10 & ", " & D11 -> ĩ, ĩã, ĩãũ
C10: ia | D10: =_xlfn.CONCAT(D4,D5) -> ĩã | E10: =_xlfn.CONCAT("i",D5) -> iã | G10: =D10 & ", " & E10 & ", " & E11 -> ĩã, iã, iãu
C11: iau | D11: =_xlfn.CONCAT(D9,D5,D6) -> ĩãũ | E11: =_xlfn.CONCAT("i",D5,"u") -> iãu

Sheet 字元
A1: Unicode字元 | B1: DEC | C1: Unicode 編碼 | D1: 附註
A2: ʔ | B2: =_xlfn.UNICODE(A2) -> 660 | C2: ="U+" & DEC2HEX(B2,4) -> U+0294 | D2: 入聲韻尾 h | G2: ap̚ | H2: =RIGHT(G2) -> ̚
A3: ̚ | B3: =_xlfn.UNICODE(A3) -> 794 | C3: ="U+" & DEC2HEX(B3,4) -> U+031A | D3: ="入聲韻尾 " & RIGHT(G2,2) -> 入聲韻尾 p̚ | G3: aʔ | H3: =RIGHT(G3) -> ʔ
A4: ̃ | B4: =_xlfn.UNICODE(A4) -> 771 | C4: ="U+" & DEC2HEX(B4,4) -> U+0303 | D4: ="鼻音韻母 " & G4 -> 鼻音韻母 ã | G4: ã | H4: =RIGHT(G4) -> ̃
A5: ʊ | B5: =_xlfn.UNICODE(A5) -> 650 | C5: ="U+" & DEC2HEX(B5,4) -> U+028A | G5: aʊ | H5: =RIGHT(G5) -> ʊ
A6: ɪ | B6: =_xlfn.UNICODE(A6) -> 618 | C6: ="U+" & DEC2HEX(B6,4) -> U+026A | G6: aɪ | H6: =RIGHT(G6) -> ɪ
A7: ŋ | B7: =_xlfn.UNICODE(A7) -> 331 | C7: ="U+" & DEC2HEX(B7,4) -> U+014B
A8: ə | B8: =_xlfn.UNICODE(A8) -> 601 | C8: ="U+" & DEC2HEX(B8,4) -> U+0259
A9: ɛ | B9: =_xlfn.UNICODE(A9) -> 603 | C9: ="U+" & DEC2HEX(B9,4) -> U+025B | G9: əŋ | H9: ㄥ
A10: ɔ | B10: =_xlfn.UNICODE(A10) -> 596 | C10: ="U+" & DEC2HEX(B10,4) -> U+0254 | G10: ŋ̍ | H10: ㆭ
A11: m̩ | B11: =_xlfn.UNICODE(A11) -> 109 | C11: ="U+" & DEC2HEX(B11,4) -> U+006D
A12: ŋ̍ | B12: =_xlfn.UNICODE(A12) -> 331 | C12: ="U+" & DEC2HEX(B12,4) -> U+014B
A13: ⁿ | B13: =_xlfn.UNICODE(A13) -> 8319 | C13: ="U+" & DEC2HEX(B13,4) -> U+207F
A16: ㄥ | B16: =_xlfn.UNICODE(A16) -> 12581 | C16: ="U+" & DEC2HEX(B16,4) -> U+3125
A17: ㆭ | B17: =_xlfn.UNICODE(A17) -> 12717 | C17: ="U+" & DEC2HEX(B17,4) -> U+31AD
