Workbook
Name 方音符號調符: 聲調對照表!$I$2:$I$9
Name 古漢語調值: 聲調對照表!$K$2:$K$9
Name 台羅調名: 聲調對照表!$E$2:$E$9
Name 台羅調值: 聲調對照表!$J$2:$J$9
Name 台羅調號: 聲調對照表!$F$2:$F$9
Name 台羅變調: 聲調對照表!$G$2:$G$9
Name 雅俗通聲調: 聲調對照表!$C$2:$C$9
Name 漢語四聲: 聲調對照表!$A$2:$A$9
Name 漢語變調: 聲調對照表!$G$2:$G$9
Name 閩拼八聲調: 聲調對照表!$H$2:$H$9
Name 廣韻聲調: 聲調對照表!$B$2:$B$9

Sheet 切語查音
B4: 方久 | D4: 切語 | E4: 方音符號 | F4: 台語音標 | G4: 聲調 | H4: 聲母 | I4: 聲母標音 | J4: 七音 | K4: 清濁 | L4: 發送收 | M4: 韻母 | N4: 韻母標音 | O4: 攝 | P4: 呼 | Q4: 等 | R4: 調 | S4: 韻 | T4: 廣韻聲調 | U4: 四声八調 | V4: 濁上調校正
B6: 上字 | D6: =LEFT( TRIM($B$4) ) -> 方 | E6: {=INDEX(聲母對照表[方音符號], MATCH(TRUE, EXACT(F6, 聲母對照表[台羅拼音]), 0))} -> ㄏ | F6: =F11 -> h | G6: =V8 -> 2 | H6: =E11 -> 非 | I6: =F11 -> h | J6: =G11 -> 脣音 | K6: =H11 -> 全清 | L6: =I11 -> 發聲
B7: 下字 | D7: =RIGHT( TRIM($B$4) ) -> 久 | E7: {=INDEX(韻母對照表[方音符號], MATCH(TRUE, EXACT(F7, 韻母對照表[台羅拼音]), 0))} -> ㄧㄨ | F7: =L11 -> iu | M7: =K11 -> 尤 | N7: =P11 -> 三 | O7: =Q11 -> 上 | P7: =R11 -> 清上 | Q7: =S11 -> 2 | R7: =T11 -> 2 | S7: =U11 -> 0
B8: 切語 | D8: =B2 -> 0 | E8: =_xlfn.CONCAT(E6,E7, _xlfn.XLOOKUP(G6, 台羅調號, 方音符號調符)) -> ㄏㄧㄨˋ | F8: =_xlfn.CONCAT(F6,F7,G6) -> hiu2 | H8: =_xlfn.CONCAT(H6,H7) -> 非 | I8: =_xlfn.CONCAT(I6,I7) -> h | J8: =_xlfn.CONCAT(J6,J7) -> 脣音 | K8: =_xlfn.CONCAT(K6,K7) -> 全清 | L8: =_xlfn.CONCAT(L6,L7) -> 發聲 | M8: =_xlfn.CONCAT(M6,M7) -> 尤 | N8: =_xlfn.CONCAT(N6,N7) -> 三 | O8: =_xlfn.CONCAT(O6,O7) -> 上 | ... S8: =_xlfn.CONCAT(S6,S7) -> 0 | T8: =R11 -> 清上 | U8: =S11 -> 2 | V8: =T11 -> 2
B10: 1 | D10: 上字 | E10: 聲母 | F10: 聲母標音 | G10: 七聲類 | H10: 清濁 | I10: 發送收 | J10: 下字 | K10: 韻母 | L10: 韻母標音 | M10: 等呼 | N10: 攝 | O10: 呼 | P10: 等 | Q10: 調 | R10: 廣韻聲調 | S10: 四声八調 | T10: 濁上調校正
B11: 1 | D11: {=_xlfn.CHOOSECOLS(_xlfn._xlws.FILTER(字表[#Data], (字表[上字]=D6) * (字表[下字]=D7), ""), MATCH({"上字","聲母","聲母標音","七聲類","清濁","發送收","下字","韻母","韻母標音","等呼","攝","呼","等","調","廣韻聲調","四声八調","濁上調校正"}, 字表[#Headers], 0))} -> 方 | E11: 非 | F11: h | G11: 脣音 | H11: 全清 | I11: 發聲 | J11: 久 | K11: 尤 | L11: iu | M11: 開細 | N11: 流 | O11: 開 | P11: 三 | Q11: 上 | R11: 清上 | S11: 2 | T11: 2
B12: 2
B13: 3

Sheet 查字表
A1: 字號 | B1: 上字 | C1: 下字 | D1: 聲母 | E1: 聲母標音 | F1: 七聲類 | G1: 清濁 | H1: 發送收 | I1: 韻母 | J1: 韻母標音 | K1: 等呼 | L1: 攝 | M1: 呼 | N1: 等 | O1: 調 | P1: 廣韻聲調 | Q1: 四声八調 | R1: 濁上調校正 | S1: 上字號 | T1: 下字號
A2: 1 | B2: =切語查音!D6 -> 方 | C2: =切語查音!D7 -> 久 | D2: {=INDEX(切語上字表[聲母], 字表[[#This Row],[上字號]])} -> 非 | E2: {=INDEX(切語上字表[聲母標音], 字表[[#This Row],[上字號]])} -> h | F2: {=INDEX(切語上字表[七聲類], 字表[[#This Row],[上字號]])} -> 脣音 | G2: {=INDEX(切語上字表[清濁], 字表[[#This Row],[上字號]])} -> 全清 | H2: {=INDEX(切語上字表[發送收], 字表[[#This Row],[上字號]])} -> 發聲 | I2: {=INDEX(切語下字表[韻母], 字表[[#This Row],[下字號]])} -> 尤 | J2: {=INDEX(切語下字表[韻母標音], 字表[[#This Row],[下字號]])} -> iu | K2: {=INDEX(切語下字表[等呼], 字表[[#This Row],[下字號]])} -> 開細 | L2: {=INDEX(切語下字表[攝], 字表[[#This Row],[下字號]])} -> 流 | M2: {=INDEX(切語下字表[呼], 字表[[#This Row],[下字號]])} -> 開 | N2: {=INDEX(切語下字表[等], 字表[[#This Row],[下字號]])} -> 三 | O2: {=INDEX(切語下字表[調], 字表[[#This Row],[下字號]])} -> 上 | P2: =RIGHT(字表[[#This Row],[清濁]],1) & LEFT(字表[[#This Row],[調]],1) -> 清上 | Q2: {=INDEX(聲調對照資料表[台羅調號], MATCH(TRUE, EXACT(字表[[#This Row],[廣韻聲調]], 聲調對照資料表[廣韻聲調]), 0))} -> 2 | R2: =IF( VALUE(字表[[#This Row],[四声八調]])=6, IF( OR( AND(字表[[#This Row],[聲母標音]]="Ø", OR( LEFT(字表[[#This Row],[韻母標音]],1)="i", LEFT(字表[[#This Row],[韻母標音]],1)="o", LEFT(字表[[#This Row],[韻母標音]],1)="u" ) ), 字表[[#This Row],[聲母標音]]="b", 字表[[#This Row],[聲母標音]]="l", 字表[[#This Row],[聲母標音]]="m", 字表[[#This Row],[聲母標音]]="n", 字表[[#This Row],[聲母標音]]="g" ), 2, 7 ), 字表[[#This Row],[四声八調]] ) -> 2 | S2: {=MATCH(TRUE, ISNUMBER( SEARCH(TRIM(字表[[#This Row],[上字]]), 切語上字表[切語上字集]) ), 0)} -> 5 | T2: {=MATCH(TRUE, ISNUMBER( SEARCH(TRIM(字表[[#This Row],[下字]]), 切語下字表[切語下字集]) ), 0)} -> 254

Sheet 【聲】聲母對照表
A1: 識別號 | B1: 國際音標 | C1: 漢字例 | D1: 十五音 | E1: 方音符號 | F1: 台語注音 | G1: 注音二式 | H1: 閩拼方案 | I1: 台羅拼音 | J1: 台語音標 | K1: 白話字 | L1: 備註 | M1: 注音符號序 | N1: 十五音序 | O1: 台羅字母序 | P1: 拼音字母序 | U1: Ø | V1: Ø
A2: 1 | B2: Ø | C2: 以 | D2: 英 | E2: Ø | F2: Ø | G2: Ø | H2: Ø | I2: Ø | J2: Ø | K2: Ø | L2: Ø | M2: 1 | N2: 11 | O2: 1 | P2: 1 | S2: 1 | T2: ㄅ | U2: l | V2: l
A3: 2 | B3: p | C3: 比 | D3: 邊 | E3: ㄅ | F3: ㄅ | G3: b | H3: b | I3: p | J3: p | K3: p | M3: 2 | N3: 2 | O3: 13 | P3: 2 | S3: 2 | T3: ㆠ | U3: b | V3: b
A4: 3 | B4: b | C4: 美 | D4: 門 | E4: ㆠ | F4: ㄪ | G4: bb | H4: bb | I4: b | J4: b | K4: b | M4: 3 | N4: 12 | O4: 2 | P4: =P3+1 -> 3 | S4: 3 | T4: ㄆ | U4: g | V4: g
A5: 4 | B5: pʰ | C5: 鄙 | D5: 頗 | E5: ㄆ | F5: ㄆ | G5: p | H5: p | I5: ph | J5: ph | K5: ph | M5: 4 | N5: 6 | O5: 14 | P5: =P4+1 -> 4 | S5: 4 | T5: ㄇ | U5: k | V5: k
A6: 5 | B6: m | C6: 毛 | D6: 毛 | E6: ㄇ | F6: ㄇ | G6: m | H6: bbn | I6: m | J6: m | K6: m | L6: b/m 本不分，此處分門/毛 | M6: 5 | N6: 16 | O6: 10 | P6: =P5+1 -> 5 | S6: 5 | T6: ㄉ | U6: d | V6: d
A7: 6 | B7: t | C7: 底 | D7: 地 | E7: ㄉ | F7: ㄉ | G7: d | H7: d | I7: t | J7: t | K7: t | M7: 6 | N7: 5 | O7: 17 | P7: =P6+1 -> 6 | S7: 6 | T7: ㄊ | U7: p | V7: p
A8: 7 | B8: tʰ | C8: 恥 | D8: 他 | E8: ㄊ | F8: ㄊ | G8: t | H8: t | I8: th | J8: th | K8: th | M8: 7 | N8: 7 | O8: 18 | P8: =P7+1 -> 7 | S8: 7 | T8: ㄋ | U8: t | V8: t
A9: 8 | B9: n | C9: 耐 | D9: 耐 | E9: ㄋ | F9: ㄋ | G9: n | H9: ln | I9: n | J9: n | K9: n | L9: l/n 本不分，此處分柳/耐 | M9: 8 | N9: 17 | O9: 11 | P9: =P8+1 -> 8 | S9: 8 | T9: ㄌ | U9: z | V9: z
A10: 9 | B10: l | C10: 理 | D10: 柳 | E10: ㄌ | F10: ㄌ | G10: l | H10: l | I10: l | J10: l | K10: l | M10: 9 | N10: 1 | O10: 9 | P10: =P9+1 -> 9 | S10: 9 | T10: ㄍ | U10: zz | V10: zz
A11: 10 | B11: k | C11: 己 | D11: 求 | E11: ㄍ | F11: ㄍ | G11: g | H11: g | I11: k | J11: k | K11: k | M11: 10 | N11: 3 | O11: 7 | P11: =P10+1 -> 10 | S11: 10 | T11: ㆣ | U11: s | V11: s
A12: 11 | B12: ɡ | C12: 禦 | D12: 語 | E12: ㆣ | F12: ㄫ | G12: gg | H12: gg | I12: g | J12: g | K12: g | M12: 11 | N12: 13 | O12: 3 | P12: =P11+1 -> 11 | S12: 11 | T12: ㄎ | U12: bb | V12: bb
A13: 12 | B13: kʰ | C13: 起 | D13: 去 | E13: ㄎ | F13: ㄎ | G13: k | H13: k | I13: kh | J13: kh | K13: kh | M13: 12 | N13: 4 | O13: 8 | P13: =P12+1 -> 12 | S13: 12 | T13: ㄫ | U13: gg | V13: gg
A14: 13 | B14: ŋ | C14: 雅 | D14: 雅 | E14: ㄫ | F14: ⁰ㄫ | G14: ng | H14: ggn | I14: ng | J14: ng | K14: ng | L14: g/ng 本不分，此處分語/雅 | M14: 13 | N14: 18 | O14: 12 | P14: =P13+1 -> 13 | S14: 13 | T14: ㄏ | U14: c | V14: c
A15: 14 | B15: h | C15: 喜 | D15: 喜 | E15: ㄏ | F15: ㄏ | G15: h | H15: h | I15: h | J15: h | K15: h | M15: 14 | N15: 15 | O15: 4 | P15: =P14+1 -> 14 | S15: 14 | T15: ㄐ | U15: h | V15: h
A16: 15 | B16: ʨ | C16: 止 | D16: 曾 | E16: ㄐ | F16: ㄐ | G16: j | H16: zi | I16: tsi | J16: zi | K16: chi | L16: ㄐ = ㄗㄧ | M16: 15 | N16: 20 | O16: 22 | P16: =P15+1 -> 15 | S16: 15 | T16: ㆢ | U16: m | V16: bbn
A17: 16 | B17: ʥ | C17: 熱 | D17: 入 | E17: ㆢ | F17: ㄖ | G17: jj | H17: zzi | I17: ji | J17: ji | K17: ji | L17: ㆢ = ㆡㄧ | M17: 16 | N17: 19 | O17: 6 | P17: =P16+1 -> 16 | S17: 16 | T17: ㄑ | U17: n | V17: ln
A18: 17 | B18: ʨʰ | C18: 測 | D18: 出 | E18: ㄑ | F18: ㄑ | G18: ch | H18: ci | I18: tshi | J18: ci | K18: chhi | L18: ㄑ = ㄘㄧ | M18: 17 | N18: 21 | O18: 21 | P18: =P17+1 -> 17 | S18: 17 | T18: ㄒ | U18: ng | V18: ggn
A19: 18 | B19: ɕ | C19: 惜 | D19: 時 | E19: ㄒ | F19: ㄒ | G19: sh | H19: si | I19: si | J19: si | K19: si | L19: ㄒ = ㄙㄧ | M19: 18 | N19: 22 | O19: 16 | P19: =P18+1 -> 18 | S19: 18 | T19: ㄗ | U19: jji | V19: zzi
A20: 19 | B20: ʦ | C20: 阻 | D20: 曾 | E20: ㄗ | F20: ㄗ | G20: z | H20: z | I20: ts | J20: z | K20: ch | M20: 19 | N20: 8 | O20: 19 | P20: =P19+1 -> 19 | S20: 19 | T20: ㆡ | U20: ji | V20: zi
A21: 20 | B21: ʣ | C21: 熱 | D21: 入 | E21: ㆡ | F21: ㄖ | G21: zz | H21: zz | I21: j | J21: j | K21: j | M21: 20 | N21: 9 | O21: 5 | P21: =P20+1 -> 20 | S21: 20 | T21: ㄘ | U21: chi | V21: ci
A22: 21 | B22: ʦʰ | C22: 取 | D22: 出 | E22: ㄘ | F22: ㄘ | G22: c | H22: c | I22: tsh | J22: c | K22: chh | M22: 21 | N22: 14 | O22: 20 | P22: =P21+1 -> 21 | S22: 21 | T22: ㄙ | U22: shi | V22: si
A23: 22 | B23: s | C23: 詞 | D23: 時 | E23: ㄙ | F23: ㄙ | G23: s | H23: s | I23: s | J23: s | K23: s | M23: 22 | N23: 10 | O23: 15 | P23: =P22+1 -> 22

Sheet 【韻】韻母對照表
A2: 序號 | B2: 國際音標 | C2: 漢字例 | D2: 十五音 | E2: 十五音識別碼 | F2: 方音符號 | G2: 台語注音 | H2: 台語注音二式 | I2: 閩拼方案 | J2: 台羅拼音 | K2: 台語音標 | L2: 白話字 | M2: 聲韻調類 | N2: 字長 | P2: 台羅拼音 | Q2: 台語音標 | S2: 台羅拼音 | T2: 標調字母 | U2: search() | V2: 台語音標 | AB2: U+0301 | AC2: U+0300 | AE2: U+030C | AF2: U+0301 | AG2: U+0304 | AH2: U+030D | AI2: U+030B | AJ2: U+030A
A3: =ROW() - 3 -> 0 | B3: a | C3: 些 | D3: =LEFT(韻母對照表[[#This Row],[十五音識別碼]],1) -> 膠 | E3: 膠（舒） | F3: ㄚ | G3: ㄚ | H3: a | I3: a | J3: a | K3: a | L3: a | N3: =LEN(K3) -> 1 | P3: =J3 -> a | Q3: =K3 -> a | S3: =_xlfn.CONCAT(P3, "(\d)") -> a(\d) | T3: a | U3: =IFERROR( IF(T3="", "", SEARCH(T3, $P3)), "") -> 1 | V3: =IFERROR( _xlfn.CONCAT(LEFT(P3,U3-1), "》", MID(P3,U3,1), "${1}", RIGHT(P3, LEN(P3)-U3)), "" ) -> 》a${1} | X3: =IF(AND(Q3<>"", P3<>""), " - xform/》" & S3 & "/" & V3 & "/", "") -> - xform/》a(\d)/》a${1}/ | Z3: a | AA3: =_xlfn.CONCAT($Z3, IF(AA$2="", "", _xlfn.UNICHAR( HEX2DEC( RIGHT(AA$2,4))))) -> a | AB3: =_xlfn.CONCAT($Z3, IF(AB$2="", "", _xlfn.UNICHAR( HEX2DEC( RIGHT(AB$2,4))))) -> á | AC3: =_xlfn.CONCAT($Z3, IF(AC$2="", "", _xlfn.UNICHAR( HEX2DEC( RIGHT(AC$2,4))))) -> à | AD3: =_xlfn.CONCAT($Z3, IF(AD$2="", "", _xlfn.UNICHAR( HEX2DEC( RIGHT(AD$2,4))))) -> a | AE3: =_xlfn.CONCAT($Z3, IF(AE$2="", "", _xlfn.UNICHAR( HEX2DEC( RIGHT(AE$2,4))))) -> ǎ | AF3: =_xlfn.CONCAT($Z3, IF(AF$2="", "", _xlfn.UNICHAR( HEX2DEC( RIGHT(AF$2,4))))) -> á | AG3: =_xlfn.CONCAT($Z3, IF(AG$2="", "", _xlfn.UNICHAR( HEX2DEC( RIGHT(AG$2,4))))) -> ā | AH3: =_xlfn.CONCAT($Z3, IF(AH$2="", "", _xlfn.UNICHAR( HEX2DEC( RIGHT(AH$2,4))))) -> a̍ | ... AJ3: =_xlfn.CONCAT($Z3, IF(AJ$2="", "", _xlfn.UNICHAR( HEX2DEC( RIGHT(AJ$2,4))))) -> å | AL3: =_xlfn.CONCAT(" - xform/》", $Z3, [1]【調】韻母標調!AJ$1, "/", AA3, "/") -> - xform/》a1/a/ | AM3: =_xlfn.CONCAT(" - xform/》", $Z3, [1]【調】韻母標調!AK$1, "/", AB3, "/") -> - xform/》a2/á/ | AN3: =_xlfn.CONCAT(" - xform/》", $Z3, [1]【調】韻母標調!AL$1, "/", AC3, "/") -> - xform/》a3/à/ | AO3: =_xlfn.CONCAT(" - xform/》", $Z3, [1]【調】韻母標調!AM$1, "/", AD3, "/") -> - xform/》a4/a/ | AP3: =_xlfn.CONCAT(" - xform/》", $Z3, [1]【調】韻母標調!AN$1, "/", AE3, "/") -> - xform/》a5/ǎ/ | AQ3: =_xlfn.CONCAT(" - xform/》", $Z3, [1]【調】韻母標調!AO$1, "/", AF3, "/") -> - xform/》a6/á/ | AR3: =_xlfn.CONCAT(" - xform/》", $Z3, [1]【調】韻母標調!AP$1, "/", AG3, "/") -> - xform/》a7/ā/ | AS3: =_xlfn.CONCAT(" - xform/》", $Z3, [1]【調】韻母標調!AQ$1, "/", AH3, "/") -> - xform/》a8/a̍/ | ... AU3: =_xlfn.CONCAT(" - xform/》", $Z3, [1]【調】韻母標調!AS$1, "/", AJ3, "/") -> - xform/》a9/å/
A4: =ROW() - 3 -> 1 | B4: aʔ | C4: 百 | D4: =LEFT(韻母對照表[[#This Row],[十五音識別碼]],1) -> 膠 | E4: 膠（促） | F4: ㄚㆷ | G4: ㄚㄏ | H4: ah | I4: ah | J4: ah | K4: ah | L4: ah | N4: =LEN(K4) -> 2 | P4: =J4 -> ah | Q4: =K4 -> ah | S4: =_xlfn.CONCAT(P4, "(\d)") -> ah(\d) | T4: a | U4: =IFERROR( IF(T4="", "", SEARCH(T4, $P4)), "") -> 1 | V4: =IFERROR( _xlfn.CONCAT(LEFT(P4,U4-1), "》", MID(P4,U4,1), "${1}", RIGHT(P4, LEN(P4)-U4)), "" ) -> 》a${1}h | X4: =IF(AND(Q4<>"", P4<>""), " - xform/》" & S4 & "/" & V4 & "/", "") -> - xform/》ah(\d)/》a${1}h/ | Z4: u | AA4: =_xlfn.CONCAT($Z4, IF(AA$2="", "", _xlfn.UNICHAR( HEX2DEC( RIGHT(AA$2,4))))) -> u | AB4: =_xlfn.CONCAT($Z4, IF(AB$2="", "", _xlfn.UNICHAR( HEX2DEC( RIGHT(AB$2,4))))) -> ú | AC4: =_xlfn.CONCAT($Z4, IF(AC$2="", "", _xlfn.UNICHAR( HEX2DEC( RIGHT(AC$2,4))))) -> ù | AD4: =_xlfn.CONCAT($Z4, IF(AD$2="", "", _xlfn.UNICHAR( HEX2DEC( RIGHT(AD$2,4))))) -> u | AE4: =_xlfn.CONCAT($Z4, IF(AE$2="", "", _xlfn.UNICHAR( HEX2DEC( RIGHT(AE$2,4))))) -> ǔ | AF4: =_xlfn.CONCAT($Z4, IF(AF$2="", "", _xlfn.UNICHAR( HEX2DEC( RIGHT(AF$2,4))))) -> ú | AG4: =_xlfn.CONCAT($Z4, IF(AG$2="", "", _xlfn.UNICHAR( HEX2DEC( RIGHT(AG$2,4))))) -> ū | AH4: =_xlfn.CONCAT($Z4, IF(AH$2="", "", _xlfn.UNICHAR( HEX2DEC( RIGHT(AH$2,4))))) -> u̍ | ... AJ4: =_xlfn.CONCAT($Z4, IF(AJ$2="", "", _xlfn.UNICHAR( HEX2DEC( RIGHT(AJ$2,4))))) -> ů | AL4: =_xlfn.CONCAT(" - xform/》", $Z4, [1]【調】韻母標調!AJ$1, "/", AA4, "/") -> - xform/》u1/u/ | AM4: =_xlfn.CONCAT(" - xform/》", $Z4, [1]【調】韻母標調!AK$1, "/", AB4, "/") -> - xform/》u2/ú/ | AN4: =_xlfn.CONCAT(" - xform/》", $Z4, [1]【調】韻母標調!AL$1, "/", AC4, "/") -> - xform/》u3/ù/ | AO4: =_xlfn.CONCAT(" - xform/》", $Z4, [1]【調】韻母標調!AM$1, "/", AD4, "/") -> - xform/》u4/u/ | AP4: =_xlfn.CONCAT(" - xform/》", $Z4, [1]【調】韻母標調!AN$1, "/", AE4, "/") -> - xform/》u5/ǔ/ | AQ4: =_xlfn.CONCAT(" - xform/》", $Z4, [1]【調】韻母標調!AO$1, "/", AF4, "/") -> - xform/》u6/ú/ | AR4: =_xlfn.CONCAT(" - xform/》", $Z4, [1]【調】韻母標調!AP$1, "/", AG4, "/") -> - xform/》u7/ū/ | AS4: =_xlfn.CONCAT(" - xform/》", $Z4, [1]【調】韻母標調!AQ$1, "/", AH4, "/") -> - xform/》u8/u̍/ | ... AU4: =_xlfn.CONCAT(" - xform/》", $Z4, [1]【調】韻母標調!AS$1, "/", AJ4, "/") -> - xform/》u9/ů/
A5: =ROW() - 3 -> 2 | B5: aɪ | C5: 埃 | D5: =LEFT(韻母對照表[[#This Row],[十五音識別碼]],1) -> 皆 | E5: 皆（舒） | F5: ㄞ | G5: ㄞ | H5: ai | I5: ai | J5: ai | K5: ai | L5: ai | N5: =LEN(K5) -> 2 | P5: =J5 -> ai | Q5: =K5 -> ai | S5: =_xlfn.CONCAT(P5, "(\d)") -> ai(\d) | T5: o | U5: =IFERROR( IF(T5="", "", SEARCH(T5, $P5)), "") | V5: =IFERROR( _xlfn.CONCAT(LEFT(P5,U5-1), "》", MID(P5,U5,1), "${1}", RIGHT(P5, LEN(P5)-U5)), "" ) | X5: =IF(AND(Q5<>"", P5<>""), " - xform/》" & S5 & "/" & V5 & "/", "") -> - xform/》ai(\d)//
A6: =ROW() - 3 -> 3 | B6: aɪʔ | C6: ◯ | D6: =LEFT(韻母對照表[[#This Row],[十五音識別碼]],1) -> 皆 | E6: 皆（促） | F6: ㄞㆷ | G6: ㄞㄏ | H6: aih | I6: aih | J6: aih | K6: aih | L6: aih | N6: =LEN(K6) -> 3 | P6: =J6 -> aih | Q6: =K6 -> aih | S6: =_xlfn.CONCAT(P6, "(\d)") -> aih(\d) | T6: a | U6: =IFERROR( IF(T6="", "", SEARCH(T6, $P6)), "") -> 1 | V6: =IFERROR( _xlfn.CONCAT(LEFT(P6,U6-1), "》", MID(P6,U6,1), "${1}", RIGHT(P6, LEN(P6)-U6)), "" ) -> 》a${1}ih | X6: =IF(AND(Q6<>"", P6<>""), " - xform/》" & S6 & "/" & V6 & "/", "") -> - xform/》aih(\d)/》a${1}ih/
A7: =ROW() - 3 -> 4 | B7: ãɪ | C7: 挨 | D7: =LEFT(韻母對照表[[#This Row],[十五音識別碼]],1) -> 閒 | E7: 閒（舒） | F7: ㆮ | G7: ⁰ㄞ | H7: ainn | I7: nai | J7: ainn | K7: ainn | L7: aiⁿ | M7: 韻-鼻 | N7: =LEN(K7) -> 4 | P7: =J7 -> ainn | Q7: =K7 -> ainn | S7: =_xlfn.CONCAT(P7, "(\d)") -> ainn(\d) | T7: a | U7: =IFERROR( IF(T7="", "", SEARCH(T7, $P7)), "") -> 1 | V7: =IFERROR( _xlfn.CONCAT(LEFT(P7,U7-1), "》", MID(P7,U7,1), "${1}", RIGHT(P7, LEN(P7)-U7)), "" ) -> 》a${1}inn | X7: =IF(AND(Q7<>"", P7<>""), " - xform/》" & S7 & "/" & V7 & "/", "") -> - xform/》ainn(\d)/》a${1}inn/
A8: =ROW() - 3 -> 5 | B8: =_xlfn.CONCAT("a","k",_xlfn.UNICHAR(794)) -> ak̚ | C8: 角 | D8: =LEFT(韻母對照表[[#This Row],[十五音識別碼]],1) -> 江 | E8: 江（促） | F8: ㄚㆻ | G8: ㄚㄍ | H8: ak | I8: ak | J8: ak | K8: ak | L8: ak | N8: =LEN(K8) -> 2 | P8: =J8 -> ak | Q8: =K8 -> ak | S8: =_xlfn.CONCAT(P8, "(\d)") -> ak(\d) | T8: e | U8: =IFERROR( IF(T8="", "", SEARCH(T8, $P8)), "") | V8: =IFERROR( _xlfn.CONCAT(LEFT(P8,U8-1), "》", MID(P8,U8,1), "${1}", RIGHT(P8, LEN(P8)-U8)), "" ) | X8: =IF(AND(Q8<>"", P8<>""), " - xform/》" & S8 & "/" & V8 & "/", "") -> - xform/》ak(\d)//
A9: =ROW() - 3 -> 6 | B9: am | C9: 堪 | D9: =LEFT(韻母對照表[[#This Row],[十五音識別碼]],1) -> 甘 | E9: 甘（舒） | F9: ㆰ | G9: ㄚㄇ | H9: am | I9: am | J9: am | K9: am | L9: am | N9: =LEN(K9) -> 2 | P9: =J9 -> am | Q9: =K9 -> am | S9: =_xlfn.CONCAT(P9, "(\d)") -> am(\d) | T9: a | U9: =IFERROR( IF(T9="", "", SEARCH(T9, $P9)), "") -> 1 | V9: =IFERROR( _xlfn.CONCAT(LEFT(P9,U9-1), "》", MID(P9,U9,1), "${1}", RIGHT(P9, LEN(P9)-U9)), "" ) -> 》a${1}m | X9: =IF(AND(Q9<>"", P9<>""), " - xform/》" & S9 & "/" & V9 & "/", "") -> - xform/》am(\d)/》a${1}m/ | Z9: o | AA9: =_xlfn.CONCAT($Z9, IF(AA$2="", "", _xlfn.UNICHAR( HEX2DEC( RIGHT(AA$2,4))))) -> o | AB9: =_xlfn.CONCAT($Z9, IF(AB$2="", "", _xlfn.UNICHAR( HEX2DEC( RIGHT(AB$2,4))))) -> ó | AC9: =_xlfn.CONCAT($Z9, IF(AC$2="", "", _xlfn.UNICHAR( HEX2DEC( RIGHT(AC$2,4))))) -> ò | AD9: =_xlfn.CONCAT($Z9, IF(AD$2="", "", _xlfn.UNICHAR( HEX2DEC( RIGHT(AD$2,4))))) -> o | AE9: =_xlfn.CONCAT($Z9, IF(AE$2="", "", _xlfn.UNICHAR( HEX2DEC( RIGHT(AE$2,4))))) -> ǒ | AF9: =_xlfn.CONCAT($Z9, IF(AF$2="", "", _xlfn.UNICHAR( HEX2DEC( RIGHT(AF$2,4))))) -> ó | AG9: =_xlfn.CONCAT($Z9, IF(AG$2="", "", _xlfn.UNICHAR( HEX2DEC( RIGHT(AG$2,4))))) -> ō | AH9: =_xlfn.CONCAT($Z9, IF(AH$2="", "", _xlfn.UNICHAR( HEX2DEC( RIGHT(AH$2,4))))) -> o̍ | ... AJ9: =_xlfn.CONCAT($Z9, IF(AJ$2="", "", _xlfn.UNICHAR( HEX2DEC( RIGHT(AJ$2,4))))) -> o̊ | AL9: =_xlfn.CONCAT(" - xform/》", $Z9, [1]【調】韻母標調!AJ$1, "/", AA9, "/") -> - xform/》o1/o/ | AM9: =_xlfn.CONCAT(" - xform/》", $Z9, [1]【調】韻母標調!AK$1, "/", AB9, "/") -> - xform/》o2/ó/ | AN9: =_xlfn.CONCAT(" - xform/》", $Z9, [1]【調】韻母標調!AL$1, "/", AC9, "/") -> - xform/》o3/ò/ | AO9: =_xlfn.CONCAT(" - xform/》", $Z9, [1]【調】韻母標調!AM$1, "/", AD9, "/") -> - xform/》o4/o/ | AP9: =_xlfn.CONCAT(" - xform/》", $Z9, [1]【調】韻母標調!AN$1, "/", AE9, "/") -> - xform/》o5/ǒ/ | AQ9: =_xlfn.CONCAT(" - xform/》", $Z9, [1]【調】韻母標調!AO$1, "/", AF9, "/") -> - xform/》o6/ó/ | AR9: =_xlfn.CONCAT(" - xform/》", $Z9, [1]【調】韻母標調!AP$1, "/", AG9, "/") -> - xform/》o7/ō/ | AS9: =_xlfn.CONCAT(" - xform/》", $Z9, [1]【調】韻母標調!AQ$1, "/", AH9, "/") -> - xform/》o8/o̍/ | ... AU9: =_xlfn.CONCAT(" - xform/》", $Z9, [1]【調】韻母標調!AS$1, "/", AJ9, "/") -> - xform/》o9/o̊/
A10: =ROW() - 3 -> 7 | B10: an | C10: 蘭 | D10: =LEFT(韻母對照表[[#This Row],[十五音識別碼]],1) -> 干 | E10: 干（舒） | F10: ㄢ | G10: ㄢ | H10: an | I10: an | J10: an | K10: an | L10: an | N10: =LEN(K10) -> 2 | P10: =J10 -> an | Q10: =K10 -> an | S10: =_xlfn.CONCAT(P10, "(\d)") -> an(\d) | T10: a | U10: =IFERROR( IF(T10="", "", SEARCH(T10, $P10)), "") -> 1 | V10: =IFERROR( _xlfn.CONCAT(LEFT(P10,U10-1), "》", MID(P10,U10,1), "${1}", RIGHT(P10, LEN(P10)-U10)), "" ) -> 》a${1}n | X10: =IF(AND(Q10<>"", P10<>""), " - xform/》" & S10 & "/" & V10 & "/", "") -> - xform/》an(\d)/》a${1}n/ | Z10: m | AA10: =_xlfn.CONCAT($Z10, IF(AA$2="", "", _xlfn.UNICHAR( HEX2DEC( RIGHT(AA$2,4))))) -> m | AB10: =_xlfn.CONCAT($Z10, IF(AB$2="", "", _xlfn.UNICHAR( HEX2DEC( RIGHT(AB$2,4))))) -> ḿ | AC10: =_xlfn.CONCAT($Z10, IF(AC$2="", "", _xlfn.UNICHAR( HEX2DEC( RIGHT(AC$2,4))))) -> m̀ | AD10: =_xlfn.CONCAT($Z10, IF(AD$2="", "", _xlfn.UNICHAR( HEX2DEC( RIGHT(AD$2,4))))) -> m | AE10: =_xlfn.CONCAT($Z10, IF(AE$2="", "", _xlfn.UNICHAR( HEX2DEC( RIGHT(AE$2,4))))) -> m̌ | AF10: =_xlfn.CONCAT($Z10, IF(AF$2="", "", _xlfn.UNICHAR( HEX2DEC( RIGHT(AF$2,4))))) -> ḿ | AG10: =_xlfn.CONCAT($Z10, IF(AG$2="", "", _xlfn.UNICHAR( HEX2DEC( RIGHT(AG$2,4))))) -> m̄ | AH10: =_xlfn.CONCAT($Z10, IF(AH$2="", "", _xlfn.UNICHAR( HEX2DEC( RIGHT(AH$2,4))))) -> m̍ | ... AJ10: =_xlfn.CONCAT($Z10, IF(AJ$2="", "", _xlfn.UNICHAR( HEX2DEC( RIGHT(AJ$2,4))))) -> m̊ | AL10: =_xlfn.CONCAT(" - xform/》", $Z10, [1]【調】韻母標調!AJ$1, "/", AA10, "/") -> - xform/》m1/m/ | AM10: =_xlfn.CONCAT(" - xform/》", $Z10, [1]【調】韻母標調!AK$1, "/", AB10, "/") -> - xform/》m2/ḿ/ | AN10: =_xlfn.CONCAT(" - xform/》", $Z10, [1]【調】韻母標調!AL$1, "/", AC10, "/") -> - xform/》m3/m̀/ | AO10: =_xlfn.CONCAT(" - xform/》", $Z10, [1]【調】韻母標調!AM$1, "/", AD10, "/") -> - xform/》m4/m/ | AP10: =_xlfn.CONCAT(" - xform/》", $Z10, [1]【調】韻母標調!AN$1, "/", AE10, "/") -> - xform/》m5/m̌/ | AQ10: =_xlfn.CONCAT(" - xform/》", $Z10, [1]【調】韻母標調!AO$1, "/", AF10, "/") -> - xform/》m6/ḿ/ | AR10: =_xlfn.CONCAT(" - xform/》", $Z10, [1]【調】韻母標調!AP$1, "/", AG10, "/") -> - xform/》m7/m̄/ | AS10: =_xlfn.CONCAT(" - xform/》", $Z10, [1]【調】韻母標調!AQ$1, "/", AH10, "/") -> - xform/》m8/m̍/ | ... AU10: =_xlfn.CONCAT(" - xform/》", $Z10, [1]【調】韻母標調!AS$1, "/", AJ10, "/") -> - xform/》m9/m̊/
A11: =ROW() - 3 -> 8 | B11: aŋ | C11: 邦 | D11: =LEFT(韻母對照表[[#This Row],[十五音識別碼]],1) -> 江 | E11: 江（舒） | F11: ㄤ | G11: ㄤ | H11: ang | I11: ang | J11: ang | K11: ang | L11: ang | N11: =LEN(K11) -> 3 | P11: =J11 -> ang | Q11: =K11 -> ang | S11: =_xlfn.CONCAT(P11, "(\d)") -> ang(\d) | T11: a | U11: =IFERROR( IF(T11="", "", SEARCH(T11, $P11)), "") -> 1 | V11: =IFERROR( _xlfn.CONCAT(LEFT(P11,U11-1), "》", MID(P11,U11,1), "${1}", RIGHT(P11, LEN(P11)-U11)), "" ) -> 》a${1}ng | X11: =IF(AND(Q11<>"", P11<>""), " - xform/》" & S11 & "/" & V11 & "/", "") -> - xform/》ang(\d)/》a${1}ng/ | Z11: n | AA11: =_xlfn.CONCAT($Z11, IF(AA$2="", "", _xlfn.UNICHAR( HEX2DEC( RIGHT(AA$2,4))))) -> n | AB11: =_xlfn.CONCAT($Z11, IF(AB$2="", "", _xlfn.UNICHAR( HEX2DEC( RIGHT(AB$2,4))))) -> ń | AC11: =_xlfn.CONCAT($Z11, IF(AC$2="", "", _xlfn.UNICHAR( HEX2DEC( RIGHT(AC$2,4))))) -> ǹ | AD11: =_xlfn.CONCAT($Z11, IF(AD$2="", "", _xlfn.UNICHAR( HEX2DEC( RIGHT(AD$2,4))))) -> n | AE11: =_xlfn.CONCAT($Z11, IF(AE$2="", "", _xlfn.UNICHAR( HEX2DEC( RIGHT(AE$2,4))))) -> ň | AF11: =_xlfn.CONCAT($Z11, IF(AF$2="", "", _xlfn.UNICHAR( HEX2DEC( RIGHT(AF$2,4))))) -> ń | AG11: =_xlfn.CONCAT($Z11, IF(AG$2="", "", _xlfn.UNICHAR( HEX2DEC( RIGHT(AG$2,4))))) -> n̄ | AH11: =_xlfn.CONCAT($Z11, IF(AH$2="", "", _xlfn.UNICHAR( HEX2DEC( RIGHT(AH$2,4))))) -> n̍ | ... AJ11: =_xlfn.CONCAT($Z11, IF(AJ$2="", "", _xlfn.UNICHAR( HEX2DEC( RIGHT(AJ$2,4))))) -> n̊ | AL11: =_xlfn.CONCAT(" - xform/》", $Z11, [1]【調】韻母標調!AJ$1, "/", AA11, "/") -> - xform/》n1/n/ | AM11: =_xlfn.CONCAT(" - xform/》", $Z11, [1]【調】韻母標調!AK$1, "/", AB11, "/") -> - xform/》n2/ń/ | AN11: =_xlfn.CONCAT(" - xform/》", $Z11, [1]【調】韻母標調!AL$1, "/", AC11, "/") -> - xform/》n3/ǹ/ | AO11: =_xlfn.CONCAT(" - xform/》", $Z11, [1]【調】韻母標調!AM$1, "/", AD11, "/") -> - xform/》n4/n/ | AP11: =_xlfn.CONCAT(" - xform/》", $Z11, [1]【調】韻母標調!AN$1, "/", AE11, "/") -> - xform/》n5/ň/ | AQ11: =_xlfn.CONCAT(" - xform/》", $Z11, [1]【調】韻母標調!AO$1, "/", AF11, "/") -> - xform/》n6/ń/ | AR11: =_xlfn.CONCAT(" - xform/》", $Z11, [1]【調】韻母標調!AP$1, "/", AG11, "/") -> - xform/》n7/n̄/ | AS11: =_xlfn.CONCAT(" - xform/》", $Z11, [1]【調】韻母標調!AQ$1, "/", AH11, "/") -> - xform/》n8/n̍/ | ... AU11: =_xlfn.CONCAT(" - xform/》", $Z11, [1]【調】韻母標調!AS$1, "/", AJ11, "/") -> - xform/》n9/n̊/
A12: =ROW() - 3 -> 9 | B12: ã | C12: 聽 | D12: =LEFT(韻母對照表[[#This Row],[十五音識別碼]],1) -> 監 | E12: 監（舒） | F12: ㆩ | G12: ⁰ㄚ | H12: ann | I12: na | J12: ann | K12: ann | L12: aⁿ | M12: 韻-鼻 | N12: =LEN(K12) -> 3 | P12: =J12 -> ann | Q12: =K12 -> ann | S12: =_xlfn.CONCAT(P12, "(\d)") -> ann(\d) | T12: a | U12: =IFERROR( IF(T12="", "", SEARCH(T12, $P12)), "") -> 1 | V12: =IFERROR( _xlfn.CONCAT(LEFT(P12,U12-1), "》", MID(P12,U12,1), "${1}", RIGHT(P12, LEN(P12)-U12)), "" ) -> 》a${1}nn | X12: =IF(AND(Q12<>"", P12<>""), " - xform/》" & S12 & "/" & V12 & "/", "") -> - xform/》ann(\d)/》a${1}nn/ | Z12: i | AA12: =_xlfn.CONCAT($Z12, IF(AA$2="", "", _xlfn.UNICHAR( HEX2DEC( RIGHT(AA$2,4))))) -> i | AB12: =_xlfn.CONCAT($Z12, IF(AB$2="", "", _xlfn.UNICHAR( HEX2DEC( RIGHT(AB$2,4))))) -> í | AC12: =_xlfn.CONCAT($Z12, IF(AC$2="", "", _xlfn.UNICHAR( HEX2DEC( RIGHT(AC$2,4))))) -> ì | AD12: =_xlfn.CONCAT($Z12, IF(AD$2="", "", _xlfn.UNICHAR( HEX2DEC( RIGHT(AD$2,4))))) -> i | AE12: =_xlfn.CONCAT($Z12, IF(AE$2="", "", _xlfn.UNICHAR( HEX2DEC( RIGHT(AE$2,4))))) -> ǐ | AF12: =_xlfn.CONCAT($Z12, IF(AF$2="", "", _xlfn.UNICHAR( HEX2DEC( RIGHT(AF$2,4))))) -> í | AG12: =_xlfn.CONCAT($Z12, IF(AG$2="", "", _xlfn.UNICHAR( HEX2DEC( RIGHT(AG$2,4))))) -> ī | AH12: =_xlfn.CONCAT($Z12, IF(AH$2="", "", _xlfn.UNICHAR( HEX2DEC( RIGHT(AH$2,4))))) -> i̍ | ... AJ12: =_xlfn.CONCAT($Z12, IF(AJ$2="", "", _xlfn.UNICHAR( HEX2DEC( RIGHT(AJ$2,4))))) -> i̊ | AL12: =_xlfn.CONCAT(" - xform/》", $Z12, [1]【調】韻母標調!AJ$1, "/", AA12, "/") -> - xform/》i1/i/ | AM12: =_xlfn.CONCAT(" - xform/》", $Z12, [1]【調】韻母標調!AK$1, "/", AB12, "/") -> - xform/》i2/í/ | AN12: =_xlfn.CONCAT(" - xform/》", $Z12, [1]【調】韻母標調!AL$1, "/", AC12, "/") -> - xform/》i3/ì/ | AO12: =_xlfn.CONCAT(" - xform/》", $Z12, [1]【調】韻母標調!AM$1, "/", AD12, "/") -> - xform/》i4/i/ | AP12: =_xlfn.CONCAT(" - xform/》", $Z12, [1]【調】韻母標調!AN$1, "/", AE12, "/") -> - xform/》i5/ǐ/ | AQ12: =_xlfn.CONCAT(" - xform/》", $Z12, [1]【調】韻母標調!AO$1, "/", AF12, "/") -> - xform/》i6/í/ | AR12: =_xlfn.CONCAT(" - xform/》", $Z12, [1]【調】韻母標調!AP$1, "/", AG12, "/") -> - xform/》i7/ī/ | AS12: =_xlfn.CONCAT(" - xform/》", $Z12, [1]【調】韻母標調!AQ$1, "/", AH12, "/") -> - xform/》i8/i̍/ | ... AU12: =_xlfn.CONCAT(" - xform/》", $Z12, [1]【調】韻母標調!AS$1, "/", AJ12, "/") -> - xform/》i9/i̊/
A13: =ROW() - 3 -> 10 | B13: ãʔ | C13: 含 | D13: =LEFT(韻母對照表[[#This Row],[十五音識別碼]],1) -> 監 | E13: 監（促） | F13: ㆩㆷ | G13: ⁰ㄚㄏ | H13: annh | I13: nah | J13: annh | K13: annh | L13: ahⁿ | M13: 韻-鼻 | N13: =LEN(K13) -> 4 | P13: =J13 -> annh | Q13: =K13 -> annh | S13: =_xlfn.CONCAT(P13, "(\d)") -> annh(\d) | T13: a | U13: =IFERROR( IF(T13="", "", SEARCH(T13, $P13)), "") -> 1 | V13: =IFERROR( _xlfn.CONCAT(LEFT(P13,U13-1), "》", MID(P13,U13,1), "${1}", RIGHT(P13, LEN(P13)-U13)), "" ) -> 》a${1}nnh | X13: =IF(AND(Q13<>"", P13<>""), " - xform/》" & S13 & "/" & V13 & "/", "") -> - xform/》annh(\d)/》a${1}nnh/ | Z13: e | AA13: =_xlfn.CONCAT($Z13, IF(AA$2="", "", _xlfn.UNICHAR( HEX2DEC( RIGHT(AA$2,4))))) -> e | AB13: =_xlfn.CONCAT($Z13, IF(AB$2="", "", _xlfn.UNICHAR( HEX2DEC( RIGHT(AB$2,4))))) -> é | AC13: =_xlfn.CONCAT($Z13, IF(AC$2="", "", _xlfn.UNICHAR( HEX2DEC( RIGHT(AC$2,4))))) -> è | AD13: =_xlfn.CONCAT($Z13, IF(AD$2="", "", _xlfn.UNICHAR( HEX2DEC( RIGHT(AD$2,4))))) -> e | AE13: =_xlfn.CONCAT($Z13, IF(AE$2="", "", _xlfn.UNICHAR( HEX2DEC( RIGHT(AE$2,4))))) -> ě | AF13: =_xlfn.CONCAT($Z13, IF(AF$2="", "", _xlfn.UNICHAR( HEX2DEC( RIGHT(AF$2,4))))) -> é | AG13: =_xlfn.CONCAT($Z13, IF(AG$2="", "", _xlfn.UNICHAR( HEX2DEC( RIGHT(AG$2,4))))) -> ē | AH13: =_xlfn.CONCAT($Z13, IF(AH$2="", "", _xlfn.UNICHAR( HEX2DEC( RIGHT(AH$2,4))))) -> e̍ | ... AJ13: =_xlfn.CONCAT($Z13, IF(AJ$2="", "", _xlfn.UNICHAR( HEX2DEC( RIGHT(AJ$2,4))))) -> e̊ | AL13: =_xlfn.CONCAT(" - xform/》", $Z13, [1]【調】韻母標調!AJ$1, "/", AA13, "/") -> - xform/》e1/e/ | AM13: =_xlfn.CONCAT(" - xform/》", $Z13, [1]【調】韻母標調!AK$1, "/", AB13, "/") -> - xform/》e2/é/ | AN13: =_xlfn.CONCAT(" - xform/》", $Z13, [1]【調】韻母標調!AL$1, "/", AC13, "/") -> - xform/》e3/è/ | AO13: =_xlfn.CONCAT(" - xform/》", $Z13, [1]【調】韻母標調!AM$1, "/", AD13, "/") -> - xform/》e4/e/ | AP13: =_xlfn.CONCAT(" - xform/》", $Z13, [1]【調】韻母標調!AN$1, "/", AE13, "/") -> - xform/》e5/ě/ | AQ13: =_xlfn.CONCAT(" - xform/》", $Z13, [1]【調】韻母標調!AO$1, "/", AF13, "/") -> - xform/》e6/é/ | AR13: =_xlfn.CONCAT(" - xform/》", $Z13, [1]【調】韻母標調!AP$1, "/", AG13, "/") -> - xform/》e7/ē/ | AS13: =_xlfn.CONCAT(" - xform/》", $Z13, [1]【調】韻母標調!AQ$1, "/", AH13, "/") -> - xform/》e8/e̍/ | ... AU13: =_xlfn.CONCAT(" - xform/》", $Z13, [1]【調】韻母標調!AS$1, "/", AJ13, "/") -> - xform/》e9/e̊/
A14: =ROW() - 3 -> 11 | B14: =_xlfn.CONCAT("a","p",_xlfn.UNICHAR(794)) -> ap̚ | C14: 答 | D14: =LEFT(韻母對照表[[#This Row],[十五音識別碼]],1) -> 甘 | E14: 甘（促） | F14: ㄚㆴ | G14: ㄚㄅ | H14: ap | I14: ap | J14: ap | K14: ap | L14: ap | N14: =LEN(K14) -> 2 | P14: =J14 -> ap | Q14: =K14 -> ap | S14: =_xlfn.CONCAT(P14, "(\d)") -> ap(\d) | T14: a | U14: =IFERROR( IF(T14="", "", SEARCH(T14, $P14)), "") -> 1 | V14: =IFERROR( _xlfn.CONCAT(LEFT(P14,U14-1), "》", MID(P14,U14,1), "${1}", RIGHT(P14, LEN(P14)-U14)), "" ) -> 》a${1}p | X14: =IF(AND(Q14<>"", P14<>""), " - xform/》" & S14 & "/" & V14 & "/", "") -> - xform/》ap(\d)/》a${1}p/
A15: =ROW() - 3 -> 12 | B15: =_xlfn.CONCAT("a","t",_xlfn.UNICHAR(794)) -> at̚ | C15: 識 | D15: =LEFT(韻母對照表[[#This Row],[十五音識別碼]],1) -> 干 | E15: 干（促） | F15: ㄚㆵ | G15: ㄚㄉ | H15: at | I15: at | J15: at | K15: at | L15: at | N15: =LEN(K15) -> 2 | P15: =J15 -> at | Q15: =K15 -> at | S15: =_xlfn.CONCAT(P15, "(\d)") -> at(\d) | T15: o | U15: =IFERROR( IF(T15="", "", SEARCH(T15, $P15)), "") | V15: =IFERROR( _xlfn.CONCAT(LEFT(P15,U15-1), "》", MID(P15,U15,1), "${1}", RIGHT(P15, LEN(P15)-U15)), "" ) | X15: =IF(AND(Q15<>"", P15<>""), " - xform/》" & S15 & "/" & V15 & "/", "") -> - xform/》at(\d)//
A16: =ROW() - 3 -> 13 | B16: aʊ | C16: 鬧 | D16: =LEFT(韻母對照表[[#This Row],[十五音識別碼]],1) -> 交 | E16: 交（舒） | F16: ㄠ | G16: ㄠ | H16: au | I16: ao | J16: au | K16: au | L16: au | N16: =LEN(K16) -> 2 | P16: =J16 -> au | Q16: =K16 -> au | S16: =_xlfn.CONCAT(P16, "(\d)") -> au(\d) | T16: a | U16: =IFERROR( IF(T16="", "", SEARCH(T16, $P16)), "") -> 1 | V16: =IFERROR( _xlfn.CONCAT(LEFT(P16,U16-1), "》", MID(P16,U16,1), "${1}", RIGHT(P16, LEN(P16)-U16)), "" ) -> 》a${1}u | X16: =IF(AND(Q16<>"", P16<>""), " - xform/》" & S16 & "/" & V16 & "/", "") -> - xform/》au(\d)/》a${1}u/
A17: =ROW() - 3 -> 14 | B17: auʔ | C17: 暴 | D17: =LEFT(韻母對照表[[#This Row],[十五音識別碼]],1) -> 交 | E17: 交（促） | F17: ㄠㆷ | G17: ㄠㄏ | H17: auh | I17: aoh | J17: auh | K17: auh | L17: auh | N17: =LEN(K17) -> 3 | P17: =J17 -> auh | Q17: =K17 -> auh | S17: =_xlfn.CONCAT(P17, "(\d)") -> auh(\d) | T17: a | U17: =IFERROR( IF(T17="", "", SEARCH(T17, $P17)), "") -> 1 | V17: =IFERROR( _xlfn.CONCAT(LEFT(P17,U17-1), "》", MID(P17,U17,1), "${1}", RIGHT(P17, LEN(P17)-U17)), "" ) -> 》a${1}uh | X17: =IF(AND(Q17<>"", P17<>""), " - xform/》" & S17 & "/" & V17 & "/", "") -> - xform/》auh(\d)/》a${1}uh/
A18: =ROW() - 3 -> 15 | B18: e | C18: 遞 | D18: =LEFT(韻母對照表[[#This Row],[十五音識別碼]],1) -> 稽 | E18: 稽（舒） | F18: ㆤ | G18: ㄝ | H18: e | I18: e | J18: e | K18: ei | L18: e | N18: =LEN(K18) -> 2 | P18: =J26 -> i | Q18: =K26 -> i | S18: =_xlfn.CONCAT(P18, "(\d)") -> i(\d) | T18: o | U18: =IFERROR( IF(T18="", "", SEARCH(T18, $P18)), "") | V18: =IFERROR( _xlfn.CONCAT(LEFT(P18,U18-1), "》", MID(P18,U18,1), "${1}", RIGHT(P18, LEN(P18)-U18)), "" ) | X18: =IF(AND(Q18<>"", P18<>""), " - xform/》" & S18 & "/" & V18 & "/", "") -> - xform/》i(\d)//
A19: =ROW() - 3 -> 16 | B19: ɛ | C19: 家 | D19: =LEFT(韻母對照表[[#This Row],[十五音識別碼]],1) -> 嘉 | E19: 嘉（舒） | F19: ㄝ | G19: ㄝ | J19: ee | K19: ee | N19: =LEN(K19) -> 2 | P19: =J18 -> e | Q19: =K18 -> ei | S19: =_xlfn.CONCAT(P19, "(\d)") -> e(\d) | T19: i | U19: =IFERROR( IF(T19="", "", SEARCH(T19, $P19)), "") | V19: =IFERROR( _xlfn.CONCAT(LEFT(P19,U19-1), "》", MID(P19,U19,1), "${1}", RIGHT(P19, LEN(P19)-U19)), "" ) | X19: =IF(AND(Q19<>"", P19<>""), " - xform/》" & S19 & "/" & V19 & "/", "") -> - xform/》e(\d)//
A20: =ROW() - 3 -> 17 | B20: =_xlfn.CONCAT(B19, "ʔ") -> ɛʔ | C20: 八 | D20: =LEFT(韻母對照表[[#This Row],[十五音識別碼]],1) -> 嘉 | E20: 嘉（促） | F20: ㄝㆷ | G20: ㄝㄏ | J20: eeh | K20: eeh | N20: =LEN(K20) -> 3 | P20: =J24 -> enn | Q20: =K24 -> enn | S20: =_xlfn.CONCAT(P20, "(\d)") -> enn(\d) | T20: i | U20: =IFERROR( IF(T20="", "", SEARCH(T20, $P20)), "") | V20: =IFERROR( _xlfn.CONCAT(LEFT(P20,U20-1), "》", MID(P20,U20,1), "${1}", RIGHT(P20, LEN(P20)-U20)), "" ) | X20: =IF(AND(Q20<>"", P20<>""), " - xform/》" & S20 & "/" & V20 & "/", "") -> - xform/》enn(\d)//
A21: =ROW() - 3 -> 18 | B21: eʔ | C21: 伯 | D21: =LEFT(韻母對照表[[#This Row],[十五音識別碼]],1) -> 伽 | E21: 伽（促） | F21: ㆤㆷ | G21: ㄝㄏ | H21: eh | I21: eh | J21: eh | K21: eh | L21: eh | N21: =LEN(K21) -> 2 | P21: =J40 -> ih | Q21: =K40 -> ih | S21: =_xlfn.CONCAT(P21, "(\d)") -> ih(\d) | T21: a | U21: =IFERROR( IF(T21="", "", SEARCH(T21, $P21)), "") | V21: =IFERROR( _xlfn.CONCAT(LEFT(P21,U21-1), "》", MID(P21,U21,1), "${1}", RIGHT(P21, LEN(P21)-U21)), "" ) | X21: =IF(AND(Q21<>"", P21<>""), " - xform/》" & S21 & "/" & V21 & "/", "") -> - xform/》ih(\d)//
A22: =ROW() - 3 -> 19 | B22: =_xlfn.CONCAT("ɪ",, "k") -> ɪk | C22: ◯ | D22: =LEFT(韻母對照表[[#This Row],[十五音識別碼]],1) -> 經 | E22: 經（促） | F22: ㄝㆻ | G22: ㄝㄍ | J22: ek | K22: ek | N22: =LEN(K22) -> 2 | P22: =J25 -> ennh | Q22: =K25 -> ennh | S22: =_xlfn.CONCAT(P22, "(\d)") -> ennh(\d) | T22: i | U22: =IFERROR( IF(T22="", "", SEARCH(T22, $P22)), "") | V22: =IFERROR( _xlfn.CONCAT(LEFT(P22,U22-1), "》", MID(P22,U22,1), "${1}", RIGHT(P22, LEN(P22)-U22)), "" ) | X22: =IF(AND(Q22<>"", P22<>""), " - xform/》" & S22 & "/" & V22 & "/", "") -> - xform/》ennh(\d)//
A23: =ROW() - 3 -> 20 | B23: =_xlfn.CONCAT("ɪ", "ŋ") -> ɪŋ | C23: ◯ | D23: =LEFT(韻母對照表[[#This Row],[十五音識別碼]],1) -> 經 | E23: 經（舒） | F23: ㄝㆭ | G23: ㄝㄥ | J23: eng | K23: eng | N23: =LEN(K23) -> 3 | P23: =J21 -> eh | Q23: =K21 -> eh | S23: =_xlfn.CONCAT(P23, "(\d)") -> eh(\d) | T23: a | U23: =IFERROR( IF(T23="", "", SEARCH(T23, $P23)), "") | V23: =IFERROR( _xlfn.CONCAT(LEFT(P23,U23-1), "》", MID(P23,U23,1), "${1}", RIGHT(P23, LEN(P23)-U23)), "" ) | X23: =IF(AND(Q23<>"", P23<>""), " - xform/》" & S23 & "/" & V23 & "/", "") -> - xform/》eh(\d)//
A24: =ROW() - 3 -> 21 | B24: ẽ | C24: 爭 | D24: =LEFT(韻母對照表[[#This Row],[十五音識別碼]],1) -> 更 | E24: 更（舒） | F24: ㆥ | G24: ⁰ㄝ | H24: enn | I24: ne | J24: enn | K24: enn | L24: eⁿ | M24: 韻-鼻 | N24: =LEN(K24) -> 3 | P24: =J45 -> inn | Q24: =K45 -> inn | S24: =_xlfn.CONCAT(P24, "(\d)") -> inn(\d) | T24: o | U24: =IFERROR( IF(T24="", "", SEARCH(T24, $P24)), "") | V24: =IFERROR( _xlfn.CONCAT(LEFT(P24,U24-1), "》", MID(P24,U24,1), "${1}", RIGHT(P24, LEN(P24)-U24)), "" ) | X24: =IF(AND(Q24<>"", P24<>""), " - xform/》" & S24 & "/" & V24 & "/", "") -> - xform/》inn(\d)//
A25: =ROW() - 3 -> 22 | B25: ẽʔ | C25: 挾 | D25: =LEFT(韻母對照表[[#This Row],[十五音識別碼]],1) -> 更 | E25: 更（促） | F25: ㆥㆷ | G25: ⁰ㄝㄏ | H25: ennh | I25: ennh | J25: ennh | K25: ennh | L25: ehⁿ | M25: 韻-鼻 | N25: =LEN(K25) -> 4 | P25: =J42 -> im | Q25: =K42 -> im | S25: =_xlfn.CONCAT(P25, "(\d)") -> im(\d) | T25: e | U25: =IFERROR( IF(T25="", "", SEARCH(T25, $P25)), "") | V25: =IFERROR( _xlfn.CONCAT(LEFT(P25,U25-1), "》", MID(P25,U25,1), "${1}", RIGHT(P25, LEN(P25)-U25)), "" ) | X25: =IF(AND(Q25<>"", P25<>""), " - xform/》" & S25 & "/" & V25 & "/", "") -> - xform/》im(\d)//
A26: =ROW() - 3 -> 23 | B26: i | C26: 爾 | D26: =LEFT(韻母對照表[[#This Row],[十五音識別碼]],1) -> 居 | E26: 居（舒） | F26: ㄧ | G26: ㄧ | H26: i | I26: i | J26: i | K26: i | L26: i | N26: =LEN(K26) -> 1 | P26: =J43 -> in | Q26: =K43 -> in | S26: =_xlfn.CONCAT(P26, "(\d)") -> in(\d) | T26: a | U26: =IFERROR( IF(T26="", "", SEARCH(T26, $P26)), "") | V26: =IFERROR( _xlfn.CONCAT(LEFT(P26,U26-1), "》", MID(P26,U26,1), "${1}", RIGHT(P26, LEN(P26)-U26)), "" ) | X26: =IF(AND(Q26<>"", P26<>""), " - xform/》" & S26 & "/" & V26 & "/", "") -> - xform/》in(\d)//
A27: =ROW() - 3 -> 24 | B27: ɪa | C27: 名 | D27: =LEFT(韻母對照表[[#This Row],[十五音識別碼]],1) -> 迦 | E27: 迦（舒） | F27: ㄧㄚ | G27: ㄧㄚ | H27: ia | I27: ia | J27: ia | K27: ia | L27: ia | N27: =LEN(K27) -> 2 | P27: =J30 -> iam | Q27: =K30 -> iam | S27: =_xlfn.CONCAT(P27, "(\d)") -> iam(\d) | T27: i | U27: =IFERROR( IF(T27="", "", SEARCH(T27, $P27)), "") -> 1 | V27: =IFERROR( _xlfn.CONCAT(LEFT(P27,U27-1), "》", MID(P27,U27,1), "${1}", RIGHT(P27, LEN(P27)-U27)), "" ) -> 》i${1}am | X27: =IF(AND(Q27<>"", P27<>""), " - xform/》" & S27 & "/" & V27 & "/", "") -> - xform/》iam(\d)/》i${1}am/
A28: =ROW() - 3 -> 25 | B28: =_xlfn.CONCAT(B27, "ʔ") -> ɪaʔ | C28: 壁 | D28: =LEFT(韻母對照表[[#This Row],[十五音識別碼]],1) -> 迦 | E28: 迦（促） | F28: ㄧㄚㆷ | G28: ㄧㄚㄏ | H28: iah | I28: iah | J28: iah | K28: iah | L28: iah | N28: =LEN(K28) -> 3 | P28: =J32 -> iang | Q28: =K32 -> iang | S28: =_xlfn.CONCAT(P28, "(\d)") -> iang(\d) | T28: i | U28: =IFERROR( IF(T28="", "", SEARCH(T28, $P28)), "") -> 1 | V28: =IFERROR( _xlfn.CONCAT(LEFT(P28,U28-1), "》", MID(P28,U28,1), "${1}", RIGHT(P28, LEN(P28)-U28)), "" ) -> 》i${1}ang | X28: =IF(AND(Q28<>"", P28<>""), " - xform/》" & S28 & "/" & V28 & "/", "") -> - xform/》iang(\d)/》i${1}ang/
A29: =ROW() - 3 -> 26 | B29: ɪak̚ | C29: 爆 | D29: =LEFT(韻母對照表[[#This Row],[十五音識別碼]],1) -> 姜 | E29: 姜（促） | F29: ㄧㄚㆻ | G29: ㄧㄚㄍ | H29: iak | I29: iak | J29: iak | K29: iak | L29: iak | N29: =LEN(K29) -> 3 | P29: =J46 -> io | Q29: =K46 -> io | S29: =_xlfn.CONCAT(P29, "(\d)") -> io(\d) | T29: a | U29: =IFERROR( IF(T29="", "", SEARCH(T29, $P29)), "") | V29: =IFERROR( _xlfn.CONCAT(LEFT(P29,U29-1), "》", MID(P29,U29,1), "${1}", RIGHT(P29, LEN(P29)-U29)), "" ) | X29: =IF(AND(Q29<>"", P29<>""), " - xform/》" & S29 & "/" & V29 & "/", "") -> - xform/》io(\d)//
A30: =ROW() - 3 -> 27 | B30: ɪam | C30: 尖 | D30: =LEFT(韻母對照表[[#This Row],[十五音識別碼]],1) -> 兼 | E30: 兼（舒） | F30: ㄧㆰ | G30: ㄧㄚㄇ | H30: iam | I30: iam | J30: iam | K30: iam | L30: iam | N30: =LEN(K30) -> 3 | P30: =J36 -> iat | Q30: =K36 -> iat | S30: =_xlfn.CONCAT(P30, "(\d)") -> iat(\d) | T30: e | U30: =IFERROR( IF(T30="", "", SEARCH(T30, $P30)), "") | V30: =IFERROR( _xlfn.CONCAT(LEFT(P30,U30-1), "》", MID(P30,U30,1), "${1}", RIGHT(P30, LEN(P30)-U30)), "" ) | X30: =IF(AND(Q30<>"", P30<>""), " - xform/》" & S30 & "/" & V30 & "/", "") -> - xform/》iat(\d)//
A31: =ROW() - 3 -> 28 | B31: ɪan | C31: 掀 | D31: =LEFT(韻母對照表[[#This Row],[十五音識別碼]],1) -> 堅 | E31: 堅（舒） | F31: ㄧㄢ | G31: ㄧㄢ | H31: ian | I31: ian | J31: ian | K31: ian | L31: ian | N31: =LEN(K31) -> 3 | P31: =J29 -> iak | Q31: =K29 -> iak | S31: =_xlfn.CONCAT(P31, "(\d)") -> iak(\d) | T31: n | U31: =IFERROR( IF(T31="", "", SEARCH(T31, $P31)), "") | V31: =IFERROR( _xlfn.CONCAT(LEFT(P31,U31-1), "》", MID(P31,U31,1), "${1}", RIGHT(P31, LEN(P31)-U31)), "" ) | X31: =IF(AND(Q31<>"", P31<>""), " - xform/》" & S31 & "/" & V31 & "/", "") -> - xform/》iak(\d)//
A32: =ROW() - 3 -> 29 | B32: ɪaŋ | C32: 將 | D32: =LEFT(韻母對照表[[#This Row],[十五音識別碼]],1) -> 姜 | E32: 姜（舒） | F32: ㄧㄤ | G32: ㄧㄤ | H32: iang | I32: iang | J32: iang | K32: iang | L32: iang | N32: =LEN(K32) -> 4 | P32: =J37 -> iau | Q32: =K37 -> iau | S32: =_xlfn.CONCAT(P32, "(\d)") -> iau(\d) | T32: o | U32: =IFERROR( IF(T32="", "", SEARCH(T32, $P32)), "") | V32: =IFERROR( _xlfn.CONCAT(LEFT(P32,U32-1), "》", MID(P32,U32,1), "${1}", RIGHT(P32, LEN(P32)-U32)), "" ) | X32: =IF(AND(Q32<>"", P32<>""), " - xform/》" & S32 & "/" & V32 & "/", "") -> - xform/》iau(\d)//
A33: =ROW() - 3 -> 30 | B33: =_xlfn.CONCAT("ɪ", "a", _xlfn.UNICHAR(771), "") -> ɪã | C33: ◯ | D33: =LEFT(韻母對照表[[#This Row],[十五音識別碼]],1) -> 驚 | E33: 驚（舒） | F33: ㄧㆩ | G33: ⁰ㄧㄚ | H33: iann | I33: nia | J33: iann | K33: iann | L33: iaⁿ | M33: 韻-鼻 | N33: =LEN(K33) -> 4 | P33: =J31 -> ian | Q33: =K31 -> ian | S33: =_xlfn.CONCAT(P33, "(\d)") -> ian(\d) | T33: i | U33: =IFERROR( IF(T33="", "", SEARCH(T33, $P33)), "") -> 1 | V33: =IFERROR( _xlfn.CONCAT(LEFT(P33,U33-1), "》", MID(P33,U33,1), "${1}", RIGHT(P33, LEN(P33)-U33)), "" ) -> 》i${1}an | X33: =IF(AND(Q33<>"", P33<>""), " - xform/》" & S33 & "/" & V33 & "/", "") -> - xform/》ian(\d)/》i${1}an/
A34: =ROW() - 3 -> 31 | B34: =_xlfn.CONCAT(B33, "ʔ") -> ɪãʔ | C34: 且 | D34: =LEFT(韻母對照表[[#This Row],[十五音識別碼]],1) -> 迦 | E34: 迦（促） | F34: ㄧㆩㆷ | G34: ⁰ㄧㄚㄏ | H34: iannh | I34: iannh | J34: iannh | K34: iannh | L34: iahⁿ | M34: 韻-鼻 | N34: =LEN(K34) -> 5 | P34: =J35 -> iap | Q34: =K35 -> iap | S34: =_xlfn.CONCAT(P34, "(\d)") -> iap(\d) | T34: i | U34: =IFERROR( IF(T34="", "", SEARCH(T34, $P34)), "") -> 1 | V34: =IFERROR( _xlfn.CONCAT(LEFT(P34,U34-1), "》", MID(P34,U34,1), "${1}", RIGHT(P34, LEN(P34)-U34)), "" ) -> 》i${1}ap | X34: =IF(AND(Q34<>"", P34<>""), " - xform/》" & S34 & "/" & V34 & "/", "") -> - xform/》iap(\d)/》i${1}ap/
A35: =ROW() - 3 -> 32 | B35: ɪap̚ | C35: 接 | D35: =LEFT(韻母對照表[[#This Row],[十五音識別碼]],1) -> 兼 | E35: 兼（促） | F35: ㄧㄚㆴ | G35: ㄧㄚㄅ | H35: iap | I35: iap | J35: iap | K35: iap | L35: iap | N35: =LEN(K35) -> 3 | P35: =J39 -> iaunn | Q35: =K39 -> iaunn | S35: =_xlfn.CONCAT(P35, "(\d)") -> iaunn(\d) | T35: o | U35: =IFERROR( IF(T35="", "", SEARCH(T35, $P35)), "") | V35: =IFERROR( _xlfn.CONCAT(LEFT(P35,U35-1), "》", MID(P35,U35,1), "${1}", RIGHT(P35, LEN(P35)-U35)), "" ) | X35: =IF(AND(Q35<>"", P35<>""), " - xform/》" & S35 & "/" & V35 & "/", "") -> - xform/》iaunn(\d)//
A36: =ROW() - 3 -> 33 | B36: ɪat̚ | C36: 別 | D36: =LEFT(韻母對照表[[#This Row],[十五音識別碼]],1) -> 堅 | E36: 堅（促） | F36: ㄧㄚㆵ | G36: ㄧㄚㄉ | H36: iat | I36: iat | J36: iat | K36: iat | L36: iat | N36: =LEN(K36) -> 3 | P36: =J38 -> iauh | Q36: =K38 -> iauh | S36: =_xlfn.CONCAT(P36, "(\d)") -> iauh(\d) | T36: o | U36: =IFERROR( IF(T36="", "", SEARCH(T36, $P36)), "") | V36: =IFERROR( _xlfn.CONCAT(LEFT(P36,U36-1), "》", MID(P36,U36,1), "${1}", RIGHT(P36, LEN(P36)-U36)), "" ) | X36: =IF(AND(Q36<>"", P36<>""), " - xform/》" & S36 & "/" & V36 & "/", "") -> - xform/》iauh(\d)//
A37: =ROW() - 3 -> 34 | B37: ɪaʊ | C37: 遙 | D37: =LEFT(韻母對照表[[#This Row],[十五音識別碼]],1) -> 嬌 | E37: 嬌（舒） | F37: ㄧㄠ | G37: ㄧㄠ | H37: iau | I37: iao | J37: iau | K37: iau | L37: iau | N37: =LEN(K37) -> 3 | P37: =J52 -> ionn | Q37: =K52 -> ionn | S37: =_xlfn.CONCAT(P37, "(\d)") -> ionn(\d) | T37: a | U37: =IFERROR( IF(T37="", "", SEARCH(T37, $P37)), "") | V37: =IFERROR( _xlfn.CONCAT(LEFT(P37,U37-1), "》", MID(P37,U37,1), "${1}", RIGHT(P37, LEN(P37)-U37)), "" ) | X37: =IF(AND(Q37<>"", P37<>""), " - xform/》" & S37 & "/" & V37 & "/", "") -> - xform/》ionn(\d)//
A38: =ROW() - 3 -> 35 | B38: =_xlfn.CONCAT(B37, "ʔ") -> ɪaʊʔ | C38: 噭 | D38: =LEFT(韻母對照表[[#This Row],[十五音識別碼]],1) -> 嬌 | E38: 嬌（促） | F38: ㄧㄠㆷ | G38: ㄧㄠㄏ | H38: iauh | I38: iaoh | J38: iauh | K38: iauh | L38: iauh | N38: =LEN(K38) -> 4 | P38: =J49 -> iong | Q38: =K49 -> iong | S38: =_xlfn.CONCAT(P38, "(\d)") -> iong(\d) | T38: a | U38: =IFERROR( IF(T38="", "", SEARCH(T38, $P38)), "") | V38: =IFERROR( _xlfn.CONCAT(LEFT(P38,U38-1), "》", MID(P38,U38,1), "${1}", RIGHT(P38, LEN(P38)-U38)), "" ) | X38: =IF(AND(Q38<>"", P38<>""), " - xform/》" & S38 & "/" & V38 & "/", "") -> - xform/》iong(\d)//
A39: =ROW() - 3 -> 36 | B39: =_xlfn.CONCAT("ɪ", "a", _xlfn.UNICHAR(771), "ʊ") -> ɪãʊ | C39: 鳥 | D39: =LEFT(韻母對照表[[#This Row],[十五音識別碼]],1) -> 嘄 | E39: 嘄（舒） | F39: ㄧㆯ | G39: ⁰ㄧㄠ | H39: iaunn | I39: niao | J39: iaunn | K39: iaunn | L39: iauⁿ | M39: 韻-鼻 | N39: =LEN(K39) -> 5 | P39: =J47 -> ioh | Q39: =K47 -> ioh | S39: =_xlfn.CONCAT(P39, "(\d)") -> ioh(\d) | T39: a | U39: =IFERROR( IF(T39="", "", SEARCH(T39, $P39)), "") | V39: =IFERROR( _xlfn.CONCAT(LEFT(P39,U39-1), "》", MID(P39,U39,1), "${1}", RIGHT(P39, LEN(P39)-U39)), "" ) | X39: =IF(AND(Q39<>"", P39<>""), " - xform/》" & S39 & "/" & V39 & "/", "") -> - xform/》ioh(\d)//
A40: =ROW() - 3 -> 37 | B40: iʔ | C40: 逼 | D40: =LEFT(韻母對照表[[#This Row],[十五音識別碼]],1) -> 居 | E40: 居（促） | F40: ㄧㆷ | G40: ㄧㄏ | H40: ih | I40: ih | J40: ih | K40: ih | L40: ih | N40: =LEN(K40) -> 2 | P40: =J50 -> ip | Q40: =K50 -> ip | S40: =_xlfn.CONCAT(P40, "(\d)") -> ip(\d) | T40: a | U40: =IFERROR( IF(T40="", "", SEARCH(T40, $P40)), "") | V40: =IFERROR( _xlfn.CONCAT(LEFT(P40,U40-1), "》", MID(P40,U40,1), "${1}", RIGHT(P40, LEN(P40)-U40)), "" ) | X40: =IF(AND(Q40<>"", P40<>""), " - xform/》" & S40 & "/" & V40 & "/", "") -> - xform/》ip(\d)//
A41: =ROW() - 3 -> 38 | B41: ik̚ | C41: 益 | D41: =LEFT(韻母對照表[[#This Row],[十五音識別碼]],1) -> 經 | E41: 經（促） | F41: ㄧㆻ | G41: ㄧㄍ | H41: iek | I41: ik | J41: ik | K41: ik | L41: ek | N41: =LEN(K41) -> 2 | P41: =J34 -> iannh | Q41: =K34 -> iannh | S41: =_xlfn.CONCAT(P41, "(\d)") -> iannh(\d) | T41: a | U41: =IFERROR( IF(T41="", "", SEARCH(T41, $P41)), "") -> 2 | V41: =IFERROR( _xlfn.CONCAT(LEFT(P41,U41-1), "》", MID(P41,U41,1), "${1}", RIGHT(P41, LEN(P41)-U41)), "" ) -> i》a${1}nnh | X41: =IF(AND(Q41<>"", P41<>""), " - xform/》" & S41 & "/" & V41 & "/", "") -> - xform/》iannh(\d)/i》a${1}nnh/
...

Sheet 廣韻41聲【閩南語聲韻學】
B2: 發音部位 舊名 | D2: 發音部位 新名 | E2: 發音方法
E3: 全清 | G3: 次清 | I3: 全濁 | K3: 次濁（清濁）
B4: 唇音 | C4: 重唇 | D4: 雙唇 | E4: p | F4: 幫 | G4: ph | H4: 滂 | I4: p | J4: 並 | K4: m | L4: 明
E5: ㄅ | F5: 邊 | G5: ㄆ | H5: 頗 | I5: ㄅ | J5: 邊 | K5: ㄇ | L5: 毛
C6: 輕唇 | D6: 唇齒 | E6: f | F6: 非 | G6: f | H6: 敷 | I6: f | J6: 奉 | K6: b | L6: 微
E7: ㄏ | F7: 喜 | G7: ㄏ | H7: 喜 | I7: ㄏ | J7: 喜 | K7: ㆠ | L7: 門
B8: 舌音 | C8: 舌頭 | D8: 舌尖中 | E8: t | F8: 端 | G8: th | H8: 透 | I8: t | J8: 定 | K8: n | L8: 泥
E9: ㄉ | F9: 地 | G9: ㄊ | H9: 他 | I9: ㄉ | J9: 地 | K9: ㄋ | L9: 耐
C10: 舌上 | D10: 舌尖後 | E10: t | F10: 知 | G10: th | H10: 徹 | I10: t | J10: 澄 | K10: n | L10: 娘
E11: ㄉ | F11: 地 | G11: ㄊ | H11: 他 | I11: ㄉ | J11: 地 | K11: ㄋ | L11: 耐
B12: 齒音 | C12: 齒頭 | D12: 舌尖前 | E12: ts | F12: 精 | G12: tsh | H12: 清 | I12: ts | J12: 從
E13: ㄗ | F13: 曾 | G13: ㄘ | H13: 出 | I13: ㆡ | J13: 入
E14: s | F14: 心 | I14: s | J14: 邪
E15: ㄙ | F15: 時 | I15: ㄙ | J15: 時
C16: 正齒近齒頭 | E16: ts | F16: 莊 | G16: tsh | H16: 初 | I16: ts | J16: 牀
E17: ㄗ | F17: 曾 | G17: ㄘ | H17: 出 | I17: ㄗ | J17: 曾
E18: s | F18: 疏
E19: ㄒ | F19: 時
C20: 正齒近舌上 | D20: 舌面前 | E20: ts | F20: 照 | G20: tsh | H20: 穿 | I20: s | J20: 神
E21: ㄐ | F21: 曾 | G21: ㄑ | H21: 出 | I21: ㄙ | J21: 入
E22: s | F22: 審 | I22: s | J22: 禪
E23: ㄙ | F23: 時 | I23: ㄙ | J23: 時
B24: 牙音 | D24: 舌根 | E24: k | F24: 見 | G24: kh | H24: 溪 | I24: g | J24: 群 | K24: ng | L24: 疑
E25: ㄍ | F25: 求 | G25: ㄎ | H25: 去 | I25: ㆣ | J25: 語 | K25: ㄫ | L25: 雅
B26: 喉音 | D26: 喉音 | E26: ʔ | F26: 影
E27: Ø | F27: 英
D28: 舌根 | E28: h | F28: 曉 | I28: h | J28: 匣 | K28: ʔ | L28: 為
E29: ㄏ | F29: 喜 | I29: ㄏ | J29: 喜 | K29: Ø | L29: 英
D30: 半元音 | K30: ʔ | L30: 喻
K31: Ø | L31: 英
B32: 半舌音 | D32: 舌尖中 | K32: l | L32: 來
K33: ㄌ | L33: 柳
B34: 半齒音 | D34: 舌面前 | K34: j | L34: 日
K35: ㆡ | L35: 入

Sheet 切語上字表
A1: 識別號 | B1: 書序 | C1: 聲母對照表之識別號 | D1: 七聲類 | E1: 發音部位 | F1: 發音方法 | G1: 聲母 | H1: 聲母標音 | I1: 清濁 | J1: 發送收 | K1: 切語上字集 | L1: 備註
A2: 1 | B2: 1 | C2: {=INDEX(聲母對照表[識別號], MATCH(TRUE, EXACT(切語上字表[[#This Row],[聲母標音]], 聲母對照表[台羅拼音]),0))} -> 2 | D2: 脣音 | E2: 重脣音 | F2: 塞、鼻音 | G2: 幫 | H2: p | I2: 全清 | J2: 發聲 | K2: 邊布補伯百北博愽巴卑并鄙必彼兵筆陂畀晡風
A3: 2 | B3: 2 | C3: {=INDEX(聲母對照表[識別號], MATCH(TRUE, EXACT(切語上字表[[#This Row],[聲母標音]], 聲母對照表[台羅拼音]),0))} -> 4 | D3: 脣音 | E3: 重脣音 | F3: 塞、鼻音 | G3: 滂 | H3: ph | I3: 次清 | J3: 送氣 | K3: 滂普匹譬披丕被
A4: 3 | B4: 3 | C4: {=INDEX(聲母對照表[識別號], MATCH(TRUE, EXACT(切語上字表[[#This Row],[聲母標音]], 聲母對照表[台羅拼音]),0))} -> 2 | D4: 脣音 | E4: 重脣音 | F4: 塞、鼻音 | G4: 並 | H4: p | I4: 全濁 | K4: 蒲裴平皮步薄白部傍便弼婢毗簿捕
A5: 4 | B5: 4 | C5: {=INDEX(聲母對照表[識別號], MATCH(TRUE, EXACT(切語上字表[[#This Row],[聲母標音]], 聲母對照表[台羅拼音]),0))} -> 5 | D5: 脣音 | E5: 重脣音 | F5: 塞、鼻音 | G5: 明 | H5: m | I5: 次濁 | J5: 收聲 | K5: 莫慕模謨摸母明彌眉綿靡美矛 | L5: 閩南語：文讀音【b】；白話音【m/b】。
A6: 5 | B6: 5 | C6: {=INDEX(聲母對照表[識別號], MATCH(TRUE, EXACT(切語上字表[[#This Row],[聲母標音]], 聲母對照表[台羅拼音]),0))} -> 14 | D6: 脣音 | E6: 輕脣音 | G6: 非 | H6: h | I6: 全清 | J6: 發聲 | K6: 方封分府甫 | L6: 閩南語讀成【曉】母，文讀音【h】；白話音【p】
A7: 6 | B7: 6 | C7: {=INDEX(聲母對照表[識別號], MATCH(TRUE, EXACT(切語上字表[[#This Row],[聲母標音]], 聲母對照表[台羅拼音]),0))} -> 14 | D7: 脣音 | E7: 輕脣音 | G7: 敷 | H7: h | I7: 次清 | J7: 送氣 | K7: 敷孚妃撫峰拂芳峯 | L7: 閩南語讀成【曉】母，文讀音【h】；白話音【ph】
A8: 7 | B8: 7 | C8: {=INDEX(聲母對照表[識別號], MATCH(TRUE, EXACT(切語上字表[[#This Row],[聲母標音]], 聲母對照表[台羅拼音]),0))} -> 14 | D8: 脣音 | E8: 輕脣音 | G8: 奉 | H8: h | I8: 全濁 | K8: 防縛附父浮苻扶馮房符 | L8: 閩南語讀成【匣】母，文讀音【h】；白話音【p】【ph】
A9: 8 | B9: 8 | C9: {=INDEX(聲母對照表[識別號], MATCH(TRUE, EXACT(切語上字表[[#This Row],[聲母標音]], 聲母對照表[台羅拼音]),0))} -> 3 | D9: 脣音 | E9: 輕脣音 | G9: 微 | H9: b | I9: 次濁 | J9: 收聲 | K9: 巫無武文望亡
A10: 9 | B10: 9 | C10: {=INDEX(聲母對照表[識別號], MATCH(TRUE, EXACT(切語上字表[[#This Row],[聲母標音]], 聲母對照表[台羅拼音]),0))} -> 6 | D10: 舌音 | E10: 舌頭音 | F10: 塞、鼻音 | G10: 端 | H10: t | I10: 全清 | J10: 發聲 | K10: 多德得丁都當冬底
A11: 10 | B11: 10 | C11: {=INDEX(聲母對照表[識別號], MATCH(TRUE, EXACT(切語上字表[[#This Row],[聲母標音]], 聲母對照表[台羅拼音]),0))} -> 7 | D11: 舌音 | E11: 舌頭音 | F11: 塞、鼻音 | G11: 透 | H11: th | I11: 次清 | J11: 送氣 | K11: 他託土通天台湯吐
A12: 11 | B12: 11 | C12: {=INDEX(聲母對照表[識別號], MATCH(TRUE, EXACT(切語上字表[[#This Row],[聲母標音]], 聲母對照表[台羅拼音]),0))} -> 6 | D12: 舌音 | E12: 舌頭音 | F12: 塞、鼻音 | G12: 定 | H12: t | I12: 全濁 | K12: 徒同特唐堂田陀地度杜大
A13: 12 | B13: 12 | C13: {=INDEX(聲母對照表[識別號], MATCH(TRUE, EXACT(切語上字表[[#This Row],[聲母標音]], 聲母對照表[台羅拼音]),0))} -> 8 | D13: 舌音 | E13: 舌頭音 | F13: 塞、鼻音 | G13: 泥 | H13: n | I13: 次濁 | J13: 收聲 | K13: 奴乃諾內内那嬭㚷妳
A14: 13 | B14: 13 | C14: {=INDEX(聲母對照表[識別號], MATCH(TRUE, EXACT(切語上字表[[#This Row],[聲母標音]], 聲母對照表[台羅拼音]),0))} -> 6 | D14: 舌音 | E14: 舌上音 | F14: 塞、鼻音 | G14: 知 | H14: t | I14: 全清 | J14: 發聲 | K14: 知張豬猪徵中追陟卓竹珍迍
A15: 14 | B15: 14 | C15: {=INDEX(聲母對照表[識別號], MATCH(TRUE, EXACT(切語上字表[[#This Row],[聲母標音]], 聲母對照表[台羅拼音]),0))} -> 7 | D15: 舌音 | E15: 舌上音 | F15: 塞、鼻音 | G15: 徹 | H15: th | I15: 次清 | J15: 送氣 | K15: 抽癡褚禇楮丑恥敕
A16: 15 | B16: 15 | C16: {=INDEX(聲母對照表[識別號], MATCH(TRUE, EXACT(切語上字表[[#This Row],[聲母標音]], 聲母對照表[台羅拼音]),0))} -> 6 | D16: 舌音 | E16: 舌上音 | F16: 塞、鼻音 | G16: 澄 | H16: t | I16: 全濁 | K16: 除場池治持持遲佇柱丈直宅馳墜遟
A17: 16 | B17: 16 | C17: {=INDEX(聲母對照表[識別號], MATCH(TRUE, EXACT(切語上字表[[#This Row],[聲母標音]], 聲母對照表[台羅拼音]),0))} -> 8 | D17: 舌音 | E17: 舌上音 | F17: 塞、鼻音 | G17: 娘 | H17: n | I17: 次濁 | J17: 收聲 | K17: 尼拏女穠匿 | L17: 孃。閩南語：文讀音【l】；白話音【n/l】。
A18: 17 | B18: 17 | C18: {=INDEX(聲母對照表[識別號], MATCH(TRUE, EXACT(切語上字表[[#This Row],[聲母標音]], 聲母對照表[台羅拼音]),0))} -> 19 | D18: 齒音 | E18: 齒頭音 | F18: 有噝塞擦音 | G18: 精 | H18: ts | I18: 全清 | J18: 發聲 | K18: 子資則兹醉遵祖臧作將即借姊茲
A19: 18 | B19: 18 | C19: {=INDEX(聲母對照表[識別號], MATCH(TRUE, EXACT(切語上字表[[#This Row],[聲母標音]], 聲母對照表[台羅拼音]),0))} -> 21 | D19: 齒音 | E19: 齒頭音 | F19: 有噝塞擦音 | G19: 清 | H19: tsh | I19: 次清 | J19: 送氣 | K19: 蒼倉雌醋麤此采親遷千青七取麁且
A20: 19 | B20: 19 | C20: {=INDEX(聲母對照表[識別號], MATCH(TRUE, EXACT(切語上字表[[#This Row],[聲母標音]], 聲母對照表[台羅拼音]),0))} -> 19 | D20: 齒音 | E20: 齒頭音 | F20: 有噝塞擦音 | G20: 從 | H20: ts | I20: 全濁 | K20: 才徂慈藏在前秦情酢自昨漸匠疾鶵
A21: 20 | B21: 20 | C21: {=INDEX(聲母對照表[識別號], MATCH(TRUE, EXACT(切語上字表[[#This Row],[聲母標音]], 聲母對照表[台羅拼音]),0))} -> 22 | D21: 齒音 | E21: 齒頭音 | F21: 有噝擦音 | G21: 心 | H21: s | I21: 全清 | J21: 發聲 | K21: 蘇桑思司斯雖素速相辛須胥先悉息寫私
A22: 21 | B22: 21 | C22: {=INDEX(聲母對照表[識別號], MATCH(TRUE, EXACT(切語上字表[[#This Row],[聲母標音]], 聲母對照表[台羅拼音]),0))} -> 22 | D22: 齒音 | E22: 齒頭音 | F22: 有噝擦音 | G22: 邪 | H22: s | I22: 全濁 | J22: =CHAR(32) | K22: 辭隨寺似徐祥詳旬夕辤辝
A23: 22 | B23: 22 | C23: {=INDEX(聲母對照表[識別號], MATCH(TRUE, EXACT(切語上字表[[#This Row],[聲母標音]], 聲母對照表[台羅拼音]),0))} -> 19 | D23: 齒音 | E23: 正齒近齒頭 | F23: 有噝塞擦音 | G23: 莊 | H23: ts | I23: 全清 | J23: 發聲 | K23: 莊爭阻鄒簪側仄壯𩛠 | L23: 照（莊／章）
A24: 23 | B24: 23 | C24: {=INDEX(聲母對照表[識別號], MATCH(TRUE, EXACT(切語上字表[[#This Row],[聲母標音]], 聲母對照表[台羅拼音]),0))} -> 21 | D24: 齒音 | E24: 正齒近齒頭 | F24: 有噝塞擦音 | G24: 初 | H24: tsh | I24: 次清 | J24: 送氣 | K24: 初叉廁厠創瘡芻測楚 | L24: 穿（初／昌）
A25: 24 | B25: 24 | C25: {=INDEX(聲母對照表[識別號], MATCH(TRUE, EXACT(切語上字表[[#This Row],[聲母標音]], 聲母對照表[台羅拼音]),0))} -> 19 | D25: 齒音 | E25: 正齒近齒頭 | F25: 有噝塞擦音 | G25: 牀 | H25: ts | I25: 全濁 | K25: 牀崇查査雛鋤鉏豺犲助俟士仕崱 | L25: 牀（崇／俟）
A26: 25 | B26: 25 | C26: {=INDEX(聲母對照表[識別號], MATCH(TRUE, EXACT(切語上字表[[#This Row],[聲母標音]], 聲母對照表[台羅拼音]),0))} -> 22 | D26: 齒音 | E26: 正齒近齒頭 | F26: 有噝擦音 | G26: 疏 | H26: s | I26: 全清 | J26: 送氣 | K26: 疏山沙砂生色數所史踈䟽疎
A27: 26 | B27: 26 | C27: {=INDEX(聲母對照表[識別號], MATCH(TRUE, EXACT(切語上字表[[#This Row],[聲母標音]], 聲母對照表[台羅拼音]),0))} -> 19 | D27: 齒音 | E27: 正齒近舌上 | F27: 有噝塞擦音 | G27: 照 | H27: ts | I27: 全清 | J27: 發聲 | K27: 之辛征諸支脂止旨職煮煑正占章遮主 | L27: 照（莊／章）
A28: 27 | B28: 27 | C28: {=INDEX(聲母對照表[識別號], MATCH(TRUE, EXACT(切語上字表[[#This Row],[聲母標音]], 聲母對照表[台羅拼音]),0))} -> 21 | D28: 齒音 | E28: 正齒近舌上 | F28: 有噝塞擦音 | G28: 穿 | H28: tsh | I28: 次清 | J28: 送氣 | K28: 昌春充叱赤尺處姝 | L28: 穿（初／昌）
A29: 28 | B29: 28 | C29: {=INDEX(聲母對照表[識別號], MATCH(TRUE, EXACT(切語上字表[[#This Row],[聲母標音]], 聲母對照表[台羅拼音]),0))} -> 22 | D29: 齒音 | E29: 正齒近舌上 | F29: 有噝擦音 | G29: 神 | H29: s | I29: 全濁 | J29: 送氣 | K29: 神乘乗食實
A30: 29 | B30: 29 | C30: {=INDEX(聲母對照表[識別號], MATCH(TRUE, EXACT(切語上字表[[#This Row],[聲母標音]], 聲母對照表[台羅拼音]),0))} -> 22 | D30: 齒音 | E30: 正齒近舌上 | F30: 有噝擦音 | G30: 審 | H30: s | I30: 全清 | J30: 送氣 | K30: 書舒傷商施失詩始釋賞識矢式試 | L30: 審（生／書）
A31: 30 | B31: 30 | C31: {=INDEX(聲母對照表[識別號], MATCH(TRUE, EXACT(切語上字表[[#This Row],[聲母標音]], 聲母對照表[台羅拼音]),0))} -> 22 | D31: 齒音 | E31: 正齒近舌上 | F31: 有噝擦音 | G31: 禪 | H31: s | I31: 全濁 | J31: 送氣 | K31: 時殊嘗甞常成臣蜀市植殖寔署是氏視承十 | L31: 禪（禪／船）
A32: 31 | B32: 31 | C32: {=INDEX(聲母對照表[識別號], MATCH(TRUE, EXACT(切語上字表[[#This Row],[聲母標音]], 聲母對照表[台羅拼音]),0))} -> 10 | D32: 牙音 | E32: 牙音 | F32: 牙音 | G32: 見 | H32: k | I32: 全清 | J32: 發聲 | K32: 古公過各規姑格詭吉紀几居九俱舉兼佳乖矩工
A33: 32 | B33: 32 | C33: {=INDEX(聲母對照表[識別號], MATCH(TRUE, EXACT(切語上字表[[#This Row],[聲母標音]], 聲母對照表[台羅拼音]),0))} -> 12 | D33: 牙音 | E33: 牙音 | F33: 牙音 | G33: 溪 | H33: kh | I33: 次清 | J33: 送氣 | K33: 康枯空口楷客恪苦窺牽謙去丘祛羌欽墟傾起綺豈區驅詰曲咎可乞袪弃卿
A34: 33 | B34: 33 | C34: {=INDEX(聲母對照表[識別號], MATCH(TRUE, EXACT(切語上字表[[#This Row],[聲母標音]], 聲母對照表[台羅拼音]),0))} -> 10 | D34: 牙音 | E34: 牙音 | F34: 牙音 | G34: 群 | H34: k | I34: 全濁 | K34: 渠強求奇衢其暨曁具巨臼跪近狂
A35: 34 | B35: 34 | C35: {=INDEX(聲母對照表[識別號], MATCH(TRUE, EXACT(切語上字表[[#This Row],[聲母標音]], 聲母對照表[台羅拼音]),0))} -> 11 | D35: 牙音 | E35: 牙音 | F35: 牙音 | G35: 疑 | H35: g | I35: 次濁 | J35: 收聲 | K35: 疑魚語宜玉遇虞愚牛擬研危五俄吾 | L35: 閩南語：文讀音【g】；白話音【ng/g】。
A36: 35 | B36: 35 | C36: {=INDEX(聲母對照表[識別號], MATCH(TRUE, EXACT(切語上字表[[#This Row],[聲母標音]], 聲母對照表[台羅拼音]),0))} -> 1 | D36: 喉音 | E36: 喉音 | G36: 影 | H36: Ø | I36: 全清 | J36: 發聲 | K36: 烏哀安紆愛握於央一伊依衣憂煙鷖憶乙謁挹委毆烟
A37: 36 | B37: 36 | C37: {=INDEX(聲母對照表[識別號], MATCH(TRUE, EXACT(切語上字表[[#This Row],[聲母標音]], 聲母對照表[台羅拼音]),0))} -> 14 | D37: 喉音 | E37: 喉音 | G37: 曉 | H37: h | I37: 次清 | J37: 送氣 | K37: 呼荒呵虛虚馨香羲休興虎火海況况朽喜許花兄
A38: 37 | B38: 37 | C38: {=INDEX(聲母對照表[識別號], MATCH(TRUE, EXACT(切語上字表[[#This Row],[聲母標音]], 聲母對照表[台羅拼音]),0))} -> 14 | D38: 喉音 | E38: 喉音 | G38: 匣 | H38: h | I38: 全濁 | J38: 送氣 | K38: 胡乎侯何黃戶戸下獲懷諧 | L38: 匣【hap8】，《唐韻》胡(hoo5)甲(kap4)切，𠀤音狎(hap8)
A39: 38 | B39: 38 | C39: {=INDEX(聲母對照表[識別號], MATCH(TRUE, EXACT(切語上字表[[#This Row],[聲母標音]], 聲母對照表[台羅拼音]),0))} -> 1 | D39: 喉音 | E39: 喉音 | G39: 為 | H39: Ø | I39: 次濁 | J39: 發聲 | K39: 于雲云筠為爲榮本王雨羽永有洧𨘏遠
A40: 39 | B40: 39 | C40: {=INDEX(聲母對照表[識別號], MATCH(TRUE, EXACT(切語上字表[[#This Row],[聲母標音]], 聲母對照表[台羅拼音]),0))} -> 1 | D40: 喉音 | E40: 喉音 | G40: 喻 | H40: Ø | I40: 次濁 | J40: 發聲 | K40: 余餘予移夷羊營以弋翼與悅薳韋 | L40: 喻【u5】，《集韻》容(iong5)朱(tsu1)切，音兪(u5)。云
...

Sheet 切語下字表
A1: 識別號 | B1: 韻母 | C1: 韻母標音 | D1: 攝 | E1: 韻 | F1: 呼 | G1: 等 | H1: 調 | I1: 等呼 | J1: 切語下字集 | K1: 備註
A2: 1 | B2: 東一 | C2: ong | D2: 通 | E2: 東 | F2: 開 | G2: 一 | H2: 平 | I2: 獨洪 | J2: 工公紅東洪空 | M2: = IF(SEARCH(LEFT([@韻],1), [@韻目] ) <> 4, INDEX(韻母標音表[舒聲標音],[@韻母標音表之識別號]), INDEX(韻母標音表[促聲標音],[@韻母標音表之識別號]))
A3: 2 | B3: 董一 | C3: ong | D3: 通 | E3: 董 | F3: 開 | G3: 一 | H3: 上 | I3: 獨洪 | J3: 動乙摠董蠓孔揔
A4: 3 | B4: 送一 | C4: ong | D4: 通 | E4: 送 | F4: 開 | G4: 一 | H4: 去 | I4: 獨洪 | J4: 貢弄送凍鳳
A5: 4 | B5: 屋一 | C5: ok | D5: 通 | E5: 屋 | F5: 開 | G5: 一 | H5: 入 | I5: 獨洪 | J5: 谷祿禄木卜
A6: 5 | B6: 東二 | C6: iong | D6: 通 | E6: 東 | F6: 開 | G6: 三 | H6: 平 | I6: 獨細 | J6: 弓戎中宮終融隆
A7: 6 | B7: 董二 | C7: iong | D7: 通 | E7: 董 | F7: 開 | G7: 三 | H7: 上 | I7: 獨細 | K7: 董韻無3等字
A8: 7 | B8: 送二 | C8: iong | D8: 通 | E8: 送 | F8: 開 | G8: 三 | H8: 去 | I8: 獨細 | J8: 仲眾衆
A9: 8 | B9: 屋二 | C9: iok | D9: 通 | E9: 屋 | F9: 開 | G9: 三 | H9: 入 | I9: 獨細 | J9: 六逐匊宿竹菊福
A10: 9 | B10: 冬 | C10: ong | D10: 通 | E10: 冬 | F10: 開 | G10: 一 | H10: 平 | I10: 獨洪 | J10: 宗冬
A11: 10 | B11: 冬 | C11: ong | D11: 通 | E11: 宋 | F11: 開 | G11: 一 | H11: 去 | I11: 獨洪 | J11: 統宋綜
A12: 11 | B12: 冬 | C12: ok | D12: 通 | E12: 沃 | F12: 開 | G12: 一 | H12: 入 | I12: 獨洪 | J12: 毒沃篤酷
A13: 12 | B13: 鍾 | C13: iong | D13: 通 | E13: 鍾 | F13: 開 | G13: 三 | H13: 平 | I13: 獨細 | J13: 容凶庸鍾恭封
A14: 13 | B14: 鍾 | C14: iong | D14: 通 | E14: 腫 | F14: 開 | G14: 三 | H14: 上 | I14: 獨細 | J14: 隴勇拱悚冢冗踵奉宂𪁪湩
A15: 14 | B15: 鍾 | C15: iong | D15: 通 | E15: 用 | F15: 開 | G15: 三 | H15: 去 | I15: 獨細 | J15: 用訟頌
A16: 15 | B16: 鍾 | C16: iok | D16: 通 | E16: 燭 | F16: 開 | G16: 三 | H16: 入 | I16: 獨細 | J16: 玉欲曲足蜀祿録錄
A17: 16 | B17: 江 | C17: ang | D17: 江 | E17: 江 | F17: 開 | G17: 二 | H17: 平 | I17: 獨洪 | J17: 雙江
A18: 17 | B18: 江 | C18: ang | D18: 江 | E18: 講 | F18: 開 | G18: 二 | H18: 上 | I18: 獨洪 | J18: 項講慃
A19: 18 | B19: 江 | C19: ang | D19: 江 | E19: 絳 | F19: 開 | G19: 二 | H19: 去 | I19: 獨洪 | J19: 巷絳降
... A51: 50 | B51: 齊一 | C51: e | D51: 蟹 | E51: 齊 | F51: 開 | G51: 四 | H51: 平 | I51: 開細 | J51: 奚雞稽低兮臡迷
A52: 51 | B52: 齊二 | C52: ui | D52: 蟹 | E52: 齊 | F52: 合 | G52: 四 | H52: 平 | I52: 合細 | J52: 圭攜 | K52: 攜：戶圭切
A53: 52 | B53: 薺一 | C53: e | D53: 蟹 | E53: 薺 | F53: 開 | G53: 四 | H53: 上 | I53: 開細 | J53: 禮啟啓弟米
A54: 53 | B54: 薺二 | C54: ui | D54: 蟹 | E54: 薺 | F54: 合 | G54: 四 | H54: 上 | I54: 合細 | K54: 薺合4無字
A55: 54 | B55: 霽一 | C55: e | D55: 蟹 | E55: 霽 | F55: 開 | G55: 四 | H55: 去 | I55: 開細 | J55: 詣計戾隸
A56: 55 | B56: 霽二 | C56: ui | D56: 蟹 | E56: 霽 | F56: 合 | G56: 四 | H56: 去 | I56: 合細 | J56: 桂惠
A57: 56 | B57: 祭一 | C57: e | D57: 蟹 | E57: 祭 | F57: 開 | G57: 三 | H57: 去 | I57: 開細 | J57: 例制罽祭憩袂蔽弊𡚁世
A58: 57 | B58: 祭二 | C58: ue | D58: 蟹 | E58: 祭 | F58: 合 | G58: 三 | H58: 去 | I58: 合細 | J58: 芮銳衛稅劌歲
A59: 58 | B59: 泰一 | C59: ai | D59: 蟹 | E59: 泰 | F59: 開 | G59: 一 | H59: 去 | I59: 開洪 | J59: 蓋太艾大帶
A60: 59 | B60: 泰二 | C60: ue | D60: 蟹 | E60: 泰 | F60: 合 | G60: 一 | H60: 去 | I60: 合洪 | J60: 外會最貝
A61: 60 | B61: 佳一 | C61: ai | D61: 蟹 | E61: 佳 | F61: 開 | G61: 二 | H61: 平 | I61: 開洪 | J61: 佳膎
A62: 61 | B62: 佳二 | C62: ua | D62: 蟹 | E62: 佳 | F62: 合 | G62: 二 | H62: 平 | I62: 合洪 | J62: 蛙媧緺
A63: 62 | B63: 蟹一 | C63: ai | D63: 蟹 | E63: 蟹 | F63: 開 | G63: 二 | H63: 上 | I63: 開洪 | J63: 蟹買𦫳
A64: 63 | B64: 蟹二 | C64: ua | D64: 蟹 | E64: 蟹 | F64: 合 | G64: 二 | H64: 上 | I64: 合洪 | J64: 夥𠁥
A65: 64 | B65: 卦一 | C65: ai | D65: 蟹 | E65: 卦 | F65: 開 | G65: 二 | H65: 去 | I65: 開洪 | J65: 隘懈賣卦
A66: 65 | B66: 卦二 | C66: ua | D66: 蟹 | E66: 卦 | F66: 合 | G66: 二 | H66: 去 | I66: 合洪
A67: 66 | B67: 皆一 | C67: ai | D67: 蟹 | E67: 皆 | F67: 開 | G67: 二 | H67: 平 | I67: 開洪 | J67: 諧皆
A68: 67 | B68: 皆二 | C68: uai | D68: 蟹 | E68: 皆 | F68: 合 | G68: 二 | H68: 平 | I68: 合洪 | J68: 乖懷淮
A69: 68 | B69: 駭一 | C69: ai | D69: 蟹 | E69: 駭 | F69: 開 | G69: 二 | H69: 上 | I69: 開洪 | J69: 駭楷
A70: 69 | B70: 駭二 | C70: uai | D70: 蟹 | E70: 駭 | F70: 合 | G70: 二 | H70: 上 | I70: 合洪
A71: 70 | B71: 怪一 | C71: ai | D71: 蟹 | E71: 怪 | F71: 開 | G71: 二 | H71: 去 | I71: 開洪 | J71: 戒介界拜殺
...

Sheet 聲調對照表
A1: 漢語四聲 | B1: 廣韻聲調 | C1: 雅俗通聲調 | D1: 十五音聲調 | E1: 台羅調名 | F1: 台羅調號 | G1: 台羅變調 | H1: 閩拼八聲調 | I1: 方音符號調符 | J1: 台羅調值 | K1: 古漢語調值 | M1: 廣韻聲調 | N1: 四聲調名 | O1: 舒促聲 | P1: 四聲調號 | R1: 四聲調號 | S1: 四聲中文 | T1: 四聲調名 | V1: 等呼名
A2: 平 | B2: 清平 | C2: 上平 | D2: 一 | E2: 陰平 | F2: 1 | G2: 7 | H2: 1 | J2: 44 | K2: 55 | M2: 上平 | N2: 平 | O2: 舒 | P2: 1 | R2: 1 | S2: 一 | T2: 平 | V2: 獨洪
A3: 上 | B3: 清上 | C3: 上上 | D3: 二 | E3: 陰上 | F3: 2 | G3: 1 | H3: 3 | I3: ˋ | J3: 42 | K3: 53 | M3: 下平 | N3: 平 | O3: 舒 | P3: 1 | R3: 2 | S3: 二 | T3: 上 | V3: 獨細
A4: 去 | B4: 清去 | C4: 上去 | D4: 三 | E4: 陰去 | F4: 3 | G4: 2 | H4: 5 | I4: ˪ | J4: 21 | K4: 11 | M4: 上 | N4: 上 | O4: 舒 | P4: 2 | R4: 3 | S4: 三 | T4: 去 | V4: 開細
A5: 入 | B5: 清入 | C5: 上入 | D5: 四 | E5: 陰入 | F5: 4 | G5: 8 | H5: 7 | J5: 30 | K5: 30 | M5: 去 | N5: 去 | O5: 舒 | P5: 3 | R5: 4 | S5: 四 | T5: 入 | V5: 獨細
A6: 平 | B6: 濁平 | C6: 下平 | D6: 五 | E6: 陽平 | F6: 5 | G6: 7 | H6: 2 | I6: ˊ | J6: 24 | K6: 35 | M6: 入 | N6: 入 | O6: 促 | P6: 4 | V6: 合細
A7: 上 | B7: 濁上 | C7: 下上 | D7: 二 | E7: 陽上 | F7: 6 | H7: 4
A8: 去 | B8: 濁去 | C8: 下去 | D8: 七 | E8: 陽去 | F8: 7 | G8: 3 | H8: 6 | I8: ˫ | J8: 22 | K8: 33 | R8: =_xlfn.XLOOKUP(F4,四聲調表[四聲調號],四聲調表[四聲調名],"四聲調號有錯！",1) -> 去
A9: 入 | B9: 濁入 | C9: 下入 | D9: 八 | E9: 陽入 | F9: 8 | G9: 4 | H9: 8 | I9: ˙ | J9: 50 | K9: 50

Sheet 【調】韻母標調
B1: 響度優先次第： a > oo > (e = o) > (i = u)〈低元音 > 高元音 > 無擦通音 > 擦音 > 塞音〉 | AJ1: 1 | AK1: 2 | AL1: 3 | AM1: 4 | AN1: 5 | AO1: 6 | AP1: 7 | AQ1: 8 | AR1: 9 | AS1: 9
B3: 調號 | C3: 調名 | D3: 鍵盤按鍵 | E3: 台羅調符編碼 | F3: 台羅拼音 | H3: 傳統調號 | I3: 調名 | J3: 調值 | K3: 調性 | L3: 鍵盤按鍵 | M3: 台羅調符編碼 | N3: 台羅拼音 | O3: 閩拼調符編碼 | P3: 閩拼方案 | Q3: 閩拼調號
B4: 1 | C4: 上平 | D4: ; | F4: =IFERROR( _xlfn.CONCAT("a"), "") -> a | H4: 1 | I4: 上平 | J4: 44 | K4: 高音調 | L4: ; | N4: =IFERROR( _xlfn.CONCAT("a", IF($M4="", "", _xlfn.UNICHAR(HEX2DEC(RIGHT($M4,4))))), "") -> a | O4: U+0304 | P4: =IFERROR( _xlfn.CONCAT("a", _xlfn.UNICHAR(HEX2DEC(RIGHT(O4,4)))), "") -> ā | Q4: 1
B5: 2 | C5: 上聲 | D5: \ | E5: U+0301 | F5: =IFERROR( _xlfn.CONCAT("a", _xlfn.UNICHAR(HEX2DEC(RIGHT($E5,4)))), "") -> á | H5: 7 | I5: 下去 | J5: 22 | K5: 中音調 | L5: - | M5: U+0304 | N5: =IFERROR( _xlfn.CONCAT("a", IF($M5="", "", _xlfn.UNICHAR(HEX2DEC(RIGHT($M5,4))))), "") -> ā | O5: U+0302 | P5: =IFERROR( _xlfn.CONCAT("a", _xlfn.UNICHAR(HEX2DEC(RIGHT(O5,4)))), "") -> â | Q5: 6
B6: 3 | C6: 上去 | D6: _ | E6: U+0300 | F6: =IFERROR( _xlfn.CONCAT("a", _xlfn.UNICHAR(HEX2DEC(RIGHT($E6,4)))), "") -> à | H6: 3 | I6: 上去 | J6: 21 | K6: 低音調 | L6: _ | M6: U+0301 | N6: =IFERROR( _xlfn.CONCAT("a", IF($M7="", "", _xlfn.UNICHAR(HEX2DEC(RIGHT($M7,4))))), "") -> à | O6: U+0300 | P6: =IFERROR( _xlfn.CONCAT("a", _xlfn.UNICHAR(HEX2DEC(RIGHT(O6,4)))), "") -> à | Q6: 5
B7: 4 | C7: 上入 | D7: [ | F7: =IFERROR( _xlfn.CONCAT("a", _xlfn.UNICHAR(HEX2DEC(RIGHT($E7,4)))), "") | H7: 2 | I7: 上聲 | J7: 53 | K7: 高降調 | L7: \ | M7: U+0300 | N7: =IFERROR( _xlfn.CONCAT("a", IF($M6="", "", _xlfn.UNICHAR(HEX2DEC(RIGHT($M6,4))))), "") -> á | O7: U+030C | P7: =IFERROR( _xlfn.CONCAT("a", _xlfn.UNICHAR(HEX2DEC(RIGHT(O7,4)))), "") -> ǎ | Q7: 3
B8: 5 | C8: 下平 | D8: / | E8: U+030C | F8: =IFERROR( _xlfn.CONCAT("a", _xlfn.UNICHAR(HEX2DEC(RIGHT($E8,4)))), "") -> ǎ | H8: 5 | I8: 下平 | J8: 24 | K8: 低升調 | L8: / | M8: U+0301 | N8: =IFERROR( _xlfn.CONCAT("a", IF($M8="", "", _xlfn.UNICHAR(HEX2DEC(RIGHT($M8,4))))), "") -> á | O8: U+0301 | P8: =IFERROR( _xlfn.CONCAT("a", _xlfn.UNICHAR(HEX2DEC(RIGHT(O8,4)))), "") -> á | Q8: 2
B9: 6 | C9: 上聲 | E9: U+0301 | F9: =IFERROR( _xlfn.CONCAT("a", _xlfn.UNICHAR(HEX2DEC(RIGHT($E9,4)))), "") -> á | H9: 7 | I9: 上入 | J9: 320 | K9: 低促調 | L9: [ | M9: U+030C | N9: =IFERROR( _xlfn.CONCAT("a", IF($M9="", "", _xlfn.UNICHAR(HEX2DEC(RIGHT($M9,4))))), "") -> ǎ | O9: U+0304 | P9: =IFERROR( _xlfn.CONCAT("a", _xlfn.UNICHAR(HEX2DEC(RIGHT(O9,4))), "h"), "") -> āh | Q9: 7
B10: 7 | C10: 下去 | D10: - | E10: U+0304 | F10: =IFERROR( _xlfn.CONCAT("a", _xlfn.UNICHAR(HEX2DEC(RIGHT($E10,4)))), "") -> ā | H10: 8 | I10: 下入 | J10: 40 | K10: 高促調 | L10: ] | M10: U+030D | N10: =IFERROR( _xlfn.CONCAT("a", IF($M10="", "", _xlfn.UNICHAR(HEX2DEC(RIGHT($M10,4))))), "") -> a̍ | O10: U+0301 | P10: =IFERROR( _xlfn.CONCAT("a", _xlfn.UNICHAR(HEX2DEC(RIGHT(O10,4))), "h"), "") -> áh | Q10: 8
