Workbook
Name 切語上字: 切語上字表!$H$2:$H$42

Sheet 查詢
B2: 反切： | C2: 戶吳 | G2: 標音： | H2: =_xlfn.CONCAT(C5, C8, C10) -> hoo1 | K2: =_xlfn.CONCAT(H4, "遇", H7, N7:N7) -> 匣遇模一 | Q2: 漢字 | R2: 切語 | S2: 台語音標
Q3: 阻 | R3: 側呂 | S3: zu7
B4: 上字： | C4: =LEFT(TRIM($C$2),1) -> 戶 | D4: =MATCH(E4, 切語上字表[切語上字集], 0) -> 37 | E4: =_xlfn.CONCAT("*", C4, "*") -> *戶* | G4: 【聲】： | H4: {=INDEX(切語上字表[聲母], 查詢!$D$4)} -> 匣 | J4: 清濁： | K4: {=INDEX(反切上字表[清濁], 查詢!$D$4)} -> 全清 | M4: =IF( RIGHT(K4)="清", "陰", "陽" ) -> 陰 | Q4: 阻 | R4: 莊助 | S4: zu7
B5: 聲母： | C5: {=INDEX(切語上字表[聲母標音], 查詢!$D$4)} -> h | Q5: 是 | R5: 承旨 | S5: si7
Q6: 上 | R6: 時掌 | S6: siong7 | T6: siang7
B7: 下字： | C7: =RIGHT(TRIM($C$2),1) -> 吳 | D7: =MATCH(E7, 切語下字表[切語下字集], 0) -> 47 | E7: =_xlfn.CONCAT("*", C7, "*") -> *吳* | G7: 【韻】： | H7: {=INDEX(切語下字表[韻母], $D$7)} -> 模 | J7: 攝： | K7: {=INDEX(切語下字表[攝], $D$7)} -> 遇 | M7: 等第： | N7: {=TEXT(INDEX(切語下字表[等], $D$7), "[DBNum1]")} -> 一 | Q7: 五 | R7: 疑古 | S7: goo2 | T7: ngoo2
B8: 韻母： | C8: {=INDEX(切語下字表[韻母標音], $D$7)} -> oo | J8: 韻系： | K8: {=INDEX(切語下字表[韻系], $D$7)} -> 模 | M8: 開合： | N8: {=INDEX(切語下字表[呼], $D$7)} -> 開 | Q8: 米 | R8: 莫禮 | S8: me2 | T8: bi2
M9: 四聲： | N9: {=INDEX(切語下字表[四聲], $D$7)} -> 平
B10: 調號： | C10: =IF(K10 <> "陽上", _xlfn.XLOOKUP(K10, 反切規則表!M2:M9, 反切規則表!N2:N9, "調值有錯！"), IF( K4 = "全濁", 7, 2) ) -> 1 | G10: 【調】： | H10: =_xlfn.CONCAT( RIGHT(K4), N9) -> 清平 | J10: 八音： | K10: =_xlfn.CONCAT(M4,N9) -> 陰平

Sheet 反切規則表
K2: 陰 | L2: 平 | M2: =_xlfn.CONCAT($K$2, L2) -> 陰平 | N2: 1 | P2: 聲母 | Q2: 清濁 | R2: 陽上轉調 | S2: 調號
L3: 上 | M3: =_xlfn.CONCAT($K$2, L3) -> 陰上 | N3: 2 | P3: 群 | Q3: 全濁 | R3: 陽去 | S3: 7
L4: 去 | M4: =_xlfn.CONCAT($K$2, L4) -> 陰去 | N4: 3 | P4: 定 | Q4: 全濁 | R4: 陽去 | S4: 7
L5: 入 | M5: =_xlfn.CONCAT($K$2, L5) -> 陰入 | N5: 4 | P5: 澄 | Q5: 全濁 | R5: 陽去 | S5: 7
K6: 陽 | L6: 平 | M6: =_xlfn.CONCAT($K$6, L6) -> 陽平 | N6: 5 | P6: 並 | Q6: 全濁 | R6: 陽去 | S6: 7
L7: 上 | M7: =_xlfn.CONCAT($K$6, L7) -> 陽上 | N7: 6 | P7: 奉 | Q7: 全濁 | R7: 陽去 | S7: 7
L8: 去 | M8: =_xlfn.CONCAT($K$6, L8) -> 陽去 | N8: 7 | P8: 從 | Q8: 全濁 | R8: 陽去 | S8: 7
L9: 入 | M9: =_xlfn.CONCAT($K$6, L9) -> 陽入 | N9: 8 | P9: 邪 | Q9: 全濁 | R9: 陽去 | S9: 7
P10: 牀 | Q10: 全濁 | R10: 陽去 | S10: 7
P11: 神 | Q11: 全濁 | R11: 陽去 | S11: 7
P12: 禪 | Q12: 全濁 | R12: 陽去 | S12: 7
P13: 匣 | Q13: 全濁 | R13: 陽去 | S13: 7
P14: 泥 | Q14: 次濁 | R14: 陰上 | S14: 2
P15: 孃 | Q15: 次濁 | R15: 陰上 | S15: 3
P16: 明 | Q16: 次濁 | R16: 陰上 | S16: 4
P17: 微 | Q17: 次濁 | R17: 陰上 | S17: 5
P18: 為 | Q18: 次濁 | R18: 陰上 | S18: 6
P19: 喻 | Q19: 次濁 | R19: 陰上 | S19: 7
P20: 來 | Q20: 次濁 | R20: 陰上 | S20: 8
P21: 日 | Q21: 次濁 | R21: 陰上 | S21: 9

Sheet 陽上轉調規則
B2: 上字聲母類型 | C2: 演變路徑 | D2: 最終調號 (漳/廈/台) | E2: 備註
B3: 全濁 (並定從群...) | C3: 濁上變去 | D3: 7 (陽去) | E3: 此規律最為整齊
B4: 次濁 (明泥來疑...) | C4: 陽上併陰上 | D4: 2 (陰上) | E4: 泉州腔多保留 6

Sheet 工作表1
A1: 序號 | B1: 發音部位 | C1: 聲類 | D1: 清濁 | E1: 發收送 | F1: 聲母擬音 | H1: 反切上字 | I1: 原序號
A2: 1 | B2: 牙音 | C2: 見 | D2: 全清 | E2: 發聲 | F2: k | H2: 居九俱舉規吉紀几古公過各格兼姑佳詭乖 | I2: 17
A3: 2 | B3: 牙音 | C3: 溪 | D3: 次清 | E3: 送氣 | F3: kh | H3: 康枯牽空謙口楷客恪苦去丘墟袪詰窺羌欽傾起綺豈區驅曲可乞棄卿弃 | I3: 18
A4: 3 | B4: 牙音 | C4: 群 | D4: 全濁 | F4: kh | H4: 渠強求巨具臼衢其奇暨跪近狂 | I4: 19
A5: 4 | B5: 牙音 | C5: 疑 | D5: 次濁 | E5: 收聲 | F5: g | H5: 疑魚牛語宜擬危五玉俄吾研遇虞愚 | I5: 20
A6: 5 | B6: 舌頭音 | C6: 端 | D6: 全清 | E6: 發聲 | F6: t | H6: 多德得丁都當冬 | I6: 9
A7: 6 | B7: 舌頭音 | C7: 透 | D7: 次清 | E7: 送氣 | F7: th | H7: 他託土吐通天台湯 | I7: 10
A8: 7 | B8: 舌頭音 | C8: 定 | D8: 全濁 | F8: t | H8: 徒同特度杜唐堂田陀地 | I8: 11
A9: 8 | B9: 舌頭音 | C9: 泥 | D9: 次濁 | E9: 收聲 | F9: n | H9: 奴乃諾內嬭妳那 | I9: 12
A10: 9 | B10: 舌上音 | C10: 知 | D10: 全清 | E10: 發聲 | F10: t | H10: 知張豬徵中追陟卓竹珍 | I10: 13
A11: 10 | B11: 舌上音 | C11: 徹 | D11: 次清 | E11: 送氣 | F11: th | H11: 抽癡楮褚丑恥敕 | I11: 14
A12: 11 | B12: 舌上音 | C12: 澄 | D12: 全濁 | F12: t | H12: 除場池治持遲＊佇柱丈直宅墜馳 | I12: 15
A13: 12 | B13: 舌上音 | C13: 娘 | D13: 次濁 | E13: 收聲 | F13: n | H13: 尼拏女穠 | I13: 16
A14: 13 | B14: 重脣音 | C14: 幫 | D14: 全清 | E14: 發聲 | F14: p | H14: 邊布補伯百北博巴卑并鄙必彼兵筆陂畀晡 | I14: 1
A15: 14 | B15: 重脣音 | C15: 滂 | D15: 次清 | E15: 送氣 | F15: ph | H15: 滂普匹譬披丕 | I15: 2
A16: 15 | B16: 重脣音 | C16: 並 | D16: 全濁 | F16: p | H16: 蒲步裴薄白傍部平皮便毗弼婢簿捕 | I16: 3
A17: 16 | B17: 重脣音 | C17: 明 | D17: 次濁 | E17: 收聲 | F17: m | H17: 莫慕模謨摸母明彌眉綿靡美 | I17: 4
A18: 17 | B18: 輕脣音 | C18: 非 | D18: 全清 | E18: 發聲 | F18: h | H18: 方封分府甫 | I18: 5
A19: 18 | B19: 輕脣音 | C19: 敷 | D19: 次清 | E19: 送氣 | F19: h | H19: 敷孚妃撫芳峰拂 | I19: 6
A20: 19 | B20: 輕脣音 | C20: 奉 | D20: 全濁 | F20: h | H20: 房防縛附符苻扶馮浮父 | I20: 7
A21: 20 | B21: 輕脣音 | C21: 微 | D21: 次濁 | E21: 收聲 | F21: b | H21: 巫無亡武文望 | I21: 8
A22: 21 | B22: 齒頭音 | C22: 精 | D22: 全清 | E22: 發聲 | F22: z | H22: 將子資即則借茲醉姊遵祖臧作＊ | I22: 21
A23: 22 | B23: 齒頭音 | C23: 清 | D23: 次清 | E23: 送氣 | F23: c | H23: 倉蒼親遷取七青采醋麁麤千此雌 | I23: 22
A24: 23 | B24: 齒頭音 | C24: 從 | D24: 全濁 | F24: z | H24: 才徂在前藏昨酢疾秦匠慈自情漸 | I24: 23
A25: 24 | B25: 齒頭音 | C25: 心 | D25: 全清 | E25: 送氣 | F25: s | H25: 蘇素速桑相悉思司斯私雖辛息須胥先寫 | I25: 24
A26: 25 | B26: 齒頭音 | C26: 邪 | D26: 全濁 | E26: 送氣 | F26: s | H26: 徐祥詳辭＊辞似旬寺夕隨 | I26: 25
A27: 26 | B27: 正齒近齒頭 | C27: 莊 | D27: 全清 | E27: 發聲 | F27: z | H27: 莊爭阻鄒簪側仄 | I27: 31
A28: 27 | B28: 正齒近齒頭 | C28: 初 | D28: 次清 | E28: 送氣 | F28: c | H28: 初楚創瘡測叉廁芻 | I28: 32
A29: 28 | B29: 正齒近齒頭 | C29: 床 | D29: 全濁 | F29: z | H29: 床鋤鉏豺崱士仕崇查俟助雛 | I29: 33
A30: 29 | B30: 正齒近齒頭 | C30: 疏 | D30: 全濁 | E30: 送氣 | F30: s | H30: 疏山沙砂生色數所史 | I30: 34
A31: 30 | B31: 正齒近舌上 | C31: 照 | D31: 全清 | E31: 發聲 | F31: z | H31: 之止章征諸煮支職正旨占脂 | I31: 26
A32: 31 | B32: 正齒近舌上 | C32: 穿 | D32: 次清 | E32: 送氣 | F32: c | H32: 昌尺赤充處叱春姝 | I32: 27
A33: 32 | B33: 正齒近舌上 | C33: 神 | D33: 全濁 | E33: 送氣 | F33: s | H33: 神乘食實 | I33: 28
A34: 33 | B34: 正齒近舌上 | C34: 審 | D34: 全清 | E34: 送氣 | F34: s | H34: 書舒傷商施失矢試式識賞詩釋始 | I34: 29
A35: 34 | B35: 正齒近舌上 | C35: 禪 | D35: 全濁 | E35: 送氣 | F35: s | H35: 時殊嘗常蜀市植殖寔署臣是氏視成 | I35: 30
A36: 35 | B36: 喉音 | C36: 影 | D36: 全清 | E36: 發聲 | F36: Ø | H36: 於央憶伊衣依憂一乙握謁紆挹烏哀安烟鷖愛委 | I36: 35
A37: 36 | B37: 喉音 | C37: 曉 | D37: 次清 | E37: 送氣 | F37: h | H37: 呼荒虎馨火海呵香朽羲休況許興喜虛花 | I37: 36
A38: 37 | B38: 喉音 | C38: 匣 | D38: 全濁 | E38: 送氣 | F38: h | H38: 胡乎侯戶下黃何獲懷 | I38: 37
A39: 38 | B39: 喉音 | C39: 為 | D39: 次濁 | E39: 發聲 | F39: Ø | H39: 于羽雨雲云王韋永有薳為洧筠＊ | I39: 39
A40: 39 | B40: 喉音 | C40: 喻 | D40: 次濁 | E40: 發聲 | F40: Ø | H40: 余餘予夷以羊弋翼與營移悅 | I40: 38
...

Sheet 廣韻三十八聲母
A1: 今名 | C1: 古名
A2: 發音部位 | B2: 發音方法 | C2: 分類 | E2: 全清 | F2: 次清 | G2: 全濁 | H2: 次濁
E3: （不送氣清音） | F3: （送氣清音） | G3: （濁音） | H3: （響輔音）
A4: 雙唇 | B4: 塞、鼻音 | C4: 唇音 | E4: 幫 | F4: 滂 | G4: 並 | H4: 明
E5: [p] | F5: [pʰ] | G5: [b] | H5: [m]
A6: 齒齦 | B6: 邊近音 | C6: 半舌音 | G6: 來
G7: [l]
B8: 塞、鼻音 | C8: 舌音 | D8: 舌頭音 | E8: 端 | F8: 透 | G8: 定 | H8: 泥
E9: [t] | F9: [tʰ] | G9: [d] | H9: [n]
A10: 捲舌／ 齦顎[b] | B10: 塞、鼻音 | D10: 舌上音 | E10: 知 | F10: 徹 | G10: 澄 | H10: 娘
E11: [ʈ]／[ȶ] | F11: [ʈʰ]／[ȶʰ] | G11: [ɖ]／[ȡ] | H11: [ɳ]／[ȵ]
A12: 齒齦 | B12: 有噝塞擦音 | C12: 齒音 | D12: 齒頭音 | E12: 精 | F12: 清 | G12: 從
E13: [t͡s] | F13: [t͡sʰ] | G13: [d͡z]
B14: 有噝擦音 | E14: 心 | G14: 邪
E15: [s] | G15: [z]
A16: 捲舌／ 齦後[c] | B16: 有噝塞擦音 | D16: 正齒音 莊組 | E16: 莊 | F16: 初 | G16: 崇
E17: [ʈ͡ʂ]／[t͡ʃ] | F17: [ʈ͡ʂʰ]／[t͡ʃʰ] | G17: [ɖ͡ʐ]／[d͡ʒ]
B18: 有噝擦音 | E18: 生 | H18: 俟
E19: [ʂ]／[ʃ] | H19: [ʐ]／[ʒ]
A20: 齦顎 | B20: 有噝塞擦音 | D20: 正齒音 章組 | E20: 章 | F20: 昌 | G20: 常
E21: [t͡ɕ] | F21: [t͡ɕʰ] | G21: [d͡ʑ]
B22: 有噝擦音 | E22: 書 | G22: 船
E23: [ɕ] | G23: [ʑ]
B24: 鼻音 | C24: 半齒音 | H24: 日
H25: [ȵ]／[ȵ͡ʑ]
A26: 軟顎 | B26: 塞、鼻音 | C26: 牙音 | E26: 見 | F26: 溪 | G26: 群 | H26: 疑
E27: [k] | F27: [kʰ] | G27: [ɡ] | H27: [ŋ]
B28: 無噝擦音 | C28: 喉音 | E28: 曉 | G28: 匣 | H28: 云
E29: [x] | G29: [ɣ] | H29: [ɣ]
A30: 硬顎 | B30: 近音 | H30: 以
H31: [j]／[∅]
A32: 聲門 | B32: 塞音 | E32: 影
E33: [ʔ]
B34: 擦音 | E34: 曉 | G34: 匣 | H34: 云
E35: [h] | G35: [ɦ] | H35: [ɦ]
A36: 零聲母 | H36: 云
H37: [∅]

Sheet 切語上字表
A1: 識別號 | B1: 七聲類 | C1: 發音部位 | D1: 聲母 | E1: 清濁 | F1: 發送收 | G1: 聲母標音 | H1: 切語上字集 | I1: 備註
A2: 1 | B2: 牙音 | C2: 牙音 | D2: 見 | E2: 全清 | F2: 發聲 | G2: k | H2: 古公過各規姑格詭吉紀几居九俱舉兼佳乖矩工
A3: 2 | B3: 牙音 | C3: 牙音 | D3: 溪 | E3: 次清 | F3: 送氣 | G3: kh | H3: 康枯空口楷客恪苦窺牽謙去丘祛羌欽墟傾起綺豈區驅詰曲咎可乞袪弃卿
A4: 3 | B4: 牙音 | C4: 牙音 | D4: 群 | E4: 全濁 | G4: k | H4: 渠強求奇衢其暨具巨臼跪近狂
A5: 4 | B5: 牙音 | C5: 牙音 | D5: 疑 | E5: 次濁 | F5: 收聲 | G5: g | H5: 疑魚語宜玉遇虞愚牛擬研危五俄吾
A6: 5 | B6: 舌音 | C6: 舌頭音 | D6: 端 | E6: 全清 | F6: 發聲 | G6: t | H6: 多德得丁都當冬底
A7: 6 | B7: 舌音 | C7: 舌頭音 | D7: 透 | E7: 次清 | F7: 送氣 | G7: th | H7: 他託土通天台湯吐
A8: 7 | B8: 舌音 | C8: 舌頭音 | D8: 定 | E8: 全濁 | G8: t | H8: 徒同特唐堂田陀地度杜大
A9: 8 | B9: 舌音 | C9: 舌頭音 | D9: 泥 | E9: 次濁 | F9: 收聲 | G9: n | H9: 奴乃諾內那嬭妳
A10: 9 | B10: 舌音 | C10: 舌上音 | D10: 知 | E10: 全清 | F10: 發聲 | G10: t | H10: 知張豬徵中追陟卓竹珍迍
A11: 10 | B11: 舌音 | C11: 舌上音 | D11: 徹 | E11: 次清 | F11: 送氣 | G11: th | H11: 抽癡褚楮丑恥敕
A12: 11 | B12: 舌音 | C12: 舌上音 | D12: 澄 | E12: 全濁 | G12: t | H12: 除場池治持持遲佇柱丈直宅馳墜
A13: 12 | B13: 舌音 | C13: 舌上音 | D13: 孃 | E13: 次濁 | F13: 收聲 | G13: l | H13: 尼拏女穠 | I13: 娘
A14: 13 | B14: 脣音 | C14: 重脣音 | D14: 幫 | E14: 全清 | F14: 發聲 | G14: p | H14: 邊布補伯百北博巴卑并鄙必彼兵筆陂畀晡風
A15: 14 | B15: 脣音 | C15: 重脣音 | D15: 滂 | E15: 次清 | F15: 送氣 | G15: ph | H15: 滂普匹譬披丕被
A16: 15 | B16: 脣音 | C16: 重脣音 | D16: 並 | E16: 全濁 | G16: p | H16: 蒲裴平皮步薄白部傍便弼婢毗簿捕
A17: 16 | B17: 脣音 | C17: 重脣音 | D17: 明 | E17: 次濁 | F17: 收聲 | G17: m | H17: 莫慕模謨摸母明彌眉綿靡美
A18: 17 | B18: 脣音 | C18: 輕脣音 | D18: 非 | E18: 全清 | F18: 發聲 | G18: h | H18: 方封分府甫
A19: 18 | B19: 脣音 | C19: 輕脣音 | D19: 敷 | E19: 次清 | F19: 送氣 | G19: h | H19: 敷孚妃撫峰拂芳峯
A20: 19 | B20: 脣音 | C20: 輕脣音 | D20: 奉 | E20: 全濁 | G20: h | H20: 防縛附父浮苻扶馮房符
A21: 20 | B21: 脣音 | C21: 輕脣音 | D21: 微 | E21: 次濁 | F21: 收聲 | G21: b | H21: 巫無武文望亡
A22: 21 | B22: 齒音 | C22: 齒頭音 | D22: 精 | E22: 全清 | F22: 發聲 | G22: z | H22: 子資則兹醉遵祖臧作將即借姊茲
A23: 22 | B23: 齒音 | C23: 齒頭音 | D23: 清 | E23: 次清 | F23: 送氣 | G23: c | H23: 蒼倉雌醋麤此采親遷千青七取麁且
A24: 23 | B24: 齒音 | C24: 齒頭音 | D24: 從 | E24: 全濁 | G24: z | H24: 才徂慈藏在前秦情酢自昨漸匠疾鶵 | I24: 崇
A25: 24 | B25: 齒音 | C25: 齒頭音 | D25: 心 | E25: 全清 | F25: 發聲 | G25: s | H25: 蘇桑思司斯雖素速相辛須胥先悉息寫私
A26: 25 | B26: 齒音 | C26: 齒頭音 | D26: 邪 | E26: 全濁 | G26: s | H26: 辭隨寺似徐祥詳旬夕辤辝
A27: 26 | B27: 齒音 | C27: 正齒近齒頭 | D27: 莊 | E27: 全清 | F27: 發聲 | G27: z | H27: 莊爭阻鄒簪側仄壯
A28: 27 | B28: 齒音 | C28: 正齒近齒頭 | D28: 初 | E28: 次清 | F28: 送氣 | G28: c | H28: 叉廁初創瘡芻測楚
A29: 28 | B29: 齒音 | C29: 正齒近齒頭 | D29: 牀 | E29: 全濁 | G29: z | H29: 牀查崇雛鋤鉏豺助俟士仕崱
A30: 29 | B30: 齒音 | C30: 正齒近齒頭 | D30: 疏 | E30: 全清 | F30: 送氣 | G30: s | H30: 疏山沙砂生色數所史踈䟽疎
A31: 30 | B31: 齒音 | C31: 正齒近舌上 | D31: 照 | E31: 全清 | F31: 發聲 | G31: z | H31: 之辛征諸支脂止旨職煮正占章遮主 | I31: 章
A32: 31 | B32: 齒音 | C32: 正齒近舌上 | D32: 穿 | E32: 次清 | F32: 送氣 | G32: c | H32: 昌春充叱赤尺處姝
A33: 32 | B33: 齒音 | C33: 正齒近舌上 | D33: 神 | E33: 全濁 | F33: 送氣 | G33: s | H33: 乘神食實
A34: 33 | B34: 齒音 | C34: 正齒近舌上 | D34: 審 | E34: 全清 | F34: 送氣 | G34: s | H34: 書舒傷商施失詩始釋賞識矢式試
A35: 34 | B35: 齒音 | C35: 正齒近舌上 | D35: 禪 | E35: 全濁 | F35: 送氣 | G35: s | H35: 時殊嘗常成臣蜀市植殖寔署是氏視承
A36: 35 | B36: 喉音 | C36: 喉音 | D36: 影 | E36: 全清 | F36: 發聲 | G36: Ø | H36: 烏哀安紆愛握於央一伊依衣憂煙鷖憶乙謁挹委毆烟
A37: 36 | B37: 喉音 | C37: 喉音 | D37: 曉 | E37: 次清 | F37: 送氣 | G37: h | H37: 呼荒呵虛馨香羲休興虎火海況朽喜許花兄
A38: 37 | B38: 喉音 | C38: 喉音 | D38: 匣 | E38: 全濁 | F38: 送氣 | G38: h | H38: 胡乎侯何黃戶下獲懷諧
A39: 38 | B39: 喉音 | C39: 喉音 | D39: 為 | E39: 次濁 | F39: 發聲 | G39: Ø | H39: 于雲云筠為榮本王雨羽永有洧𨘏遠
A40: 39 | B40: 喉音 | C40: 喉音 | D40: 喻 | E40: 次濁 | F40: 發聲 | G40: Ø | H40: 余餘予移夷羊營以弋翼與悅薳韋 | I40: 云
...

Sheet 切語下字表
A1: 識別號 | B1: 識別號2 | C1: 韻系標音表之識別號 | D1: 韻目表之識別號 | E1: 韻母 | F1: 韻系列號 | G1: 韻目索引 | H1: 目次 | I1: 攝 | J1: 韻系 | K1: 韻目 | L1: 四聲 | M1: 四聲調號 | N1: 舒促聲 | O1: 等呼 | P1: 等 | Q1: 呼 | R1: 韻母標音 | S1: 切語下字集 | T1: 備註
A2: 1 | B2: 1 | C2: 1 | D2: 1 | E2: 東一 | F2: 1 | G2: 01獨洪 | H2: 上平01東 | I2: 通 | J2: 東一 | K2: 東 | L2: 平 | M2: 1 | N2: 舒 | O2: 獨洪 | P2: 1 | Q2: 開 | R2: ong | S2: 工公紅東洪空
A3: 2 | B3: 3 | C3: 1 | D3: 58 | E3: 董一 | F3: 1 | G3: 01獨洪 | H3: 上01董 | I3: 通 | J3: 東一 | K3: 董 | L3: 上 | M3: 2 | N3: 舒 | O3: 獨洪 | P3: 1 | Q3: 開 | R3: ong | S3: 動乙摠董蠓孔揔
A4: 3 | B4: 5 | C4: 1 | D4: 113 | E4: 送一 | F4: 1 | G4: 01獨洪 | H4: 去01送 | I4: 通 | J4: 東一 | K4: 送 | L4: 去 | M4: 3 | N4: 舒 | O4: 獨洪 | P4: 1 | Q4: 開 | R4: ong | S4: 貢弄送凍鳳
A5: 4 | B5: 7 | C5: 1 | D5: 174 | E5: 屋一 | F5: 1 | G5: 01獨洪 | H5: 入01屋 | I5: 通 | J5: 東一 | K5: 屋 | L5: 入 | M5: 4 | N5: 舒 | O5: 獨洪 | P5: 1 | Q5: 開 | R5: ok | S5: 谷祿禄木卜
A6: 5 | B6: 2 | C6: 2 | D6: 1 | E6: 東二 | F6: 1 | G6: 01獨細 | H6: 上平01東 | I6: 通 | J6: 東二 | K6: 東 | L6: 平 | M6: 1 | N6: 舒 | O6: 獨細 | P6: 3 | Q6: 開 | R6: iong | S6: 弓戎中宮終融隆
A7: 6 | B7: 4 | C7: 2 | D7: 58 | E7: 董二 | F7: 1 | G7: 01獨細 | H7: 上01董 | I7: 通 | J7: 東二 | K7: 董 | L7: 上 | M7: 2 | N7: 舒 | O7: 獨細 | P7: 3 | Q7: 開 | R7: iong | T7: 董韻無3等字
A8: 7 | B8: 6 | C8: 2 | D8: 113 | E8: 送二 | F8: 1 | G8: 01獨細 | H8: 去01送 | I8: 通 | J8: 東二 | K8: 送 | L8: 去 | M8: 3 | N8: 舒 | O8: 獨細 | P8: 3 | Q8: 開 | R8: iong | S8: 仲眾衆
A9: 8 | B9: 8 | C9: 2 | D9: 174 | E9: 屋二 | F9: 1 | G9: 01獨細 | H9: 入01屋 | I9: 通 | J9: 東二 | K9: 屋 | L9: 入 | M9: 4 | N9: 舒 | O9: 獨細 | P9: 3 | Q9: 開 | R9: iok | S9: 六逐匊宿竹菊福
A10: 9 | B10: 9 | C10: 3 | D10: 2 | E10: 冬 | F10: 2 | G10: 02獨洪 | H10: 上平02冬 | I10: 通 | J10: 冬 | K10: 冬 | L10: 平 | M10: 1 | N10: 舒 | O10: 獨洪 | P10: 1 | Q10: 開 | R10: ong | S10: 宗冬
A11: 10 | B11: 10 | C11: 3 | D11: 114 | E11: 宋 | F11: 2 | G11: 02獨洪 | H11: 去02宋 | I11: 通 | J11: 冬 | K11: 宋 | L11: 去 | M11: 3 | N11: 舒 | O11: 獨洪 | P11: 1 | Q11: 開 | R11: ong | S11: 統宋綜
A12: 11 | B12: 11 | C12: 3 | D12: 175 | E12: 沃 | F12: 2 | G12: 02獨洪 | H12: 入02沃 | I12: 通 | J12: 冬 | K12: 沃 | L12: 入 | M12: 4 | N12: 舒 | O12: 獨洪 | P12: 1 | Q12: 開 | R12: ok | S12: 毒沃篤酷
A13: 12 | B13: 12 | C13: 4 | D13: 3 | E13: 鍾 | F13: 3 | G13: 03獨細 | H13: 上平03鍾 | I13: 通 | J13: 鍾 | K13: 鍾 | L13: 平 | M13: 1 | N13: 舒 | O13: 獨細 | P13: 3 | Q13: 開 | R13: iong | S13: 容凶庸鍾恭封
A14: 13 | B14: 13 | C14: 4 | D14: 59 | E14: 腫 | F14: 3 | G14: 03獨細 | H14: 上02腫 | I14: 通 | J14: 鍾 | K14: 腫 | L14: 上 | M14: 2 | N14: 舒 | O14: 獨細 | P14: 3 | Q14: 開 | R14: iong | S14: 隴勇拱悚冢冗踵奉宂𪁪湩
A15: 14 | B15: 14 | C15: 4 | D15: 115 | E15: 用 | F15: 3 | G15: 03獨細 | H15: 去03用 | I15: 通 | J15: 鍾 | K15: 用 | L15: 去 | M15: 3 | N15: 舒 | O15: 獨細 | P15: 3 | Q15: 開 | R15: iong | S15: 用訟頌
A16: 15 | B16: 15 | C16: 4 | D16: 176 | E16: 燭 | F16: 3 | G16: 03獨細 | H16: 入03燭 | I16: 通 | J16: 鍾 | K16: 燭 | L16: 入 | M16: 4 | N16: 舒 | O16: 獨細 | P16: 3 | Q16: 開 | R16: iok | S16: 玉欲曲足蜀祿録錄
A17: 16 | B17: 16 | C17: 5 | D17: 4 | E17: 江 | F17: 4 | G17: 04獨洪 | H17: 上平04江 | I17: 江 | J17: 江 | K17: 江 | L17: 平 | M17: 1 | N17: 舒 | O17: 獨洪 | P17: 2 | Q17: 開 | R17: ang | S17: 雙江
A18: 17 | B18: 17 | C18: 5 | D18: 60 | E18: 講 | F18: 4 | G18: 04獨洪 | H18: 上03講 | I18: 江 | J18: 江 | K18: 講 | L18: 上 | M18: 2 | N18: 舒 | O18: 獨洪 | P18: 2 | Q18: 開 | R18: ang | S18: 項講慃
A19: 18 | B19: 18 | C19: 5 | D19: 116 | E19: 絳 | F19: 4 | G19: 04獨洪 | H19: 去04絳 | I19: 江 | J19: 江 | K19: 絳 | L19: 去 | M19: 3 | N19: 舒 | O19: 獨洪 | P19: 2 | Q19: 開 | R19: ang | S19: 巷絳降
... A53: 52 | B53: 54 | C53: 16 | D53: 124 | E53: 霽一 | F53: 12 | G53: 12開細 | H53: 去12霽 | I53: 蟹 | J53: 齊一 | K53: 霽 | L53: 去 | M53: 3 | N53: 舒 | O53: 開細 | P53: 4 | Q53: 開 | R53: e | S53: 詣計戾隸
A54: 53 | B54: 51 | C54: 17 | D54: 12 | E54: 齊二 | F54: 12 | G54: 12合細 | H54: 上平12齊 | I54: 蟹 | J54: 齊二 | K54: 齊 | L54: 平 | M54: 1 | N54: 舒 | O54: 合細 | P54: 4 | Q54: 合 | R54: ui | S54: 圭攜 | T54: 攜：戶圭切
A55: 54 | B55: 53 | C55: 17 | D55: 68 | E55: 薺二 | F55: 12 | G55: 12合細 | H55: 上11薺 | I55: 蟹 | J55: 齊二 | K55: 薺 | L55: 上 | M55: 2 | N55: 舒 | O55: 合細 | P55: 4 | Q55: 合 | R55: ui | T55: 薺合4無字
A56: 55 | B56: 55 | C56: 17 | D56: 124 | E56: 霽二 | F56: 12 | G56: 12合細 | H56: 去12霽 | I56: 蟹 | J56: 齊二 | K56: 霽 | L56: 去 | M56: 3 | N56: 舒 | O56: 合細 | P56: 4 | Q56: 合 | R56: ui | S56: 桂惠
A57: 56 | B57: 56 | C57: 18 | D57: 125 | E57: 祭一 | F57: 13 | G57: 13開細 | H57: 去13祭 | I57: 蟹 | J57: 祭一 | K57: 祭 | L57: 去 | M57: 3 | N57: 舒 | O57: 開細 | P57: 3 | Q57: 開 | R57: e | S57: 例制罽祭憩袂蔽弊𡚁世
A58: 57 | B58: 57 | C58: 19 | D58: 125 | E58: 祭二 | F58: 13 | G58: 13合細 | H58: 去13祭 | I58: 蟹 | J58: 祭二 | K58: 祭 | L58: 去 | M58: 3 | N58: 舒 | O58: 合細 | P58: 3 | Q58: 合 | R58: ue | S58: 芮銳衛稅劌歲
A59: 58 | B59: 58 | C59: 20 | D59: 126 | E59: 泰一 | F59: 14 | G59: 14開洪 | H59: 去14泰 | I59: 蟹 | J59: 泰一 | K59: 泰 | L59: 去 | M59: 3 | N59: 舒 | O59: 開洪 | P59: 1 | Q59: 開 | R59: ai | S59: 蓋太艾大帶
A60: 59 | B60: 59 | C60: 21 | D60: 126 | E60: 泰二 | F60: 14 | G60: 14合洪 | H60: 去14泰 | I60: 蟹 | J60: 泰二 | K60: 泰 | L60: 去 | M60: 3 | N60: 舒 | O60: 合洪 | P60: 1 | Q60: 合 | R60: ue | S60: 外會最貝
A61: 60 | B61: 60 | C61: 22 | D61: 13 | E61: 佳一 | F61: 15 | G61: 15開洪 | H61: 上平13佳 | I61: 蟹 | J61: 佳一 | K61: 佳 | L61: 平 | M61: 1 | N61: 舒 | O61: 開洪 | P61: 2 | Q61: 開 | R61: ai | S61: 佳膎
A62: 61 | B62: 62 | C62: 22 | D62: 69 | E62: 蟹一 | F62: 15 | G62: 15開洪 | H62: 上12蟹 | I62: 蟹 | J62: 佳一 | K62: 蟹 | L62: 上 | M62: 2 | N62: 舒 | O62: 開洪 | P62: 2 | Q62: 開 | R62: ai | S62: 蟹買𦫳
A63: 62 | B63: 64 | C63: 22 | D63: 127 | E63: 卦一 | F63: 15 | G63: 15開洪 | H63: 去15卦 | I63: 蟹 | J63: 佳一 | K63: 卦 | L63: 去 | M63: 3 | N63: 舒 | O63: 開洪 | P63: 2 | Q63: 開 | R63: ai | S63: 隘懈賣卦
A64: 63 | B64: 61 | C64: 23 | D64: 13 | E64: 佳二 | F64: 15 | G64: 15合洪 | H64: 上平13佳 | I64: 蟹 | J64: 佳二 | K64: 佳 | L64: 平 | M64: 1 | N64: 舒 | O64: 合洪 | P64: 2 | Q64: 合 | R64: ua | S64: 蛙媧緺
A65: 64 | B65: 63 | C65: 23 | D65: 69 | E65: 蟹二 | F65: 15 | G65: 15合洪 | H65: 上12蟹 | I65: 蟹 | J65: 佳二 | K65: 蟹 | L65: 上 | M65: 2 | N65: 舒 | O65: 合洪 | P65: 2 | Q65: 合 | R65: ua | S65: 夥𠁥
A66: 65 | B66: 65 | C66: 23 | D66: 127 | E66: 卦二 | F66: 15 | G66: 15合洪 | H66: 去15卦 | I66: 蟹 | J66: 佳二 | K66: 卦 | L66: 去 | M66: 3 | N66: 舒 | O66: 合洪 | P66: 2 | Q66: 合 | R66: ua
A67: 66 | B67: 66 | C67: 24 | D67: 14 | E67: 皆一 | F67: 16 | G67: 16開洪 | H67: 上平14皆 | I67: 蟹 | J67: 皆一 | K67: 皆 | L67: 平 | M67: 1 | N67: 舒 | O67: 開洪 | P67: 2 | Q67: 開 | R67: ai | S67: 諧皆
A68: 67 | B68: 68 | C68: 24 | D68: 70 | E68: 駭一 | F68: 16 | G68: 16開洪 | H68: 上13駭 | I68: 蟹 | J68: 皆一 | K68: 駭 | L68: 上 | M68: 2 | N68: 舒 | O68: 開洪 | P68: 2 | Q68: 開 | R68: ai | S68: 駭楷
A69: 68 | B69: 70 | C69: 24 | D69: 128 | E69: 怪一 | F69: 16 | G69: 16開洪 | H69: 去16怪 | I69: 蟹 | J69: 皆一 | K69: 怪 | L69: 去 | M69: 3 | N69: 舒 | O69: 開洪 | P69: 2 | Q69: 開 | R69: ai | S69: 戒介界拜殺
A70: 69 | B70: 67 | C70: 25 | D70: 14 | E70: 皆二 | F70: 16 | G70: 16合洪 | H70: 上平14皆 | I70: 蟹 | J70: 皆二 | K70: 皆 | L70: 平 | M70: 1 | N70: 舒 | O70: 合洪 | P70: 2 | Q70: 合 | R70: uai | S70: 乖懷淮
A71: 70 | B71: 69 | C71: 25 | D71: 70 | E71: 駭二 | F71: 16 | G71: 16合洪 | H71: 上13駭 | I71: 蟹 | J71: 皆二 | K71: 駭 | L71: 上 | M71: 2 | N71: 舒 | O71: 合洪 | P71: 2 | Q71: 合 | R71: uai
A72: 71 | B72: 71 | C72: 25 | D72: 128 | E72: 怪二 | F72: 16 | G72: 16合洪 | H72: 去16怪 | I72: 蟹 | J72: 皆二 | K72: 怪 | L72: 去 | M72: 3 | N72: 舒 | O72: 合洪 | P72: 2 | Q72: 合 | R72: uai | S72: 怪壞
A73: 72 | B73: 72 | C73: 26 | D73: 129 | E73: 夬一 | F73: 17 | G73: 17開洪 | H73: 去17夬 | I73: 蟹 | J73: 夬一 | K73: 夬 | L73: 去 | M73: 3 | N73: 舒 | O73: 開洪 | P73: 2 | Q73: 開 | R73: ai | S73: 介喝犗
...

Sheet 反切上字與聲母
A1: 序 | B1: 類 | C1: 聲母 | D1: 清濁 | E1: 發送收 | F1: 台羅音標 | G1: 國際音標 | H1: 反切上字
A2: 1 | B2: 重脣音 | C2: 幫 | D2: 全清 | E2: 發聲 | F2: p | G2: p | H2: 邊 布 補 伯 百 北 博 巴 卑 并 鄙 必 彼 兵 筆 陂 畀 晡
A3: 2 | B3: 重脣音 | C3: 滂 | D3: 次清 | E3: 送氣 | F3: ph | G3: pʰ | H3: 滂 普 匹 譬 披 丕
A4: 3 | B4: 重脣音 | C4: 並 | D4: 全濁 | F4: b | G4: b | H4: 蒲 裴 平 皮 步 薄 白 部 傍 便 弼 婢 毗 簿 捕
A5: 4 | B5: 重脣音 | C5: 明 | D5: 次濁 | E5: 收聲 | F5: m | G5: m | H5: 莫 慕 模 謨 摸 母 明 彌 眉 綿 靡 美
B6: 輕脣音 | C6: 非 | D6: 全清 | E6: 發聲 | F6: h | H6: 方 封 分 府 甫
B7: 輕脣音 | C7: 敷 | D7: 次清 | E7: 送氣 | F7: h | H7: 敷 孚 妃 撫 峯 拂 芳
B8: 輕脣音 | C8: 奉 | D8: 全濁 | F8: h | H8: 房 防 縛 附 父 浮 符 苻 扶 馮
B9: 輕脣音 | C9: 微 | D9: 次濁 | E9: 收聲 | F9: b | H9: 巫 無 武 文 望 亡
A10: 5 | B10: 舌頭音 | C10: 端 | D10: 全清 | E10: 發聲 | F10: t | G10: t | H10: 德 都 丁 當 多 得 冬
A11: 6 | B11: 舌頭音 | C11: 透 | D11: 次清 | E11: 送氣 | F11: th | G11: tʰ | H11: 他 土 吐 託 天 湯 通 台
A12: 7 | B12: 舌頭音 | C12: 定 | D12: 全濁 | F12: d | G12: d | H12: 徒 同 杜 度 墜 特 堂 唐 田 陀
A13: 8 | B13: 舌頭音 | C13: 泥 | D13: 次濁 | E13: 收聲 | F13: n | G13: n | H13: 奴 乃 諾 那 内
A14: 9 | B14: 舌上音 | C14: 知 | D14: 全清 | E14: 發聲 | F14: t | G14: ȶ | H14: 陟 都 竹 丁 卓 張 中 知 豬 珍 追 猪 徵
A15: 10 | B15: 舌上音 | C15: 徹 | D15: 次清 | E15: 送氣 | F15: th | G15: ȶʰ | H15: 敕 他 丑 褚 楮 癡 抽 恥
A16: 11 | B16: 舌上音 | C16: 澄 | D16: 全濁 | F16: t | G16: ȡ | H16: 徒 直 宅 柱 池 丈 持 除 治 馳 遟 佇 場
A17: 12 | B17: 舌上音 | C17: 孃 | D17: 次濁 | E17: 收聲 | F17: l | G17: n | H17: 奴 女 乃 妳 諾 尼 拏 穠
A18: 13 | B18: 齒頭音 | C18: 精 | D18: 全清 | E18: 發聲 | F18: ts | G18: ts | H18: 子 作 即 姊 遵 醉 則 祖 臧 將 借 兹 𩛠 資 姉
A19: 14 | B19: 齒頭音 | C19: 清 | D19: 次清 | E19: 送氣 | F19: tsh | G19: tsʰ | H19: 倉 七 此 取 蒼 醋 千 雌 采 親 麁 靑 麤 遷
A20: 15 | B20: 齒頭音 | C20: 從 | D20: 全濁 | F20: ts | G20: dz | H20: 徂 藏 疾 昨 匠 在 才 自 慈 秦 漸 情 前
A21: 16 | B21: 齒頭音 | C21: 心 | D21: 全清 | E21: 收聲 | F21: s | G21: s | H21: 息 蘇 私 相 素 先 思 須 寫 桑 速 斯 胥 悉 雖 司 辛
A22: 17 | B22: 齒頭音 | C22: 邪 | D22: 全濁 | F22: s | G22: z | H22: 祥 旬 似 詳 夕 徐 隨 辝 辭 寺
A23: 18 | B23: 正齒音莊組 | C23: 莊 | D23: 全清 | E23: 發聲 | F23: ts | G23: tʃ | H23: 子 側 莊 阻 仄 爭 鄒 簪
A24: 19 | B24: 正齒音莊組 | C24: 初 | D24: 次清 | E24: 送氣 | F24: tsh | G24: tʃʰ | H24: 楚 叉 測 初 創 瘡 芻 廁
A25: 20 | B25: 正齒音莊組 | C25: 崇 | D25: 全濁 | F25: ts | G25: dʒ | H25: 鋤 士 仕 崇 鉏 助 牀 鶵 雛 犲 崱 查 査
A26: 21 | B26: 正齒音莊組 | C26: 生 | D26: 全清 | E26: 收聲 | F26: s | G26: ʃ | H26: 所 山 疏 數 色 史 踈 砂 沙 生
A27: 22 | B27: 正齒音莊組 | C27: 俟 | D27: 全濁 | F27: s | G27: ʒ | H27: 俟 牀
A28: 23 | B28: 正齒音章組 | C28: 章 | D28: 全清 | E28: 發聲 | F28: ts | G28: tʃ | H28: 職 章 旨 止 諸 正 煑 之 占 支 脂 征
A29: 24 | B29: 正齒音章組 | C29: 昌 | D29: 次清 | E29: 送氣 | F29: tsh | G29: tʃʰ | H29: 昌 尺 叱 處 叉 赤 充 姝
A30: 25 | B30: 正齒音章組 | C30: 常 | D30: 全濁 | F30: ts | G30: dʒ | H30: 蜀 是 視 市 署 成 植 常 氏 時 承 臣 殖 甞 寔 殊 十
A31: 26 | B31: 正齒音章組 | C31: 書 | D31: 全清 | E31: 收聲 | F31: s | G31: ʃ | H31: 書 式 傷 失 識 施 詩 舒 賞 矢 釋 商 試 始
A32: 27 | B32: 正齒音章組 | C32: 船 | D32: 全濁 | F32: s | G32: ʒ | H32: 食 神 實 乗
A33: 28 | B33: 牙音 | C33: 見 | D33: 全清 | E33: 發聲 | F33: k | G33: k | H33: 居 古 九 舉 公 過 俱 佳 乖 姑 各 兼 詭 規 几 吉 紀 格
A34: 29 | B34: 牙音 | C34: 溪 | D34: 次清 | E34: 送氣 | F34: kh | G34: kʰ | H34: 去 苦 曲 丘 豈 口 可 起 乞 客 綺 恪 康 墟 袪 羌 驅 弃 空 牽 枯 欽 謙 區 窺 卿 詰 傾 楷
A35: 30 | B35: 牙音 | C35: 群 | D35: 全濁 | F35: k | G35: ɡ | H35: 渠 巨 強 其 跪 求 曁 狂 奇 具 臼 衢
A36: 31 | B36: 牙音 | C36: 疑 | D36: 次濁 | E36: 收聲 | F36: g | G36: ŋ | H36: 五 魚 牛 語 遇 擬 愚 俄 虞 疑 研 宜 危 吾 玉
A37: 34 | B37: 喉音 | C37: 影 | D37: 全清 | E37: 發聲 | F37: Ø | H37: 烏 於 握 央 憶 哀 乙 謁 一 委 挹 安 紆 烟 衣 依 鷖 伊 憂 愛
A38: 32 | B38: 喉音 | C38: 曉 | D38: 全清 | E38: 送氣 | F38: h | G38: x | H38: 呼 許 香 喜 朽 況 荒 火 虚 虎 興 花 休 况 馨 海 羲 呵
A39: 33 | B39: 喉音 | C39: 匣 | D39: 全濁 | F39: h | G39: ɣ | H39: 戸 下 胡 獲 侯 懷 何 乎 黃
A40: 35 | B40: 喉音 | C40: 云 | D40: 次濁 | E40: 收聲 | F40: Ø | G40: ɣ | H40: 羽 下 薳 洧 雨 爲 王 有 于 永 韋 榮 云 雲 筠
...

Sheet 反切下字與韻母
A1: 序 | B1: 攝 | C1: 韻系 | D1: 等 | E1: 呼 | F1: 韻母 | G1: 台羅音標 | H1: 國際音標 | I1: 反切下字
A2: 1 | B2: 通 | C2: 東 | D2: 一 | E2: 開 | F2: 東一 | G2: ong | H2: [-uŋ] | I2: 紅 公 東 動 孔 董 揔 蠓 弄 貢 送 凍
A3: =A2+1 -> 2 | B3: 通 | C3: 東 | D3: 三 | E3: 開 | F3: 東三 | G3: iong | H3: [-ĭuŋ] | I3: 弓 戎 中 融 宮 空 終 貢 衆 鳳 仲
A4: =A3+1 -> 3 | B4: 通 | C4: 冬 | D4: 一 | E4: 開 | F4: 冬 | G4: ong | H4: [-uoŋ] | I4: 宗 冬 𪁪 湩 統 宋 綜
A5: =A4+1 -> 4 | B5: 通 | C5: 鍾 | D5: 三 | E5: 開 | F5: 鍾 | G5: iong | H5: [-ĭwoŋ] | I5: 容 鍾 封 凶 庸 恭 隴 踵 奉 宂 悚 拱 勇 冢 頌 用
A6: =A5+1 -> 5 | B6: 江 | C6: 江 | D6: 二 | E6: 開 | F6: 江 | G6: ang | H6: [-ɔŋ] | I6: 雙 江 項 講 慃 巷 絳 降
A7: =A6+1 -> 6 | B7: 通 | C7: 東 | D7: 一 | E7: 開 | F7: 屋一 | G7: ok | H7: [-uk] | I7: 谷 禄 木 卜
A8: =A7+1 -> 7 | B8: 通 | C8: 東 | D8: 三 | E8: 開 | F8: 屋三 | G8: iok | H8: [-ĭuk] | I8: 六 竹 匊 宿 福 逐 菊
A9: =A8+1 -> 8 | B9: 通 | C9: 冬 | D9: 一 | E9: 開 | F9: 沃 | G9: ok | H9: [-uok] | I9: 酷 沃 毒 篤
A10: =A9+1 -> 9 | B10: 通 | C10: 鍾 | D10: 三 | E10: 開 | F10: 燭 | G10: iok | H10: [-ĭwok] | I10: 欲 玉 蜀 録 足 曲
A11: =A10+1 -> 10 | B11: 江 | C11: 江 | D11: 二 | E11: 開 | F11: 覺 | G11: ak | H11: [-ɔk] | I11: 岳 角 覺
A12: =A11+1 -> 11 | B12: 止 | C12: 支 | D12: 三 | E12: 開 | F12: 支開 | G12: i | H12: [-ĭe] | I12: 移 支 宜 知 離 氏 紙 綺 爾 是 此 帋 豸 侈 義 智 寄 賜 豉
A13: =A12+1 -> 12 | B13: 止 | C13: 支 | D13: 三 | E13: 合 | F13: 支合 | G13: ui | H13: [-ĭwe] | I13: 支 爲 垂 危 吹 委 累 婢 捶 髓 睡 僞 瑞 恚
A14: =A13+1 -> 13 | B14: 止 | C14: 支A | D14: 三 | E14: 開 | F14: 支A開 | G14: i | H14: [-ĭe] | I14: 移 支 弭 婢 俾 帋 義 智 賜 企
... A42: =A41+1 -> 41 | B42: 蟹 | C42: 祭A | D42: 三 | E42: 開 | F42: 祭A開 | G42: e | H42: [-ĭɛi] | I42: 祭 袂 𡚁 蔽
A43: =A42+1 -> 42 | B43: 蟹 | C43: 祭A | D43: 三 | E43: 合 | F43: 祭A合 | G43: ue | H43: [-ĭwɛi]
A44: =A43+1 -> 43 | B44: 蟹 | C44: 祭B | D44: 三 | E44: 開 | F44: 祭B開 | G44: e | H44: [-ĭɛi] | I44: 例 罽 憩
A45: =A44+1 -> 44 | B45: 蟹 | C45: 祭B | D45: 三 | E45: 合 | F45: 祭B合 | G45: ue | H45: [-ĭwɛi] | I45: 衞
A46: =A45+1 -> 45 | B46: 蟹 | C46: 齊 | D46: 四 | E46: 開 | F46: 齊開 | G46: e | H46: [-iei] | I46: 奚 稽 兮 雞 迷 低 臡 禮 啓 米 弟 計 詣 戾
A47: =A46+1 -> 46 | B47: 蟹 | C47: 齊 | D47: 四 | E47: 合 | F47: 齊合 | G47: ui/ue | H47: [-iwei] | I47: 攜 圭 桂 惠
A48: =A47+1 -> 47 | B48: 蟹 | C48: 咍 | D48: 一 | E48: 開 | F48: 咍 | G48: ai | H48: [-ɒi] | I48: 來 哀 開 哉 才 改 亥 愷 宰 紿 乃 在 蓋 耐 代 漑 槩 愛
A49: =A48+1 -> 48 | B49: 蟹 | C49: 灰 | D49: 一 | E49: 合 | F49: 灰 | G49: ue | H49: [-uɒi] | I49: 恢 回 杯 灰 罪 賄 猥 對 昧 佩 内 隊 繢 妹 輩
A50: =A49+1 -> 49 | B50: 臻 | C50: 眞 | D50: 三 | E50: 開 | F50: 眞開 | G50: in | I50: 鄰 人 眞 珍 忍 軫 引 紖 刃 晉 振 遴
A51: =A50+1 -> 50 | B51: 臻 | C51: 眞 | D51: 三 | E51: 合 | F51: 眞合 | G51: in | I51: 贇 敏
A52: =A51+1 -> 51 | B52: 臻 | C52: 眞A | D52: 三 | E52: 開 | F52: 眞A | G52: in | I52: 鄰 人 眞 賓 忍 盡 腎 刃 印
A53: =A52+1 -> 52 | B53: 臻 | C53: 眞B | D53: 三 | E53: 開 | F53: 眞B開 | G53: in | I53: 巾 銀 引 殞 刃 覲 遴
A54: =A53+1 -> 53 | B54: 臻 | C54: 眞B | D54: 三 | E54: 合 | F54: 眞B合 | G54: in | I54: 筠 倫 殞
A55: =A54+1 -> 54 | B55: 臻 | C55: 臻 | D55: 三 | E55: 開 | F55: 臻 | G55: in | H55: [-ĭen] | I55: 詵 臻 謹 覲
A56: =A55+1 -> 55 | B56: 臻 | C56: 諄 | D56: 三 | E56: 合 | F56: 諄 | G56: un | H56: [-ĭuĕn] | I56: 倫 勻 迍 綸 脣 旬 遵 尹 準 允 峻 閏 順
A57: =A56+1 -> 56 | B57: 臻 | C57: 諄A | D57: 三 | E57: 合 | F57: 諄A | G57: un | H57: [-ĭuĕn] | I57: 勻 尹 峻
A58: =A57+1 -> 57 | B58: 臻 | C58: 痕 | D58: 一 | E58: 開 | F58: 痕 | G58: un/irn | H58: [-ən] | I58: 恩 痕 根 墾 很 艮 恨
A59: =A58+1 -> 58 | B59: 臻 | C59: 魂 | D59: 一 | E59: 合 | F59: 魂 | G59: un | H59: [-uən] | I59: 昆 渾 奔 尊 魂 本 忖 損 衮 困 悶 寸
A60: =A59+1 -> 59 | B60: 臻 | C60: 欣 | D60: 三 | E60: 開 | F60: 欣 | G60: in | H60: [-ĭən] | I60: 斤 欣 謹 隱 靳 焮
A61: =A60+1 -> 60 | B61: 臻 | C61: 文 | D61: 三 | E61: 合 | F61: 文 | G61: un | H61: [-ĭuən] | I61: 分 云 文 粉 吻 運 問
A62: =A61+1 -> 61 | B62: 山 | C62: 寒 | D62: 一 | E62: 開 | F62: 寒 | G62: an | H62: [-ɑn] | I62: 安 寒 干 笴 旱 但 旰 旦 按 案 賛
A63: =A62+1 -> 62 | B63: 山 | C63: 桓 | D63: 一 | E63: 合 | F63: 桓 | G63: uan | H63: [-uɑn] | I63: 官 丸 端 潘 旱 管 緩 滿 纂 伴 玩 筭 貫 亂 換 段 半 慢 喚
A64: =A63+1 -> 63 | B64: 臻 | C64: 元 | D64: 三 | E64: 開 | F64: 元開 | G64: ian | H64: [-ĭɐn] | I64: 軒 言 幰 偃 万 建 堰
A65: =A64+1 -> 64 | B65: 臻 | C65: 元 | D65: 三 | E65: 合 | F65: 元合 | G65: uan | H65: [-ĭwɐn] | I65: 袁 元 煩 遠 阮 晚 怨 願 販 万
A66: =A65+1 -> 65 | B66: 山 | C66: 刪 | D66: 二 | E66: 開 | F66: 刪開 | G66: an | H66: [-an] | I66: 姦 還 顔 班 板 綰 赧 晏 澗 患 諫 鴈
... A77: =A76+1 -> 76 | B77: 山 | C77: 先 | D77: 四 | E77: 合 | F77: 先合 | G77: ian | H77: [-iwen] | I77: 玄 涓 畎 泫 縣 練
...

Sheet 韻目檢索表
J2: 1 | N2: 2 | R2: 3 | V2: 4
J3: 開 | L3: 合 | N3: 開 | P3: 合 | R3: 開 | T3: 合 | V3: 開 | X3: 合
B4: 識別號 | C4: 攝 | D4: 韻 | E4: 韻目 | F4: 平聲 | G4: 上聲 | H4: 去聲 | I4: 入聲 | J4: 舒聲韻 | K4: 促聲韻 | L4: 舒聲韻 | M4: 促聲韻 | N4: 舒聲韻 | O4: 促聲韻 | P4: 舒聲韻 | Q4: 促聲韻 | R4: 舒聲韻 | S4: 促聲韻 | T4: 舒聲韻 | U4: 促聲韻 | V4: 舒聲韻 | W4: 促聲韻 | X4: 舒聲韻 | Y4: 促聲韻
B5: 1 | C5: 通 | D5: 東 | E5: =_xlfn.CONCAT(韻表_3[[#This Row],[平聲]:[入聲]]) -> 東董送屋 | F5: 東 | G5: 董 | H5: 送 | I5: 屋 | J5: ong | K5: ok | R5: iong | S5: iok
B6: 2 | C6: 通 | D6: 冬 | E6: =_xlfn.CONCAT(韻表_3[[#This Row],[平聲]:[入聲]]) -> 冬∅宋沃 | F6: 冬 | G6: ∅ | H6: 宋 | I6: 沃 | J6: ong | K6: ok
B7: 3 | C7: 通 | D7: 鍾 | E7: =_xlfn.CONCAT(韻表_3[[#This Row],[平聲]:[入聲]]) -> 鍾腫用燭 | F7: 鍾 | G7: 腫 | H7: 用 | I7: 燭 | R7: iong | S7: iok
B8: 4 | C8: 江 | D8: 江 | E8: =_xlfn.CONCAT(韻表_3[[#This Row],[平聲]:[入聲]]) -> 江講絳覺 | F8: 江 | G8: 講 | H8: 絳 | I8: 覺 | N8: ang | O8: ak
B9: 5 | C9: 止 | D9: 支 | E9: =_xlfn.CONCAT(韻表_3[[#This Row],[平聲]:[入聲]]) -> 支紙寘∅ | F9: 支 | G9: 紙 | H9: 寘 | I9: ∅ | R9: i | T9: ui
B10: 6 | C10: 止 | D10: 脂 | E10: =_xlfn.CONCAT(韻表_3[[#This Row],[平聲]:[入聲]]) -> 脂旨至∅ | F10: 脂 | G10: 旨 | H10: 至 | I10: ∅ | R10: i | T10: ui
B11: 7 | C11: 止 | D11: 之 | E11: =_xlfn.CONCAT(韻表_3[[#This Row],[平聲]:[入聲]]) -> 之止志∅ | F11: 之 | G11: 止 | H11: 志 | I11: ∅ | R11: i
B12: 8 | C12: 止 | D12: 微 | E12: =_xlfn.CONCAT(韻表_3[[#This Row],[平聲]:[入聲]]) -> 微尾未∅ | F12: 微 | G12: 尾 | H12: 未 | I12: ∅ | R12: i | T12: ui
B13: 9 | C13: 遇 | D13: 魚 | E13: =_xlfn.CONCAT(韻表_3[[#This Row],[平聲]:[入聲]]) -> 魚語御∅ | F13: 魚 | G13: 語 | H13: 御 | I13: ∅ | R13: u/ir
B14: 10 | C14: 遇 | D14: 虞 | E14: =_xlfn.CONCAT(韻表_3[[#This Row],[平聲]:[入聲]]) -> 虞麌遇∅ | F14: 虞 | G14: 麌 | H14: 遇 | I14: ∅ | R14: u
B15: 11 | C15: 遇 | D15: 模 | E15: =_xlfn.CONCAT(韻表_3[[#This Row],[平聲]:[入聲]]) -> 模姥暮∅ | F15: 模 | G15: 姥 | H15: 暮 | I15: ∅ | J15: oo
B16: 12 | C16: 蟹 | D16: 齊 | E16: =_xlfn.CONCAT(韻表_3[[#This Row],[平聲]:[入聲]]) -> 齊薺霽∅ | F16: 齊 | G16: 薺 | H16: 霽 | I16: ∅ | V16: e | X16: ui/ue
B17: 13 | C17: 蟹 | D17: 佳 | E17: =_xlfn.CONCAT(韻表_3[[#This Row],[平聲]:[入聲]]) -> 佳蟹卦∅ | F17: 佳 | G17: 蟹 | H17: 卦 | I17: ∅ | N17: ai | P17: ua
B18: 14 | C18: 蟹 | D18: 皆 | E18: =_xlfn.CONCAT(韻表_3[[#This Row],[平聲]:[入聲]]) -> 皆駭怪∅ | F18: 皆 | G18: 駭 | H18: 怪 | I18: ∅ | N18: ai | P18: uai
B19: 15 | C19: 蟹 | D19: 灰 | E19: =_xlfn.CONCAT(韻表_3[[#This Row],[平聲]:[入聲]]) -> 灰賄隊∅ | F19: 灰 | G19: 賄 | H19: 隊 | I19: ∅ | K19: ue
B20: 16 | C20: 蟹 | D20: 咍 | E20: =_xlfn.CONCAT(韻表_3[[#This Row],[平聲]:[入聲]]) -> 咍海代∅ | F20: 咍 | G20: 海 | H20: 代 | I20: ∅ | J20: ai
B21: 17 | C21: 臻 | D21: 真 | E21: =_xlfn.CONCAT(韻表_3[[#This Row],[平聲]:[入聲]]) -> 真軫震質 | F21: 真 | G21: 軫 | H21: 震 | I21: 質 | R21: in | S21: it
B22: 18 | C22: 臻 | D22: 諄 | E22: =_xlfn.CONCAT(韻表_3[[#This Row],[平聲]:[入聲]]) -> 諄準稕術 | F22: 諄 | G22: 準 | H22: 稕 | I22: 術 | R22: un | S22: ut
B23: 19 | C23: 臻 | D23: 臻 | E23: =_xlfn.CONCAT(韻表_3[[#This Row],[平聲]:[入聲]]) -> 臻∅齔櫛 | F23: 臻 | G23: ∅ | H23: 齔 | I23: 櫛 | N23: in | O23: it
B24: 20 | C24: 臻 | D24: 文 | E24: =_xlfn.CONCAT(韻表_3[[#This Row],[平聲]:[入聲]]) -> 文吻問物 | F24: 文 | G24: 吻 | H24: 問 | I24: 物 | R24: un | S24: ut
B25: 21 | C25: 臻 | D25: 殷 | E25: =_xlfn.CONCAT(韻表_3[[#This Row],[平聲]:[入聲]]) -> 殷隱焮迄 | F25: 殷 | G25: 隱 | H25: 焮 | I25: 迄 | R25: in | S25: it
B26: 22 | C26: 臻 | D26: 元 | E26: =_xlfn.CONCAT(韻表_3[[#This Row],[平聲]:[入聲]]) -> 元阮願月 | F26: 元 | G26: 阮 | H26: 願 | I26: 月 | R26: ian | S26: iat | T26: uan | U26: uat
B27: 23 | C27: 臻 | D27: 魂 | E27: =_xlfn.CONCAT(韻表_3[[#This Row],[平聲]:[入聲]]) -> 魂混慁沒 | F27: 魂 | G27: 混 | H27: 慁 | I27: 沒 | J27: un | K27: ut
B28: 24 | C28: 臻 | D28: 痕 | E28: =_xlfn.CONCAT(韻表_3[[#This Row],[平聲]:[入聲]]) -> 痕很恨∅ | F28: 痕 | G28: 很 | H28: 恨 | I28: ∅ | J28: un/irn
B29: 25 | C29: 山 | D29: 寒 | E29: =_xlfn.CONCAT(韻表_3[[#This Row],[平聲]:[入聲]]) -> 寒旱翰曷 | F29: 寒 | G29: 旱 | H29: 翰 | I29: 曷 | J29: an | K29: at
B30: 26 | C30: 山 | D30: 桓 | E30: =_xlfn.CONCAT(韻表_3[[#This Row],[平聲]:[入聲]]) -> 桓緩換末 | F30: 桓 | G30: 緩 | H30: 換 | I30: 末 | N30: uan | O30: uat
B31: 27 | C31: 山 | D31: 刪 | E31: =_xlfn.CONCAT(韻表_3[[#This Row],[平聲]:[入聲]]) -> 刪潸諫黠 | F31: 刪 | G31: 潸 | H31: 諫 | I31: 黠 | N31: an | O31: at | P31: uan | Q31: uat
B32: 28 | C32: 山 | D32: 山 | E32: =_xlfn.CONCAT(韻表_3[[#This Row],[平聲]:[入聲]]) -> 山產襇鎋 | F32: 山 | G32: 產 | H32: 襇 | I32: 鎋 | N32: an | O32: at | P32: uan | Q32: uat
B33: 29 | C33: 山 | D33: 先 | E33: =_xlfn.CONCAT(韻表_3[[#This Row],[平聲]:[入聲]]) -> 先銑霰屑 | F33: 先 | G33: 銑 | H33: 霰 | I33: 屑 | V33: ian | W33: iat
B34: 30 | C34: 山 | D34: 仙 | E34: =_xlfn.CONCAT(韻表_3[[#This Row],[平聲]:[入聲]]) -> 仙獮線薛 | F34: 仙 | G34: 獮 | H34: 線 | I34: 薛 | R34: ian | S34: iat | T34: uan | U34: uat
B35: 31 | C35: 效 | D35: 蕭 | E35: =_xlfn.CONCAT(韻表_3[[#This Row],[平聲]:[入聲]]) -> 蕭篠嘯∅ | F35: 蕭 | G35: 篠 | H35: 嘯 | I35: ∅ | V35: iau
B36: 32 | C36: 效 | D36: 宵 | E36: =_xlfn.CONCAT(韻表_3[[#This Row],[平聲]:[入聲]]) -> 宵小笑∅ | F36: 宵 | G36: 小 | H36: 笑 | I36: ∅ | R36: iau
B37: 33 | C37: 效 | D37: 肴 | E37: =_xlfn.CONCAT(韻表_3[[#This Row],[平聲]:[入聲]]) -> 肴巧效∅ | F37: 肴 | G37: 巧 | H37: 效 | I37: ∅ | N37: au
B38: 34 | C38: 效 | D38: 豪 | E38: =_xlfn.CONCAT(韻表_3[[#This Row],[平聲]:[入聲]]) -> 豪晧号∅ | F38: 豪 | G38: 晧 | H38: 号 | I38: ∅ | J38: o/au
B39: 35 | C39: 果 | D39: 歌 | E39: =_xlfn.CONCAT(韻表_3[[#This Row],[平聲]:[入聲]]) -> 歌哿箇∅ | F39: 歌 | G39: 哿 | H39: 箇 | I39: ∅ | J39: o
B40: 36 | C40: 果 | D40: 戈 | E40: =_xlfn.CONCAT(韻表_3[[#This Row],[平聲]:[入聲]]) -> 戈果過∅ | F40: 戈 | G40: 果 | H40: 過 | I40: ∅ | J40: o
B41: 37 | C41: 假 | D41: 麻 | E41: =_xlfn.CONCAT(韻表_3[[#This Row],[平聲]:[入聲]]) -> 麻馬禡∅ | F41: 麻 | G41: 馬 | H41: 禡 | I41: ∅ | N41: a | P41: ua | R41: ia
...

Sheet 韻目表
B2: 列號 | C2: 韻攝 | D2: 平聲 | E2: 上聲 | F2: 去聲 | G2: 入聲
B3: 1 | C3: 通 | D3: 東 【上平聲一東】 | E3: 董 【上聲一董】 | F3: 送 【去聲一送】 | G3: 屋 【入聲一屋】
B4: 2 | C4: 通 | D4: 冬 【上平聲二冬】 | F4: 宋 【去聲二宋】 | G4: 沃 【入聲二沃】
B5: 3 | C5: 通 | D5: 鍾 【上平聲三鍾】 | E5: 腫 【上聲二腫】 | F5: 用 【去聲三用】 | G5: 燭 【入聲三燭】
B6: 4 | C6: 江 | D6: 江 【上平聲四江】 | E6: 講 【上聲三講】 | F6: 絳 【去聲四絳】 | G6: 覺 【入聲四覺】
B7: 5 | C7: 止 | D7: 支 【上平聲五支】 | E7: 紙 【上聲四紙】 | F7: 寘 【去聲五寘】
B8: 6 | C8: 止 | D8: 脂 【上平聲六脂】 | E8: 旨 【上聲五旨】 | F8: 至 【去聲六至】
B9: 7 | C9: 止 | D9: 之 【上平聲七之】 | E9: 止 【上聲六止】 | F9: 志 【去聲七志】
B10: 8 | C10: 止 | D10: 微 【上平聲八微】 | E10: 尾 【上聲七尾】 | F10: 未 【去聲八未】
B11: 9 | C11: 遇 | D11: 魚 【上平聲九魚】 | E11: 語 【上聲八語】 | F11: 御 【去聲九御】
B12: 10 | C12: 遇 | D12: 虞 【上平聲十虞】 | E12: 麌 【上聲九麌】 | F12: 遇 【去聲十遇】
B13: 11 | C13: 遇 | D13: 模 【上平聲十一模】 | E13: 姥 【上聲十姥】 | F13: 暮 【去聲十一暮】
B14: 12 | C14: 蟹 | D14: 齊 【上平聲十二齊】 | E14: 薺 【上聲十一薺】 | F14: 霽 【去聲十二霽】
B15: 13 | C15: 蟹 | F15: 祭 【去聲十三祭】
B16: 14 | C16: 蟹 | F16: 泰 【去聲十四泰】
B17: 15 | C17: 蟹 | D17: 佳 【上平聲十三佳】 | E17: 蟹 【上聲十二蟹】 | F17: 卦 【去聲十五卦】
B18: 16 | C18: 蟹 | D18: 皆 【上平聲十四皆】 | E18: 駭 【上聲十三駭】 | F18: 怪 【去聲十六怪】
B19: 17 | C19: 蟹 | F19: 夬 【去聲十七夬】
B20: 18 | C20: 蟹 | D20: 灰 【上平聲十五灰】 | E20: 賄 【上聲十四賄】 | F20: 隊 【去聲十八隊】
B21: 19 | C21: 蟹 | D21: 咍 【上平聲十六咍】 | E21: 海 【上聲十五海】 | F21: 代 【去聲十九代】
B22: 20 | C22: 蟹 | F22: 廢 【去聲二十廢】
B23: 21 | C23: 臻 | D23: 真 【上平聲十七眞】 | E23: 軫 【上聲十六軫】 | F23: 震 【去聲二十一震】 | G23: 質 【入聲五質】
B24: 22 | C24: 臻 | D24: 諄 【上平聲十八諄】 | E24: 準 【上聲十七準】 | F24: 稕 【去聲二十二稕】 | G24: 術 【入聲六術】
B25: 23 | C25: 臻 | D25: 臻 【上平聲十九臻】 | F25: 齔 【去聲二十一齔】 | G25: 櫛 【入聲七櫛】
B26: 24 | C26: 臻 | D26: 文 【上平聲二十文】 | E26: 吻 【上聲十八吻】 | F26: 問 【去聲二十三問】 | G26: 物 【入聲八物】
B27: 25 | C27: 臻 | D27: 殷 【上平聲二十一殷】 | E27: 隱 【上聲十九隱】 | F27: 焮 【去聲二十四焮】 | G27: 迄 【入聲九迄】
B28: 26 | C28: 臻 | D28: 元 【上平聲二十二元】 | E28: 阮 【上聲二十阮】 | F28: 願 【去聲二十五願】 | G28: 月 【入聲十月】
B29: 27 | C29: 臻 | D29: 魂 【上平聲二十三魂】 | E29: 混 【上聲二十一混】 | F29: 慁 【去聲二十六慁】 | G29: 沒 【入聲十一沒】
B30: 28 | C30: 臻 | D30: 痕 【上平聲二十四痕】 | E30: 很 【上聲二十二很】 | F30: 恨 【去聲二十七恨】 | G30: 麧 【入聲十一麧】
B31: 29 | C31: 山 | D31: 寒 【上平聲二十五寒】 | E31: 旱 【上聲二十三旱】 | F31: 翰 【去聲二十八翰】 | G31: 曷 【入聲十二曷】
B32: 30 | C32: 山 | D32: 桓 【上平聲二十六桓】 | E32: 緩 【上聲二十四緩】 | F32: 換 【去聲二十九換】 | G32: 末 【入聲十三末】
B33: 31 | C33: 山 | D33: 刪 【上平聲二十七刪】 | E33: 潸 【上聲二十五潸】 | F33: 諫 【去聲三十諫】 | G33: 黠 【入聲十四黠】
B34: 32 | C34: 山 | D34: 山 【上平聲二十八山】 | E34: 產 【上聲二十六產】 | F34: 襇 【去聲三十一襇】 | G34: 鎋 【入聲十五鎋】
B35: 33 | C35: 山 | D35: 先 【下平聲一先】 | E35: 銑 【上聲二十七銑】 | F35: 霰 【去聲三十二霰】 | G35: 屑 【入聲十六屑】
B36: 34 | C36: 山 | D36: 仙 【下平聲二仙】 | E36: 獮 【上聲二十八獮】 | F36: 線 【去聲三十三線】 | G36: 薛 【入聲十七薛】
B37: 35 | C37: 效 | D37: 蕭 【下平聲三蕭】 | E37: 篠 【上聲二十九篠】 | F37: 嘯 【去聲三十四嘯】
B38: 36 | C38: 效 | D38: 宵 【下平聲四宵】 | E38: 小 【上聲三十小】 | F38: 笑 【去聲三十五笑】
B39: 37 | C39: 效 | D39: 肴 【下平聲五肴】 | E39: 巧 【上聲三十一巧】 | F39: 效 【去聲三十六效】
B40: 38 | C40: 效 | D40: 豪 【下平聲六豪】 | E40: 晧 【上聲三十二晧】 | F40: 号 【去聲三十七号】
B41: 39 | C41: 果 | D41: 歌 【下平聲七歌】 | E41: 哿 【上聲三十三哿】 | F41: 箇 【去聲三十八箇】
...

Sheet 廣韻韻目表【韻母206字】
B2: 攝 | C2: 韻目 列號 | D2: 韻系 | E2: 《廣韻》206 韻 | I2: 四声調 | J2: 一等 | L2: 二等 | N2: 三等 | P2: 四等
E3: 平聲 | F3: 上聲 | G3: 去聲 | H3: 入聲 | J3: 開口 | K3: 合口 | L3: 開口 | M3: 合口 | N3: 開口 | O3: 合口 | P3: 開口 | Q3: 合口
B4: 通 | C4: 1 | D4: 東 | E4: 1東 | F4: 1董 | G4: 1送 | I4: 平上去 | J4: ong | N4: iong
H5: 1屋 | I5: 入 | J5: ok | N5: iok
C6: 2 | D6: 冬 | E6: 2冬 | G6: 2宋 | I6: 平上去 | J6: ong
H7: 2沃 | I7: 入 | J7: ok
C8: 3 | D8: 鍾 | E8: 3鍾 | F8: 2腫 | G8: 3用 | I8: 平上去 | N8: iong
H9: 3燭 | I9: 入 | N9: iok
B10: 江 | C10: 4 | D10: 江 | E10: 4江 | F10: 3講 | G10: 4絳 | I10: 平上去 | L10: ang
H11: 4覺 | I11: 入 | L11: ak
B12: 止 | C12: 5 | D12: 支 | E12: 5支 | F12: 4紙 | G12: 5寘 | I12: 平上去 | N12: i/ir | O12: ui
C13: 6 | D13: 脂 | E13: 6脂 | F13: 5旨 | G13: 6至 | I13: 平上去 | N13: i/ir | O13: ui
C14: 7 | D14: 之 | E14: 7之 | F14: 6止 | G14: 7志 | I14: 平上去 | N14: i/ir
C15: 8 | D15: 微 | E15: 8微 | F15: 7尾 | G15: 8未 | I15: 平上去 | N15: i | O15: ui
B16: 遇 | C16: 9 | D16: 魚 | E16: 9魚 | F16: 8語 | G16: 9禦 | I16: 平上去 | N16: u/ir
C17: 10 | D17: 虞 | E17: 10虞 | F17: 9麌 | G17: 10遇 | I17: 平上去 | N17: u
C18: 11 | D18: 模 | E18: 11模 | F18: 10姥 | G18: 11暮 | I18: 平上去 | J18: oo
B19: 蟹 | C19: 12 | D19: 齊 | E19: 12齊 | F19: 11薺 | G19: 12霽 | I19: 平上去 | P19: e | Q19: ui/ue
C20: 13 | D20: 祭 | G20: 13祭 | I20: 平上去 | N20: e | O20: ue
C21: 14 | D21: 泰 | G21: 14泰 | I21: 平上去 | J21: ai | K21: ue
C22: 15 | D22: 佳 | E22: 13佳 | F22: 12蟹 | G22: 15卦 | I22: 平上去 | L22: ai | M22: ua
C23: 16 | D23: 皆 | E23: 14皆 | F23: 13駭 | G23: 16怪 | I23: 平上去 | L23: ai | M23: uai
C24: 17 | D24: 夬 | G24: 17夬 | I24: 平上去 | L24: ai | M24: uai
C25: 18 | D25: 灰 | E25: 15灰 | F25: 14賄 | G25: 18隊 | I25: 平上去 | K25: ue
C26: 19 | D26: 咍 | E26: 16咍 | F26: 15海 | G26: 19代 | I26: 平上去 | J26: ai
C27: 20 | D27: 廢 | G27: 20廢 | I27: 平上去 | O27: ui/ue
B28: 臻 | C28: 21 | D28: 真 | E28: 17 真 | F28: 16軫 | G28: 21震 | I28: 平上去 | N28: in
H29: 5質 | I29: 入 | N29: it
C30: 22 | D30: 諄 | E30: 18諄 | F30: 17準 | G30: 22稕 | I30: 平上去 | O30: un
H31: 6術 | I31: 入 | O31: ut
C32: 23 | D32: 臻 | E32: 19臻 | I32: 平上去 | L32: in
H33: 7櫛 | I33: 入 | L33: it
C34: 24 | D34: 文 | E34: 20文 | F34: 18吻 | G34: 23問 | I34: 平上去 | O34: un
H35: 8物 | I35: 入 | O35: ut
C36: 25 | D36: 欣 | E36: 21欣 | F36: 19隱 | G36: 24焮 | I36: 平上去 | N36: in
H37: 9迄 | I37: 入 | N37: it
C38: 26 | D38: 魂 | E38: 22魂 | F38: 20混 | G38: 25慁 | I38: 平上去 | K38: un
H39: 10沒 | I39: 入 | K39: ut
C40: 27 | D40: 痕 | E40: 23痕 | F40: 21很 | G40: 26恨 | I40: 平上去 | J40: un
I41: 入
...

Sheet 工作底稿
B1: 全濁 | D1: 識別號 | E1: 七聲類 | F1: 發音部位 | G1: 聲母 | H1: 清濁 | I1: 發送收 | J1: 聲母標音 | K1: 切語上字集 | L1: 備註 | O1: 聲母 | P1: 清濁 | Q1: 陽上轉調 | R1: 調號
B2: =G2 -> 群 | D2: {=_xlfn._xlws.FILTER(切語上字表[], 切語上字表[清濁]="全濁")} -> 3 | E2: 牙音 | F2: 牙音 | G2: 群 | H2: 全濁 | J2: k | K2: 渠強求奇衢其暨具巨臼跪近狂 | L2: 0 | O2: 群 | P2: 全濁 | Q2: 陽去 | R2: 7
B3: =G3 -> 定 | D3: 7 | E3: 舌音 | F3: 舌頭音 | G3: 定 | H3: 全濁 | J3: t | K3: 徒同特唐堂田陀地度杜大 | L3: 0 | O3: 定 | P3: 全濁 | Q3: 陽去 | R3: 7
B4: =G4 -> 澄 | D4: 11 | E4: 舌音 | F4: 舌上音 | G4: 澄 | H4: 全濁 | J4: t | K4: 除場池治持持遲佇柱丈直宅馳墜 | L4: 0 | O4: 澄 | P4: 全濁 | Q4: 陽去 | R4: 7
B5: =G5 -> 並 | D5: 15 | E5: 脣音 | F5: 重脣音 | G5: 並 | H5: 全濁 | J5: p | K5: 蒲裴平皮步薄白部傍便弼婢毗簿捕 | L5: 0 | O5: 並 | P5: 全濁 | Q5: 陽去 | R5: 7
B6: =G6 -> 奉 | D6: 19 | E6: 脣音 | F6: 輕脣音 | G6: 奉 | H6: 全濁 | J6: h | K6: 防縛附父浮苻扶馮房符 | L6: 0 | O6: 奉 | P6: 全濁 | Q6: 陽去 | R6: 7
B7: =G7 -> 從 | D7: 23 | E7: 齒音 | F7: 齒頭音 | G7: 從 | H7: 全濁 | J7: z | K7: 才徂慈藏在前秦情酢自昨漸匠疾鶵 | L7: 崇 | O7: 從 | P7: 全濁 | Q7: 陽去 | R7: 7
B8: =G8 -> 邪 | D8: 25 | E8: 齒音 | F8: 齒頭音 | G8: 邪 | H8: 全濁 | I8: 0 | J8: s | K8: 辭隨寺似徐祥詳旬夕辤辝 | L8: 0 | O8: 邪 | P8: 全濁 | Q8: 陽去 | R8: 7
B9: =G9 -> 牀 | D9: 28 | E9: 齒音 | F9: 正齒近齒頭 | G9: 牀 | H9: 全濁 | J9: z | K9: 牀查崇雛鋤鉏豺助俟士仕崱 | L9: 0 | O9: 牀 | P9: 全濁 | Q9: 陽去 | R9: 7
B10: =G10 -> 神 | D10: 32 | E10: 齒音 | F10: 正齒近舌上 | G10: 神 | H10: 全濁 | I10: 送氣 | J10: s | K10: 乘神食實 | L10: 0 | O10: 神 | P10: 全濁 | Q10: 陽去 | R10: 7
B11: =G11 -> 禪 | D11: 34 | E11: 齒音 | F11: 正齒近舌上 | G11: 禪 | H11: 全濁 | I11: 送氣 | J11: s | K11: 時殊嘗常成臣蜀市植殖寔署是氏視承 | L11: 0 | O11: 禪 | P11: 全濁 | Q11: 陽去 | R11: 7
B12: =G12 -> 匣 | D12: 37 | E12: 喉音 | F12: 喉音 | G12: 匣 | H12: 全濁 | I12: 送氣 | J12: h | K12: 胡乎侯何黃戶下獲懷諧 | L12: 0 | O12: 匣 | P12: 全濁 | Q12: 陽去 | R12: 7
O13: 泥 | P13: 次濁 | Q13: 陰上 | R13: 2
B14: 次濁 | D14: {=_xlfn._xlws.FILTER(切語上字表[],切語上字表[清濁]="次濁")} -> 4 | E14: 牙音 | F14: 牙音 | G14: 疑 | H14: 次濁 | I14: 收聲 | J14: g | K14: 疑魚語宜玉遇虞愚牛擬研危五俄吾 | L14: 0 | O14: 孃 | P14: 次濁 | Q14: 陰上 | R14: 3
B15: =G15 -> 泥 | D15: 8 | E15: 舌音 | F15: 舌頭音 | G15: 泥 | H15: 次濁 | I15: 收聲 | J15: n | K15: 奴乃諾內那嬭妳 | L15: 0 | O15: 明 | P15: 次濁 | Q15: 陰上 | R15: 4
B16: =G16 -> 孃 | D16: 12 | E16: 舌音 | F16: 舌上音 | G16: 孃 | H16: 次濁 | I16: 收聲 | J16: l | K16: 尼拏女穠 | L16: 娘 | O16: 微 | P16: 次濁 | Q16: 陰上 | R16: 5
B17: =G17 -> 明 | D17: 16 | E17: 脣音 | F17: 重脣音 | G17: 明 | H17: 次濁 | I17: 收聲 | J17: m | K17: 莫慕模謨摸母明彌眉綿靡美 | L17: 0 | O17: 為 | P17: 次濁 | Q17: 陰上 | R17: 6
B18: =G18 -> 微 | D18: 20 | E18: 脣音 | F18: 輕脣音 | G18: 微 | H18: 次濁 | I18: 收聲 | J18: b | K18: 巫無武文望亡 | L18: 0 | O18: 喻 | P18: 次濁 | Q18: 陰上 | R18: 7
B19: =G19 -> 為 | D19: 38 | E19: 喉音 | F19: 喉音 | G19: 為 | H19: 次濁 | I19: 發聲 | J19: Ø | K19: 于雲云筠為榮本王雨羽永有洧𨘏遠 | L19: 0 | O19: 來 | P19: 次濁 | Q19: 陰上 | R19: 8
B20: =G20 -> 喻 | D20: 39 | E20: 喉音 | F20: 喉音 | G20: 喻 | H20: 次濁 | I20: 發聲 | J20: Ø | K20: 余餘予移夷羊營以弋翼與悅薳韋 | L20: 云 | O20: 日 | P20: 次濁 | Q20: 陰上 | R20: 9
B21: =G21 -> 來 | D21: 40 | E21: 半舌音 | F21: 半舌 | G21: 來 | H21: 次濁 | I21: 收聲 | J21: l | K21: 來盧郎賴洛落勒力呂良林離里練魯紬連縷 | L21: 0
B22: =G22 -> 日 | D22: 41 | E22: 半齒音 | F22: 半齒 | G22: 日 | H22: 次濁 | I22: 收聲 | J22: j | K22: 如儒人仍汝兒而耳 | L22: 0

Sheet 韻攝表
A1: 韻目列號 | B1: 攝 | C1: 四聲韻目
A2: 1 | B2: 通 | C2: =_xlfn.CONCAT([1]韻目工作底稿!L4,[1]韻目工作底稿!P4,[1]韻目工作底稿!T4,[1]韻目工作底稿!X4) -> 東董送屋
A3: 2 | B3: 通 | C3: =_xlfn.CONCAT([1]韻目工作底稿!L5,[1]韻目工作底稿!P5,[1]韻目工作底稿!T5,[1]韻目工作底稿!X5) -> 冬∅宋沃
A4: 3 | B4: 通 | C4: =_xlfn.CONCAT([1]韻目工作底稿!L6,[1]韻目工作底稿!P6,[1]韻目工作底稿!T6,[1]韻目工作底稿!X6) -> 鍾腫用燭
A5: 4 | B5: 江 | C5: =_xlfn.CONCAT([1]韻目工作底稿!L7,[1]韻目工作底稿!P7,[1]韻目工作底稿!T7,[1]韻目工作底稿!X7) -> 江講絳覺
A6: 5 | B6: 止 | C6: =_xlfn.CONCAT([1]韻目工作底稿!L8,[1]韻目工作底稿!P8,[1]韻目工作底稿!T8,[1]韻目工作底稿!X8) -> 支紙寘∅
A7: 6 | B7: 止 | C7: =_xlfn.CONCAT([1]韻目工作底稿!L9,[1]韻目工作底稿!P9,[1]韻目工作底稿!T9,[1]韻目工作底稿!X9) -> 脂旨至∅
A8: 7 | B8: 止 | C8: =_xlfn.CONCAT([1]韻目工作底稿!L10,[1]韻目工作底稿!P10,[1]韻目工作底稿!T10,[1]韻目工作底稿!X10) -> 之止志∅
A9: 8 | B9: 止 | C9: =_xlfn.CONCAT([1]韻目工作底稿!L11,[1]韻目工作底稿!P11,[1]韻目工作底稿!T11,[1]韻目工作底稿!X11) -> 微尾未∅
A10: 9 | B10: 遇 | C10: =_xlfn.CONCAT([1]韻目工作底稿!L12,[1]韻目工作底稿!P12,[1]韻目工作底稿!T12,[1]韻目工作底稿!X12) -> 魚語御∅
A11: 10 | B11: 遇 | C11: =_xlfn.CONCAT([1]韻目工作底稿!L13,[1]韻目工作底稿!P13,[1]韻目工作底稿!T13,[1]韻目工作底稿!X13) -> 虞麌遇∅
A12: 11 | B12: 遇 | C12: =_xlfn.CONCAT([1]韻目工作底稿!L14,[1]韻目工作底稿!P14,[1]韻目工作底稿!T14,[1]韻目工作底稿!X14) -> 模姥暮∅
A13: 12 | B13: 蟹 | C13: =_xlfn.CONCAT([1]韻目工作底稿!L15,[1]韻目工作底稿!P15,[1]韻目工作底稿!T15,[1]韻目工作底稿!X15) -> 齊薺霽∅
... A62: 61 | B62: 咸 | C62: =_xlfn.CONCAT([1]韻目工作底稿!L64,[1]韻目工作底稿!P64,[1]韻目工作底稿!T64,[1]韻目工作底稿!X64) -> 凡范梵乏
