Workbook
Name FILE_NAME: env!$C$5
Name IMAGE_URL: env!$C$7
Name INPUT_FILE_PATH: env!$C$4
Name OUTPUT_PATH: env!$C$8
Name TITLE: env!$C$6
Name 上邊標音: env!$C$18
Name 文件版本: env!$C$3
Name 右邊標音: env!$C$19
Name 每列總字數: env!$C$12
Name 每頁總列數: env!$C$11
Name 格式版本: env!$C$2
Name 章節序號: env!$C$9
Name 漢字庫: env!$C$14
Name 網頁每列字數: env!$C$20
Name 網頁格式: env!$C$16
Name 語音類型: env!$C$13
Name 標音方式: env!$C$17
Name 標音方法: env!$C$15
Name 聲母碼: [1]十五音聲母對照表!$F$4:$F$25
Name 顯示注音輸入: env!$C$10

Sheet env
B1: Key | C1: Value
B2: 格式版本 | C2: 1
B3: 文件版本 | C3: 0.0.0.1
B4: INPUT_FILE_PATH | C4: C:\\work\\Piau-Im
B5: FILE_NAME | C5: 【河洛文讀注音-閩拼調號】《歸去來辭》.xlsx
B6: TITLE | C6: 歸去來辭
B7: IMAGE_URL | C7: Gui-Ku-Lai-Su.png
B8: OUTPUT_PATH | C8: output7
B9: 章節序號 | C9: None
B10: 顯示注音輸入 | C10: TRUE
B11: 每頁總列數 | C11: 34
B12: 每列總字數 | C12: 15
B13: 語音類型 | C13: 文讀音
B14: 漢字庫 | C14: 河洛話
B15: 標音方法 | C15: 閩拼調號
B16: 網頁格式 | C16: 無預設
B17: 標音方式 | C17: 上及右
B18: 上邊標音 | C18: 雅俗通
B19: 右邊標音 | C19: 方音符號
B20: 網頁每列字數 | C20: 0

Sheet 網頁匯入
A1: 漢字 | B1: 漢字標音 | C1: 台語音標 | D1: 台語音標之聲 | E1: 台語音標之韻 | F1: 台語音標之調
A2: 《 | D2: {=_xlfn._xlws.PY(0,0,B2:B669)} | H2: ====》 | I2: =IF(B2="", A2, _xlfn.CONCAT("<ruby>", A2, "<rt>", B2, "</rt>", "</ruby>")) -> 《
A3: 前 | B3: 堅五曾 | C3: zian5 | D3: z | E3: ian | F3: 5 | H3: ====》 | I3: =IF(B3="", A3, _xlfn.CONCAT("<ruby>", A3, "<rt>", B3, "</rt>", "</ruby>")) -> <ruby>前<rt>堅五曾</rt></ruby>
A4: 赤 | B4: 經四出 | C4: cik4 | D4: c | E4: ik | F4: 4 | H4: ====》 | I4: =IF(B4="", A4, _xlfn.CONCAT("<ruby>", A4, "<rt>", B4, "</rt>", "</ruby>")) -> <ruby>赤<rt>經四出</rt></ruby>
A5: 壁 | B5: 經四邊 | C5: pik4 | D5: p | E5: ik | F5: 4 | H5: ====》 | I5: =IF(B5="", A5, _xlfn.CONCAT("<ruby>", A5, "<rt>", B5, "</rt>", "</ruby>")) -> <ruby>壁<rt>經四邊</rt></ruby>
A6: 賦 | B6: 艍三喜 | C6: hu3 | D6: h | E6: u | F6: 3 | H6: ====》 | I6: =IF(B6="", A6, _xlfn.CONCAT("<ruby>", A6, "<rt>", B6, "</rt>", "</ruby>")) -> <ruby>賦<rt>艍三喜</rt></ruby>
A7: 》 | H7: ====》 | I7: =IF(B7="", A7, _xlfn.CONCAT("<ruby>", A7, "<rt>", B7, "</rt>", "</ruby>")) -> 》
A8: 北 | B8: 公四邊 | C8: pok4 | D8: p | E8: ok | F8: 4 | H8: ====》 | I8: =IF(B8="", A8, _xlfn.CONCAT("<ruby>", A8, "<rt>", B8, "</rt>", "</ruby>")) -> <ruby>北<rt>公四邊</rt></ruby>
A9: 宋 | B9: 公三時 | C9: song3 | D9: s | E9: ong | F9: 3 | H9: ====》 | I9: =IF(B9="", A9, _xlfn.CONCAT("<ruby>", A9, "<rt>", B9, "</rt>", "</ruby>")) -> <ruby>宋<rt>公三時</rt></ruby>
A10: ： | H10: ====》 | I10: =IF(B10="", A10, _xlfn.CONCAT("<ruby>", A10, "<rt>", B10, "</rt>", "</ruby>")) -> ：
A11: 蘇 | B11: 沽一時 | C11: soo1 | D11: s | E11: oo | F11: 1 | H11: ====》 | I11: =IF(B11="", A11, _xlfn.CONCAT("<ruby>", A11, "<rt>", B11, "</rt>", "</ruby>")) -> <ruby>蘇<rt>沽一時</rt></ruby>
A12: 軾 | B12: 經四時 | C12: sik4 | D12: s | E12: ik | F12: 4 | H12: ====》 | I12: =IF(B12="", A12, _xlfn.CONCAT("<ruby>", A12, "<rt>", B12, "</rt>", "</ruby>")) -> <ruby>軾<rt>經四時</rt></ruby>
A13: =CHAR(10) | H13: ====》 | I13: =IF(B13="", A13, _xlfn.CONCAT("<ruby>", A13, "<rt>", B13, "</rt>", "</ruby>"))
A14: 壬 | B14: 金五入 | C14: jim5 | D14: j | E14: im | F14: 5 | H14: ====》 | I14: =IF(B14="", A14, _xlfn.CONCAT("<ruby>", A14, "<rt>", B14, "</rt>", "</ruby>")) -> <ruby>壬<rt>金五入</rt></ruby>
A15: 戌 | B15: 君四時 | C15: sut4 | D15: s | E15: ut | F15: 4 | H15: ====》 | I15: =IF(B15="", A15, _xlfn.CONCAT("<ruby>", A15, "<rt>", B15, "</rt>", "</ruby>")) -> <ruby>戌<rt>君四時</rt></ruby>
A16: 之 | B16: 居一曾 | C16: zi1 | D16: z | E16: i | F16: 1 | H16: ====》 | I16: =IF(B16="", A16, _xlfn.CONCAT("<ruby>", A16, "<rt>", B16, "</rt>", "</ruby>")) -> <ruby>之<rt>居一曾</rt></ruby>
A17: 秋 | B17: 丩一出 | C17: ciu1 | D17: c | E17: iu | F17: 1 | H17: ====》 | I17: =IF(B17="", A17, _xlfn.CONCAT("<ruby>", A17, "<rt>", B17, "</rt>", "</ruby>")) -> <ruby>秋<rt>丩一出</rt></ruby>
A18: ， | H18: ====》 | I18: =IF(B18="", A18, _xlfn.CONCAT("<ruby>", A18, "<rt>", B18, "</rt>", "</ruby>")) -> ，
A19: 七 | B19: 巾四出 | C19: cit4 | D19: c | E19: it | F19: 4 | H19: ====》 | I19: =IF(B19="", A19, _xlfn.CONCAT("<ruby>", A19, "<rt>", B19, "</rt>", "</ruby>")) -> <ruby>七<rt>巾四出</rt></ruby>
A20: 月 | B20: 觀八語 | C20: guat8 | D20: g | E20: uat | F20: 8 | H20: ====》 | I20: =IF(B20="", A20, _xlfn.CONCAT("<ruby>", A20, "<rt>", B20, "</rt>", "</ruby>")) -> <ruby>月<rt>觀八語</rt></ruby>
A21: 既 | B21: 居三求 | C21: ki3 | D21: k | E21: i | F21: 3
A22: 望 | B22: 公七門 | C22: bong7 | D22: b | E22: ong | F22: 7
A23: ，
A24: 蘇 | B24: 沽一時 | C24: soo1 | D24: s | E24: oo | F24: 1
A25: 子 | B25: 艍二曾 | C25: zu2 | D25: z | E25: u | F25: 2
A26: 與 | B26: 艍二英 | C26: u2 | E26: u | F26: 2
A27: 客 | B27: 經四去 | C27: khik4 | D27: kh | E27: ik | F27: 4
A28: 泛 | B28: 觀三喜 | C28: huan3 | D28: h | E28: uan | F28: 3
A29: 舟 | B29: 丩一曾 | C29: ziu1 | D29: z | E29: iu | F29: 1
A30: 遊 | B30: 丩五英 | C30: iu5 | E30: iu | F30: 5
A31: 於 | B31: 艍一英 | C31: u1 | E31: u | F31: 1
A32: 赤 | B32: 經四出 | C32: cik4 | D32: c | E32: ik | F32: 4
A33: 壁 | B33: 經四邊 | C33: pik4 | D33: p | E33: ik | F33: 4
A34: 之 | B34: 居一曾 | C34: zi1 | D34: z | E34: i | F34: 1
A35: 下 | B35: 膠二喜 | C35: ha2 | D35: h | E35: a | F35: 2
A36: 。
A37: 清 | B37: 經一出 | C37: cing1 | D37: c | E37: ing | F37: 1
A38: 風 | B38: 公一喜 | C38: hong1 | D38: h | E38: ong | F38: 1
A39: 徐 | B39: 艍五時 | C39: su5 | D39: s | E39: u | F39: 5
A40: 來 | B40: 皆五柳 | C40: lai5 | D40: l | E40: ai | F40: 5
...

Sheet 網頁匯入 (有Bug)
A1: 漢字 | B1: 漢字標音 | C1: 台語音標 | D1: 台語音標之聲 | E1: 台語音標之韻 | F1: 台語音標之調
A2: 《
A3: 前 | B3: 堅五曾 | C3: zian5 | D3: z | E3: ian | F3: 5
A4: 赤 | B4: 經四出 | C4: cik4 | D4: c | E4: ik | F4: 4
A5: 壁 | B5: 經四邊 | C5: pik4 | D5: p | E5: ik | F5: 4
A6: 賦 | B6: 艍三喜 | C6: hu3 | D6: h | E6: u | F6: 3
A7: 》
A8: 北 | B8: 公四邊 | C8: pok4 | D8: p | E8: ok | F8: 4
A9: 宋 | B9: 公三時 | C9: song3 | D9: s | E9: ong | F9: 3
A10: ：
A11: 蘇 | B11: 沽一時 | C11: soo1 | D11: s | E11: oo | F11: 1
A12: 軾 | B12: 經四時 | C12: sik4 | D12: s | E12: ik | F12: 4
A13: 壬 | B13: 金五入 | C13: jim5 | D13: j | E13: im | F13: 5
A14: 戌 | B14: 君四時 | C14: sut4 | D14: s | E14: ut | F14: 4
A15: 之 | B15: 居一曾 | C15: zi1 | D15: z | E15: i | F15: 1
A16: 秋 | B16: 丩一出 | C16: ciu1 | D16: c | E16: iu | F16: 1
A17: ，
A18: 七 | B18: 巾四出 | C18: cit4 | D18: c | E18: it | F18: 4
A19: 月 | B19: 觀八語 | C19: guat8 | D19: g | E19: uat | F19: 8
A20: 既 | B20: 居三求 | C20: ki3 | D20: k | E20: i | F20: 3
A21: 望 | B21: 恭七門 | C21: bong7 | D21: b | E21: ong | F21: 7
A22: ，
A23: 蘇 | B23: 沽一時 | C23: soo1 | D23: s | E23: oo | F23: 1
A24: 子 | B24: 艍二曾 | C24: zu2 | D24: z | E24: u | F24: 2
A25: 與 | B25: 艍二英 | C25: qu2 | D25: q | E25: u | F25: 2
A26: 客 | B26: 經四去 | C26: khik4 | D26: kh | E26: ik | F26: 4
A27: 泛 | B27: 觀三喜 | C27: huan3 | D27: h | E27: uan | F27: 3
A28: 舟 | B28: 丩一曾 | C28: ziu1 | D28: z | E28: iu | F28: 1
A29: 遊 | B29: 丩五英 | C29: qiu5 | D29: q | E29: iu | F29: 5
A30: 於 | B30: 艍一英 | C30: qu1 | D30: q | E30: u | F30: 1
A31: 赤 | B31: 經四出 | C31: cik4 | D31: c | E31: ik | F31: 4
A32: 壁 | B32: 經四邊 | C32: pik4 | D32: p | E32: ik | F32: 4
A33: 之 | B33: 居一曾 | C33: zi1 | D33: z | E33: i | F33: 1
A34: 下 | B34: 膠二喜 | C34: hee7 | D34: h | E34: ee | F34: 7
A35: 。
A36: 清 | B36: 經一出 | C36: cing1 | D36: c | E36: ing | F36: 1
A37: 風 | B37: 恭一喜 | C37: hiong1 | D37: h | E37: iong | F37: 1
A38: 徐 | B38: 艍五時 | C38: su5 | D38: s | E38: u | F38: 5
A39: 來 | B39: 皆五柳 | C39: lai5 | D39: l | E39: ai | F39: 5
A40: ，
...

Sheet 網頁匯入 (2)
A1: 漢字 | B1: 漢字標音 | C1: 台語音標 | D1: 台語音標之聲 | E1: 台語音標之韻 | F1: 台語音標之調
A2: 《 | D2: =IF($B2="", "", _xlfn.XLOOKUP(RIGHT($B2), 聲母對照表[十五音], 聲母對照表[台語音標], "N/A")) | E2: {=_xlfn._xlws.PY(1,1,B2:B103,F2:F103)} -> #VALUE! | F2: =IF($B2="", "", _xlfn.XLOOKUP(MID($B2,2,1), 聲調對照表[十五音調號], 聲調對照表[傳統八聲調], "N/A"))
A3: 前 | B3: 堅五曾 | C3: zian5 | D3: =IF($B3="", "", _xlfn.XLOOKUP(RIGHT($B3), 聲母對照表[十五音], 聲母對照表[台語音標], "N/A")) -> z | F3: =IF($B3="", "", _xlfn.XLOOKUP(MID($B3,2,1), 聲調對照表[十五音調號], 聲調對照表[傳統八聲調], "N/A")) -> 5
A4: 赤 | B4: 經四出 | C4: cik4 | D4: =IF($B4="", "", _xlfn.XLOOKUP(RIGHT($B4), 聲母對照表[十五音], 聲母對照表[台語音標], "N/A")) -> c | E4: =IF($B4="", "", _xlfn.XLOOKUP(LEFT($B4), 韻母對照表[十五音], 韻母對照表[台語音標], "N/A")) -> ik | F4: =IF($B4="", "", _xlfn.XLOOKUP(MID($B4,2,1), 聲調對照表[十五音調號], 聲調對照表[傳統八聲調], "N/A")) -> 4
A5: 壁 | B5: 經四邊 | C5: pik4 | D5: =IF($B5="", "", _xlfn.XLOOKUP(RIGHT($B5), 聲母對照表[十五音], 聲母對照表[台語音標], "N/A")) -> p | E5: =IF($B5="", "", _xlfn.XLOOKUP(LEFT($B5), 韻母對照表[十五音], 韻母對照表[台語音標], "N/A")) -> ik | F5: =IF($B5="", "", _xlfn.XLOOKUP(MID($B5,2,1), 聲調對照表[十五音調號], 聲調對照表[傳統八聲調], "N/A")) -> 4
A6: 賦 | B6: 艍三喜 | C6: hu3 | D6: =IF($B6="", "", _xlfn.XLOOKUP(RIGHT($B6), 聲母對照表[十五音], 聲母對照表[台語音標], "N/A")) -> h | E6: =IF($B6="", "", _xlfn.XLOOKUP(LEFT($B6), 韻母對照表[十五音], 韻母對照表[台語音標], "N/A")) -> u | F6: =IF($B6="", "", _xlfn.XLOOKUP(MID($B6,2,1), 聲調對照表[十五音調號], 聲調對照表[傳統八聲調], "N/A")) -> 3
A7: 》 | D7: =IF($B7="", "", _xlfn.XLOOKUP(RIGHT($B7), 聲母對照表[十五音], 聲母對照表[台語音標], "N/A")) | E7: =IF($B7="", "", _xlfn.XLOOKUP(LEFT($B7), 韻母對照表[十五音], 韻母對照表[台語音標], "N/A")) | F7: =IF($B7="", "", _xlfn.XLOOKUP(MID($B7,2,1), 聲調對照表[十五音調號], 聲調對照表[傳統八聲調], "N/A"))
A8: 北 | B8: 公四邊 | C8: pok4 | D8: =IF($B8="", "", _xlfn.XLOOKUP(RIGHT($B8), 聲母對照表[十五音], 聲母對照表[台語音標], "N/A")) -> p | E8: =IF($B8="", "", _xlfn.XLOOKUP(LEFT($B8), 韻母對照表[十五音], 韻母對照表[台語音標], "N/A")) -> ok | F8: =IF($B8="", "", _xlfn.XLOOKUP(MID($B8,2,1), 聲調對照表[十五音調號], 聲調對照表[傳統八聲調], "N/A")) -> 4
A9: 宋 | B9: 公三時 | C9: song3 | D9: =IF($B9="", "", _xlfn.XLOOKUP(RIGHT($B9), 聲母對照表[十五音], 聲母對照表[台語音標], "N/A")) -> s | E9: =IF($B9="", "", _xlfn.XLOOKUP(LEFT($B9), 韻母對照表[十五音], 韻母對照表[台語音標], "N/A")) -> ok | F9: =IF($B9="", "", _xlfn.XLOOKUP(MID($B9,2,1), 聲調對照表[十五音調號], 聲調對照表[傳統八聲調], "N/A")) -> 3
A10: ： | D10: =IF($B10="", "", _xlfn.XLOOKUP(RIGHT($B10), 聲母對照表[十五音], 聲母對照表[台語音標], "N/A")) | E10: =IF($B10="", "", _xlfn.XLOOKUP(LEFT($B10), 韻母對照表[十五音], 韻母對照表[台語音標], "N/A")) | F10: =IF($B10="", "", _xlfn.XLOOKUP(MID($B10,2,1), 聲調對照表[十五音調號], 聲調對照表[傳統八聲調], "N/A"))
A11: 蘇 | B11: 沽一時 | C11: soo1 | D11: =IF($B11="", "", _xlfn.XLOOKUP(RIGHT($B11), 聲母對照表[十五音], 聲母對照表[台語音標], "N/A")) -> s | E11: =IF($B11="", "", _xlfn.XLOOKUP(LEFT($B11), 韻母對照表[十五音], 韻母對照表[台語音標], "N/A")) -> oo | F11: =IF($B11="", "", _xlfn.XLOOKUP(MID($B11,2,1), 聲調對照表[十五音調號], 聲調對照表[傳統八聲調], "N/A")) -> 1
A12: 軾 | B12: 經四時 | C12: sik4 | D12: =IF($B12="", "", _xlfn.XLOOKUP(RIGHT($B12), 聲母對照表[十五音], 聲母對照表[台語音標], "N/A")) -> s | E12: =IF($B12="", "", _xlfn.XLOOKUP(LEFT($B12), 韻母對照表[十五音], 韻母對照表[台語音標], "N/A")) -> ik | F12: =IF($B12="", "", _xlfn.XLOOKUP(MID($B12,2,1), 聲調對照表[十五音調號], 聲調對照表[傳統八聲調], "N/A")) -> 4
A13: 壬 | B13: 金五入 | C13: jim5 | D13: =IF($B13="", "", _xlfn.XLOOKUP(RIGHT($B13), 聲母對照表[十五音], 聲母對照表[台語音標], "N/A")) -> j | E13: =IF($B13="", "", _xlfn.XLOOKUP(LEFT($B13), 韻母對照表[十五音], 韻母對照表[台語音標], "N/A")) -> im | F13: =IF($B13="", "", _xlfn.XLOOKUP(MID($B13,2,1), 聲調對照表[十五音調號], 聲調對照表[傳統八聲調], "N/A")) -> 5
A14: 戌 | B14: 君四時 | C14: sut4 | D14: =IF($B14="", "", _xlfn.XLOOKUP(RIGHT($B14), 聲母對照表[十五音], 聲母對照表[台語音標], "N/A")) -> s | E14: =IF($B14="", "", _xlfn.XLOOKUP(LEFT($B14), 韻母對照表[十五音], 韻母對照表[台語音標], "N/A")) -> un | F14: =IF($B14="", "", _xlfn.XLOOKUP(MID($B14,2,1), 聲調對照表[十五音調號], 聲調對照表[傳統八聲調], "N/A")) -> 4
A15: 之 | B15: 居一曾 | C15: zi1 | D15: =IF($B15="", "", _xlfn.XLOOKUP(RIGHT($B15), 聲母對照表[十五音], 聲母對照表[台語音標], "N/A")) -> z | E15: =IF($B15="", "", _xlfn.XLOOKUP(LEFT($B15), 韻母對照表[十五音], 韻母對照表[台語音標], "N/A")) -> i | F15: =IF($B15="", "", _xlfn.XLOOKUP(MID($B15,2,1), 聲調對照表[十五音調號], 聲調對照表[傳統八聲調], "N/A")) -> 1
A16: 秋 | B16: 丩一出 | C16: ciu1 | D16: =IF($B16="", "", _xlfn.XLOOKUP(RIGHT($B16), 聲母對照表[十五音], 聲母對照表[台語音標], "N/A")) -> c | E16: =IF($B16="", "", _xlfn.XLOOKUP(LEFT($B16), 韻母對照表[十五音], 韻母對照表[台語音標], "N/A")) -> iu | F16: =IF($B16="", "", _xlfn.XLOOKUP(MID($B16,2,1), 聲調對照表[十五音調號], 聲調對照表[傳統八聲調], "N/A")) -> 1
A17: ， | D17: =IF($B17="", "", _xlfn.XLOOKUP(RIGHT($B17), 聲母對照表[十五音], 聲母對照表[台語音標], "N/A")) | E17: =IF($B17="", "", _xlfn.XLOOKUP(LEFT($B17), 韻母對照表[十五音], 韻母對照表[台語音標], "N/A")) | F17: =IF($B17="", "", _xlfn.XLOOKUP(MID($B17,2,1), 聲調對照表[十五音調號], 聲調對照表[傳統八聲調], "N/A"))
A18: 七 | B18: 巾四出 | C18: cit4 | D18: =IF($B18="", "", _xlfn.XLOOKUP(RIGHT($B18), 聲母對照表[十五音], 聲母對照表[台語音標], "N/A")) -> c | E18: =IF($B18="", "", _xlfn.XLOOKUP(LEFT($B18), 韻母對照表[十五音], 韻母對照表[台語音標], "N/A")) -> in | F18: =IF($B18="", "", _xlfn.XLOOKUP(MID($B18,2,1), 聲調對照表[十五音調號], 聲調對照表[傳統八聲調], "N/A")) -> 4
A19: 月 | B19: 觀八語 | C19: guat8 | D19: =IF($B19="", "", _xlfn.XLOOKUP(RIGHT($B19), 聲母對照表[十五音], 聲母對照表[台語音標], "N/A")) -> g | E19: =IF($B19="", "", _xlfn.XLOOKUP(LEFT($B19), 韻母對照表[十五音], 韻母對照表[台語音標], "N/A")) -> uan | F19: =IF($B19="", "", _xlfn.XLOOKUP(MID($B19,2,1), 聲調對照表[十五音調號], 聲調對照表[傳統八聲調], "N/A")) -> 8
A20: 既 | B20: 居三求 | C20: ki3 | D20: =IF($B20="", "", _xlfn.XLOOKUP(RIGHT($B20), 聲母對照表[十五音], 聲母對照表[台語音標], "N/A")) -> k | E20: =IF($B20="", "", _xlfn.XLOOKUP(LEFT($B20), 韻母對照表[十五音], 韻母對照表[台語音標], "N/A")) -> i | F20: =IF($B20="", "", _xlfn.XLOOKUP(MID($B20,2,1), 聲調對照表[十五音調號], 聲調對照表[傳統八聲調], "N/A")) -> 3
A21: 望 | B21: 公七門 | C21: bong7 | D21: =IF($B21="", "", _xlfn.XLOOKUP(RIGHT($B21), 聲母對照表[十五音], 聲母對照表[台語音標], "N/A")) -> b | E21: =IF($B21="", "", _xlfn.XLOOKUP(LEFT($B21), 韻母對照表[十五音], 韻母對照表[台語音標], "N/A")) -> ok | F21: =IF($B21="", "", _xlfn.XLOOKUP(MID($B21,2,1), 聲調對照表[十五音調號], 聲調對照表[傳統八聲調], "N/A")) -> 7
A22: ， | D22: =IF($B22="", "", _xlfn.XLOOKUP(RIGHT($B22), 聲母對照表[十五音], 聲母對照表[台語音標], "N/A")) | E22: =IF($B22="", "", _xlfn.XLOOKUP(LEFT($B22), 韻母對照表[十五音], 韻母對照表[台語音標], "N/A")) | F22: =IF($B22="", "", _xlfn.XLOOKUP(MID($B22,2,1), 聲調對照表[十五音調號], 聲調對照表[傳統八聲調], "N/A"))
A23: 蘇 | B23: 沽一時 | C23: soo1 | D23: =IF($B23="", "", _xlfn.XLOOKUP(RIGHT($B23), 聲母對照表[十五音], 聲母對照表[台語音標], "N/A")) -> s | E23: =IF($B23="", "", _xlfn.XLOOKUP(LEFT($B23), 韻母對照表[十五音], 韻母對照表[台語音標], "N/A")) -> oo | F23: =IF($B23="", "", _xlfn.XLOOKUP(MID($B23,2,1), 聲調對照表[十五音調號], 聲調對照表[傳統八聲調], "N/A")) -> 1
A24: 子 | B24: 艍二曾 | C24: zu2 | D24: =IF($B24="", "", _xlfn.XLOOKUP(RIGHT($B24), 聲母對照表[十五音], 聲母對照表[台語音標], "N/A")) -> z | E24: =IF($B24="", "", _xlfn.XLOOKUP(LEFT($B24), 韻母對照表[十五音], 韻母對照表[台語音標], "N/A")) -> u | F24: =IF($B24="", "", _xlfn.XLOOKUP(MID($B24,2,1), 聲調對照表[十五音調號], 聲調對照表[傳統八聲調], "N/A")) -> 2
A25: 與 | B25: 艍二英 | C25: u2 | D25: =IF($B25="", "", _xlfn.XLOOKUP(RIGHT($B25), 聲母對照表[十五音], 聲母對照表[台語音標], "N/A")) -> Ø | E25: =IF($B25="", "", _xlfn.XLOOKUP(LEFT($B25), 韻母對照表[十五音], 韻母對照表[台語音標], "N/A")) -> u | F25: =IF($B25="", "", _xlfn.XLOOKUP(MID($B25,2,1), 聲調對照表[十五音調號], 聲調對照表[傳統八聲調], "N/A")) -> 2
A26: 客 | B26: 經四去 | C26: khik4 | D26: =IF($B26="", "", _xlfn.XLOOKUP(RIGHT($B26), 聲母對照表[十五音], 聲母對照表[台語音標], "N/A")) -> kh | E26: =IF($B26="", "", _xlfn.XLOOKUP(LEFT($B26), 韻母對照表[十五音], 韻母對照表[台語音標], "N/A")) -> ik | F26: =IF($B26="", "", _xlfn.XLOOKUP(MID($B26,2,1), 聲調對照表[十五音調號], 聲調對照表[傳統八聲調], "N/A")) -> 4
A27: 泛 | B27: 觀三喜 | C27: huan3 | D27: =IF($B27="", "", _xlfn.XLOOKUP(RIGHT($B27), 聲母對照表[十五音], 聲母對照表[台語音標], "N/A")) -> h | E27: =IF($B27="", "", _xlfn.XLOOKUP(LEFT($B27), 韻母對照表[十五音], 韻母對照表[台語音標], "N/A")) -> uan | F27: =IF($B27="", "", _xlfn.XLOOKUP(MID($B27,2,1), 聲調對照表[十五音調號], 聲調對照表[傳統八聲調], "N/A")) -> 3
A28: 舟 | B28: 丩一曾 | C28: ziu1 | D28: =IF($B28="", "", _xlfn.XLOOKUP(RIGHT($B28), 聲母對照表[十五音], 聲母對照表[台語音標], "N/A")) -> z | E28: =IF($B28="", "", _xlfn.XLOOKUP(LEFT($B28), 韻母對照表[十五音], 韻母對照表[台語音標], "N/A")) -> iu | F28: =IF($B28="", "", _xlfn.XLOOKUP(MID($B28,2,1), 聲調對照表[十五音調號], 聲調對照表[傳統八聲調], "N/A")) -> 1
A29: 遊 | B29: 丩五英 | C29: iu5 | D29: =IF($B29="", "", _xlfn.XLOOKUP(RIGHT($B29), 聲母對照表[十五音], 聲母對照表[台語音標], "N/A")) -> Ø | E29: =IF($B29="", "", _xlfn.XLOOKUP(LEFT($B29), 韻母對照表[十五音], 韻母對照表[台語音標], "N/A")) -> iu | F29: =IF($B29="", "", _xlfn.XLOOKUP(MID($B29,2,1), 聲調對照表[十五音調號], 聲調對照表[傳統八聲調], "N/A")) -> 5
A30: 於 | B30: 艍一英 | C30: u1 | D30: =IF($B30="", "", _xlfn.XLOOKUP(RIGHT($B30), 聲母對照表[十五音], 聲母對照表[台語音標], "N/A")) -> Ø | E30: =IF($B30="", "", _xlfn.XLOOKUP(LEFT($B30), 韻母對照表[十五音], 韻母對照表[台語音標], "N/A")) -> u | F30: =IF($B30="", "", _xlfn.XLOOKUP(MID($B30,2,1), 聲調對照表[十五音調號], 聲調對照表[傳統八聲調], "N/A")) -> 1
A31: 赤 | B31: 經四出 | C31: cik4 | D31: =IF($B31="", "", _xlfn.XLOOKUP(RIGHT($B31), 聲母對照表[十五音], 聲母對照表[台語音標], "N/A")) -> c | E31: =IF($B31="", "", _xlfn.XLOOKUP(LEFT($B31), 韻母對照表[十五音], 韻母對照表[台語音標], "N/A")) -> ik | F31: =IF($B31="", "", _xlfn.XLOOKUP(MID($B31,2,1), 聲調對照表[十五音調號], 聲調對照表[傳統八聲調], "N/A")) -> 4
A32: 壁 | B32: 經四邊 | C32: pik4 | D32: =IF($B32="", "", _xlfn.XLOOKUP(RIGHT($B32), 聲母對照表[十五音], 聲母對照表[台語音標], "N/A")) -> p | E32: =IF($B32="", "", _xlfn.XLOOKUP(LEFT($B32), 韻母對照表[十五音], 韻母對照表[台語音標], "N/A")) -> ik | F32: =IF($B32="", "", _xlfn.XLOOKUP(MID($B32,2,1), 聲調對照表[十五音調號], 聲調對照表[傳統八聲調], "N/A")) -> 4
A33: 之 | B33: 居一曾 | C33: zi1 | D33: =IF($B33="", "", _xlfn.XLOOKUP(RIGHT($B33), 聲母對照表[十五音], 聲母對照表[台語音標], "N/A")) -> z | E33: =IF($B33="", "", _xlfn.XLOOKUP(LEFT($B33), 韻母對照表[十五音], 韻母對照表[台語音標], "N/A")) -> i | F33: =IF($B33="", "", _xlfn.XLOOKUP(MID($B33,2,1), 聲調對照表[十五音調號], 聲調對照表[傳統八聲調], "N/A")) -> 1
A34: 下 | B34: 膠二喜 | C34: ha2 | D34: =IF($B34="", "", _xlfn.XLOOKUP(RIGHT($B34), 聲母對照表[十五音], 聲母對照表[台語音標], "N/A")) -> h | E34: =IF($B34="", "", _xlfn.XLOOKUP(LEFT($B34), 韻母對照表[十五音], 韻母對照表[台語音標], "N/A")) -> a | F34: =IF($B34="", "", _xlfn.XLOOKUP(MID($B34,2,1), 聲調對照表[十五音調號], 聲調對照表[傳統八聲調], "N/A")) -> 2
A35: 。 | D35: =IF($B35="", "", _xlfn.XLOOKUP(RIGHT($B35), 聲母對照表[十五音], 聲母對照表[台語音標], "N/A")) | E35: =IF($B35="", "", _xlfn.XLOOKUP(LEFT($B35), 韻母對照表[十五音], 韻母對照表[台語音標], "N/A")) | F35: =IF($B35="", "", _xlfn.XLOOKUP(MID($B35,2,1), 聲調對照表[十五音調號], 聲調對照表[傳統八聲調], "N/A"))
A36: 清 | B36: 經一出 | C36: cing1 | D36: =IF($B36="", "", _xlfn.XLOOKUP(RIGHT($B36), 聲母對照表[十五音], 聲母對照表[台語音標], "N/A")) -> c | E36: =IF($B36="", "", _xlfn.XLOOKUP(LEFT($B36), 韻母對照表[十五音], 韻母對照表[台語音標], "N/A")) -> ik | F36: =IF($B36="", "", _xlfn.XLOOKUP(MID($B36,2,1), 聲調對照表[十五音調號], 聲調對照表[傳統八聲調], "N/A")) -> 1
A37: 風 | B37: 公一喜 | C37: hong1 | D37: =IF($B37="", "", _xlfn.XLOOKUP(RIGHT($B37), 聲母對照表[十五音], 聲母對照表[台語音標], "N/A")) -> h | E37: =IF($B37="", "", _xlfn.XLOOKUP(LEFT($B37), 韻母對照表[十五音], 韻母對照表[台語音標], "N/A")) -> ok | F37: =IF($B37="", "", _xlfn.XLOOKUP(MID($B37,2,1), 聲調對照表[十五音調號], 聲調對照表[傳統八聲調], "N/A")) -> 1
A38: 徐 | B38: 艍五時 | C38: su5 | D38: =IF($B38="", "", _xlfn.XLOOKUP(RIGHT($B38), 聲母對照表[十五音], 聲母對照表[台語音標], "N/A")) -> s | E38: =IF($B38="", "", _xlfn.XLOOKUP(LEFT($B38), 韻母對照表[十五音], 韻母對照表[台語音標], "N/A")) -> u | F38: =IF($B38="", "", _xlfn.XLOOKUP(MID($B38,2,1), 聲調對照表[十五音調號], 聲調對照表[傳統八聲調], "N/A")) -> 5
A39: 來 | B39: 皆五柳 | C39: lai5 | D39: =IF($B39="", "", _xlfn.XLOOKUP(RIGHT($B39), 聲母對照表[十五音], 聲母對照表[台語音標], "N/A")) -> l | E39: =IF($B39="", "", _xlfn.XLOOKUP(LEFT($B39), 韻母對照表[十五音], 韻母對照表[台語音標], "N/A")) -> ai | F39: =IF($B39="", "", _xlfn.XLOOKUP(MID($B39,2,1), 聲調對照表[十五音調號], 聲調對照表[傳統八聲調], "N/A")) -> 5
A40: ， | D40: =IF($B40="", "", _xlfn.XLOOKUP(RIGHT($B40), 聲母對照表[十五音], 聲母對照表[台語音標], "N/A")) | E40: =IF($B40="", "", _xlfn.XLOOKUP(LEFT($B40), 韻母對照表[十五音], 韻母對照表[台語音標], "N/A")) | F40: =IF($B40="", "", _xlfn.XLOOKUP(MID($B40,2,1), 聲調對照表[十五音調號], 聲調對照表[傳統八聲調], "N/A"))
...

Sheet 網頁匯入(v0.0.3)
A1: 漢字 | B1: 漢字標音 | C1: 台語音標 | D1: 台語音標之聲 | E1: 台語音標之韻 | F1: 台語音標之調
A2: 《
A3: 前 | B3: 堅五曾 | C3: zian5 | D3: 曾 | E3: 堅 | F3: 5
A4: 赤 | B4: 經四出 | C4: cik4 | D4: 出 | E4: 經 | F4: 4
A5: 壁 | B5: 經四邊 | C5: pik4 | D5: 邊 | E5: 經 | F5: 4
A6: 賦 | B6: 艍三喜 | C6: hu3 | D6: 喜 | E6: 艍 | F6: 3
A7: 》
A8: 北 | B8: 公四邊 | C8: pok4 | D8: 邊 | E8: 公 | F8: 4
A9: 宋 | B9: 公三時 | C9: song3 | D9: 時 | E9: 公 | F9: 3
A10: ：
A11: 蘇 | B11: 沽一時 | C11: soo1 | D11: 時 | E11: 沽 | F11: 1
A12: 軾 | B12: 經四時 | C12: sik4 | D12: 時 | E12: 經 | F12: 4
A13: 壬 | B13: 金五入 | C13: jim5 | D13: 入 | E13: 金 | F13: 5
A14: 戌 | B14: 君四時 | C14: sut4 | D14: 時 | E14: 君 | F14: 4
A15: 之 | B15: 居一曾 | C15: zi1 | D15: 曾 | E15: 居 | F15: 1
A16: 秋 | B16: 丩一出 | C16: ciu1 | D16: 出 | E16: 丩 | F16: 1
A17: ，
A18: 七 | B18: 巾四出 | C18: cit4 | D18: 出 | E18: 巾 | F18: 4
A19: 月 | B19: 觀八語 | C19: guat8 | D19: 語 | E19: 觀 | F19: 8
A20: 既 | B20: 居三求 | C20: ki3 | D20: 求 | E20: 居 | F20: 3
A21: 望 | B21: 公七門 | C21: bong7 | D21: 門 | E21: 恭 | F21: 7
A22: ，
A23: 蘇 | B23: 沽一時 | C23: soo1 | D23: 時 | E23: 沽 | F23: 1
A24: 子 | B24: 艍二曾 | C24: zu2 | D24: 曾 | E24: 艍 | F24: 2
A25: 與 | B25: 艍二英 | C25: u2 | D25: 英 | E25: 艍 | F25: 2
A26: 客 | B26: 經四去 | C26: khik4 | D26: 去 | E26: 經 | F26: 4
A27: 泛 | B27: 觀三喜 | C27: huan3 | D27: 喜 | E27: 觀 | F27: 3
A28: 舟 | B28: 丩一曾 | C28: ziu1 | D28: 曾 | E28: 丩 | F28: 1
A29: 遊 | B29: 丩五英 | C29: iu5 | D29: 英 | E29: 丩 | F29: 5
A30: 於 | B30: 艍一英 | C30: u1 | D30: 英 | E30: 艍 | F30: 1
A31: 赤 | B31: 經四出 | C31: cik4 | D31: 出 | E31: 經 | F31: 4
A32: 壁 | B32: 經四邊 | C32: pik4 | D32: 邊 | E32: 經 | F32: 4
A33: 之 | B33: 居一曾 | C33: zi1 | D33: 曾 | E33: 居 | F33: 1
A34: 下 | B34: 膠二喜 | C34: ha2 | D34: 喜 | E34: 膠 | F34: 2
A35: 。
A36: 清 | B36: 經一出 | C36: cing1 | D36: 出 | E36: 經 | F36: 1
A37: 風 | B37: 公一喜 | C37: hong1 | D37: 喜 | E37: 恭 | F37: 1
A38: 徐 | B38: 艍五時 | C38: su5 | D38: 時 | E38: 艍 | F38: 5
A39: 來 | B39: 皆五柳 | C39: lai5 | D39: 柳 | E39: 皆 | F39: 5
A40: ，
...

Sheet 十五音轉台語音標字典
B2: "邊" : "p", | D2: "君" : ["un", "ut"],
B3: "頗" : "ph", | D3: "堅" : ["ian", "iat"],
B4: "門" : "b", | D4: "金" : ["im", "ip"],
B5: "毛" : "m", | D5: "規" : ["ui", ""],
B6: "地" : "t", | D6: "嘉" : ["ee", "eeh"],
B7: "他" : "th", | D7: "干" : ["an", "at"],
B8: "耐" : "n", | D8: "公" : ["ong", "ok"],
B9: "柳" : "l", | D9: "乖" : ["uai", "uaih"],
B10: "曾" : "z", | D10: "經" : ["ing", "ik"],
B11: "出" : "c", | D11: "觀" : ["uan", "uat"],
B12: "時" : "s", | D12: "沽" : ["oo", ""],
B13: "入" : "j", | D13: "嬌" : ["iau", "iauh"],
... B20: "英" : "Ø", | D20: "甘" : ["am", "ap"],
D21: "瓜" : ["ua", "uah"],
D22: "江" : ["ang", "ak"],
D23: "兼" : ["iam", "iap"],
D24: "交" : ["au", "auh"],
D25: "迦" : ["ia", "iah"],
D26: "檜" : ["ue", "ueh"],
D27: "監" : ["ann", "ahnn"],
D28: "艍" : ["u", "uh"],
D29: "膠" : ["a", "ah"],
D30: "居" : ["i", "ih"],
D31: "丩" : ["iu", ""],
D32: "更" : ["enn", "ehnn"],
... D51: "牛" : ["iunn", ""],

Sheet 聲母對照表
B2: 漢字範例 | C2: 十五音 | D2: 國際音標 | E2: 台語音標 | F2: 注音二式 | G2: 注音符號
B3: 邊 | C3: 邊 | D3: p | E3: p | F3: b | G3: ㄅ
B4: 頗 | C4: 頗 | D4: pʰ | E4: ph | F4: p | G4: ㄆ
B5: 門 | C5: 門 | D5: b | E5: b | F5: bb | G5: ㆠ
B6: 毛 | C6: 毛 | D6: m | E6: m | F6: m | G6: ㄇ
B7: 地 | C7: 地 | D7: t | E7: t | F7: d | G7: ㄉ
B8: 他 | C8: 他 | D8: tʰ | E8: th | F8: t | G8: ㄊ
B9: 耐 | C9: 耐 | D9: n | E9: n | F9: n | G9: ㄋ
B10: 柳 | C10: 柳 | D10: l | E10: l | F10: l | G10: ㄌ
B11: 曾 | C11: 曾 | D11: ʦ | E11: z | F11: z | G11: ㄗ
B12: 出 | C12: 出 | D12: ʦʰ | E12: c | F12: c | G12: ㄘ
B13: 時 | C13: 時 | D13: s | E13: s | F13: s | G13: ㄙ
... B20: 喜 | C20: 喜 | D20: h | E20: h | F20: h | G20: ㄏ
B21: 英 | C21: 英 | D21: ʔ | E21: Ø | F21: Ø | G21: 0

Sheet 韻母對照表
B2: 識別號 | C2: 漢字例 | D2: 國際音標 | E2: 十五音 | F2: 方音符號 | G2: 台語音標 | H2: 台羅拼音 | I2: 白話字 | J2: 閩拼方案 | K2: 注音二式 | L2: 舒促聲 | M2: 十五音識別碼 | N2: 十五音韻母序
B3: 55 | C3: 些 | D3: a | E3: 膠 | F3: ㄚ | G3: a | H3: a | I3: a | J3: a | K3: a | L3: 舒聲 | M3: 膠舒 | N3: 28
B4: 56 | C4: 百 | D4: a? | E4: 膠 | F4: ㄚㆷ | G4: ah | H4: ah | I4: ah | J4: ah | K4: ah | L4: 促聲 | M4: 膠促 | N4: 28
B5: 52 | C5: 含 | D5: ã? | E5: 監 | F5: ㆩㆷ | G5: ahnn | H5: annh | I5: aⁿh | J5: nah | K5: annh | L5: 促聲 | M5: 監促 | N5: 26
B6: 31 | C6: 埃 | D6: ai | E6: 皆 | F6: ㄞ | G6: ai | H6: ai | I6: ai | J6: ai | K6: ai | L6: 舒聲 | M6: 皆舒 | N6: 16
B7: 79 | C7: 挨 | D7: ãi | E7: 閒 | F7: ㆮ | G7: ainn | H7: ainn | I7: aiⁿ | J7: nai | K7: ainn | L7: 舒聲 | M7: 閒舒 | N7: 40
B8: 42 | C8: 角 | D8: ak̚ | E8: 江 | F8: ㄚㆻ | G8: ak | H8: ak | I8: ak | J8: ak | K8: ak | L8: 促聲 | M8: 江促 | N8: 21
B9: 37 | C9: 堪 | D9: am | E9: 甘 | F9: ㆰ | G9: am | H9: am | I9: am | J9: am | K9: am | L9: 舒聲 | M9: 甘舒 | N9: 19
B10: 11 | C10: 蘭 | D10: an | E10: 干 | F10: ㄢ | G10: an | H10: an | I10: an | J10: an | K10: an | L10: 舒聲 | M10: 干舒 | N10: 6
B11: 41 | C11: 邦 | D11: aŋ | E11: 江 | F11: ㄤ | G11: ang | H11: ang | I11: ang | J11: ang | K11: ang | L11: 舒聲 | M11: 江舒 | N11: 21
B12: 51 | C12: 聽 | D12: ã | E12: 監 | F12: ㆩ | G12: ann | H12: ann | I12: aⁿ | J12: na | K12: ann | L12: 舒聲 | M12: 監舒 | N12: 26
B13: 38 | C13: 答 | D13: ap̚ | E13: 甘 | F13: ㄚㆴ | G13: ap | H13: ap | I13: ap | J13: ap | K13: ap | L13: 促聲 | M13: 甘促 | N13: 19
... B86: 2 | C86: 不 | D86: ut̚ | E86: 君 | F86: ㄨㆵ | G86: ut | H86: ut | I86: ut | J86: ut | K86: ut | L86: 促聲 | M86: 君促 | N86: 1

Sheet 十五音韻母對照表
B1: {=COLUMN() - COLUMN($A:$A)} -> 1 | C1: {=COLUMN() - COLUMN($A:$A)} -> 2 | D1: {=COLUMN() - COLUMN($A:$A)} -> 3 | E1: {=COLUMN() - COLUMN($A:$A)} -> 4 | F1: {=COLUMN() - COLUMN($A:$A)} -> 5 | G1: {=COLUMN() - COLUMN($A:$A)} -> 6 | H1: {=COLUMN() - COLUMN($A:$A)} -> 7 | I1: {=COLUMN() - COLUMN($A:$A)} -> 8 | ... O1: {=COLUMN() - COLUMN($A:$A)} -> 14
B3: 識別號 | C3: 漢字例 | D3: 國際音標 | E3: 十五音 | F3: 方音符號 | G3: 台語音標 | H3: 台羅拼音 | I3: 白話字 | J3: 閩拼方案 | K3: 注音二式 | L3: 舒促聲 | M3: 十五音識別碼 | N3: 十五音韻母序 | O3: 字長 | Q3: {=_xlfn._xlws.FILTER(B2:N103, G2:G103<>"") & ""} -> 識別號 | R3: 漢字例 | S3: 國際音標 | T3: 十五音 | U3: 方音符號 | V3: 台語音標 | W3: 台羅拼音 | X3: 白話字 | Y3: 閩拼方案 | Z3: 注音二式 | AA3: 舒促聲 | AB3: 十五音識別碼 | AC3: 十五音韻母序 | AF3: python_dict | AH3: {=_xlfn._xlws.FILTER(AF4:AF103, AF4:AF103<>"")} -> "君" : ["un", "ut"],
B4: 1 | C4: 汾 | D4: un | E4: 君 | F4: ㄨㄣ | G4: un | H4: un | I4: un | J4: un | K4: un | L4: 舒聲 （平/上/去） | M4: =十五音韻母對照表!$E4&LEFT(十五音韻母對照表!$L4,1) -> 君舒 | N4: 1 | O4: =IF(十五音韻母對照表!$G4="", 0, LEN(十五音韻母對照表!$G4)) -> 2 | Q4: 1 | R4: 汾 | S4: un | T4: 君 | U4: ㄨㄣ | V4: un | W4: un | X4: un | Y4: un | Z4: un | AA4: 舒聲 （平/上/去） | AB4: 君舒 | AC4: 1 | AF4: =IF(AND(MOD(B4,2)<>1, G4<>""), "", _xlfn.CONCAT("""", 十五音韻母對照表!$E4, """", " : [", """", 十五音韻母對照表!$G4, """", ", """, G5, """", "],")) -> "君" : ["un", "ut"], | AH4: "堅" : ["ian", "iat"],
B5: 2 | C5: 不 | D5: ut̚ | E5: 君 | F5: ㄨㆵ | G5: ut | H5: ut | I5: ut | J5: ut | K5: ut | L5: 促聲 （入） | M5: =十五音韻母對照表!$E5&LEFT(十五音韻母對照表!$L5,1) -> 君促 | N5: 1 | O5: =IF(十五音韻母對照表!$G5="", 0, LEN(十五音韻母對照表!$G5)) -> 2 | Q5: 2 | R5: 不 | S5: ut̚ | T5: 君 | U5: ㄨㆵ | V5: ut | W5: ut | X5: ut | Y5: ut | Z5: ut | AA5: 促聲 （入） | AB5: 君促 | AC5: 1 | AF5: =IF(AND(MOD(B5,2)<>1, G5<>""), "", _xlfn.CONCAT("""", 十五音韻母對照表!$E5, """", " : [", """", 十五音韻母對照表!$G5, """", ", """, G6, """", "],")) | AH5: "金" : ["im", "ip"],
B6: 3 | C6: 掀 | D6: ian | E6: 堅 | F6: ㄧㄢ | G6: ian | H6: ian | I6: ian | J6: ian | K6: ian | L6: 舒聲 （平/上/去） | M6: =十五音韻母對照表!$E6&LEFT(十五音韻母對照表!$L6,1) -> 堅舒 | N6: 2 | O6: =IF(十五音韻母對照表!$G6="", 0, LEN(十五音韻母對照表!$G6)) -> 3 | Q6: 3 | R6: 掀 | S6: ian | T6: 堅 | U6: ㄧㄢ | V6: ian | W6: ian | X6: ian | Y6: ian | Z6: ian | AA6: 舒聲 （平/上/去） | AB6: 堅舒 | AC6: 2 | AF6: =IF(AND(MOD(B6,2)<>1, G6<>""), "", _xlfn.CONCAT("""", 十五音韻母對照表!$E6, """", " : [", """", 十五音韻母對照表!$G6, """", ", """, G7, """", "],")) -> "堅" : ["ian", "iat"], | AH6: "規" : ["ui", ""],
B7: 4 | C7: 別 | D7: iat̚ | E7: 堅 | F7: ㄧㄚㆵ | G7: iat | H7: iat | I7: iat | J7: iat | K7: iat | L7: 促聲 （入） | M7: =十五音韻母對照表!$E7&LEFT(十五音韻母對照表!$L7,1) -> 堅促 | N7: 2 | O7: =IF(十五音韻母對照表!$G7="", 0, LEN(十五音韻母對照表!$G7)) -> 3 | Q7: 4 | R7: 別 | S7: iat̚ | T7: 堅 | U7: ㄧㄚㆵ | V7: iat | W7: iat | X7: iat | Y7: iat | Z7: iat | AA7: 促聲 （入） | AB7: 堅促 | AC7: 2 | AF7: =IF(AND(MOD(B7,2)<>1, G7<>""), "", _xlfn.CONCAT("""", 十五音韻母對照表!$E7, """", " : [", """", 十五音韻母對照表!$G7, """", ", """, G8, """", "],")) | AH7: "嘉" : ["ee", "eeh"],
B8: 5 | C8: 深 | D8: im | E8: 金 | F8: ㄧㆬ | G8: im | H8: im | I8: im | J8: im | K8: im | L8: 舒聲 （平/上/去） | M8: =十五音韻母對照表!$E8&LEFT(十五音韻母對照表!$L8,1) -> 金舒 | N8: 3 | O8: =IF(十五音韻母對照表!$G8="", 0, LEN(十五音韻母對照表!$G8)) -> 2 | Q8: 5 | R8: 深 | S8: im | T8: 金 | U8: ㄧㆬ | V8: im | W8: im | X8: im | Y8: im | Z8: im | AA8: 舒聲 （平/上/去） | AB8: 金舒 | AC8: 3 | AF8: =IF(AND(MOD(B8,2)<>1, G8<>""), "", _xlfn.CONCAT("""", 十五音韻母對照表!$E8, """", " : [", """", 十五音韻母對照表!$G8, """", ", """, G9, """", "],")) -> "金" : ["im", "ip"], | AH8: "干" : ["an", "at"],
B9: 6 | C9: 蟄 | D9: ip̚ | E9: 金 | F9: 一ㆴ | G9: ip | H9: ip | I9: ip | J9: ip | K9: ip | L9: 促聲 （入） | M9: =十五音韻母對照表!$E9&LEFT(十五音韻母對照表!$L9,1) -> 金促 | N9: 3 | O9: =IF(十五音韻母對照表!$G9="", 0, LEN(十五音韻母對照表!$G9)) -> 2 | Q9: 6 | R9: 蟄 | S9: ip̚ | T9: 金 | U9: 一ㆴ | V9: ip | W9: ip | X9: ip | Y9: ip | Z9: ip | AA9: 促聲 （入） | AB9: 金促 | AC9: 3 | AF9: =IF(AND(MOD(B9,2)<>1, G9<>""), "", _xlfn.CONCAT("""", 十五音韻母對照表!$E9, """", " : [", """", 十五音韻母對照表!$G9, """", ", """, G10, """", "],")) | AH9: "公" : ["ong", "ok"],
B10: 7 | C10: 歸 | D10: ui | E10: 規 | F10: ㄨㄧ | G10: ui | H10: ui | I10: ui | J10: ui | K10: ui | L10: 舒聲 （平/上/去） | M10: =十五音韻母對照表!$E10&LEFT(十五音韻母對照表!$L10,1) -> 規舒 | N10: 4 | O10: =IF(十五音韻母對照表!$G10="", 0, LEN(十五音韻母對照表!$G10)) -> 2 | Q10: 7 | R10: 歸 | S10: ui | T10: 規 | U10: ㄨㄧ | V10: ui | W10: ui | X10: ui | Y10: ui | Z10: ui | AA10: 舒聲 （平/上/去） | AB10: 規舒 | AC10: 4 | AF10: =IF(AND(MOD(B10,2)<>1, G10<>""), "", _xlfn.CONCAT("""", 十五音韻母對照表!$E10, """", " : [", """", 十五音韻母對照表!$G10, """", ", """, G11, """", "],")) -> "規" : ["ui", ""], | AH10: "乖" : ["uai", "uaih"],
B11: 8 | O11: =IF(十五音韻母對照表!$G11="", 0, LEN(十五音韻母對照表!$G11)) -> 0 | Q11: 9 | R11: 家 | S11: ɛ | T11: 嘉 | U11: ㄝ | V11: ee | W11: ee | X11: e | Y11: ee | Z11: e | AA11: 舒聲 （平/上/去） | AB11: 嘉舒 | AC11: 5 | AH11: "經" : ["ing", "ik"],
B12: 9 | C12: 家 | D12: ɛ | E12: 嘉 | F12: ㄝ | G12: ee | H12: ee | I12: e | J12: ee | K12: e | L12: 舒聲 （平/上/去） | M12: =十五音韻母對照表!$E12&LEFT(十五音韻母對照表!$L12,1) -> 嘉舒 | N12: 5 | O12: =IF(十五音韻母對照表!$G12="", 0, LEN(十五音韻母對照表!$G12)) -> 2 | Q12: 10 | R12: 八 | S12: ɛ? | T12: 嘉 | U12: ㄝㆷ | V12: eeh | W12: eeh | X12: eeh | Y12: 0 | Z12: eh | AA12: 促聲 （入） | AB12: 嘉促 | AC12: 5 | AF12: =IF(AND(MOD(B12,2)<>1, G12<>""), "", _xlfn.CONCAT("""", 十五音韻母對照表!$E12, """", " : [", """", 十五音韻母對照表!$G12, """", ", """, G13, """", "],")) -> "嘉" : ["ee", "eeh"], | AH12: "觀" : ["uan", "uat"],
B13: 10 | C13: 八 | D13: ɛ? | E13: 嘉 | F13: ㄝㆷ | G13: eeh | H13: eeh | I13: eeh | J13: 0 | K13: eh | L13: 促聲 （入） | M13: =十五音韻母對照表!$E13&LEFT(十五音韻母對照表!$L13,1) -> 嘉促 | N13: 5 | O13: =IF(十五音韻母對照表!$G13="", 0, LEN(十五音韻母對照表!$G13)) -> 3 | Q13: 11 | R13: 蘭 | S13: an | T13: 干 | U13: ㄢ | V13: an | W13: an | X13: an | Y13: an | Z13: an | AA13: 舒聲 （平/上/去） | AB13: 干舒 | AC13: 6 | AF13: =IF(AND(MOD(B13,2)<>1, G13<>""), "", _xlfn.CONCAT("""", 十五音韻母對照表!$E13, """", " : [", """", 十五音韻母對照表!$G13, """", ", """, G14, """", "],")) | AH13: "沽" : ["oo", ""],
B14: 11 | C14: 蘭 | D14: an | E14: 干 | F14: ㄢ | G14: an | H14: an | I14: an | J14: an | K14: an | L14: 舒聲 （平/上/去） | M14: =十五音韻母對照表!$E14&LEFT(十五音韻母對照表!$L14,1) -> 干舒 | N14: 6 | O14: =IF(十五音韻母對照表!$G14="", 0, LEN(十五音韻母對照表!$G14)) -> 2 | Q14: 12 | R14: 識 | S14: at̚ | T14: 干 | U14: ㄚㆵ | V14: at | W14: at | X14: at | Y14: at | Z14: at | AA14: 促聲 （入） | AB14: 干促 | AC14: 6 | AF14: =IF(AND(MOD(B14,2)<>1, G14<>""), "", _xlfn.CONCAT("""", 十五音韻母對照表!$E14, """", " : [", """", 十五音韻母對照表!$G14, """", ", """, G15, """", "],")) -> "干" : ["an", "at"], | AH14: "嬌" : ["iau", "iauh"],
B15: 12 | C15: 識 | D15: at̚ | E15: 干 | F15: ㄚㆵ | G15: at | H15: at | I15: at | J15: at | K15: at | L15: 促聲 （入） | M15: =十五音韻母對照表!$E15&LEFT(十五音韻母對照表!$L15,1) -> 干促 | N15: 6 | O15: =IF(十五音韻母對照表!$G15="", 0, LEN(十五音韻母對照表!$G15)) -> 2 | Q15: 13 | R15: 風 | S15: ɔŋ | T15: 公 | U15: ㆲ | V15: ong | W15: ong | X15: ong | Y15: ong | Z15: ong | AA15: 舒聲 （平/上/去） | AB15: 公舒 | AC15: 7 | AF15: =IF(AND(MOD(B15,2)<>1, G15<>""), "", _xlfn.CONCAT("""", 十五音韻母對照表!$E15, """", " : [", """", 十五音韻母對照表!$G15, """", ", """, G16, """", "],")) | AH15: "稽" : ["ei", ""],
B16: 13 | C16: 風 | D16: ɔŋ | E16: 公 | F16: ㆲ | G16: ong | H16: ong | I16: ong | J16: ong | K16: ong | L16: 舒聲 （平/上/去） | M16: =十五音韻母對照表!$E16&LEFT(十五音韻母對照表!$L16,1) -> 公舒 | N16: 7 | O16: =IF(十五音韻母對照表!$G16="", 0, LEN(十五音韻母對照表!$G16)) -> 3 | Q16: 14 | R16: 福 | S16: ɔk̚ | T16: 公 | U16: ㆦㆻ | V16: ok | W16: ok | X16: ok | Y16: ok | Z16: ok | AA16: 促聲 （入） | AB16: 公促 | AC16: 7 | AF16: =IF(AND(MOD(B16,2)<>1, G16<>""), "", _xlfn.CONCAT("""", 十五音韻母對照表!$E16, """", " : [", """", 十五音韻母對照表!$G16, """", ", """, G17, """", "],")) -> "公" : ["ong", "ok"], | AH16: "恭" : ["iong", "iok"],
B17: 14 | C17: 福 | D17: ɔk̚ | E17: 公 | F17: ㆦㆻ | G17: ok | H17: ok | I17: ok | J17: ok | K17: ok | L17: 促聲 （入） | M17: =十五音韻母對照表!$E17&LEFT(十五音韻母對照表!$L17,1) -> 公促 | N17: 7 | O17: =IF(十五音韻母對照表!$G17="", 0, LEN(十五音韻母對照表!$G17)) -> 2 | Q17: 15 | R17: 怪 | S17: uai | T17: 乖 | U17: ㄨㄞ | V17: uai | W17: uai | X17: oai | Y17: uai | Z17: uai | AA17: 舒聲 （平/上/去） | AB17: 乖舒 | AC17: 8 | AF17: =IF(AND(MOD(B17,2)<>1, G17<>""), "", _xlfn.CONCAT("""", 十五音韻母對照表!$E17, """", " : [", """", 十五音韻母對照表!$G17, """", ", """, G18, """", "],")) | AH17: "高" : ["o", "oh"],
B18: 15 | C18: 怪 | D18: uai | E18: 乖 | F18: ㄨㄞ | G18: uai | H18: uai | I18: oai | J18: uai | K18: uai | L18: 舒聲 （平/上/去） | M18: =十五音韻母對照表!$E18&LEFT(十五音韻母對照表!$L18,1) -> 乖舒 | N18: 8 | O18: =IF(十五音韻母對照表!$G18="", 0, LEN(十五音韻母對照表!$G18)) -> 3 | Q18: 16 | R18: ◯ | S18: uai? | T18: 乖 | U18: ㄨㄞㆷ | V18: uaih | W18: uaih | X18: oaih | Y18: uaih | Z18: uaih | AA18: 促聲 （入） | AB18: 乖促 | AC18: 8 | AF18: =IF(AND(MOD(B18,2)<>1, G18<>""), "", _xlfn.CONCAT("""", 十五音韻母對照表!$E18, """", " : [", """", 十五音韻母對照表!$G18, """", ", """, G19, """", "],")) -> "乖" : ["uai", "uaih"], | AH18: "皆" : ["ai", ""],
B19: 16 | C19: ◯ | D19: uai? | E19: 乖 | F19: ㄨㄞㆷ | G19: uaih | H19: uaih | I19: oaih | J19: uaih | K19: uaih | L19: 促聲 （入） | M19: =十五音韻母對照表!$E19&LEFT(十五音韻母對照表!$L19,1) -> 乖促 | N19: 8 | O19: =IF(十五音韻母對照表!$G19="", 0, LEN(十五音韻母對照表!$G19)) -> 4 | Q19: 17 | R19: 情 | S19: iŋ | T19: 經 | U19: ㄧㄥ | V19: ing | W19: ing | X19: eng | Y19: ing | Z19: ing | AA19: 舒聲 （平/上/去） | AB19: 經舒 | AC19: 9 | AF19: =IF(AND(MOD(B19,2)<>1, G19<>""), "", _xlfn.CONCAT("""", 十五音韻母對照表!$E19, """", " : [", """", 十五音韻母對照表!$G19, """", ", """, G20, """", "],")) | AH19: "巾" : ["in", "it"],
B20: 17 | C20: 情 | D20: iŋ | E20: 經 | F20: ㄧㄥ | G20: ing | H20: ing | I20: eng | J20: ing | K20: ing | L20: 舒聲 （平/上/去） | M20: =十五音韻母對照表!$E20&LEFT(十五音韻母對照表!$L20,1) -> 經舒 | N20: 9 | O20: =IF(十五音韻母對照表!$G20="", 0, LEN(十五音韻母對照表!$G20)) -> 3 | Q20: 18 | R20: 益 | S20: ik̚ | T20: 經 | U20: ㄧㆻ | V20: ik | W20: ik | X20: ek | Y20: ik | Z20: ik | AA20: 促聲 （入） | AB20: 經促 | AC20: 9 | AF20: =IF(AND(MOD(B20,2)<>1, G20<>""), "", _xlfn.CONCAT("""", 十五音韻母對照表!$E20, """", " : [", """", 十五音韻母對照表!$G20, """", ", """, G21, """", "],")) -> "經" : ["ing", "ik"], | AH20: "姜" : ["iang", "iak"],
B21: 18 | C21: 益 | D21: ik̚ | E21: 經 | F21: ㄧㆻ | G21: ik | H21: ik | I21: ek | J21: ik | K21: ik | L21: 促聲 （入） | M21: =十五音韻母對照表!$E21&LEFT(十五音韻母對照表!$L21,1) -> 經促 | N21: 9 | O21: =IF(十五音韻母對照表!$G21="", 0, LEN(十五音韻母對照表!$G21)) -> 2 | Q21: 19 | R21: 猿 | S21: uan | T21: 觀 | U21: ㄨㄢ | V21: uan | W21: uan | X21: oan | Y21: uan | Z21: uan | AA21: 舒聲 （平/上/去） | AB21: 觀舒 | AC21: 10 | AF21: =IF(AND(MOD(B21,2)<>1, G21<>""), "", _xlfn.CONCAT("""", 十五音韻母對照表!$E21, """", " : [", """", 十五音韻母對照表!$G21, """", ", """, G22, """", "],")) | AH21: "甘" : ["am", "ap"],
B22: 19 | C22: 猿 | D22: uan | E22: 觀 | F22: ㄨㄢ | G22: uan | H22: uan | I22: oan | J22: uan | K22: uan | L22: 舒聲 （平/上/去） | M22: =十五音韻母對照表!$E22&LEFT(十五音韻母對照表!$L22,1) -> 觀舒 | N22: 10 | O22: =IF(十五音韻母對照表!$G22="", 0, LEN(十五音韻母對照表!$G22)) -> 3 | Q22: 20 | R22: 說 | S22: uat̚ | T22: 觀 | U22: ㄨㄚㆵ | V22: uat | W22: uat | X22: oat | Y22: uat | Z22: uat | AA22: 促聲 （入） | AB22: 觀促 | AC22: 10 | AF22: =IF(AND(MOD(B22,2)<>1, G22<>""), "", _xlfn.CONCAT("""", 十五音韻母對照表!$E22, """", " : [", """", 十五音韻母對照表!$G22, """", ", """, G23, """", "],")) -> "觀" : ["uan", "uat"], | AH22: "瓜" : ["ua", "uah"],
B23: 20 | C23: 說 | D23: uat̚ | E23: 觀 | F23: ㄨㄚㆵ | G23: uat | H23: uat | I23: oat | J23: uat | K23: uat | L23: 促聲 （入） | M23: =十五音韻母對照表!$E23&LEFT(十五音韻母對照表!$L23,1) -> 觀促 | N23: 10 | O23: =IF(十五音韻母對照表!$G23="", 0, LEN(十五音韻母對照表!$G23)) -> 3 | Q23: 21 | R23: 捕 | S23: ou | T23: 沽 | U23: ㆦ | V23: oo | W23: oo | X23: o͘ | Y23: oo | Z23: oo | AA23: 舒聲 （平/上/去） | AB23: 沽舒 | AC23: 11 | AF23: =IF(AND(MOD(B23,2)<>1, G23<>""), "", _xlfn.CONCAT("""", 十五音韻母對照表!$E23, """", " : [", """", 十五音韻母對照表!$G23, """", ", """, G24, """", "],")) | AH23: "江" : ["ang", "ak"],
B24: 21 | C24: 捕 | D24: ou | E24: 沽 | F24: ㆦ | G24: oo | H24: oo | I24: o͘ | J24: oo | K24: oo | L24: 舒聲 （平/上/去） | M24: =十五音韻母對照表!$E24&LEFT(十五音韻母對照表!$L24,1) -> 沽舒 | N24: 11 | O24: =IF(十五音韻母對照表!$G24="", 0, LEN(十五音韻母對照表!$G24)) -> 2 | Q24: 23 | R24: 遙 | S24: iau | T24: 嬌 | U24: ㄧㄠ | V24: iau | W24: iau | X24: iau | Y24: iao | Z24: iau | AA24: 舒聲 （平/上/去） | AB24: 嬌舒 | AC24: 12 | AF24: =IF(AND(MOD(B24,2)<>1, G24<>""), "", _xlfn.CONCAT("""", 十五音韻母對照表!$E24, """", " : [", """", 十五音韻母對照表!$G24, """", ", """, G25, """", "],")) -> "沽" : ["oo", ""], | AH24: "兼" : ["iam", "iap"],
B25: 22 | O25: =IF(十五音韻母對照表!$G25="", 0, LEN(十五音韻母對照表!$G25)) -> 0 | Q25: 24 | R25: 噭 | S25: iau? | T25: 嬌 | U25: ㄧㄠㆷ | V25: iauh | W25: iauh | X25: iauh | Y25: iaoh | Z25: iauh | AA25: 促聲 （入） | AB25: 嬌促 | AC25: 12 | AH25: "交" : ["au", "auh"],
B26: 23 | C26: 遙 | D26: iau | E26: 嬌 | F26: ㄧㄠ | G26: iau | H26: iau | I26: iau | J26: iao | K26: iau | L26: 舒聲 （平/上/去） | M26: =十五音韻母對照表!$E26&LEFT(十五音韻母對照表!$L26,1) -> 嬌舒 | N26: 12 | O26: =IF(十五音韻母對照表!$G26="", 0, LEN(十五音韻母對照表!$G26)) -> 3 | Q26: 25 | R26: 遞 | S26: ei | T26: 稽 | U26: ㆤ | V26: ei | W26: e | X26: e | Y26: e | Z26: e | AA26: 舒聲 （平/上/去） | AB26: 稽舒 | AC26: 13 | AF26: =IF(AND(MOD(B26,2)<>1, G26<>""), "", _xlfn.CONCAT("""", 十五音韻母對照表!$E26, """", " : [", """", 十五音韻母對照表!$G26, """", ", """, G27, """", "],")) -> "嬌" : ["iau", "iauh"], | AH26: "迦" : ["ia", "iah"],
B27: 24 | C27: 噭 | D27: iau? | E27: 嬌 | F27: ㄧㄠㆷ | G27: iauh | H27: iauh | I27: iauh | J27: iaoh | K27: iauh | L27: 促聲 （入） | M27: =十五音韻母對照表!$E27&LEFT(十五音韻母對照表!$L27,1) -> 嬌促 | N27: 12 | O27: =IF(十五音韻母對照表!$G27="", 0, LEN(十五音韻母對照表!$G27)) -> 4 | Q27: 27 | R27: 中 | S27: iɔŋ | T27: 恭 | U27: ㄧㆲ | V27: iong | W27: iong | X27: iong | Y27: iong | Z27: iong | AA27: 舒聲 （平/上/去） | AB27: 恭舒 | AC27: 14 | AF27: =IF(AND(MOD(B27,2)<>1, G27<>""), "", _xlfn.CONCAT("""", 十五音韻母對照表!$E27, """", " : [", """", 十五音韻母對照表!$G27, """", ", """, G28, """", "],")) | AH27: "檜" : ["ue", "ueh"],
B28: 25 | C28: 遞 | D28: ei | E28: 稽 | F28: ㆤ | G28: ei | H28: e | I28: e | J28: e | K28: e | L28: 舒聲 （平/上/去） | M28: =十五音韻母對照表!$E28&LEFT(十五音韻母對照表!$L28,1) -> 稽舒 | N28: 13 | O28: =IF(十五音韻母對照表!$G28="", 0, LEN(十五音韻母對照表!$G28)) -> 2 | Q28: 28 | R28: 俗 | S28: iɔk̚ | T28: 恭 | U28: ㄧㆦㆻ | V28: iok | W28: iok | X28: iok | Y28: iok | Z28: iok | AA28: 促聲 （入） | AB28: 恭促 | AC28: 14 | AF28: =IF(AND(MOD(B28,2)<>1, G28<>""), "", _xlfn.CONCAT("""", 十五音韻母對照表!$E28, """", " : [", """", 十五音韻母對照表!$G28, """", ", """, G29, """", "],")) -> "稽" : ["ei", ""], | AH28: "監" : ["ann", "ahnn"],
B29: 26 | O29: =IF(十五音韻母對照表!$G29="", 0, LEN(十五音韻母對照表!$G29)) -> 0 | Q29: 29 | R29: 果 | S29: o | T29: 高 | U29: ㄜ | V29: o | W29: o | X29: o | Y29: o | Z29: or | AA29: 舒聲 （平/上/去） | AB29: 高舒 | AC29: 15 | AH29: "艍" : ["u", "uh"],
B30: 27 | C30: 中 | D30: iɔŋ | E30: 恭 | F30: ㄧㆲ | G30: iong | H30: iong | I30: iong | J30: iong | K30: iong | L30: 舒聲 （平/上/去） | M30: =十五音韻母對照表!$E30&LEFT(十五音韻母對照表!$L30,1) -> 恭舒 | N30: 14 | O30: =IF(十五音韻母對照表!$G30="", 0, LEN(十五音韻母對照表!$G30)) -> 4 | Q30: 30 | R30: 卜 | S30: o? | T30: 高 | U30: ㄜㆷ | V30: oh | W30: oh | X30: oh | Y30: oh | Z30: orh | AA30: 促聲 （入） | AB30: 高促 | AC30: 15 | AF30: =IF(AND(MOD(B30,2)<>1, G30<>""), "", _xlfn.CONCAT("""", 十五音韻母對照表!$E30, """", " : [", """", 十五音韻母對照表!$G30, """", ", """, G31, """", "],")) -> "恭" : ["iong", "iok"], | AH30: "膠" : ["a", "ah"],
B31: 28 | C31: 俗 | D31: iɔk̚ | E31: 恭 | F31: ㄧㆦㆻ | G31: iok | H31: iok | I31: iok | J31: iok | K31: iok | L31: 促聲 （入） | M31: =十五音韻母對照表!$E31&LEFT(十五音韻母對照表!$L31,1) -> 恭促 | N31: 14 | O31: =IF(十五音韻母對照表!$G31="", 0, LEN(十五音韻母對照表!$G31)) -> 3 | Q31: 31 | R31: 埃 | S31: ai | T31: 皆 | U31: ㄞ | V31: ai | W31: ai | X31: ai | Y31: ai | Z31: ai | AA31: 舒聲 （平/上/去） | AB31: 皆舒 | AC31: 16 | AF31: =IF(AND(MOD(B31,2)<>1, G31<>""), "", _xlfn.CONCAT("""", 十五音韻母對照表!$E31, """", " : [", """", 十五音韻母對照表!$G31, """", ", """, G32, """", "],")) | AH31: "居" : ["i", "ih"],
B32: 29 | C32: 果 | D32: o | E32: 高 | F32: ㄜ | G32: o | H32: o | I32: o | J32: o | K32: or | L32: 舒聲 （平/上/去） | M32: =十五音韻母對照表!$E32&LEFT(十五音韻母對照表!$L32,1) -> 高舒 | N32: 15 | O32: =IF(十五音韻母對照表!$G32="", 0, LEN(十五音韻母對照表!$G32)) -> 1 | Q32: 33 | R32: 恩 | S32: in | T32: 巾 | U32: ㄧㄣ | V32: in | W32: in | X32: in | Y32: in | Z32: in | AA32: 舒聲 （平/上/去） | AB32: 巾舒 | AC32: 17 | AF32: =IF(AND(MOD(B32,2)<>1, G32<>""), "", _xlfn.CONCAT("""", 十五音韻母對照表!$E32, """", " : [", """", 十五音韻母對照表!$G32, """", ", """, G33, """", "],")) -> "高" : ["o", "oh"], | AH32: "丩" : ["iu", ""],
B33: 30 | C33: 卜 | D33: o? | E33: 高 | F33: ㄜㆷ | G33: oh | H33: oh | I33: oh | J33: oh | K33: orh | L33: 促聲 （入） | M33: =十五音韻母對照表!$E33&LEFT(十五音韻母對照表!$L33,1) -> 高促 | N33: 15 | O33: =IF(十五音韻母對照表!$G33="", 0, LEN(十五音韻母對照表!$G33)) -> 2 | Q33: 34 | R33: 一 | S33: it̚ | T33: 巾 | U33: ㄧㆵ | V33: it | W33: it | X33: it | Y33: it | Z33: it | AA33: 促聲 （入） | AB33: 巾促 | AC33: 17 | AF33: =IF(AND(MOD(B33,2)<>1, G33<>""), "", _xlfn.CONCAT("""", 十五音韻母對照表!$E33, """", " : [", """", 十五音韻母對照表!$G33, """", ", """, G34, """", "],")) | AH33: "更" : ["enn", "ehnn"],
B34: 31 | C34: 埃 | D34: ai | E34: 皆 | F34: ㄞ | G34: ai | H34: ai | I34: ai | J34: ai | K34: ai | L34: 舒聲 （平/上/去） | M34: =十五音韻母對照表!$E34&LEFT(十五音韻母對照表!$L34,1) -> 皆舒 | N34: 16 | O34: =IF(十五音韻母對照表!$G34="", 0, LEN(十五音韻母對照表!$G34)) -> 2 | Q34: 35 | R34: 將 | S34: iaŋ | T34: 姜 | U34: ㄧㄤ | V34: iang | W34: iang | X34: iang | Y34: iang | Z34: iang | AA34: 舒聲 （平/上/去） | AB34: 姜舒 | AC34: 18 | AF34: =IF(AND(MOD(B34,2)<>1, G34<>""), "", _xlfn.CONCAT("""", 十五音韻母對照表!$E34, """", " : [", """", 十五音韻母對照表!$G34, """", ", """, G35, """", "],")) -> "皆" : ["ai", ""], | AH34: "褌" : ["uinn", ""],
B35: 32 | O35: =IF(十五音韻母對照表!$G35="", 0, LEN(十五音韻母對照表!$G35)) -> 0 | Q35: 36 | R35: 爆 | S35: iak̚ | T35: 姜 | U35: ㄧㄚㆻ | V35: iak | W35: iak | X35: iak | Y35: iak | Z35: iak | AA35: 促聲 （入） | AB35: 姜促 | AC35: 18 | AH35: "茄" : ["io", "ioh"],
B36: 33 | C36: 恩 | D36: in | E36: 巾 | F36: ㄧㄣ | G36: in | H36: in | I36: in | J36: in | K36: in | L36: 舒聲 （平/上/去） | M36: =十五音韻母對照表!$E36&LEFT(十五音韻母對照表!$L36,1) -> 巾舒 | N36: 17 | O36: =IF(十五音韻母對照表!$G36="", 0, LEN(十五音韻母對照表!$G36)) -> 2 | Q36: 37 | R36: 堪 | S36: am | T36: 甘 | U36: ㆰ | V36: am | W36: am | X36: am | Y36: am | Z36: am | AA36: 舒聲 （平/上/去） | AB36: 甘舒 | AC36: 19 | AF36: =IF(AND(MOD(B36,2)<>1, G36<>""), "", _xlfn.CONCAT("""", 十五音韻母對照表!$E36, """", " : [", """", 十五音韻母對照表!$G36, """", ", """, G37, """", "],")) -> "巾" : ["in", "it"], | AH36: "梔" : ["inn", "ihnn"],
B37: 34 | C37: 一 | D37: it̚ | E37: 巾 | F37: ㄧㆵ | G37: it | H37: it | I37: it | J37: it | K37: it | L37: 促聲 （入） | M37: =十五音韻母對照表!$E37&LEFT(十五音韻母對照表!$L37,1) -> 巾促 | N37: 17 | O37: =IF(十五音韻母對照表!$G37="", 0, LEN(十五音韻母對照表!$G37)) -> 2 | Q37: 38 | R37: 答 | S37: ap̚ | T37: 甘 | U37: ㄚㆴ | V37: ap | W37: ap | X37: ap | Y37: ap | Z37: ap | AA37: 促聲 （入） | AB37: 甘促 | AC37: 19 | AF37: =IF(AND(MOD(B37,2)<>1, G37<>""), "", _xlfn.CONCAT("""", 十五音韻母對照表!$E37, """", " : [", """", 十五音韻母對照表!$G37, """", ", """, G38, """", "],")) | AH37: "薑" : ["ionn", ""],
B38: 35 | C38: 將 | D38: iaŋ | E38: 姜 | F38: ㄧㄤ | G38: iang | H38: iang | I38: iang | J38: iang | K38: iang | L38: 舒聲 （平/上/去） | M38: =十五音韻母對照表!$E38&LEFT(十五音韻母對照表!$L38,1) -> 姜舒 | N38: 18 | O38: =IF(十五音韻母對照表!$G38="", 0, LEN(十五音韻母對照表!$G38)) -> 4 | Q38: 39 | R38: 花 | S38: ua | T38: 瓜 | U38: ㄨㄚ | V38: ua | W38: ua | X38: oa | Y38: ua | Z38: ua | AA38: 舒聲 （平/上/去） | AB38: 瓜舒 | AC38: 20 | AF38: =IF(AND(MOD(B38,2)<>1, G38<>""), "", _xlfn.CONCAT("""", 十五音韻母對照表!$E38, """", " : [", """", 十五音韻母對照表!$G38, """", ", """, G39, """", "],")) -> "姜" : ["iang", "iak"], | AH38: "驚" : ["iann", ""],
B39: 36 | C39: 爆 | D39: iak̚ | E39: 姜 | F39: ㄧㄚㆻ | G39: iak | H39: iak | I39: iak | J39: iak | K39: iak | L39: 促聲 （入） | M39: =十五音韻母對照表!$E39&LEFT(十五音韻母對照表!$L39,1) -> 姜促 | N39: 18 | O39: =IF(十五音韻母對照表!$G39="", 0, LEN(十五音韻母對照表!$G39)) -> 3 | Q39: 40 | R39: 缽 | S39: ua? | T39: 瓜 | U39: ㄨㄚㆷ | V39: uah | W39: uah | X39: oah | Y39: uah | Z39: uah | AA39: 促聲 （入） | AB39: 瓜促 | AC39: 20 | AF39: =IF(AND(MOD(B39,2)<>1, G39<>""), "", _xlfn.CONCAT("""", 十五音韻母對照表!$E39, """", " : [", """", 十五音韻母對照表!$G39, """", ", """, G40, """", "],")) | AH39: "官" : ["uann", ""],
B40: 37 | C40: 堪 | D40: am | E40: 甘 | F40: ㆰ | G40: am | H40: am | I40: am | J40: am | K40: am | L40: 舒聲 （平/上/去） | M40: =十五音韻母對照表!$E40&LEFT(十五音韻母對照表!$L40,1) -> 甘舒 | N40: 19 | O40: =IF(十五音韻母對照表!$G40="", 0, LEN(十五音韻母對照表!$G40)) -> 2 | Q40: 41 | R40: 邦 | S40: aŋ | T40: 江 | U40: ㄤ | V40: ang | W40: ang | X40: ang | Y40: ang | Z40: ang | AA40: 舒聲 （平/上/去） | AB40: 江舒 | AC40: 21 | AF40: =IF(AND(MOD(B40,2)<>1, G40<>""), "", _xlfn.CONCAT("""", 十五音韻母對照表!$E40, """", " : [", """", 十五音韻母對照表!$G40, """", ", """, G41, """", "],")) -> "甘" : ["am", "ap"], | AH40: "鋼" : ["ng", ""],
B41: 38 | C41: 答 | D41: ap̚ | E41: 甘 | F41: ㄚㆴ | G41: ap | H41: ap | I41: ap | J41: ap | K41: ap | L41: 促聲 （入） | M41: =十五音韻母對照表!$E41&LEFT(十五音韻母對照表!$L41,1) -> 甘促 | N41: 19 | O41: =IF(十五音韻母對照表!$G41="", 0, LEN(十五音韻母對照表!$G41)) -> 2 | Q41: 42 | R41: 角 | S41: ak̚ | T41: 江 | U41: ㄚㆻ | V41: ak | W41: ak | X41: ak | Y41: ak | Z41: ak | AA41: 促聲 （入） | AB41: 江促 | AC41: 21 | AF41: =IF(AND(MOD(B41,2)<>1, G41<>""), "", _xlfn.CONCAT("""", 十五音韻母對照表!$E41, """", " : [", """", 十五音韻母對照表!$G41, """", ", """, G42, """", "],")) | AH41: "伽" : ["e", "eh"],
...

Sheet 聲調對照表
B2: 十五音調號 | C2: 傳統八聲調 | D2: 閩拼八聲調 | E2: 雅俗通調名 | F2: 台羅調名 | G2: 調名 | H2: 方音符號調符 | I2: 白話字調符編碼 | J2: 白話字調符
B3: =TEXT(C3, "[DBNum1][$-zh-TW]G/通用格式") -> 一 | C3: 1 | D3: 1 | E3: =_xlfn.CONCAT( LEFT(G3), RIGHT(G3)) -> 上平 | F3: =_xlfn.CONCAT( MID(G3,3,1), RIGHT(G3)) -> 陰平 | G3: 上（陰）平 | H3: =_xlfn.UNICHAR(HEX2DEC("02C9")) -> ˉ | J3: =_xlfn.CONCAT("◌", [2]!聲調表[[#This Row],[白話字調符編碼]]) -> ◌
B4: =TEXT(C4, "[DBNum1][$-zh-TW]G/通用格式") -> 二 | C4: 2 | D4: 3 | E4: =_xlfn.CONCAT( LEFT(G4), RIGHT(G4)) -> 上上 | F4: =_xlfn.CONCAT( MID(G4,3,1), RIGHT(G4)) -> 陰上 | G4: 上（陰）上 | H4: =_xlfn.UNICHAR(HEX2DEC("02CB")) -> ˋ | I4: =_xlfn.UNICHAR(HEX2DEC("0301")) -> ́ | J4: =_xlfn.CONCAT("◌", [2]!聲調表[[#This Row],[白話字調符編碼]]) -> ◌́
B5: =TEXT(C5, "[DBNum1][$-zh-TW]G/通用格式") -> 三 | C5: 3 | D5: 5 | E5: =_xlfn.CONCAT( LEFT(G5), RIGHT(G5)) -> 上去 | F5: =_xlfn.CONCAT( MID(G5,3,1), RIGHT(G5)) -> 陰去 | G5: 上（陰）去 | H5: =_xlfn.UNICHAR(HEX2DEC("02EA")) -> ˪ | I5: =_xlfn.UNICHAR(HEX2DEC("0300")) -> ̀ | J5: =_xlfn.CONCAT("◌", [2]!聲調表[[#This Row],[白話字調符編碼]]) -> ◌̀
B6: =TEXT(C6, "[DBNum1][$-zh-TW]G/通用格式") -> 四 | C6: 4 | D6: 7 | E6: =_xlfn.CONCAT( LEFT(G6), RIGHT(G6)) -> 上入 | F6: =_xlfn.CONCAT( MID(G6,3,1), RIGHT(G6)) -> 陰入 | G6: 上（陰）入 | H6: =_xlfn.UNICHAR(HEX2DEC("02C9")) -> ˉ | J6: =_xlfn.CONCAT("◌", [2]!聲調表[[#This Row],[白話字調符編碼]]) -> ◌
B7: =TEXT(C7, "[DBNum1][$-zh-TW]G/通用格式") -> 五 | C7: 5 | D7: 2 | E7: =_xlfn.CONCAT( LEFT(G7), RIGHT(G7)) -> 下平 | F7: =_xlfn.CONCAT( MID(G7,3,1), RIGHT(G7)) -> 陽平 | G7: 下（陽）平 | H7: =_xlfn.UNICHAR(HEX2DEC("02CA")) -> ˊ | I7: =_xlfn.UNICHAR(HEX2DEC("0302")) -> ̂ | J7: =_xlfn.CONCAT("◌", [2]!聲調表[[#This Row],[白話字調符編碼]]) -> ◌̂
B8: =TEXT(C8, "[DBNum1][$-zh-TW]G/通用格式") -> 六 | C8: 6 | D8: 4 | E8: =_xlfn.CONCAT( LEFT(G8), RIGHT(G8)) -> 下上 | F8: =_xlfn.CONCAT( MID(G8,3,1), RIGHT(G8)) -> 陽上 | G8: 下（陽）上 | H8: =_xlfn.UNICHAR(HEX2DEC("02CB")) -> ˋ | I8: =_xlfn.UNICHAR(HEX2DEC("030C")) -> ̌ | J8: =_xlfn.CONCAT("◌", [2]!聲調表[[#This Row],[白話字調符編碼]]) -> ◌̌
B9: =TEXT(C9, "[DBNum1][$-zh-TW]G/通用格式") -> 七 | C9: 7 | D9: 6 | E9: =_xlfn.CONCAT( LEFT(G9), RIGHT(G9)) -> 下去 | F9: =_xlfn.CONCAT( MID(G9,3,1), RIGHT(G9)) -> 陽去 | G9: 下（陽）去 | H9: =_xlfn.UNICHAR(HEX2DEC("02EB")) -> ˫ | I9: =_xlfn.UNICHAR(HEX2DEC("0304")) -> ̄ | J9: =_xlfn.CONCAT("◌", [2]!聲調表[[#This Row],[白話字調符編碼]]) -> ◌̄
B10: =TEXT(C10, "[DBNum1][$-zh-TW]G/通用格式") -> 八 | C10: 8 | D10: 8 | E10: =_xlfn.CONCAT( LEFT(G10), RIGHT(G10)) -> 下入 | F10: =_xlfn.CONCAT( MID(G10,3,1), RIGHT(G10)) -> 陽入 | G10: 下（陽）入 | H10: =_xlfn.UNICHAR(HEX2DEC("02D9")) -> ˙ | I10: =_xlfn.UNICHAR(HEX2DEC("030D")) -> ̍ | J10: =_xlfn.CONCAT("◌", [2]!聲調表[[#This Row],[白話字調符編碼]]) -> ◌̍
