Workbook
Name 元音及韻化輔音: 聲調表!$C$5:$C$13
Name 方音符號聲調: ' 閩拼八聲調'!$Q$3:$Q$10
Name 方音符號聲調: 設定!$K$3:$K$10
Name 方音聲調符號表: 聲調表!$Z$5:$AG$5
Name 閩拚聲調符號表: 聲調表!$P$5:$W$13
Name 閩拼八聲調: ' 閩拼八聲調'!$L$3:$L$10
Name 閩拼八聲調: 設定!$I$3:$I$10
Name 聲母碼: 聲母對照表!$B$4:$B$21
Name 聲調對照表: 聲調表!$F$5:$M$13
Name 韻母碼: 彙集雅俗通十五音原書索引!$E$4:$E$103
Name 韻母碼: 韻母對照表!$B$4:$B$103

Sheet 彙集雅俗通十五音原書索引
A1: =COLUMN() -> 1 | B1: =COLUMN() -> 2 | C1: =COLUMN() -> 3 | D1: =COLUMN() -> 4 | E1: =COLUMN() -> 5 | F1: =COLUMN() -> 6 | G1: =COLUMN() -> 7 | H1: =COLUMN() -> 8 | J1: =COLUMN() -> 10 | K1: =COLUMN() -> 11 | L1: =COLUMN() -> 12 | N1: =COLUMN() -> 14 | P1: =COLUMN() -> 16 | Q1: =COLUMN() -> 17 | R1: =COLUMN() -> 18 | S1: =COLUMN() -> 19
A3: 識別號 | B3: 十五音 | C3: 方音 | D3: 國際音標 | E3: 韻母碼 | F3: 白話字 | G3: 台羅 | H3: 閩拼 | I3: 注音二式 | J3: 十五音序 | K3: 舒促聲 | L3: 十五音識別碼 | N3: 識別號 | O3: 卷號 | P3: 十五音 | Q3: 方音 | R3: 國際音標 | S3: 台語音標
A4: 1 | B4: 君 | C4: ㄨㄣ | D4: un | E4: un | F4: un | G4: un | H4: un | J4: 1 | K4: 舒聲 | L4: 君舒 | N4: 1 | O4: 一 | P4: 君 | Q4: ㄨㄣ | R4: un | S4: un
A5: 2 | B5: 君 | C5: ㄨㆵ | D5: ut̚ | E5: ut | F5: ut | G5: ut | H5: ut | J5: 1 | K5: 促聲 | L5: 君促 | Q5: ㄨㆵ | R5: ut̚ | S5: ut
A6: 3 | B6: 堅 | C6: ㄧㄢ | D6: ian | E6: ian | F6: ian | G6: ian | H6: ian | J6: 2 | K6: 舒聲 | L6: 堅舒 | N6: 2 | P6: 堅 | Q6: ㄧㄢ | R6: ian | S6: ian
A7: 4 | B7: 堅 | C7: ㄧㄚㆵ | D7: iat̚ | E7: iat | F7: iat | G7: iat | H7: iat | J7: 2 | K7: 促聲 | L7: 堅促 | Q7: ㄧㄚㆵ | R7: iat̚ | S7: iat
A8: 5 | B8: 金 | C8: ㄧㆬ | D8: im | E8: im | F8: im | G8: im | H8: im | J8: 3 | K8: 舒聲 | L8: 金舒 | N8: 3 | P8: 金 | Q8: ㄧㆬ | R8: im | S8: im
A9: 6 | B9: 金 | C9: 一ㆴ | D9: ip̚ | E9: ip | F9: ip | G9: ip | H9: ip | J9: 3 | K9: 促聲 | L9: 金促 | Q9: 一ㆴ | R9: ip̚ | S9: ip
A10: 7 | B10: 規 | C10: ㄨㄧ | D10: ui | E10: ui | F10: ui | G10: ui | H10: ui | J10: 4 | K10: 舒聲 | L10: 規舒 | N10: 4 | P10: 規 | Q10: ㄨㄧ | R10: ui | S10: ui
A11: 8 | B11: 規 | C11: 0 | D11: 0 | E11: 0 | F11: 0 | G11: 0 | H11: 0 | J11: 4 | K11: 促聲 | L11: 規促 | Q11: 0 | R11: 0 | S11: 0
A12: 9 | B12: 嘉 | C12: ㄝ | D12: ɛ | E12: ee | F12: e | G12: ee | H12: e | J12: 5 | K12: 舒聲 | L12: 嘉舒 | N12: 5 | P12: 嘉 | Q12: ㄝ | R12: ɛ | S12: ee
A13: 10 | B13: 嘉 | C13: ㄝㆷ | D13: ɛ? | E13: eeh | F13: eeh | G13: eeh | H13: 0 | J13: 5 | K13: 促聲 | L13: 嘉促 | Q13: ㄝㆷ | R13: ɛ? | S13: eeh
A14: 11 | B14: 干 | C14: ㄢ | D14: an | E14: an | F14: an | G14: an | H14: an | J14: 6 | K14: 舒聲 | L14: 干舒 | N14: 6 | O14: 二 | P14: 干 | Q14: ㄢ | R14: an | S14: an
A15: 12 | B15: 干 | C15: ㄚㆵ | D15: at̚ | E15: at | F15: at | G15: at | H15: at | J15: 6 | K15: 促聲 | L15: 干促 | Q15: ㄚㆵ | R15: at̚ | S15: at
A16: 13 | B16: 公 | C16: ㆲ | D16: ɔŋ | E16: ong | F16: ong | G16: ong | H16: ong | J16: 7 | K16: 舒聲 | L16: 公舒 | N16: 7 | P16: 公 | Q16: ㆲ | R16: ɔŋ | S16: ong
A17: 14 | B17: 公 | C17: ㆦㆻ | D17: ɔk̚ | E17: ok | F17: ok | G17: ok | H17: ok | J17: 7 | K17: 促聲 | L17: 公促 | Q17: ㆦㆻ | R17: ɔk̚ | S17: ok
A18: 15 | B18: 乖 | C18: ㄨㄞ | D18: uai | E18: uai | F18: oai | G18: uai | H18: uai | J18: 8 | K18: 舒聲 | L18: 乖舒 | N18: 8 | P18: 乖 | Q18: ㄨㄞ | R18: uai | S18: uai
A19: 16 | B19: 乖 | C19: ㄨㄞㆷ | D19: uai? | E19: uaih | F19: oaih | G19: uaih | H19: uaih | J19: 8 | K19: 促聲 | L19: 乖促 | Q19: ㄨㄞㆷ | R19: uai? | S19: uaih
A20: 17 | B20: 經 | C20: ㄧㄥ | D20: iŋ | E20: ing | F20: eng | G20: ing | H20: ing | J20: 9 | K20: 舒聲 | L20: 經舒 | N20: 9 | P20: 經 | Q20: ㄧㄥ | R20: iŋ | S20: ing
A21: 18 | B21: 經 | C21: ㄧㆻ | D21: ik̚ | E21: ik | F21: ek | G21: ik | H21: ik | J21: 9 | K21: 促聲 | L21: 經促 | Q21: ㄧㆻ | R21: ik̚ | S21: ik
A22: 19 | B22: 觀 | C22: ㄨㄢ | D22: uan | E22: uan | F22: oan | G22: uan | H22: uan | J22: 10 | K22: 舒聲 | L22: 觀舒 | N22: 10 | P22: 觀 | Q22: ㄨㄢ | R22: uan | S22: uan
A23: 20 | B23: 觀 | C23: ㄨㄚㆵ | D23: uat̚ | E23: uat | F23: oat | G23: uat | H23: uat | J23: 10 | K23: 促聲 | L23: 觀促 | Q23: ㄨㄚㆵ | R23: uat̚ | S23: uat
A24: 21 | B24: 沽 | C24: ㆦ | D24: ɔu | E24: oo | F24: o͘ | G24: oo | H24: oo | J24: 11 | K24: 舒聲 | L24: 沽舒 | N24: 11 | O24: 三 | P24: 沽 | Q24: ㆦ | R24: ɔu | S24: oo
A25: 22 | B25: 沽 | C25: 0 | D25: 0 | E25: 0 | F25: 0 | G25: 0 | H25: 0 | J25: 11 | K25: 促聲 | L25: 沽促 | Q25: 0 | R25: 0 | S25: 0
A26: 23 | B26: 嬌 | C26: ㄧㄠ | D26: iau | E26: iau | F26: iau | G26: iau | H26: iao | J26: 12 | K26: 舒聲 | L26: 嬌舒 | N26: 12 | P26: 嬌 | Q26: ㄧㄠ | R26: iau | S26: iau
A27: 24 | B27: 嬌 | C27: ㄧㄠㆷ | D27: iau? | E27: iauh | F27: iauh | G27: iauh | H27: iaoh | J27: 12 | K27: 促聲 | L27: 嬌促 | Q27: ㄧㄠㆷ | R27: iau? | S27: iauh
A28: 25 | B28: 稽 | C28: ㆤ | D28: ei | E28: ei | F28: e | G28: e | H28: e | J28: 13 | K28: 舒聲 | L28: 稽舒 | N28: 13 | P28: 稽 | Q28: ㆤ | R28: ei | S28: ei
A29: 26 | B29: 稽 | C29: 0 | D29: 0 | E29: 0 | F29: 0 | G29: 0 | H29: 0 | J29: 13 | K29: 促聲 | L29: 稽促 | Q29: 0 | R29: 0 | S29: 0
A30: 27 | B30: 恭 | C30: ㄧㆲ | D30: iɔŋ | E30: iong | F30: iong | G30: iong | H30: iong | J30: 14 | K30: 舒聲 | L30: 恭舒 | N30: 14 | P30: 恭 | Q30: ㄧㆲ | R30: iɔŋ | S30: iong
A31: 28 | B31: 恭 | C31: ㄧㆦㆻ | D31: iɔk̚ | E31: iok | F31: iok | G31: iok | H31: iok | J31: 14 | K31: 促聲 | L31: 恭促 | Q31: ㄧㆦㆻ | R31: iɔk̚ | S31: iok
A32: 29 | B32: 高 | C32: ㄜ | D32: ə | E32: o | F32: o | G32: o | H32: o | J32: 15 | K32: 舒聲 | L32: 高舒 | N32: 15 | P32: 高 | Q32: ㄜ | R32: ə | S32: o
A33: 30 | B33: 高 | C33: ㄜㆷ | D33: ə? | E33: oh | F33: oh | G33: oh | H33: oh | J33: 15 | K33: 促聲 | L33: 高促 | Q33: ㄜㆷ | R33: ə? | S33: oh
A34: 31 | B34: 皆 | C34: ㄞ | D34: ai | E34: ai | F34: ai | G34: ai | H34: ai | J34: 16 | K34: 舒聲 | L34: 皆舒 | N34: 16 | O34: 四 | P34: 皆 | Q34: ㄞ | R34: ai | S34: ai
A35: 32 | B35: 皆 | C35: 0 | D35: 0 | E35: 0 | F35: 0 | G35: 0 | H35: 0 | J35: 16 | K35: 促聲 | L35: 皆促 | Q35: 0 | R35: 0 | S35: 0
A36: 33 | B36: 巾 | C36: ㄧㄣ | D36: in | E36: in | F36: in | G36: in | H36: in | J36: 17 | K36: 舒聲 | L36: 巾舒 | N36: 17 | P36: 巾 | Q36: ㄧㄣ | R36: in | S36: in
A37: 34 | B37: 巾 | C37: ㄧㆵ | D37: it̚ | E37: it | F37: it | G37: it | H37: it | J37: 17 | K37: 促聲 | L37: 巾促 | Q37: ㄧㆵ | R37: it̚ | S37: it
A38: 35 | B38: 姜 | C38: ㄧㄤ | D38: iaŋ | E38: iang | F38: iang | G38: iang | H38: iang | J38: 18 | K38: 舒聲 | L38: 姜舒 | N38: 18 | P38: 姜 | Q38: ㄧㄤ | R38: iaŋ | S38: iang
A39: 36 | B39: 姜 | C39: ㄧㄚㆻ | D39: iak̚ | E39: iak | F39: iak | G39: iak | H39: iak | J39: 18 | K39: 促聲 | L39: 姜促 | Q39: ㄧㄚㆻ | R39: iak̚ | S39: iak
A40: 37 | B40: 甘 | C40: ㆰ | D40: am | E40: am | F40: am | G40: am | H40: am | J40: 19 | K40: 舒聲 | L40: 甘舒 | N40: 19 | P40: 甘 | Q40: ㆰ | R40: am | S40: am
A41: 38 | B41: 甘 | C41: ㄚㆴ | D41: ap̚ | E41: ap | F41: ap | G41: ap | H41: ap | J41: 19 | K41: 促聲 | L41: 甘促 | Q41: ㄚㆴ | R41: ap̚ | S41: ap
...

Sheet 使用PY轉TLPA
A1: 漢字 | B1: 漢字標音 | C1: 台語音標 | D1: 台語音標之聲 | E1: 台語音標之韻 | F1: 台語音標之調
A2: 《 | C2: {=_xlfn._xlws.PY(0,0,B2:B668)} | H2: ====》 | I2: =IF(B2="", A2, _xlfn.CONCAT("<ruby>", A2, "<rt>", B2, "</rt>", "</ruby>")) -> 《
A3: 前 | B3: 堅五曾 | C3: zian5 | D3: z | E3: ian | F3: 5 | H3: ====》 | I3: =IF(B3="", A3, _xlfn.CONCAT("<ruby>", A3, "<rt>", B3, "</rt>", "</ruby>")) -> <ruby>前<rt>堅五曾</rt></ruby>
A4: 赤 | B4: 經四出 | C4: cik4 | D4: c | E4: ik | F4: 4 | H4: ====》 | I4: =IF(B4="", A4, _xlfn.CONCAT("<ruby>", A4, "<rt>", B4, "</rt>", "</ruby>")) -> <ruby>赤<rt>經四出</rt></ruby>
A5: 壁 | B5: 經四邊 | C5: pik4 | D5: p | E5: ik | F5: 4 | H5: ====》 | I5: =IF(B5="", A5, _xlfn.CONCAT("<ruby>", A5, "<rt>", B5, "</rt>", "</ruby>")) -> <ruby>壁<rt>經四邊</rt></ruby>
A6: 賦 | B6: 艍三喜 | C6: hu3 | D6: h | E6: u | F6: 3 | H6: ====》 | I6: =IF(B6="", A6, _xlfn.CONCAT("<ruby>", A6, "<rt>", B6, "</rt>", "</ruby>")) -> <ruby>賦<rt>艍三喜</rt></ruby>
A7: 》 | H7: ====》 | I7: =IF(B7="", A7, _xlfn.CONCAT("<ruby>", A7, "<rt>", B7, "</rt>", "</ruby>")) -> 》
A8: 北 | B8: 公四邊 | C8: pok4 | D8: p | E8: ok | F8: 4 | H8: ====》 | I8: =IF(B8="", A8, _xlfn.CONCAT("<ruby>", A8, "<rt>", B8, "</rt>", "</ruby>")) -> <ruby>北<rt>公四邊</rt></ruby>
A9: 宋 | B9: 公三時 | C9: song3 | D9: s | E9: ong | F9: 3 | H9: ====》 | I9: =IF(B9="", A9, _xlfn.CONCAT("<ruby>", A9, "<rt>", B9, "</rt>", "</ruby>")) -> <ruby>宋<rt>公三時</rt></ruby>
A10: ： | H10: ====》 | I10: =IF(B10="", A10, _xlfn.CONCAT("<ruby>", A10, "<rt>", B10, "</rt>", "</ruby>")) -> ：
A11: 蘇 | B11: 沽一時 | C11: soo1 | D11: s | E11: oo | F11: 1 | H11: ====》 | I11: =IF(B11="", A11, _xlfn.CONCAT("<ruby>", A11, "<rt>", B11, "</rt>", "</ruby>")) -> <ruby>蘇<rt>沽一時</rt></ruby>
A12: 軾 | B12: 經四時 | C12: sik4 | D12: s | E12: ik | F12: 4 | H12: ====》 | I12: =IF(B12="", A12, _xlfn.CONCAT("<ruby>", A12, "<rt>", B12, "</rt>", "</ruby>")) -> <ruby>軾<rt>經四時</rt></ruby>
A13: =CHAR(10) | H13: ====》 | I13: =IF(B13="", A13, _xlfn.CONCAT("<ruby>", A13, "<rt>", B13, "</rt>", "</ruby>"))
A14: 壬 | B14: 金五入 | C14: jim5 | D14: j | E14: im | F14: 5 | H14: ====》 | I14: =IF(B14="", A14, _xlfn.CONCAT("<ruby>", A14, "<rt>", B14, "</rt>", "</ruby>")) -> <ruby>壬<rt>金五入</rt></ruby>
A15: 戌 | B15: 君四時 | C15: sut4 | D15: s | E15: ut | F15: 4 | H15: ====》 | I15: =IF(B15="", A15, _xlfn.CONCAT("<ruby>", A15, "<rt>", B15, "</rt>", "</ruby>")) -> <ruby>戌<rt>君四時</rt></ruby>
A16: 之 | B16: 居一曾 | C16: zi1 | D16: z | E16: i | F16: 1 | H16: ====》 | I16: =IF(B16="", A16, _xlfn.CONCAT("<ruby>", A16, "<rt>", B16, "</rt>", "</ruby>")) -> <ruby>之<rt>居一曾</rt></ruby>
A17: 秋 | B17: 丩一出 | C17: ciu1 | D17: c | E17: iu | F17: 1 | H17: ====》 | I17: =IF(B17="", A17, _xlfn.CONCAT("<ruby>", A17, "<rt>", B17, "</rt>", "</ruby>")) -> <ruby>秋<rt>丩一出</rt></ruby>
A18: ， | H18: ====》 | I18: =IF(B18="", A18, _xlfn.CONCAT("<ruby>", A18, "<rt>", B18, "</rt>", "</ruby>")) -> ，
A19: 七 | B19: 巾四出 | C19: cit4 | D19: c | E19: it | F19: 4 | H19: ====》 | I19: =IF(B19="", A19, _xlfn.CONCAT("<ruby>", A19, "<rt>", B19, "</rt>", "</ruby>")) -> <ruby>七<rt>巾四出</rt></ruby>
A20: 月 | B20: 觀八語 | C20: guat8 | D20: g | E20: uat | F20: 8 | H20: ====》 | I20: =IF(B20="", A20, _xlfn.CONCAT("<ruby>", A20, "<rt>", B20, "</rt>", "</ruby>")) -> <ruby>月<rt>觀八語</rt></ruby>
A21: 既 | B21: 居三求 | C21: ki3 | D21: k | E21: i | F21: 3
A22: 望 | B22: 公七門 | C22: bong7 | D22: b | E22: ong | F22: 7
A23: ，
A24: 蘇 | B24: 沽一時 | C24: soo1 | D24: s | E24: oo | F24: 1
A25: 子 | B25: 艍二曾 | C25: zu2 | D25: z | E25: u | F25: 2
A26: 與 | B26: 艍二英 | C26: u2 | E26: u | F26: 2
A27: 客 | B27: 經四去 | C27: khik4 | D27: kh | E27: ik | F27: 4
A28: 泛 | B28: 觀三喜 | C28: huan3 | D28: h | E28: uan | F28: 3
A29: 舟 | B29: 丩一曾 | C29: ziu1 | D29: z | E29: iu | F29: 1
A30: 遊 | B30: 丩五英 | C30: iu5 | E30: iu | F30: 5
A31: 於 | B31: 艍一英 | C31: u1 | E31: u | F31: 1
A32: 赤 | B32: 經四出 | C32: cik4 | D32: c | E32: ik | F32: 4
A33: 壁 | B33: 經四邊 | C33: pik4 | D33: p | E33: ik | F33: 4
A34: 之 | B34: 居一曾 | C34: zi1 | D34: z | E34: i | F34: 1
A35: 下 | B35: 膠二喜 | C35: ha2 | D35: h | E35: a | F35: 2
A36: 。
A37: 清 | B37: 經一出 | C37: cing1 | D37: c | E37: ing | F37: 1
A38: 風 | B38: 公一喜 | C38: hong1 | D38: h | E38: ong | F38: 1
A39: 徐 | B39: 艍五時 | C39: su5 | D39: s | E39: u | F39: 5
A40: 來 | B40: 皆五柳 | C40: lai5 | D40: l | E40: ai | F40: 5
...

Sheet SQLite漢字庫
A1: 識別號 | B1: 漢字 | C1: 台語音標 | D1: 常用度 | E1: 聲母 | F1: 韻母 | G1: 調號
A2: 10575 | B2: 㔂 | C2: lan5 | D2: 0.1 | E2: l | F2: an | G2: 5
A3: 4547 | B3: 㜅 | C3: thik4 | D3: 0.01 | E3: th | F3: ik | G3: 4
A4: 909 | B4: 㝥 | C4: bai2 | D4: 0.01 | E4: b | F4: ai | G4: 2
A5: 10576 | B5: 㤉 | C5: ge5 | D5: 0.1 | E5: g | F5: e | G5: 5
A6: 2157 | B6: 㤉 | C6: ger5 | D6: 0.01 | E6: g | F6: e | G6: 5
A7: 10577 | B7: 㧌 | C7: mau1 | D7: 0.1 | E7: m | F7: au | G7: 1
A8: 10578 | B8: 㧎 | C8: khe5 | D8: 0.1 | E8: kh | F8: e | G8: 5
A9: 10579 | B9: 㧒 | C9: hiat1 | D9: 0.1 | E9: h | F9: iat | G9: 1
A10: 2458 | B10: 㧒 | C10: hiat4 | D10: 0.01 | E10: h | F10: iat | G10: 4
A11: 2853 | B11: 㧣 | C11: tu1 | D11: 0.01 | E11: t | F11: u | G11: 1
A12: 10580 | B12: 㧻 | C12: tok1 | D12: 0.1 | E12: t | F12: ok | G12: 1
A13: 3640 | B13: 㧻 | C13: tok4 | D13: 0.01 | E13: t | F13: ok | G13: 4
... A33: 622 | B33: 䘥 | C33: kah4 | D33: 0.01 | E33: k | F33: ah | G33: 4
A34: 10587 | B34: 䘼 | C34: ng2 | D34: 0.1 | F34: ng | G34: 2
A35: 4952 | B35: 䘼 | C35: uinn2 | D35: 0.01 | F35: uinn | G35: 2
A36: 4953 | B36: 䘿 | C36: khut8 | D36: 0.01 | E36: kh | F36: ut | G36: 8
A37: 10588 | B37: 䠡 | C37: ce5 | D37: 0.1 | E37: c | F37: e | G37: 5
A38: 6096 | B38: 䠡 | C38: cere5 | D38: 0.01 | E38: c | F38: ue | G38: 5
A39: 5880 | B39: 䫌 | C39: phue2 | D39: 0.01 | E39: ph | F39: ue | G39: 2
A40: 6097 | B40: 䭔 | C40: ter1 | D40: 0.01 | E40: t | F40: e | G40: 1
A41: 1542 | B41: 䭕 | C41: ziann2 | D41: 0.01 | E41: z | F41: iann | G41: 2
A42: 10589 | B42: 一 | C42: it1 | D42: 0.1 | F42: it | G42: 1
A43: 1665 | B43: 一 | C43: it4 | D43: 0.8 | F43: it | G43: 4
A44: 6939 | B44: 一 | C44: zit8 | D44: 0.6 | E44: z | F44: it | G44: 8
A45: 1668 | B45: 丁 | C45: ting1 | D45: 0.01 | E45: t | F45: ing | G45: 1
A46: 10590 | B46: 七 | C46: cit1 | D46: 0.1 | E46: c | F46: it | G46: 1
A47: 1669 | B47: 七 | C47: cit4 | D47: 0.8 | E47: c | F47: it | G47: 4
A48: 1686 | B48: 丈 | C48: tiang6 | D48: 0.01 | E48: t | F48: iang | G48: 6
A49: 1687 | B49: 丈 | C49: tiunn6 | D49: 0.01 | E49: t | F49: iunn | G49: 6
A50: 1688 | B50: 丈 | C50: tng6 | D50: 0.01 | E50: t | F50: ng | G50: 6
A51: 10591 | B51: 丈 | C51: tng7 | D51: 0.1 | E51: t | F51: ng | G51: 7
A52: 9 | B52: 三 | C52: sam1 | D52: 0.8 | E52: s | F52: am | G52: 1
A53: 10 | B53: 三 | C53: sam3 | D53: 0.7 | E53: s | F53: am | G53: 3
A54: 7131 | B54: 三 | C54: sann1 | D54: 0.8 | E54: s | F54: ann | G54: 1
A55: 1689 | B55: 上 | C55: siang6 | D55: 0.01 | E55: s | F55: iang | G55: 6
... A62: 10592 | B62: 上 | C62: ziunn7 | D62: 0.1 | E62: z | F62: iunn | G62: 7
A63: 1698 | B63: 下 | C63: e7 | D63: 0.6 | F63: e | G63: 7
A64: 1694 | B64: 下 | C64: ee6 | D64: 0.01 | F64: e | G64: 6
A65: 1695 | B65: 下 | C65: ee7 | D65: 0.01 | F65: e | G65: 7
...

Sheet SQLite漢字庫(BAK)
A1: 識別號 | B1: 漢字 | C1: 台語音標 | D1: 常用度 | E1: 聲母 | F1: 韻母 | G1: 調號
A2: 10575 | B2: 㔂 | C2: lan5 | D2: 0.1 | E2: l | F2: an | G2: 5
A3: 4547 | B3: 㜅 | C3: thik4 | D3: 0.01 | E3: th | F3: ik | G3: 4
A4: 909 | B4: 㝥 | C4: bai2 | D4: 0.01 | E4: b | F4: ai | G4: 2
A5: 10576 | B5: 㤉 | C5: ge5 | D5: 0.1 | E5: g | F5: e | G5: 5
A6: 2157 | B6: 㤉 | C6: ger5 | D6: 0.01 | E6: g | F6: e | G6: 5
A7: 10577 | B7: 㧌 | C7: mau1 | D7: 0.1 | E7: m | F7: au | G7: 1
A8: 10578 | B8: 㧎 | C8: khe5 | D8: 0.1 | E8: kh | F8: e | G8: 5
A9: 10579 | B9: 㧒 | C9: hiat1 | D9: 0.1 | E9: h | F9: iat | G9: 1
A10: 2458 | B10: 㧒 | C10: hiat4 | D10: 0.01 | E10: h | F10: iat | G10: 4
A11: 2853 | B11: 㧣 | C11: tu1 | D11: 0.01 | E11: t | F11: u | G11: 1
A12: 10580 | B12: 㧻 | C12: tok1 | D12: 0.1 | E12: t | F12: ok | G12: 1
A13: 3640 | B13: 㧻 | C13: tok4 | D13: 0.01 | E13: t | F13: ok | G13: 4
... A33: 622 | B33: 䘥 | C33: kah4 | D33: 0.01 | E33: k | F33: ah | G33: 4
A34: 10587 | B34: 䘼 | C34: ng2 | D34: 0.1 | F34: ng | G34: 2
A35: 4952 | B35: 䘼 | C35: uinn2 | D35: 0.01 | F35: uinn | G35: 2
A36: 4953 | B36: 䘿 | C36: khut8 | D36: 0.01 | E36: kh | F36: ut | G36: 8
A37: 10588 | B37: 䠡 | C37: tshe5 | D37: 0.1 | E37: c | F37: e | G37: 5
A38: 6096 | B38: 䠡 | C38: tshere5 | D38: 0.01 | E38: c | F38: ue | G38: 5
A39: 5880 | B39: 䫌 | C39: phue2 | D39: 0.01 | E39: ph | F39: ue | G39: 2
A40: 6097 | B40: 䭔 | C40: ter1 | D40: 0.01 | E40: t | F40: e | G40: 1
A41: 1542 | B41: 䭕 | C41: tsiann2 | D41: 0.01 | E41: z | F41: iann | G41: 2
A42: 10589 | B42: 一 | C42: it1 | D42: 0.1 | F42: it | G42: 1
A43: 1665 | B43: 一 | C43: it4 | D43: 0.8 | F43: it | G43: 4
A44: 6939 | B44: 一 | C44: tsit8 | D44: 0.6 | E44: z | F44: it | G44: 8
A45: 1668 | B45: 丁 | C45: ting1 | D45: 0.01 | E45: t | F45: ing | G45: 1
A46: 10590 | B46: 七 | C46: tshit1 | D46: 0.1 | E46: c | F46: it | G46: 1
A47: 1669 | B47: 七 | C47: tshit4 | D47: 0.8 | E47: c | F47: it | G47: 4
A48: 1686 | B48: 丈 | C48: tiang6 | D48: 0.01 | E48: t | F48: iang | G48: 6
A49: 1687 | B49: 丈 | C49: tiunn6 | D49: 0.01 | E49: t | F49: iunn | G49: 6
A50: 1688 | B50: 丈 | C50: tng6 | D50: 0.01 | E50: t | F50: ng | G50: 6
A51: 10591 | B51: 丈 | C51: tng7 | D51: 0.1 | E51: t | F51: ng | G51: 7
A52: 9 | B52: 三 | C52: sam1 | D52: 0.8 | E52: s | F52: am | G52: 1
A53: 10 | B53: 三 | C53: sam3 | D53: 0.7 | E53: s | F53: am | G53: 3
A54: 7131 | B54: 三 | C54: sann1 | D54: 0.8 | E54: s | F54: ann | G54: 1
A55: 1689 | B55: 上 | C55: siang6 | D55: 0.01 | E55: s | F55: iang | G55: 6
... A62: 10592 | B62: 上 | C62: tsiunn7 | D62: 0.1 | E62: z | F62: iunn | G62: 7
A63: 1698 | B63: 下 | C63: e7 | D63: 0.6 | F63: e | G63: 7
A64: 1694 | B64: 下 | C64: ee6 | D64: 0.01 | F64: e | G64: 6
A65: 1695 | B65: 下 | C65: ee7 | D65: 0.01 | F65: e | G65: 7
...

Sheet 漢字查音
B1: 漢字
B2: 徘
B4: 漢字 | C4: 台羅拼音 | D4: 白話字拼音 | E4: 閩拼標音 | F4: 方音符號 | H4: 十五音標音 | I4: 雅俗通標音 | K4: 識別號 | L4: 漢字 | M4: 切音 | N4: 字韻 | O4: 聲調 | P4: 原資料拼音 | Q4: 舒促聲 | R4: 聲 | S4: 韻 | T4: 調 | U4: 拼音碼 | V4: 雅俗通標音 | W4: 十五音標音 | X4: 常用度
B5: =IF( $K5="", "", L5) -> 徘 | C5: =IF($K5="","", IF($N5="英", "", INDEX(聲母對照資料表[], MATCH($R5,聲母碼,0), 5)) & $S5 & $T5 ) -> pai5 | D5: =IF($K5="","", IF($N5="英", "", INDEX(聲母對照資料表[], MATCH($R5,聲母碼,0), 5)) & INDEX(韻母對照資料表[], MATCH($S5, 韻母碼,0), 4) & $T5 ) -> pai5 | E5: {=IF($K5="","", IF($N5="英", "", INDEX(聲母對照資料表[], MATCH($R5,聲母碼,0), 5)) & INDEX(韻母對照資料表[],MATCH($S5,韻母碼,0),6) & INDEX(閩拼八聲調,$T5))} -> pai2 | F5: =IFERROR( SUBSTITUTE($G5, LEFT($G5,2), INDEX(設定!$X$9:$X$12,MATCH(LEFT($G5,2), 設定!$W$9:$W$12,0))), $G5) -> ˊ | G5: {=IF($K5="","", IF($N5="英", "", INDEX(聲母對照資料表[],MATCH($R5,聲母碼,0),7)) & INDEX(韻母對照資料表[],MATCH($S5,韻母碼,0),7) & INDEX(方音符號聲調,$T5))} -> ˊ | H5: =IF($K5="", "", $W5) -> 皆五邊 | I5: =IF($K5="", "", $V5) -> 皆下平聲邊 | K5: {=_xlfn._xlws.FILTER(雅俗通字典[],雅俗通字典[漢字]=B2)} -> 6695 | L5: 徘 | M5: 邊 | N5: 皆 | O5: 下平 | P5: pai5 | Q5: 舒聲 | R5: p | S5: ai | T5: 5 | U5: pai5 | V5: 皆下平聲邊 | W5: 皆五邊 | X5: 0
B6: =IF( $K6="", "", L6) | C6: =IF($K6="","", IF($N6="英", "", INDEX(聲母對照資料表[], MATCH($R6,聲母碼,0), 5)) & $S6 & $T6 ) | D6: =IF($K6="","", IF($N6="英", "", INDEX(聲母對照資料表[], MATCH($R6,聲母碼,0), 5)) & INDEX(韻母對照資料表[], MATCH($S6, 韻母碼,0), 4) & $T6 ) | E6: {=IF($K6="","", IF($N6="英", "", INDEX(聲母對照資料表[], MATCH($R6,聲母碼,0), 5)) & INDEX(韻母對照資料表[],MATCH($S6,韻母碼,0),6) & INDEX(閩拼八聲調,$T6))} | F6: =IFERROR( SUBSTITUTE($G6, LEFT($G6,2), INDEX(設定!$X$9:$X$12,MATCH(LEFT($G6,2), 設定!$W$9:$W$12,0))), $G6) | G6: {=IF($K6="","", IF($N6="英", "", INDEX(聲母對照資料表[],MATCH($R6,聲母碼,0),7)) & INDEX(韻母對照資料表[],MATCH($S6,韻母碼,0),7) & INDEX(方音符號聲調,$T6))} | H6: =IF($K6="", "", $W6) | I6: =IF($K6="", "", $V6)
B7: =IF( $K7="", "", L7) | C7: =IF($K7="","", IF($N7="英", "", INDEX(聲母對照資料表[], MATCH($R7,聲母碼,0), 5)) & $S7 & $T7 ) | D7: =IF($K7="","", IF($N7="英", "", INDEX(聲母對照資料表[], MATCH($R7,聲母碼,0), 5)) & INDEX(韻母對照資料表[], MATCH($S7, 韻母碼,0), 4) & $T7 ) | E7: {=IF($K7="","", IF($N7="英", "", INDEX(聲母對照資料表[], MATCH($R7,聲母碼,0), 5)) & INDEX(韻母對照資料表[],MATCH($S7,韻母碼,0),6) & INDEX(閩拼八聲調,$T7))} | F7: =IFERROR( SUBSTITUTE($G7, LEFT($G7,2), INDEX(設定!$X$9:$X$12,MATCH(LEFT($G7,2), 設定!$W$9:$W$12,0))), $G7) | G7: {=IF($K7="","", IF($N7="英", "", INDEX(聲母對照資料表[],MATCH($R7,聲母碼,0),7)) & INDEX(韻母對照資料表[],MATCH($S7,韻母碼,0),7) & INDEX(方音符號聲調,$T7))} | H7: =IF($K7="", "", $W7) | I7: =IF($K7="", "", $V7)
B8: =IF( $K8="", "", L8) | C8: =IF($K8="","", IF($N8="英", "", INDEX(聲母對照資料表[], MATCH($R8,聲母碼,0), 5)) & $S8 & $T8 ) | D8: =IF($K8="","", IF($N8="英", "", INDEX(聲母對照資料表[], MATCH($R8,聲母碼,0), 5)) & INDEX(韻母對照資料表[], MATCH($S8, 韻母碼,0), 4) & $T8 ) | E8: {=IF($K8="","", IF($N8="英", "", INDEX(聲母對照資料表[], MATCH($R8,聲母碼,0), 5)) & INDEX(韻母對照資料表[],MATCH($S8,韻母碼,0),6) & INDEX(閩拼八聲調,$T8))} | F8: =IFERROR( SUBSTITUTE($G8, LEFT($G8,2), INDEX(設定!$X$9:$X$12,MATCH(LEFT($G8,2), 設定!$W$9:$W$12,0))), $G8) | G8: {=IF($K8="","", IF($N8="英", "", INDEX(聲母對照資料表[],MATCH($R8,聲母碼,0),7)) & INDEX(韻母對照資料表[],MATCH($S8,韻母碼,0),7) & INDEX(方音符號聲調,$T8))} | H8: =IF($K8="", "", $W8) | I8: =IF($K8="", "", $V8)
B9: =IF( $K9="", "", L9) | C9: =IF($K9="","", IF($N9="英", "", INDEX(聲母對照資料表[], MATCH($R9,聲母碼,0), 5)) & $S9 & $T9 ) | D9: =IF($K9="","", IF($N9="英", "", INDEX(聲母對照資料表[], MATCH($R9,聲母碼,0), 5)) & INDEX(韻母對照資料表[], MATCH($S9, 韻母碼,0), 4) & $T9 ) | E9: {=IF($K9="","", IF($N9="英", "", INDEX(聲母對照資料表[], MATCH($R9,聲母碼,0), 5)) & INDEX(韻母對照資料表[],MATCH($S9,韻母碼,0),6) & INDEX(閩拼八聲調,$T9))} | F9: =IFERROR( SUBSTITUTE($G9, LEFT($G9,2), INDEX(設定!$X$9:$X$12,MATCH(LEFT($G9,2), 設定!$W$9:$W$12,0))), $G9) | G9: {=IF($K9="","", IF($N9="英", "", INDEX(聲母對照資料表[],MATCH($R9,聲母碼,0),7)) & INDEX(韻母對照資料表[],MATCH($S9,韻母碼,0),7) & INDEX(方音符號聲調,$T9))} | H9: =IF($K9="", "", $W9) | I9: =IF($K9="", "", $V9)
B10: =IF( $K10="", "", L10) | C10: =IF($K10="","", IF($N10="英", "", INDEX(聲母對照資料表[], MATCH($R10,聲母碼,0), 5)) & $S10 & $T10 ) | D10: =IF($K10="","", IF($N10="英", "", INDEX(聲母對照資料表[], MATCH($R10,聲母碼,0), 5)) & INDEX(韻母對照資料表[], MATCH($S10, 韻母碼,0), 4) & $T10 ) | E10: {=IF($K10="","", IF($N10="英", "", INDEX(聲母對照資料表[], MATCH($R10,聲母碼,0), 5)) & INDEX(韻母對照資料表[],MATCH($S10,韻母碼,0),6) & INDEX(閩拼八聲調,$T10))} | F10: =IFERROR( SUBSTITUTE($G10, LEFT($G10,2), INDEX(設定!$X$9:$X$12,MATCH(LEFT($G10,2), 設定!$W$9:$W$12,0))), $G10) | G10: {=IF($K10="","", IF($N10="英", "", INDEX(聲母對照資料表[],MATCH($R10,聲母碼,0),7)) & INDEX(韻母對照資料表[],MATCH($S10,韻母碼,0),7) & INDEX(方音符號聲調,$T10))} | H10: =IF($K10="", "", $W10) | I10: =IF($K10="", "", $V10)
B11: =IF( $K11="", "", L11) | C11: =IF($K11="","", IF($N11="英", "", INDEX(聲母對照資料表[], MATCH($R11,聲母碼,0), 5)) & $S11 & $T11 ) | D11: =IF($K11="","", IF($N11="英", "", INDEX(聲母對照資料表[], MATCH($R11,聲母碼,0), 5)) & INDEX(韻母對照資料表[], MATCH($S11, 韻母碼,0), 4) & $T11 ) | E11: {=IF($K11="","", IF($N11="英", "", INDEX(聲母對照資料表[], MATCH($R11,聲母碼,0), 5)) & INDEX(韻母對照資料表[],MATCH($S11,韻母碼,0),6) & INDEX(閩拼八聲調,$T11))} | F11: =IFERROR( SUBSTITUTE($G11, LEFT($G11,2), INDEX(設定!$X$9:$X$12,MATCH(LEFT($G11,2), 設定!$W$9:$W$12,0))), $G11) | G11: {=IF($K11="","", IF($N11="英", "", INDEX(聲母對照資料表[],MATCH($R11,聲母碼,0),7)) & INDEX(韻母對照資料表[],MATCH($S11,韻母碼,0),7) & INDEX(方音符號聲調,$T11))} | H11: =IF($K11="", "", $W11) | I11: =IF($K11="", "", $V11)
B12: =IF( $K12="", "", L12) | C12: =IF($K12="","", IF($N12="英", "", INDEX(聲母對照資料表[], MATCH($R12,聲母碼,0), 5)) & $S12 & $T12 ) | D12: =IF($K12="","", IF($N12="英", "", INDEX(聲母對照資料表[], MATCH($R12,聲母碼,0), 5)) & INDEX(韻母對照資料表[], MATCH($S12, 韻母碼,0), 4) & $T12 ) | E12: {=IF($K12="","", IF($N12="英", "", INDEX(聲母對照資料表[], MATCH($R12,聲母碼,0), 5)) & INDEX(韻母對照資料表[],MATCH($S12,韻母碼,0),6) & INDEX(閩拼八聲調,$T12))} | F12: =IFERROR( SUBSTITUTE($G12, LEFT($G12,2), INDEX(設定!$X$9:$X$12,MATCH(LEFT($G12,2), 設定!$W$9:$W$12,0))), $G12) | G12: {=IF($K12="","", IF($N12="英", "", INDEX(聲母對照資料表[],MATCH($R12,聲母碼,0),7)) & INDEX(韻母對照資料表[],MATCH($S12,韻母碼,0),7) & INDEX(方音符號聲調,$T12))} | H12: =IF($K12="", "", $W12) | I12: =IF($K12="", "", $V12)
B13: =IF( $K13="", "", L13) | C13: =IF($K13="","", IF($N13="英", "", INDEX(聲母對照資料表[], MATCH($R13,聲母碼,0), 5)) & $S13 & $T13 ) | D13: =IF($K13="","", IF($N13="英", "", INDEX(聲母對照資料表[], MATCH($R13,聲母碼,0), 5)) & INDEX(韻母對照資料表[], MATCH($S13, 韻母碼,0), 4) & $T13 ) | E13: {=IF($K13="","", IF($N13="英", "", INDEX(聲母對照資料表[], MATCH($R13,聲母碼,0), 5)) & INDEX(韻母對照資料表[],MATCH($S13,韻母碼,0),6) & INDEX(閩拼八聲調,$T13))} | F13: =IFERROR( SUBSTITUTE($G13, LEFT($G13,2), INDEX(設定!$X$9:$X$12,MATCH(LEFT($G13,2), 設定!$W$9:$W$12,0))), $G13) | G13: {=IF($K13="","", IF($N13="英", "", INDEX(聲母對照資料表[],MATCH($R13,聲母碼,0),7)) & INDEX(韻母對照資料表[],MATCH($S13,韻母碼,0),7) & INDEX(方音符號聲調,$T13))} | H13: =IF($K13="", "", $W13) | I13: =IF($K13="", "", $V13)
B14: =IF( $K14="", "", L14) | C14: =IF($K14="","", IF($N14="英", "", INDEX(聲母對照資料表[], MATCH($R14,聲母碼,0), 5)) & $S14 & $T14 ) | D14: =IF($K14="","", IF($N14="英", "", INDEX(聲母對照資料表[], MATCH($R14,聲母碼,0), 5)) & INDEX(韻母對照資料表[], MATCH($S14, 韻母碼,0), 4) & $T14 ) | E14: {=IF($K14="","", IF($N14="英", "", INDEX(聲母對照資料表[], MATCH($R14,聲母碼,0), 5)) & INDEX(韻母對照資料表[],MATCH($S14,韻母碼,0),6) & INDEX(閩拼八聲調,$T14))} | F14: =IFERROR( SUBSTITUTE($G14, LEFT($G14,2), INDEX(設定!$X$9:$X$12,MATCH(LEFT($G14,2), 設定!$W$9:$W$12,0))), $G14) | G14: {=IF($K14="","", IF($N14="英", "", INDEX(聲母對照資料表[],MATCH($R14,聲母碼,0),7)) & INDEX(韻母對照資料表[],MATCH($S14,韻母碼,0),7) & INDEX(方音符號聲調,$T14))} | H14: =IF($K14="", "", $W14) | I14: =IF($K14="", "", $V14)
B15: =IF( $K15="", "", L15) | C15: =IF($K15="","", IF($N15="英", "", INDEX(聲母對照資料表[], MATCH($R15,聲母碼,0), 5)) & $S15 & $T15 ) | D15: =IF($K15="","", IF($N15="英", "", INDEX(聲母對照資料表[], MATCH($R15,聲母碼,0), 5)) & INDEX(韻母對照資料表[], MATCH($S15, 韻母碼,0), 4) & $T15 ) | E15: {=IF($K15="","", IF($N15="英", "", INDEX(聲母對照資料表[], MATCH($R15,聲母碼,0), 5)) & INDEX(韻母對照資料表[],MATCH($S15,韻母碼,0),6) & INDEX(閩拼八聲調,$T15))} | F15: =IFERROR( SUBSTITUTE($G15, LEFT($G15,2), INDEX(設定!$X$9:$X$12,MATCH(LEFT($G15,2), 設定!$W$9:$W$12,0))), $G15) | G15: {=IF($K15="","", IF($N15="英", "", INDEX(聲母對照資料表[],MATCH($R15,聲母碼,0),7)) & INDEX(韻母對照資料表[],MATCH($S15,韻母碼,0),7) & INDEX(方音符號聲調,$T15))} | H15: =IF($K15="", "", $W15) | I15: =IF($K15="", "", $V15)
B16: =IF( $K16="", "", L16) | C16: =IF($K16="","", IF($N16="英", "", INDEX(聲母對照資料表[], MATCH($R16,聲母碼,0), 5)) & $S16 & $T16 ) | D16: =IF($K16="","", IF($N16="英", "", INDEX(聲母對照資料表[], MATCH($R16,聲母碼,0), 5)) & INDEX(韻母對照資料表[], MATCH($S16, 韻母碼,0), 4) & $T16 ) | E16: {=IF($K16="","", IF($N16="英", "", INDEX(聲母對照資料表[], MATCH($R16,聲母碼,0), 5)) & INDEX(韻母對照資料表[],MATCH($S16,韻母碼,0),6) & INDEX(閩拼八聲調,$T16))} | F16: =IFERROR( SUBSTITUTE($G16, LEFT($G16,2), INDEX(設定!$X$9:$X$12,MATCH(LEFT($G16,2), 設定!$W$9:$W$12,0))), $G16) | G16: {=IF($K16="","", IF($N16="英", "", INDEX(聲母對照資料表[],MATCH($R16,聲母碼,0),7)) & INDEX(韻母對照資料表[],MATCH($S16,韻母碼,0),7) & INDEX(方音符號聲調,$T16))} | H16: =IF($K16="", "", $W16) | I16: =IF($K16="", "", $V16)
B17: =IF( $K17="", "", L17) | C17: =IF($K17="","", IF($N17="英", "", INDEX(聲母對照資料表[], MATCH($R17,聲母碼,0), 5)) & $S17 & $T17 ) | D17: =IF($K17="","", IF($N17="英", "", INDEX(聲母對照資料表[], MATCH($R17,聲母碼,0), 5)) & INDEX(韻母對照資料表[], MATCH($S17, 韻母碼,0), 4) & $T17 ) | E17: {=IF($K17="","", IF($N17="英", "", INDEX(聲母對照資料表[], MATCH($R17,聲母碼,0), 5)) & INDEX(韻母對照資料表[],MATCH($S17,韻母碼,0),6) & INDEX(閩拼八聲調,$T17))} | F17: =IFERROR( SUBSTITUTE($G17, LEFT($G17,2), INDEX(設定!$X$9:$X$12,MATCH(LEFT($G17,2), 設定!$W$9:$W$12,0))), $G17) | G17: {=IF($K17="","", IF($N17="英", "", INDEX(聲母對照資料表[],MATCH($R17,聲母碼,0),7)) & INDEX(韻母對照資料表[],MATCH($S17,韻母碼,0),7) & INDEX(方音符號聲調,$T17))} | H17: =IF($K17="", "", $W17) | I17: =IF($K17="", "", $V17)
... B104: =IF( $K104="", "", L104) | C104: =IF($K104="","", IF($N104="英", "", INDEX(聲母對照資料表[], MATCH($R104,聲母碼,0), 5)) & $S104 & $T104 ) | D104: =IF($K104="","", IF($N104="英", "", INDEX(聲母對照資料表[], MATCH($R104,聲母碼,0), 5)) & INDEX(韻母對照資料表[], MATCH($S104, 韻母碼,0), 4) & $T104 ) | E104: {=IF($K104="","", IF($N104="英", "", INDEX(聲母對照資料表[], MATCH($R104,聲母碼,0), 5)) & INDEX(韻母對照資料表[],MATCH($S104,韻母碼,0),6) & INDEX(閩拼八聲調,$T104))} | F104: =IFERROR( SUBSTITUTE($G104, LEFT($G104,2), INDEX(設定!$X$9:$X$12,MATCH(LEFT($G104,2), 設定!$W$9:$W$12,0))), $G104) | G104: {=IF($K104="","", IF($N104="英", "", INDEX(聲母對照資料表[],MATCH($R104,聲母碼,0),7)) & INDEX(韻母對照資料表[],MATCH($S104,韻母碼,0),7) & INDEX(方音符號聲調,$T104))} | H104: =IF($K104="", "", $W104) | I104: =IF($K104="", "", $V104)
B105: =IF( $K105="", "", L105) | C105: =IF($K105="","", INDEX(聲母對照資料表[], MATCH($O105,聲母碼,0), 5) & $P105 & $Q105 ) | D105: =IF($K105="","", INDEX(聲母對照資料表[], MATCH($O105,聲母碼,0), 4) & INDEX(韻母對照資料表[], MATCH($P105, 韻母碼,0), 4) & $Q105 ) | E105: {=IF($K105="","",INDEX(聲母對照資料表[],MATCH($O105,聲母碼,0),6) & INDEX(韻母對照資料表[],MATCH($P105,韻母碼,0),6) & INDEX(閩拼八聲調,$Q105))} | F105: =IFERROR( SUBSTITUTE($G105, LEFT($G105,2), INDEX(設定!$X$9:$X$12,MATCH(LEFT($G105,2), 設定!$W$9:$W$12,0))), $G105) | G105: {=IF($K105="","",INDEX(聲母對照資料表[],MATCH($O105,聲母碼,0),7) & INDEX(韻母對照資料表[],MATCH($P105,韻母碼,0),7) & INDEX(方音符號聲調,$Q105))} | I105: {=IF($K105="", "", $U105 & INDEX(設定!$E$2:$E$9, $Q105) & 漢字查音!$T105)}
B106: =IF( $K106="", "", L106) | C106: =IF($K106="","", INDEX(聲母對照資料表[], MATCH($O106,聲母碼,0), 5) & $P106 & $Q106 ) | D106: =IF($K106="","", INDEX(聲母對照資料表[], MATCH($O106,聲母碼,0), 4) & INDEX(韻母對照資料表[], MATCH($P106, 韻母碼,0), 4) & $Q106 ) | E106: {=IF($K106="","",INDEX(聲母對照資料表[],MATCH($O106,聲母碼,0),6) & INDEX(韻母對照資料表[],MATCH($P106,韻母碼,0),6) & INDEX(閩拼八聲調,$Q106))} | F106: =IFERROR( SUBSTITUTE($G106, LEFT($G106,2), INDEX(設定!$X$9:$X$12,MATCH(LEFT($G106,2), 設定!$W$9:$W$12,0))), $G106) | G106: {=IF($K106="","",INDEX(聲母對照資料表[],MATCH($O106,聲母碼,0),7) & INDEX(韻母對照資料表[],MATCH($P106,韻母碼,0),7) & INDEX(方音符號聲調,$Q106))} | I106: {=IF($K106="", "", $U106 & INDEX(設定!$E$2:$E$9, $Q106) & 漢字查音!$T106)}
B107: =IF( $K107="", "", L107) | C107: =IF($K107="","", INDEX(聲母對照資料表[], MATCH($O107,聲母碼,0), 5) & $P107 & $Q107 ) | D107: =IF($K107="","", INDEX(聲母對照資料表[], MATCH($O107,聲母碼,0), 4) & INDEX(韻母對照資料表[], MATCH($P107, 韻母碼,0), 4) & $Q107 ) | E107: {=IF($K107="","",INDEX(聲母對照資料表[],MATCH($O107,聲母碼,0),6) & INDEX(韻母對照資料表[],MATCH($P107,韻母碼,0),6) & INDEX(閩拼八聲調,$Q107))} | F107: =IFERROR( SUBSTITUTE($G107, LEFT($G107,2), INDEX(設定!$X$9:$X$12,MATCH(LEFT($G107,2), 設定!$W$9:$W$12,0))), $G107) | G107: {=IF($K107="","",INDEX(聲母對照資料表[],MATCH($O107,聲母碼,0),7) & INDEX(韻母對照資料表[],MATCH($P107,韻母碼,0),7) & INDEX(方音符號聲調,$Q107))} | I107: {=IF($K107="", "", $U107 & INDEX(設定!$E$2:$E$9, $Q107) & 漢字查音!$T107)}
B108: =IF( $K108="", "", L108) | C108: =IF($K108="","", INDEX(聲母對照資料表[], MATCH($O108,聲母碼,0), 5) & $P108 & $Q108 ) | D108: =IF($K108="","", INDEX(聲母對照資料表[], MATCH($O108,聲母碼,0), 4) & INDEX(韻母對照資料表[], MATCH($P108, 韻母碼,0), 4) & $Q108 ) | E108: {=IF($K108="","",INDEX(聲母對照資料表[],MATCH($O108,聲母碼,0),6) & INDEX(韻母對照資料表[],MATCH($P108,韻母碼,0),6) & INDEX(閩拼八聲調,$Q108))} | F108: =IFERROR( SUBSTITUTE($G108, LEFT($G108,2), INDEX(設定!$X$9:$X$12,MATCH(LEFT($G108,2), 設定!$W$9:$W$12,0))), $G108) | G108: {=IF($K108="","",INDEX(聲母對照資料表[],MATCH($O108,聲母碼,0),7) & INDEX(韻母對照資料表[],MATCH($P108,韻母碼,0),7) & INDEX(方音符號聲調,$Q108))} | I108: {=IF($K108="", "", $U108 & INDEX(設定!$E$2:$E$9, $Q108) & 漢字查音!$T108)}
B109: =IF( $K109="", "", L109) | C109: =IF($K109="","", INDEX(聲母對照資料表[], MATCH($O109,聲母碼,0), 5) & $P109 & $Q109 ) | D109: =IF($K109="","", INDEX(聲母對照資料表[], MATCH($O109,聲母碼,0), 4) & INDEX(韻母對照資料表[], MATCH($P109, 韻母碼,0), 4) & $Q109 ) | E109: {=IF($K109="","",INDEX(聲母對照資料表[],MATCH($O109,聲母碼,0),6) & INDEX(韻母對照資料表[],MATCH($P109,韻母碼,0),6) & INDEX(閩拼八聲調,$Q109))} | F109: =IFERROR( SUBSTITUTE($G109, LEFT($G109,2), INDEX(設定!$X$9:$X$12,MATCH(LEFT($G109,2), 設定!$W$9:$W$12,0))), $G109) | G109: {=IF($K109="","",INDEX(聲母對照資料表[],MATCH($O109,聲母碼,0),7) & INDEX(韻母對照資料表[],MATCH($P109,韻母碼,0),7) & INDEX(方音符號聲調,$Q109))} | I109: {=IF($K109="", "", $U109 & INDEX(設定!$E$2:$E$9, $Q109) & 漢字查音!$T109)}
B110: =IF( $K110="", "", L110) | C110: =IF($K110="","", INDEX(聲母對照資料表[], MATCH($O110,聲母碼,0), 5) & $P110 & $Q110 ) | D110: =IF($K110="","", INDEX(聲母對照資料表[], MATCH($O110,聲母碼,0), 4) & INDEX(韻母對照資料表[], MATCH($P110, 韻母碼,0), 4) & $Q110 ) | E110: {=IF($K110="","",INDEX(聲母對照資料表[],MATCH($O110,聲母碼,0),6) & INDEX(韻母對照資料表[],MATCH($P110,韻母碼,0),6) & INDEX(閩拼八聲調,$Q110))} | F110: =IFERROR( SUBSTITUTE($G110, LEFT($G110,2), INDEX(設定!$X$9:$X$12,MATCH(LEFT($G110,2), 設定!$W$9:$W$12,0))), $G110) | G110: {=IF($K110="","",INDEX(聲母對照資料表[],MATCH($O110,聲母碼,0),7) & INDEX(韻母對照資料表[],MATCH($P110,韻母碼,0),7) & INDEX(方音符號聲調,$Q110))} | I110: {=IF($K110="", "", $U110 & INDEX(設定!$E$2:$E$9, $Q110) & 漢字查音!$T110)}
B111: =IF( $K111="", "", L111) | C111: =IF($K111="","", INDEX(聲母對照資料表[], MATCH($O111,聲母碼,0), 5) & $P111 & $Q111 ) | D111: =IF($K111="","", INDEX(聲母對照資料表[], MATCH($O111,聲母碼,0), 4) & INDEX(韻母對照資料表[], MATCH($P111, 韻母碼,0), 4) & $Q111 ) | E111: {=IF($K111="","",INDEX(聲母對照資料表[],MATCH($O111,聲母碼,0),6) & INDEX(韻母對照資料表[],MATCH($P111,韻母碼,0),6) & INDEX(閩拼八聲調,$Q111))} | F111: =IFERROR( SUBSTITUTE($G111, LEFT($G111,2), INDEX(設定!$X$9:$X$12,MATCH(LEFT($G111,2), 設定!$W$9:$W$12,0))), $G111) | G111: {=IF($K111="","",INDEX(聲母對照資料表[],MATCH($O111,聲母碼,0),7) & INDEX(韻母對照資料表[],MATCH($P111,韻母碼,0),7) & INDEX(方音符號聲調,$Q111))} | I111: {=IF($K111="", "", $U111 & INDEX(設定!$E$2:$E$9, $Q111) & 漢字查音!$T111)}
B112: =IF( $K112="", "", L112) | C112: =IF($K112="","", INDEX(聲母對照資料表[], MATCH($O112,聲母碼,0), 5) & $P112 & $Q112 ) | D112: =IF($K112="","", INDEX(聲母對照資料表[], MATCH($O112,聲母碼,0), 4) & INDEX(韻母對照資料表[], MATCH($P112, 韻母碼,0), 4) & $Q112 ) | E112: {=IF($K112="","",INDEX(聲母對照資料表[],MATCH($O112,聲母碼,0),6) & INDEX(韻母對照資料表[],MATCH($P112,韻母碼,0),6) & INDEX(閩拼八聲調,$Q112))} | F112: =IFERROR( SUBSTITUTE($G112, LEFT($G112,2), INDEX(設定!$X$9:$X$12,MATCH(LEFT($G112,2), 設定!$W$9:$W$12,0))), $G112) | G112: {=IF($K112="","",INDEX(聲母對照資料表[],MATCH($O112,聲母碼,0),7) & INDEX(韻母對照資料表[],MATCH($P112,韻母碼,0),7) & INDEX(方音符號聲調,$Q112))} | I112: {=IF($K112="", "", $U112 & INDEX(設定!$E$2:$E$9, $Q112) & 漢字查音!$T112)}
B113: =IF( $K113="", "", L113) | C113: =IF($K113="","", INDEX(聲母對照資料表[], MATCH($O113,聲母碼,0), 5) & $P113 & $Q113 ) | D113: =IF($K113="","", INDEX(聲母對照資料表[], MATCH($O113,聲母碼,0), 4) & INDEX(韻母對照資料表[], MATCH($P113, 韻母碼,0), 4) & $Q113 ) | E113: {=IF($K113="","",INDEX(聲母對照資料表[],MATCH($O113,聲母碼,0),6) & INDEX(韻母對照資料表[],MATCH($P113,韻母碼,0),6) & INDEX(閩拼八聲調,$Q113))} | F113: =IFERROR( SUBSTITUTE($G113, LEFT($G113,2), INDEX(設定!$X$9:$X$12,MATCH(LEFT($G113,2), 設定!$W$9:$W$12,0))), $G113) | G113: {=IF($K113="","",INDEX(聲母對照資料表[],MATCH($O113,聲母碼,0),7) & INDEX(韻母對照資料表[],MATCH($P113,韻母碼,0),7) & INDEX(方音符號聲調,$Q113))} | I113: {=IF($K113="", "", $U113 & INDEX(設定!$E$2:$E$9, $Q113) & 漢字查音!$T113)}
B114: =IF( $K114="", "", L114) | C114: =IF($K114="","", INDEX(聲母對照資料表[], MATCH($O114,聲母碼,0), 5) & $P114 & $Q114 ) | D114: =IF($K114="","", INDEX(聲母對照資料表[], MATCH($O114,聲母碼,0), 4) & INDEX(韻母對照資料表[], MATCH($P114, 韻母碼,0), 4) & $Q114 ) | E114: {=IF($K114="","",INDEX(聲母對照資料表[],MATCH($O114,聲母碼,0),6) & INDEX(韻母對照資料表[],MATCH($P114,韻母碼,0),6) & INDEX(閩拼八聲調,$Q114))} | F114: =IFERROR( SUBSTITUTE($G114, LEFT($G114,2), INDEX(設定!$X$9:$X$12,MATCH(LEFT($G114,2), 設定!$W$9:$W$12,0))), $G114) | G114: {=IF($K114="","",INDEX(聲母對照資料表[],MATCH($O114,聲母碼,0),7) & INDEX(韻母對照資料表[],MATCH($P114,韻母碼,0),7) & INDEX(方音符號聲調,$Q114))} | I114: {=IF($K114="", "", $U114 & INDEX(設定!$E$2:$E$9, $Q114) & 漢字查音!$T114)}
B115: =IF( $K115="", "", L115) | C115: =IF($K115="","", INDEX(聲母對照資料表[], MATCH($O115,聲母碼,0), 5) & $P115 & $Q115 ) | D115: =IF($K115="","", INDEX(聲母對照資料表[], MATCH($O115,聲母碼,0), 4) & INDEX(韻母對照資料表[], MATCH($P115, 韻母碼,0), 4) & $Q115 ) | E115: {=IF($K115="","",INDEX(聲母對照資料表[],MATCH($O115,聲母碼,0),6) & INDEX(韻母對照資料表[],MATCH($P115,韻母碼,0),6) & INDEX(閩拼八聲調,$Q115))} | F115: =IFERROR( SUBSTITUTE($G115, LEFT($G115,2), INDEX(設定!$X$9:$X$12,MATCH(LEFT($G115,2), 設定!$W$9:$W$12,0))), $G115) | G115: {=IF($K115="","",INDEX(聲母對照資料表[],MATCH($O115,聲母碼,0),7) & INDEX(韻母對照資料表[],MATCH($P115,韻母碼,0),7) & INDEX(方音符號聲調,$Q115))} | I115: {=IF($K115="", "", $U115 & INDEX(設定!$E$2:$E$9, $Q115) & 漢字查音!$T115)}
B116: =IF( $K116="", "", L116) | C116: =IF($K116="","", INDEX(聲母對照資料表[], MATCH($O116,聲母碼,0), 5) & $P116 & $Q116 ) | D116: =IF($K116="","", INDEX(聲母對照資料表[], MATCH($O116,聲母碼,0), 4) & INDEX(韻母對照資料表[], MATCH($P116, 韻母碼,0), 4) & $Q116 ) | E116: {=IF($K116="","",INDEX(聲母對照資料表[],MATCH($O116,聲母碼,0),6) & INDEX(韻母對照資料表[],MATCH($P116,韻母碼,0),6) & INDEX(閩拼八聲調,$Q116))} | F116: =IFERROR( SUBSTITUTE($G116, LEFT($G116,2), INDEX(設定!$X$9:$X$12,MATCH(LEFT($G116,2), 設定!$W$9:$W$12,0))), $G116) | G116: {=IF($K116="","",INDEX(聲母對照資料表[],MATCH($O116,聲母碼,0),7) & INDEX(韻母對照資料表[],MATCH($P116,韻母碼,0),7) & INDEX(方音符號聲調,$Q116))} | I116: {=IF($K116="", "", $U116 & INDEX(設定!$E$2:$E$9, $Q116) & 漢字查音!$T116)}
... B127: =IF( $K127="", "", L127) | C127: =IF($K127="","", INDEX(聲母對照資料表[], MATCH($O127,聲母碼,0), 5) & $P127 & $Q127 ) | D127: =IF($K127="","", INDEX(聲母對照資料表[], MATCH($O127,聲母碼,0), 4) & INDEX(韻母對照資料表[], MATCH($P127, 韻母碼,0), 4) & $Q127 ) | E127: {=IF($K127="","",INDEX(聲母對照資料表[],MATCH($O127,聲母碼,0),6) & INDEX(韻母對照資料表[],MATCH($P127,韻母碼,0),6) & INDEX(閩拼八聲調,$Q127))} | F127: =IFERROR( SUBSTITUTE($G127, LEFT($G127,2), INDEX(設定!$X$9:$X$12,MATCH(LEFT($G127,2), 設定!$W$9:$W$12,0))), $G127) | G127: {=IF($K127="","",INDEX(聲母對照資料表[],MATCH($O127,聲母碼,0),7) & INDEX(韻母對照資料表[],MATCH($P127,韻母碼,0),7) & INDEX(方音符號聲調,$Q127))} | I127: {=IF($K127="", "", $U127 & INDEX(設定!$E$2:$E$9, $Q127) & 漢字查音!$T127)}
B128: =IF($K128="", "", $L128) | C128: =IF($K128="","", INDEX(聲母對照資料表[], MATCH(N128,聲母碼,0), 5) & O128 & P128 ) | D128: =IF($K128="", "", $R128) | I128: =IF(OR($K128="", $M128=""), "", $M128)
B129: =IF($K129="", "", $L129) | C129: =IF($K129="","", INDEX(聲母對照資料表[], MATCH(N129,聲母碼,0), 5) & O129 & P129 ) | D129: =IF($K129="", "", $R129) | I129: =IF(OR($K129="", $M129=""), "", $M129)
B130: =IF($K130="", "", $L130) | C130: =IF($K130="","", INDEX(聲母對照資料表[], MATCH(N130,聲母碼,0), 5) & O130 & P130 ) | D130: =IF($K130="", "", $R130) | I130: =IF(OR($K130="", $M130=""), "", $M130)
B131: =IF($K131="", "", $L131) | C131: =IF($K131="","", INDEX(聲母對照資料表[], MATCH(N131,聲母碼,0), 5) & O131 & P131 ) | D131: =IF($K131="", "", $R131) | I131: =IF(OR($K131="", $M131=""), "", $M131)
B132: =IF($K132="", "", $L132) | C132: =IF($K132="","", INDEX(聲母對照資料表[], MATCH(N132,聲母碼,0), 5) & O132 & P132 ) | D132: =IF($K132="", "", $R132) | I132: =IF(OR($K132="", $M132=""), "", $M132)
B133: =IF($K133="", "", $L133) | C133: =IF($K133="","", INDEX(聲母對照資料表[], MATCH(N133,聲母碼,0), 5) & O133 & P133 ) | D133: =IF($K133="", "", $R133) | I133: =IF(OR($K133="", $M133=""), "", $M133)
B134: =IF($K134="", "", $L134) | C134: =IF($K134="","", INDEX(聲母對照資料表[], MATCH(N134,聲母碼,0), 5) & O134 & P134 ) | D134: =IF($K134="", "", $R134) | I134: =IF(OR($K134="", $M134=""), "", $M134)

Sheet 漢字查音 (多字)
B1: 漢字 | K1: 識別號 | L1: 漢字 | M1: 切音 | N1: 字韻 | O1: 聲調 | P1: 原資料拼音 | Q1: 舒促聲 | R1: 聲 | S1: 韻 | T1: 調 | U1: 拼音碼 | V1: 雅俗通標音 | W1: 十五音標音 | X1: 常用度 | Z1: 雅俗通字典[#全部]
B2: 土 | L2: =B2 -> 土
B3: 塗 | L3: =IF(B3="", "",B3) -> 塗
L4: =IF(B4="", "",B4)
B6: 漢字 | C6: 台羅拼音 | D6: 白話字拼音 | E6: 閩拼標音 | F6: 方音符號 | H6: 十五音標音 | I6: 雅俗通標音 | K6: 識別號 | L6: 漢字 | M6: 切音 | N6: 字韻 | O6: 聲調 | P6: 原資料拼音 | Q6: 舒促聲 | R6: 聲 | S6: 韻 | T6: 調 | U6: 拼音碼 | V6: 雅俗通標音 | W6: 十五音標音 | X6: 常用度
B7: =IF( $K7="", "", L7) -> 千 | C7: =IF($K7="","", IF($N7="英", "", INDEX(聲母對照資料表[], MATCH($R7,聲母碼,0), 5)) & $S7 & $T7 ) -> tshian1 | D7: =IF($K7="","", IF($N7="英", "", INDEX(聲母對照資料表[], MATCH($R7,聲母碼,0), 5)) & INDEX(韻母對照資料表[], MATCH($S7, 韻母碼,0), 4) & $T7 ) -> tshian1 | E7: {=IF($K7="","", IF($N7="英", "", INDEX(聲母對照資料表[], MATCH($R7,聲母碼,0), 5)) & INDEX(韻母對照資料表[],MATCH($S7,韻母碼,0),6) & INDEX(閩拼八聲調,$T7))} -> tshian1 | F7: =IFERROR( SUBSTITUTE($G7, LEFT($G7,2), INDEX(設定!$X$9:$X$12,MATCH(LEFT($G7,2), 設定!$W$9:$W$12,0))), $G7) -> ˉ | G7: {=IF($K7="","", IF($N7="英", "", INDEX(聲母對照資料表[],MATCH($R7,聲母碼,0),7)) & INDEX(韻母對照資料表[],MATCH($S7,韻母碼,0),7) & INDEX(方音符號聲調,$T7))} -> ˉ | H7: =IF($K7="", "", $X7) -> 堅一出 | I7: =IF($K7="", "", $W7) -> 堅上平聲出 | J7: =IF($M7="", "", $Y7) | K7: 724 | L7: 千 | N7: 出 | O7: 堅 | P7: 上平 | Q7: 舒聲 | R7: c | S7: ian | T7: 1 | U7: cian1 | V7: tshian1 | W7: 堅上平聲出 | X7: 堅一出
B8: =IF( $K8="", "", L8) -> 剪 | C8: =IF($K8="","", IF($N8="英", "", INDEX(聲母對照資料表[], MATCH($R8,聲母碼,0), 5)) & $S8 & $T8 ) -> tsian2 | D8: =IF($K8="","", IF($N8="英", "", INDEX(聲母對照資料表[], MATCH($R8,聲母碼,0), 5)) & INDEX(韻母對照資料表[], MATCH($S8, 韻母碼,0), 4) & $T8 ) -> tsian2 | E8: {=IF($K8="","", IF($N8="英", "", INDEX(聲母對照資料表[], MATCH($R8,聲母碼,0), 5)) & INDEX(韻母對照資料表[],MATCH($S8,韻母碼,0),6) & INDEX(閩拼八聲調,$T8))} -> tsian3 | F8: =IFERROR( SUBSTITUTE($G8, LEFT($G8,2), INDEX(設定!$X$9:$X$12,MATCH(LEFT($G8,2), 設定!$W$9:$W$12,0))), $G8) -> ˋ | G8: {=IF($K8="","", IF($N8="英", "", INDEX(聲母對照資料表[],MATCH($R8,聲母碼,0),7)) & INDEX(韻母對照資料表[],MATCH($S8,韻母碼,0),7) & INDEX(方音符號聲調,$T8))} -> ˋ | H8: =IF($K8="", "", $X8) -> 堅二曾 | I8: =IF($K8="", "", $W8) -> 堅上上聲曾 | K8: 796 | L8: 剪 | N8: 曾 | O8: 堅 | P8: 上上 | Q8: 舒聲 | R8: z | S8: ian | T8: 2 | U8: zian2 | V8: tsian2 | W8: 堅上上聲曾 | X8: 堅二曾
B9: =IF( $K9="", "", L9) -> 濁 | C9: =IF($K9="","", IF($N9="英", "", INDEX(聲母對照資料表[], MATCH($R9,聲母碼,0), 5)) & $S9 & $T9 ) -> tsok8 | D9: =IF($K9="","", IF($N9="英", "", INDEX(聲母對照資料表[], MATCH($R9,聲母碼,0), 5)) & INDEX(韻母對照資料表[], MATCH($S9, 韻母碼,0), 4) & $T9 ) -> tsok8 | E9: {=IF($K9="","", IF($N9="英", "", INDEX(聲母對照資料表[], MATCH($R9,聲母碼,0), 5)) & INDEX(韻母對照資料表[],MATCH($S9,韻母碼,0),6) & INDEX(閩拼八聲調,$T9))} -> tsok8 | F9: =IFERROR( SUBSTITUTE($G9, LEFT($G9,2), INDEX(設定!$X$9:$X$12,MATCH(LEFT($G9,2), 設定!$W$9:$W$12,0))), $G9) -> ˙ | G9: {=IF($K9="","", IF($N9="英", "", INDEX(聲母對照資料表[],MATCH($R9,聲母碼,0),7)) & INDEX(韻母對照資料表[],MATCH($S9,韻母碼,0),7) & INDEX(方音符號聲調,$T9))} -> ˙ | H9: =IF($K9="", "", $X9) -> 公八曾 | I9: =IF($K9="", "", $W9) -> 公下入聲曾 | K9: 3014 | L9: 濁 | N9: 曾 | O9: 公 | P9: 下入 | Q9: 促聲 | R9: z | S9: ok | T9: 8 | U9: zok8 | V9: tsok8 | W9: 公下入聲曾 | X9: 公八曾
B10: =IF( $K10="", "", L10) | C10: =IF($K10="","", IF($N10="英", "", INDEX(聲母對照資料表[], MATCH($R10,聲母碼,0), 5)) & $S10 & $T10 ) | D10: =IF($K10="","", IF($N10="英", "", INDEX(聲母對照資料表[], MATCH($R10,聲母碼,0), 5)) & INDEX(韻母對照資料表[], MATCH($S10, 韻母碼,0), 4) & $T10 ) | E10: {=IF($K10="","", IF($N10="英", "", INDEX(聲母對照資料表[], MATCH($R10,聲母碼,0), 5)) & INDEX(韻母對照資料表[],MATCH($S10,韻母碼,0),6) & INDEX(閩拼八聲調,$T10))} | F10: =IFERROR( SUBSTITUTE($G10, LEFT($G10,2), INDEX(設定!$X$9:$X$12,MATCH(LEFT($G10,2), 設定!$W$9:$W$12,0))), $G10) | G10: {=IF($K10="","", IF($N10="英", "", INDEX(聲母對照資料表[],MATCH($R10,聲母碼,0),7)) & INDEX(韻母對照資料表[],MATCH($S10,韻母碼,0),7) & INDEX(方音符號聲調,$T10))} | H10: =IF($K10="", "", $X10) | I10: =IF($K10="", "", $W10)
B11: =IF( $K11="", "", L11) | C11: =IF($K11="","", IF($N11="英", "", INDEX(聲母對照資料表[], MATCH($R11,聲母碼,0), 5)) & $S11 & $T11 ) | D11: =IF($K11="","", IF($N11="英", "", INDEX(聲母對照資料表[], MATCH($R11,聲母碼,0), 5)) & INDEX(韻母對照資料表[], MATCH($S11, 韻母碼,0), 4) & $T11 ) | E11: {=IF($K11="","", IF($N11="英", "", INDEX(聲母對照資料表[], MATCH($R11,聲母碼,0), 5)) & INDEX(韻母對照資料表[],MATCH($S11,韻母碼,0),6) & INDEX(閩拼八聲調,$T11))} | F11: =IFERROR( SUBSTITUTE($G11, LEFT($G11,2), INDEX(設定!$X$9:$X$12,MATCH(LEFT($G11,2), 設定!$W$9:$W$12,0))), $G11) | G11: {=IF($K11="","", IF($N11="英", "", INDEX(聲母對照資料表[],MATCH($R11,聲母碼,0),7)) & INDEX(韻母對照資料表[],MATCH($S11,韻母碼,0),7) & INDEX(方音符號聲調,$T11))} | H11: =IF($K11="", "", $X11) | I11: =IF($K11="", "", $W11)
B12: =IF( $K12="", "", L12) | C12: =IF($K12="","", IF($N12="英", "", INDEX(聲母對照資料表[], MATCH($R12,聲母碼,0), 5)) & $S12 & $T12 ) | D12: =IF($K12="","", IF($N12="英", "", INDEX(聲母對照資料表[], MATCH($R12,聲母碼,0), 5)) & INDEX(韻母對照資料表[], MATCH($S12, 韻母碼,0), 4) & $T12 ) | E12: {=IF($K12="","", IF($N12="英", "", INDEX(聲母對照資料表[], MATCH($R12,聲母碼,0), 5)) & INDEX(韻母對照資料表[],MATCH($S12,韻母碼,0),6) & INDEX(閩拼八聲調,$T12))} | F12: =IFERROR( SUBSTITUTE($G12, LEFT($G12,2), INDEX(設定!$X$9:$X$12,MATCH(LEFT($G12,2), 設定!$W$9:$W$12,0))), $G12) | G12: {=IF($K12="","", IF($N12="英", "", INDEX(聲母對照資料表[],MATCH($R12,聲母碼,0),7)) & INDEX(韻母對照資料表[],MATCH($S12,韻母碼,0),7) & INDEX(方音符號聲調,$T12))} | H12: =IF($K12="", "", $X12) | I12: =IF($K12="", "", $W12)
B13: =IF( $K13="", "", L13) | C13: =IF($K13="","", IF($N13="英", "", INDEX(聲母對照資料表[], MATCH($R13,聲母碼,0), 5)) & $S13 & $T13 ) | D13: =IF($K13="","", IF($N13="英", "", INDEX(聲母對照資料表[], MATCH($R13,聲母碼,0), 5)) & INDEX(韻母對照資料表[], MATCH($S13, 韻母碼,0), 4) & $T13 ) | E13: {=IF($K13="","", IF($N13="英", "", INDEX(聲母對照資料表[], MATCH($R13,聲母碼,0), 5)) & INDEX(韻母對照資料表[],MATCH($S13,韻母碼,0),6) & INDEX(閩拼八聲調,$T13))} | F13: =IFERROR( SUBSTITUTE($G13, LEFT($G13,2), INDEX(設定!$X$9:$X$12,MATCH(LEFT($G13,2), 設定!$W$9:$W$12,0))), $G13) | G13: {=IF($K13="","", IF($N13="英", "", INDEX(聲母對照資料表[],MATCH($R13,聲母碼,0),7)) & INDEX(韻母對照資料表[],MATCH($S13,韻母碼,0),7) & INDEX(方音符號聲調,$T13))} | H13: =IF($K13="", "", $X13) | I13: =IF($K13="", "", $W13)
B14: =IF( $K14="", "", L14) | C14: =IF($K14="","", IF($N14="英", "", INDEX(聲母對照資料表[], MATCH($R14,聲母碼,0), 5)) & $S14 & $T14 ) | D14: =IF($K14="","", IF($N14="英", "", INDEX(聲母對照資料表[], MATCH($R14,聲母碼,0), 5)) & INDEX(韻母對照資料表[], MATCH($S14, 韻母碼,0), 4) & $T14 ) | E14: {=IF($K14="","", IF($N14="英", "", INDEX(聲母對照資料表[], MATCH($R14,聲母碼,0), 5)) & INDEX(韻母對照資料表[],MATCH($S14,韻母碼,0),6) & INDEX(閩拼八聲調,$T14))} | F14: =IFERROR( SUBSTITUTE($G14, LEFT($G14,2), INDEX(設定!$X$9:$X$12,MATCH(LEFT($G14,2), 設定!$W$9:$W$12,0))), $G14) | G14: {=IF($K14="","", IF($N14="英", "", INDEX(聲母對照資料表[],MATCH($R14,聲母碼,0),7)) & INDEX(韻母對照資料表[],MATCH($S14,韻母碼,0),7) & INDEX(方音符號聲調,$T14))} | H14: =IF($K14="", "", $X14) | I14: =IF($K14="", "", $W14)
B15: =IF( $K15="", "", L15) | C15: =IF($K15="","", IF($N15="英", "", INDEX(聲母對照資料表[], MATCH($R15,聲母碼,0), 5)) & $S15 & $T15 ) | D15: =IF($K15="","", IF($N15="英", "", INDEX(聲母對照資料表[], MATCH($R15,聲母碼,0), 5)) & INDEX(韻母對照資料表[], MATCH($S15, 韻母碼,0), 4) & $T15 ) | E15: {=IF($K15="","", IF($N15="英", "", INDEX(聲母對照資料表[], MATCH($R15,聲母碼,0), 5)) & INDEX(韻母對照資料表[],MATCH($S15,韻母碼,0),6) & INDEX(閩拼八聲調,$T15))} | F15: =IFERROR( SUBSTITUTE($G15, LEFT($G15,2), INDEX(設定!$X$9:$X$12,MATCH(LEFT($G15,2), 設定!$W$9:$W$12,0))), $G15) | G15: {=IF($K15="","", IF($N15="英", "", INDEX(聲母對照資料表[],MATCH($R15,聲母碼,0),7)) & INDEX(韻母對照資料表[],MATCH($S15,韻母碼,0),7) & INDEX(方音符號聲調,$T15))} | H15: =IF($K15="", "", $X15) | I15: =IF($K15="", "", $W15)
B16: =IF( $K16="", "", L16) | C16: =IF($K16="","", IF($N16="英", "", INDEX(聲母對照資料表[], MATCH($R16,聲母碼,0), 5)) & $S16 & $T16 ) | D16: =IF($K16="","", IF($N16="英", "", INDEX(聲母對照資料表[], MATCH($R16,聲母碼,0), 5)) & INDEX(韻母對照資料表[], MATCH($S16, 韻母碼,0), 4) & $T16 ) | E16: {=IF($K16="","", IF($N16="英", "", INDEX(聲母對照資料表[], MATCH($R16,聲母碼,0), 5)) & INDEX(韻母對照資料表[],MATCH($S16,韻母碼,0),6) & INDEX(閩拼八聲調,$T16))} | F16: =IFERROR( SUBSTITUTE($G16, LEFT($G16,2), INDEX(設定!$X$9:$X$12,MATCH(LEFT($G16,2), 設定!$W$9:$W$12,0))), $G16) | G16: {=IF($K16="","", IF($N16="英", "", INDEX(聲母對照資料表[],MATCH($R16,聲母碼,0),7)) & INDEX(韻母對照資料表[],MATCH($S16,韻母碼,0),7) & INDEX(方音符號聲調,$T16))} | H16: =IF($K16="", "", $X16) | I16: =IF($K16="", "", $W16)
B17: =IF( $K17="", "", L17) | C17: =IF($K17="","", IF($N17="英", "", INDEX(聲母對照資料表[], MATCH($R17,聲母碼,0), 5)) & $S17 & $T17 ) | D17: =IF($K17="","", IF($N17="英", "", INDEX(聲母對照資料表[], MATCH($R17,聲母碼,0), 5)) & INDEX(韻母對照資料表[], MATCH($S17, 韻母碼,0), 4) & $T17 ) | E17: {=IF($K17="","", IF($N17="英", "", INDEX(聲母對照資料表[], MATCH($R17,聲母碼,0), 5)) & INDEX(韻母對照資料表[],MATCH($S17,韻母碼,0),6) & INDEX(閩拼八聲調,$T17))} | F17: =IFERROR( SUBSTITUTE($G17, LEFT($G17,2), INDEX(設定!$X$9:$X$12,MATCH(LEFT($G17,2), 設定!$W$9:$W$12,0))), $G17) | G17: {=IF($K17="","", IF($N17="英", "", INDEX(聲母對照資料表[],MATCH($R17,聲母碼,0),7)) & INDEX(韻母對照資料表[],MATCH($S17,韻母碼,0),7) & INDEX(方音符號聲調,$T17))} | H17: =IF($K17="", "", $X17) | I17: =IF($K17="", "", $W17)
B18: =IF( $K18="", "", L18) | C18: =IF($K18="","", IF($N18="英", "", INDEX(聲母對照資料表[], MATCH($R18,聲母碼,0), 5)) & $S18 & $T18 ) | D18: =IF($K18="","", IF($N18="英", "", INDEX(聲母對照資料表[], MATCH($R18,聲母碼,0), 5)) & INDEX(韻母對照資料表[], MATCH($S18, 韻母碼,0), 4) & $T18 ) | E18: {=IF($K18="","", IF($N18="英", "", INDEX(聲母對照資料表[], MATCH($R18,聲母碼,0), 5)) & INDEX(韻母對照資料表[],MATCH($S18,韻母碼,0),6) & INDEX(閩拼八聲調,$T18))} | F18: =IFERROR( SUBSTITUTE($G18, LEFT($G18,2), INDEX(設定!$X$9:$X$12,MATCH(LEFT($G18,2), 設定!$W$9:$W$12,0))), $G18) | G18: {=IF($K18="","", IF($N18="英", "", INDEX(聲母對照資料表[],MATCH($R18,聲母碼,0),7)) & INDEX(韻母對照資料表[],MATCH($S18,韻母碼,0),7) & INDEX(方音符號聲調,$T18))} | H18: =IF($K18="", "", $X18) | I18: =IF($K18="", "", $W18)
B19: =IF( $K19="", "", L19) | C19: =IF($K19="","", IF($N19="英", "", INDEX(聲母對照資料表[], MATCH($R19,聲母碼,0), 5)) & $S19 & $T19 ) | D19: =IF($K19="","", IF($N19="英", "", INDEX(聲母對照資料表[], MATCH($R19,聲母碼,0), 5)) & INDEX(韻母對照資料表[], MATCH($S19, 韻母碼,0), 4) & $T19 ) | E19: {=IF($K19="","", IF($N19="英", "", INDEX(聲母對照資料表[], MATCH($R19,聲母碼,0), 5)) & INDEX(韻母對照資料表[],MATCH($S19,韻母碼,0),6) & INDEX(閩拼八聲調,$T19))} | F19: =IFERROR( SUBSTITUTE($G19, LEFT($G19,2), INDEX(設定!$X$9:$X$12,MATCH(LEFT($G19,2), 設定!$W$9:$W$12,0))), $G19) | G19: {=IF($K19="","", IF($N19="英", "", INDEX(聲母對照資料表[],MATCH($R19,聲母碼,0),7)) & INDEX(韻母對照資料表[],MATCH($S19,韻母碼,0),7) & INDEX(方音符號聲調,$T19))} | H19: =IF($K19="", "", $X19) | I19: =IF($K19="", "", $W19)
B20: =IF( $K20="", "", L20) | C20: =IF($K20="","", IF($N20="英", "", INDEX(聲母對照資料表[], MATCH($R20,聲母碼,0), 5)) & $S20 & $T20 ) | D20: =IF($K20="","", IF($N20="英", "", INDEX(聲母對照資料表[], MATCH($R20,聲母碼,0), 5)) & INDEX(韻母對照資料表[], MATCH($S20, 韻母碼,0), 4) & $T20 ) | E20: {=IF($K20="","", IF($N20="英", "", INDEX(聲母對照資料表[], MATCH($R20,聲母碼,0), 5)) & INDEX(韻母對照資料表[],MATCH($S20,韻母碼,0),6) & INDEX(閩拼八聲調,$T20))} | F20: =IFERROR( SUBSTITUTE($G20, LEFT($G20,2), INDEX(設定!$X$9:$X$12,MATCH(LEFT($G20,2), 設定!$W$9:$W$12,0))), $G20) | G20: {=IF($K20="","", IF($N20="英", "", INDEX(聲母對照資料表[],MATCH($R20,聲母碼,0),7)) & INDEX(韻母對照資料表[],MATCH($S20,韻母碼,0),7) & INDEX(方音符號聲調,$T20))} | H20: =IF($K20="", "", $X20) | I20: =IF($K20="", "", $W20)
B21: =IF( $K21="", "", L21) | C21: =IF($K21="","", IF($N21="英", "", INDEX(聲母對照資料表[], MATCH($R21,聲母碼,0), 5)) & $S21 & $T21 ) | D21: =IF($K21="","", IF($N21="英", "", INDEX(聲母對照資料表[], MATCH($R21,聲母碼,0), 5)) & INDEX(韻母對照資料表[], MATCH($S21, 韻母碼,0), 4) & $T21 ) | E21: {=IF($K21="","", IF($N21="英", "", INDEX(聲母對照資料表[], MATCH($R21,聲母碼,0), 5)) & INDEX(韻母對照資料表[],MATCH($S21,韻母碼,0),6) & INDEX(閩拼八聲調,$T21))} | F21: =IFERROR( SUBSTITUTE($G21, LEFT($G21,2), INDEX(設定!$X$9:$X$12,MATCH(LEFT($G21,2), 設定!$W$9:$W$12,0))), $G21) | G21: {=IF($K21="","", IF($N21="英", "", INDEX(聲母對照資料表[],MATCH($R21,聲母碼,0),7)) & INDEX(韻母對照資料表[],MATCH($S21,韻母碼,0),7) & INDEX(方音符號聲調,$T21))} | H21: =IF($K21="", "", $X21) | I21: =IF($K21="", "", $W21)
... B32: =IF( $K32="", "", L32) | C32: =IF($K32="","", IF($N32="英", "", INDEX(聲母對照資料表[], MATCH($R32,聲母碼,0), 5)) & $S32 & $T32 ) | D32: =IF($K32="","", IF($N32="英", "", INDEX(聲母對照資料表[], MATCH($R32,聲母碼,0), 5)) & INDEX(韻母對照資料表[], MATCH($S32, 韻母碼,0), 4) & $T32 ) | E32: {=IF($K32="","", IF($N32="英", "", INDEX(聲母對照資料表[], MATCH($R32,聲母碼,0), 5)) & INDEX(韻母對照資料表[],MATCH($S32,韻母碼,0),6) & INDEX(閩拼八聲調,$T32))} | F32: =IFERROR( SUBSTITUTE($G32, LEFT($G32,2), INDEX(設定!$X$9:$X$12,MATCH(LEFT($G32,2), 設定!$W$9:$W$12,0))), $G32) | G32: {=IF($K32="","", IF($N32="英", "", INDEX(聲母對照資料表[],MATCH($R32,聲母碼,0),7)) & INDEX(韻母對照資料表[],MATCH($S32,韻母碼,0),7) & INDEX(方音符號聲調,$T32))} | H32: =IF($K32="", "", $X32) | I32: =IF($K32="", "", $W32)
B33: =IF($K33="", "", $L33) | C33: =IF($K33="", "",#REF!) | D33: =IF($K33="","", INDEX(聲母對照資料表[], MATCH($N33,聲母碼,0), 4) & INDEX(韻母對照資料表[], MATCH($O33, 韻母碼,0), 4) & $P33 ) | E33: =IF($K33="","", INDEX(聲母對照資料表[], MATCH($N33,聲母碼,0), 6) & INDEX(韻母對照資料表[], MATCH($O33, 韻母碼,0), 6) & $P33 ) | F33: {=IF($K33="","",INDEX(聲母對照資料表[],MATCH($N33,聲母碼,0),7)&INDEX(韻母對照資料表[],MATCH($O33,韻母碼,0),7)&INDEX(方音符號聲調,$P33))} | H33: =IF($K33="", "", $R33)
B34: =IF($K34="", "", $L34) | C34: =IF($K34="", "",#REF!) | D34: =IF($K34="","", INDEX(聲母對照資料表[], MATCH($N34,聲母碼,0), 4) & INDEX(韻母對照資料表[], MATCH($O34, 韻母碼,0), 4) & $P34 ) | E34: =IF($K34="","", INDEX(聲母對照資料表[], MATCH($N34,聲母碼,0), 6) & INDEX(韻母對照資料表[], MATCH($O34, 韻母碼,0), 6) & $P34 ) | F34: {=IF($K34="","",INDEX(聲母對照資料表[],MATCH($N34,聲母碼,0),7)&INDEX(韻母對照資料表[],MATCH($O34,韻母碼,0),7)&INDEX(方音符號聲調,$P34))} | H34: =IF($K34="", "", $R34)
B35: =IF($K35="", "", $L35) | C35: =IF($K35="", "",#REF!) | D35: =IF($K35="","", INDEX(聲母對照資料表[], MATCH($N35,聲母碼,0), 4) & INDEX(韻母對照資料表[], MATCH($O35, 韻母碼,0), 4) & $P35 ) | E35: =IF($K35="","", INDEX(聲母對照資料表[], MATCH($N35,聲母碼,0), 6) & INDEX(韻母對照資料表[], MATCH($O35, 韻母碼,0), 6) & $P35 ) | F35: {=IF($K35="","",INDEX(聲母對照資料表[],MATCH($N35,聲母碼,0),7)&INDEX(韻母對照資料表[],MATCH($O35,韻母碼,0),7)&INDEX(方音符號聲調,$P35))} | H35: =IF($K35="", "", $R35)
B36: =IF($K36="", "", $L36) | C36: =IF($K36="", "",#REF!) | D36: =IF($K36="","", INDEX(聲母對照資料表[], MATCH($N36,聲母碼,0), 4) & INDEX(韻母對照資料表[], MATCH($O36, 韻母碼,0), 4) & $P36 ) | E36: =IF($K36="","", INDEX(聲母對照資料表[], MATCH($N36,聲母碼,0), 6) & INDEX(韻母對照資料表[], MATCH($O36, 韻母碼,0), 6) & $P36 ) | F36: {=IF($K36="","",INDEX(聲母對照資料表[],MATCH($N36,聲母碼,0),7)&INDEX(韻母對照資料表[],MATCH($O36,韻母碼,0),7)&INDEX(方音符號聲調,$P36))} | H36: =IF($K36="", "", $R36)
B37: =IF($K37="", "", $L37) | C37: =IF($K37="", "",#REF!) | D37: =IF($K37="","", INDEX(聲母對照資料表[], MATCH($N37,聲母碼,0), 4) & INDEX(韻母對照資料表[], MATCH($O37, 韻母碼,0), 4) & $P37 ) | E37: =IF($K37="","", INDEX(聲母對照資料表[], MATCH($N37,聲母碼,0), 6) & INDEX(韻母對照資料表[], MATCH($O37, 韻母碼,0), 6) & $P37 ) | F37: {=IF($K37="","",INDEX(聲母對照資料表[],MATCH($N37,聲母碼,0),7)&INDEX(韻母對照資料表[],MATCH($O37,韻母碼,0),7)&INDEX(方音符號聲調,$P37))} | H37: =IF($K37="", "", $R37)
B38: =IF($K38="", "", $L38) | C38: =IF($K38="", "",#REF!) | D38: =IF($K38="","", INDEX(聲母對照資料表[], MATCH($N38,聲母碼,0), 4) & INDEX(韻母對照資料表[], MATCH($O38, 韻母碼,0), 4) & $P38 ) | E38: =IF($K38="","", INDEX(聲母對照資料表[], MATCH($N38,聲母碼,0), 6) & INDEX(韻母對照資料表[], MATCH($O38, 韻母碼,0), 6) & $P38 ) | F38: {=IF($K38="","",INDEX(聲母對照資料表[],MATCH($N38,聲母碼,0),7)&INDEX(韻母對照資料表[],MATCH($O38,韻母碼,0),7)&INDEX(方音符號聲調,$P38))} | H38: =IF($K38="", "", $R38)
B39: =IF($K39="", "", $L39) | C39: =IF($K39="", "",#REF!) | D39: =IF($K39="","", INDEX(聲母對照資料表[], MATCH($N39,聲母碼,0), 4) & INDEX(韻母對照資料表[], MATCH($O39, 韻母碼,0), 4) & $P39 ) | E39: =IF($K39="","", INDEX(聲母對照資料表[], MATCH($N39,聲母碼,0), 6) & INDEX(韻母對照資料表[], MATCH($O39, 韻母碼,0), 6) & $P39 ) | F39: {=IF($K39="","",INDEX(聲母對照資料表[],MATCH($N39,聲母碼,0),7)&INDEX(韻母對照資料表[],MATCH($O39,韻母碼,0),7)&INDEX(方音符號聲調,$P39))} | H39: =IF($K39="", "", $R39)
B40: =IF($K40="", "", $L40) | C40: =IF($K40="", "",#REF!) | D40: =IF($K40="","", INDEX(聲母對照資料表[], MATCH($N40,聲母碼,0), 4) & INDEX(韻母對照資料表[], MATCH($O40, 韻母碼,0), 4) & $P40 ) | E40: =IF($K40="","", INDEX(聲母對照資料表[], MATCH($N40,聲母碼,0), 6) & INDEX(韻母對照資料表[], MATCH($O40, 韻母碼,0), 6) & $P40 ) | F40: {=IF($K40="","",INDEX(聲母對照資料表[],MATCH($N40,聲母碼,0),7)&INDEX(韻母對照資料表[],MATCH($O40,韻母碼,0),7)&INDEX(方音符號聲調,$P40))} | H40: =IF($K40="", "", $R40)
B41: =IF($K41="", "", $L41) | C41: =IF($K41="", "",#REF!) | D41: =IF($K41="","", INDEX(聲母對照資料表[], MATCH($N41,聲母碼,0), 4) & INDEX(韻母對照資料表[], MATCH($O41, 韻母碼,0), 4) & $P41 ) | E41: =IF($K41="","", INDEX(聲母對照資料表[], MATCH($N41,聲母碼,0), 6) & INDEX(韻母對照資料表[], MATCH($O41, 韻母碼,0), 6) & $P41 ) | F41: {=IF($K41="","",INDEX(聲母對照資料表[],MATCH($N41,聲母碼,0),7)&INDEX(韻母對照資料表[],MATCH($O41,韻母碼,0),7)&INDEX(方音符號聲調,$P41))} | H41: =IF($K41="", "", $R41)
B42: =IF($K42="", "", $L42) | C42: =IF($K42="", "",#REF!) | D42: =IF($K42="","", INDEX(聲母對照資料表[], MATCH($N42,聲母碼,0), 4) & INDEX(韻母對照資料表[], MATCH($O42, 韻母碼,0), 4) & $P42 ) | E42: =IF($K42="","", INDEX(聲母對照資料表[], MATCH($N42,聲母碼,0), 6) & INDEX(韻母對照資料表[], MATCH($O42, 韻母碼,0), 6) & $P42 ) | F42: {=IF($K42="","",INDEX(聲母對照資料表[],MATCH($N42,聲母碼,0),7)&INDEX(韻母對照資料表[],MATCH($O42,韻母碼,0),7)&INDEX(方音符號聲調,$P42))} | H42: =IF($K42="", "", $R42)
B43: =IF($K43="", "", $L43) | C43: =IF($K43="", "",#REF!) | D43: =IF($K43="","", INDEX(聲母對照資料表[], MATCH($N43,聲母碼,0), 4) & INDEX(韻母對照資料表[], MATCH($O43, 韻母碼,0), 4) & $P43 ) | E43: =IF($K43="","", INDEX(聲母對照資料表[], MATCH($N43,聲母碼,0), 6) & INDEX(韻母對照資料表[], MATCH($O43, 韻母碼,0), 6) & $P43 ) | F43: {=IF($K43="","",INDEX(聲母對照資料表[],MATCH($N43,聲母碼,0),7)&INDEX(韻母對照資料表[],MATCH($O43,韻母碼,0),7)&INDEX(方音符號聲調,$P43))} | H43: =IF($K43="", "", $R43)
B44: =IF($K44="", "", $L44) | C44: =IF($K44="", "",#REF!) | D44: =IF($K44="","", INDEX(聲母對照資料表[], MATCH($N44,聲母碼,0), 4) & INDEX(韻母對照資料表[], MATCH($O44, 韻母碼,0), 4) & $P44 ) | E44: =IF($K44="","", INDEX(聲母對照資料表[], MATCH($N44,聲母碼,0), 6) & INDEX(韻母對照資料表[], MATCH($O44, 韻母碼,0), 6) & $P44 ) | F44: {=IF($K44="","",INDEX(聲母對照資料表[],MATCH($N44,聲母碼,0),7)&INDEX(韻母對照資料表[],MATCH($O44,韻母碼,0),7)&INDEX(方音符號聲調,$P44))} | H44: =IF($K44="", "", $R44)
... B136: =IF($K136="", "", $L136) | C136: =IF($K136="", "",#REF!) | D136: =IF($K136="","", INDEX(聲母對照資料表[], MATCH($N136,聲母碼,0), 4) & INDEX(韻母對照資料表[], MATCH($O136, 韻母碼,0), 4) & $P136 ) | E136: =IF($K136="","", INDEX(聲母對照資料表[], MATCH($N136,聲母碼,0), 6) & INDEX(韻母對照資料表[], MATCH($O136, 韻母碼,0), 6) & $P136 ) | F136: {=IF($K136="","",INDEX(聲母對照資料表[],MATCH($N136,聲母碼,0),7)&INDEX(韻母對照資料表[],MATCH($O136,韻母碼,0),7)&INDEX(方音符號聲調,$P136))} | H136: =IF($K136="", "", $R136)

Sheet 十五音查詢 (PY)
O1: 【聲母】 | R1: 【韻母】
B2: 前 | D2: 聲／韻／調 | E2: 台語音標 | F2: 方音符號 | G2: 雅俗通 | H2: 十五音 | I2: 方音符號 | J2: 國際音標 | K2: 白話字 | L2: 閩拼 | M2: 台羅拼音 | O2: 拼音類別 | P2: 聲母欄位 | R2: 雅俗通韻母 | S2: 韻母聲類 | T2: 韻母序號 | V2: 韻母識別號 | W2: 雅俗通 | X2: 方音符號 | Y2: 國際音標 | Z2: 白話字 | AA2: 閩拼方案 | AB2: 台羅拼音
D3: 聲母 | E3: =IF(OR(LEFT(B7,2)="kh",LEFT(B7,2)="ph",LEFT(B7,2)="th",LEFT(B7,2)="ng"),LEFT(B7,2),LEFT(B7,1)) -> z | F3: {=_xlfn.XLOOKUP($E$3,聲母碼,聲母對照資料表[方音])} -> ㄗ | G3: =_xlfn.CONCAT(R3,_xlfn.XLOOKUP($E$5, 聲調表[傳統八聲調], 聲調表[雅俗通調號]),P3) -> 堅五曾 | H3: =_xlfn.CONCAT(P3, R3,_xlfn.XLOOKUP($E$5, 聲調表[傳統八聲調], 聲調表[方音符號調符])) -> 曾堅ˊ | I3: =_xlfn.CONCAT(P4,X3,_xlfn.XLOOKUP($E$5, 聲調表[傳統八聲調], 聲調表[方音符號調符])) -> ㄗㄧㄢˊ | J3: =_xlfn.CONCAT(P5,Y3,E5) -> ʦian5 | K3: {=_xlfn._xlws.PY(1,1,E3,E4,E5)} -> ziân | L3: =_xlfn.CONCAT(P7,AA3,E5) -> zian5 | M3: =_xlfn.CONCAT(P8,AB3,E5) -> tsian5 | O3: 雅俗通 | P3: {=_xlfn.XLOOKUP($E$3,聲母碼,聲母對照資料表[十五音])} -> 曾 | R3: {=_xlfn.XLOOKUP('十五音查詢 (PY)'!E4, 韻母碼, 韻母對照資料表[十五音])} -> 堅 | S3: 舒聲 | T3: =_xlfn.XLOOKUP(_xlfn.CONCAT(R3,LEFT(S3)), 韻母對照資料表[十五音識別碼], 韻母對照資料表[識別號]) -> 3 | V3: =IF(OR(E5=4,E5=8),T4,T3) -> 3 | W3: {=_xlfn.XLOOKUP('十五音查詢 (PY)'!E4, 韻母碼, 韻母對照資料表[十五音])} -> 堅 | X3: {=INDEX(韻母對照資料表[方音], $V3)} -> ㄧㄢ | Y3: {=INDEX(韻母對照資料表[國際音標], $V3)} -> ian | Z3: {=INDEX(韻母對照資料表[白話字], $V3)} -> ian | AA3: {=INDEX(韻母對照資料表[閩拼], $V3)} -> ian | AB3: {=INDEX(韻母對照資料表[台羅], $V3)} -> ian
D4: 韻母 | E4: =MID(B7, LEN(E3)+1, (LEN(B7)-LEN(E3) - 1)) -> ian | F4: {=_xlfn.XLOOKUP($E$4, 韻母碼, 韻母對照資料表[方音])} -> ㄧㄢ | O4: 方音符號 | P4: {=_xlfn.XLOOKUP($E$3,聲母碼,聲母對照資料表[方音])} -> ㄗ | R4: {=_xlfn.XLOOKUP('十五音查詢 (PY)'!E4, 韻母碼, 韻母對照資料表[十五音])} -> 堅 | S4: 促聲 | T4: =_xlfn.XLOOKUP(_xlfn.CONCAT(R4,LEFT(S4)), 韻母對照資料表[十五音識別碼], 韻母對照資料表[識別號]) -> 4 | W4: =_xlfn.XLOOKUP($E$5, 聲調表[傳統八聲調], 聲調表[雅俗通調號]) -> 五 | X4: =_xlfn.XLOOKUP($E$5, 聲調表[傳統八聲調], 聲調表[方音符號調符]) -> ˊ | Y4: =$E$5 -> 5 | Z4: =$E$5 -> 5 | AA4: =$E$5 -> 5 | AB4: =$E$5 -> 5
D5: 聲調 | E5: =VALUE(RIGHT(B7)) -> 5 | F5: =_xlfn.XLOOKUP($E$5, 聲調表[傳統八聲調], 聲調表[方音符號調符]) -> ˊ | O5: 國際音標 | P5: {=_xlfn.XLOOKUP($E$3,聲母碼,聲母對照資料表[國際音標])} -> ʦ
B6: =_xlfn.XLOOKUP('十五音查詢 (PY)'!B2, 雅俗通字典[漢字], 雅俗通字典[十五音標音], "查不到") -> 堅五曾 | O6: 白話字 | P6: {=_xlfn.XLOOKUP($E$3,聲母碼,聲母對照資料表[白話字])} -> ch
B7: =_xlfn.XLOOKUP('十五音查詢 (PY)'!B2, 雅俗通字典[漢字], 雅俗通字典[標音碼], "查不到") -> zian5 | O7: 閩拼方案 | P7: {=_xlfn.XLOOKUP($E$3,聲母碼,聲母對照資料表[閩拼])} -> z
O8: 台羅拼音 | P8: {=_xlfn.XLOOKUP($E$3,聲母碼,聲母對照資料表[台羅])} -> ts
O10: 【聲母】 | R10: 【韻母】
B11: 我 | D11: 聲／韻／調 | E11: 台語音標 | F11: 方音符號 | G11: 雅俗通 | H11: 十五音 | I11: 方音符號 | J11: 國際音標 | K11: 白話字 | L11: 閩拼 | M11: 台羅拼音 | O11: 拼音類別 | P11: 聲母欄位 | R11: 雅俗通韻母 | S11: 韻母聲類 | T11: 韻母序號 | V11: 韻母識別號 | W11: 雅俗通 | X11: 方音符號 | Y11: 國際音標 | Z11: 白話字 | AA11: 閩拼方案 | AB11: 台羅拼音
D12: 聲母 | E12: =IF(OR(LEFT(B16,2)="kh",LEFT(B16,2)="ph",LEFT(B16,2)="th",LEFT(B16,2)="ng"),LEFT(B16,2),LEFT(B16,1)) -> ng | F12: {=_xlfn.XLOOKUP($E$12,聲母碼,聲母對照資料表[方音])} -> ㄫ | G12: =_xlfn.CONCAT(R12,_xlfn.XLOOKUP($E$5, 聲調表[傳統八聲調], 聲調表[雅俗通調號]),P12) -> 扛五雅 | H12: =_xlfn.CONCAT(P12, R12,_xlfn.XLOOKUP($E$5, 聲調表[傳統八聲調], 聲調表[方音符號調符])) -> 雅扛ˊ | I12: =_xlfn.CONCAT(P13,X12,_xlfn.XLOOKUP($E$5, 聲調表[傳統八聲調], 聲調表[方音符號調符])) -> ㄫㆧˊ | J12: =_xlfn.CONCAT(P14,Y12,E14) -> ŋõ2 | K12: {=_xlfn._xlws.PY(2,1,E12,E13,E14)} -> ngónn | L12: =_xlfn.CONCAT(P16,AA12,E14) -> ggnnoo2 | M12: =_xlfn.CONCAT(P17,AB12,E14) -> ngonn2 | O12: 雅俗通 | P12: {=_xlfn.XLOOKUP($E$12,聲母碼,聲母對照資料表[十五音])} -> 雅 | R12: {=_xlfn.XLOOKUP('十五音查詢 (PY)'!E13, 韻母碼, 韻母對照資料表[十五音])} -> 扛 | S12: 舒聲 | T12: =_xlfn.XLOOKUP(_xlfn.CONCAT(R12,LEFT(S12)), 韻母對照資料表[十五音識別碼], 韻母對照資料表[識別號]) -> 97 | V12: =IF(OR(E14=4,E14=8),T13,T12) -> 97 | W12: {=_xlfn.XLOOKUP('十五音查詢 (PY)'!E13, 韻母碼, 韻母對照資料表[十五音])} -> 扛 | X12: {=INDEX(韻母對照資料表[方音], $V12)} -> ㆧ | Y12: {=INDEX(韻母對照資料表[國際音標], $V12)} -> õ | Z12: {=INDEX(韻母對照資料表[白話字], $V12)} -> oⁿ | AA12: {=INDEX(韻母對照資料表[閩拼], $V12)} -> noo | AB12: {=INDEX(韻母對照資料表[台羅], $V12)} -> onn
D13: 韻母 | E13: =MID(B16, LEN(E12)+1, (LEN(B16)-LEN(E12) - 1)) -> onn | F13: {=_xlfn.XLOOKUP($E$13, 韻母碼, 韻母對照資料表[方音])} -> ㆧ | O13: 方音符號 | P13: {=_xlfn.XLOOKUP($E$12,聲母碼,聲母對照資料表[方音])} -> ㄫ | R13: {=_xlfn.XLOOKUP('十五音查詢 (PY)'!E13, 韻母碼, 韻母對照資料表[十五音])} -> 扛 | S13: 促聲 | T13: =_xlfn.XLOOKUP(_xlfn.CONCAT(R13,LEFT(S13)), 韻母對照資料表[十五音識別碼], 韻母對照資料表[識別號]) -> 98 | W13: =_xlfn.XLOOKUP($E$14, 聲調表[傳統八聲調], 聲調表[雅俗通調號]) -> 二 | X13: =_xlfn.XLOOKUP($E$14, 聲調表[傳統八聲調], 聲調表[方音符號調符]) -> ˋ | Y13: =$E$14 -> 2 | Z13: =$E$14 -> 2 | AA13: =$E$14 -> 2 | AB13: =$E$14 -> 2
D14: 聲調 | E14: =VALUE(RIGHT(B16)) -> 2 | F14: =_xlfn.XLOOKUP($E$14, 聲調表[傳統八聲調], 聲調表[方音符號調符]) -> ˋ | O14: 國際音標 | P14: {=_xlfn.XLOOKUP($E$12,聲母碼,聲母對照資料表[國際音標])} -> ŋ
B15: =_xlfn.XLOOKUP('十五音查詢 (PY)'!B11, 雅俗通字典[漢字], 雅俗通字典[十五音標音], "查不到") -> 扛二雅 | O15: 白話字 | P15: {=_xlfn.XLOOKUP($E$12,聲母碼,聲母對照資料表[白話字])} -> ng
B16: =_xlfn.XLOOKUP('十五音查詢 (PY)'!B11, 雅俗通字典[漢字], 雅俗通字典[標音碼], "查不到") -> ngonn2 | O16: 閩拼方案 | P16: {=_xlfn.XLOOKUP($E$12,聲母碼,聲母對照資料表[閩拼])} -> ggn
O17: 台羅拼音 | P17: {=_xlfn.XLOOKUP($E$12,聲母碼,聲母對照資料表[台羅])} -> ng
G19: :w

Sheet 十五音查詢
O1: 【聲母】 | R1: 【韻母】
B2: 我 | D2: 聲／韻／調 | E2: 台語音標 | F2: 方音符號 | G2: 雅俗通 | H2: 十五音 | I2: 方音符號 | J2: 國際音標 | K2: 白話字 | L2: 閩拼 | M2: 台羅拼音 | O2: 拼音類別 | P2: 聲母欄位 | R2: 雅俗通韻母 | S2: 韻母聲類 | T2: 韻母序號 | V2: 韻母識別號 | W2: 雅俗通 | X2: 方音符號 | Y2: 國際音標 | Z2: 白話字 | AA2: 閩拼方案 | AB2: 台羅拼音
